File: projects/python/data/20231030/txt/bloodtip_600_785 nm_10 s_1_2023_10_30_15_54_39_01.txt
#Sample=bloodtip
#Laser=785 nm
#Gating=600
#Exposition=10 s
#Accumulation=1
#Acquired=30.10.2023 15:54:39
2745.96	90.6667
2743.18	84
2740.41	85.6667
2737.63	91.3333
2734.85	76
2732.07	92
2729.29	83.6667
2726.5	88
2723.72	88
2720.93	92
2718.14	88
2715.34	88.3333
2712.55	86.6667
2709.75	88
2706.95	90.6667
2704.15	88.3333
2701.35	83.6667
2698.55	93.3333
2695.74	97.6667
2692.93	85
2690.12	89
2687.31	94.6667
2684.49	93.3333
2681.67	91
2678.85	93.6667
2676.03	95.3333
2673.21	92.6667
2670.38	89
2667.56	92.3333
2664.73	88.6667
2661.9	86.6667
2659.06	89.6667
2656.23	84
2653.39	83.6667
2650.55	86.6667
2647.71	93.3333
2644.86	83.6667
2642.02	91
2639.17	91.6667
2636.32	102.667
2633.47	92.6667
2630.62	84
2627.76	90.3333
2624.9	89
2622.04	86.3333
2619.18	88.6667
2616.31	91
2613.45	92
2610.58	94.3333
2607.71	90.6667
2604.84	95
2601.96	88
2599.08	106.333
2596.21	91.3333
2593.32	96
2590.44	98.3333
2587.56	93
2584.67	84.6667
2581.78	96.6667
2578.89	92.3333
2575.99	101
2573.1	100.333
2570.2	92.3333
2567.3	86.3333
2564.4	101
2561.5	95
2558.59	101
2555.68	87
2552.77	96.6667
2549.86	95
2546.94	92.3333
2544.03	101.667
2541.11	102.333
2538.19	94.3333
2535.26	104.333
2532.34	93
2529.41	104
2526.48	96.6667
2523.55	99.6667
2520.62	96
2517.68	99.6667
2514.74	104.667
2511.8	99.6667
2508.86	103.667
2505.92	106.667
2502.97	100
2500.02	101.333
2497.07	106.667
2494.12	93.3333
2491.16	100.667
2488.2	97
2485.25	102
2482.28	105.333
2479.32	101
2476.35	96.6667
2473.39	99.3333
2470.42	106
2467.44	104
2464.47	101.667
2461.49	105
2458.51	105.333
2455.53	110
2452.55	107
2449.56	121
2446.58	114.333
2443.59	108
2440.59	108.667
2437.6	110.333
2434.6	110.333
2431.61	113.333
2428.61	114.667
2425.6	118.667
2422.6	108.333
2419.59	116
2416.58	113.333
2413.57	112
2410.56	109.333
2407.54	106
2404.52	112.333
2401.5	102
2398.48	111.667
2395.45	104.333
2392.43	100
2389.4	107
2386.37	112.667
2383.33	108.333
2380.3	113.667
2377.26	107
2374.22	105.667
2371.17	105.333
2368.13	122.333
2365.08	114
2362.03	113.667
2358.98	107
2355.93	105.667
2352.87	112.667
2349.81	107.333
2346.75	114.333
2343.69	110
2340.63	109.333
2337.56	114.333
2334.49	115.333
2331.42	115.667
2328.35	113.333
2325.27	120.667
2322.19	116
2319.11	115.667
2316.03	128.333
2312.94	114
2309.85	126.333
2306.77	122
2303.67	125
2300.58	118
2297.48	113
2294.38	129
2291.28	123.333
2288.18	127.667
2285.07	119
2281.97	123.667
2278.86	126.667
2275.74	119.333
2272.63	124.667
2269.51	116.667
2266.39	129.333
2263.27	115
2260.15	121
2257.02	120
2253.89	121.667
2250.76	125
2247.63	129.667
2244.49	126.667
2241.36	135.333
2238.22	128.333
2235.08	133
2231.93	132.333
2228.78	133
2225.63	125.333
2222.48	132.667
2219.33	122.667
2216.17	130
2213.01	133.667
2209.85	129.667
2206.69	132.333
2203.53	120.333
2200.36	122
2197.19	133.333
2194.02	134.333
2190.84	134.333
2187.66	130
2184.48	123.333
2181.3	130
2178.12	139.667
2174.93	130.333
2171.74	138.333
2168.55	146.667
2165.36	140.333
2162.16	138.333
2158.97	141.333
2155.76	137
2152.56	139.667
2149.36	149
2146.15	138
2142.94	140.333
2139.73	147
2136.51	143.667
2133.29	137.333
2130.08	143.667
2126.85	137.667
2123.63	146
2120.4	135
2117.17	149.333
2113.94	143.667
2110.71	146.333
2107.47	152.333
2104.23	154.333
2100.99	137
2097.75	154.333
2094.5	142.667
2091.26	151.333
2088.01	150.667
2084.75	149.333
2081.5	159.333
2078.24	144.333
2074.98	147
2071.72	150.667
2068.45	150
2065.18	144.333
2061.92	157
2058.64	155.333
2055.37	156.667
2052.09	149.333
2048.81	152.667
2045.53	156.333
2042.25	147.667
2038.96	157.333
2035.67	159
2032.38	144
2029.08	154
2025.79	152.667
2022.49	152.333
2019.19	145.667
2015.88	161.667
2012.58	149.333
2009.27	163.333
2005.96	171.667
2002.64	166.333
1999.33	158.667
1996.01	167.667
1992.69	164.667
1989.36	169.667
1986.04	178.667
1982.71	166.333
1979.38	180.333
1976.05	170.667
1972.71	177.667
1969.37	183.667
1966.03	187.333
1962.69	194.667
1959.34	194.333
1955.99	200.667
1952.64	199
1949.29	196.333
1945.93	195.667
1942.58	203
1939.21	207
1935.85	207.667
1932.49	209.333
1929.12	206.333
1925.75	192
1922.37	215.333
1919	207.667
1915.62	202.333
1912.24	213
1908.86	205.667
1905.47	222
1902.08	209.333
1898.69	218
1895.3	215.333
1891.9	215.333
1888.5	212.333
1885.1	214.667
1881.7	222.667
1878.29	208.333
1874.88	217.333
1871.47	224.333
1868.06	214.667
1864.64	212
1861.22	217.333
1857.8	224.333
1854.38	224
1850.95	219
1847.52	212.667
1844.09	223.333
1840.66	217.667
1837.22	227.667
1833.78	218.667
1830.34	225
1826.9	214.333
1823.45	221.667
1820	232.667
1816.55	231.333
1813.09	226.333
1809.64	236
1806.18	232.667
1802.71	239.333
1799.25	251.333
1795.78	249.667
1792.31	251
1788.84	246.667
1785.36	256.333
1781.88	249.667
1778.4	254.667
1774.92	256.333
1771.43	267.667
1767.95	259.333
1764.45	250.667
1760.96	255
1757.47	269.333
1753.97	268
1750.47	270
1746.96	273.667
1743.45	268.333
1739.94	273
1736.43	260.667
1732.92	276
1729.4	288
1725.88	283
1722.36	294
1718.83	298.333
1715.3	299
1711.77	301.333
1708.24	310.667
1704.71	322.667
1701.17	311.333
1697.63	324.667
1694.08	327.333
1690.54	334
1686.99	327
1683.44	334
1679.88	342
1676.32	326.667
1672.76	339
1669.2	336.333
1665.64	337.667
1662.07	354.333
1658.5	345
1654.92	351
1651.35	361.667
1647.77	364.333
1644.19	368.667
1640.61	379.667
1637.02	384.667
1633.43	374
1629.84	397
1626.24	398.333
1622.64	396
1619.04	394.667
1615.44	384.667
1611.84	380.667
1608.23	388.333
1604.62	397.333
1601	399.333
1597.39	395.667
1593.77	393.667
1590.15	401
1586.52	393.667
1582.89	402
1579.26	410.667
1575.63	405.333
1571.99	418
1568.36	421.333
1564.72	442.333
1561.07	432
1557.42	435
1553.78	434
1550.12	436
1546.47	411.667
1542.81	425.333
1539.15	428.333
1535.49	430.333
1531.82	396.667
1528.15	413
1524.48	402.667
1520.81	401.333
1517.13	397.333
1513.45	407.667
1509.77	413.667
1506.08	399.333
1502.39	402.333
1498.7	399.667
1495.01	407
1491.31	406.667
1487.61	401.333
1483.91	394.333
1480.21	411.333
1476.5	403
1472.79	411
1469.07	417.333
1465.36	426.667
1461.64	426
1457.92	427
1454.19	430.667
1450.46	423.333
1446.73	440.667
1443	431
1439.26	435.333
1435.52	423
1431.78	422.333
1428.04	411
1424.29	424
1420.54	411.333
1416.79	413.333
1413.03	402.333
1409.27	410.333
1405.51	398.333
1401.75	399.333
1397.98	412.667
1394.21	419
1390.44	418
1386.66	424.667
1382.88	412.333
1379.1	414.333
1375.31	413
1371.53	413.333
1367.74	420
1363.94	410.333
1360.15	428.333
1356.35	428
1352.55	425
1348.74	435.333
1344.93	421
1341.12	425.667
1337.31	429.667
1333.49	434.333
1329.67	425.667
1325.85	438.333
1322.03	444.333
1318.2	433.667
1314.37	438.333
1310.53	443.333
1306.7	441.333
1302.86	456
1299.01	440
1295.17	455
1291.32	443
1287.47	456.333
1283.61	467.667
1279.76	454
1275.9	464.333
1272.03	478.667
1268.17	462
1264.3	454.333
1260.42	464.333
1256.55	460.667
1252.67	459
1248.79	451.333
1244.91	461.333
1241.02	442.667
1237.13	454.667
1233.24	454
1229.34	445.333
1225.44	428.333
1221.54	434.333
1217.63	404.333
1213.73	409.333
1209.81	409.667
1205.9	397
1201.98	384.333
1198.06	379.333
1194.14	383
1190.21	386.667
1186.29	381
1182.35	385.333
1178.42	376.667
1174.48	380.333
1170.54	395.333
1166.6	379.333
1162.65	385.667
1158.7	384
1154.74	379.667
1150.79	384.667
1146.83	385.333
1142.87	386.667
1138.9	393.667
1134.93	385.667
1130.96	385.667
1126.99	383
1123.01	381.333
1119.03	376
1115.04	373
1111.06	369
1107.07	380.667
1103.08	376.333
1099.08	376.333
1095.08	397.667
1091.08	378
1087.07	383.333
1083.06	382
1079.05	377.333
1075.04	380.667
1071.02	367.333
1067	375.667
1062.98	370.333
1058.95	362.667
1054.92	371
1050.89	354.333
1046.85	364.333
1042.81	361.667
1038.77	350.667
1034.72	360.333
1030.67	359.667
1026.62	364.667
1022.57	363
1018.51	360.667
1014.45	364
1010.38	372.667
1006.32	369
1002.24	378.333
998.171	386.333
994.094	366.333
990.013	375.333
985.93	374
981.843	378.667
977.754	389.667
973.661	374.333
969.565	375.333
965.466	388
961.364	377.333
957.258	387
953.15	382.667
949.038	381
944.923	384
940.804	395.333
936.683	388.667
932.558	391.333
928.43	377
924.299	382.667
920.165	384.333
916.028	395.667
911.887	389.667
907.743	381
903.595	374.667
899.445	382.333
895.292	379.667
891.135	367.667
886.975	385.667
882.812	363.667
878.646	374
874.475	373.667
870.303	371
866.126	377
861.947	384.667
857.764	375.667
853.578	376.333
849.389	376.667
845.196	383
841	387.333
836.801	379.667
832.599	380
828.393	391
824.184	381.333
819.972	367.667
815.757	374.667
811.538	369.667
807.316	377.333
803.091	374
798.863	371.667
794.631	374.667
790.395	365.333
786.157	381.667
781.915	370.667
777.669	372.667
773.421	392.333
769.169	391.667
764.915	392
760.656	382
756.394	376
752.129	386.667
747.861	388.333
743.588	376.333
739.314	381
735.035	380.333
730.753	375.667
726.469	363.667
722.18	366.333
717.888	369.667
713.593	368.333
709.294	366.667
704.992	360.667
700.687	360.667
696.378	371.333
692.066	363.333
687.751	356.667
683.432	360.667
679.109	356
674.784	351.667
670.455	356.667
666.122	343.667
661.787	371.667
657.448	360.667
653.104	355.667
648.759	358.333
644.409	367
640.056	376.667
635.7	378
631.34	376
626.977	363.333
622.61	379.333
618.24	370
613.867	364.333
609.49	366.333
605.11	359
600.726	358.667
596.339	364
591.948	354.667
587.554	357.333
583.156	371.333
578.755	367
574.35	394.667
569.943	385
565.531	382.667
561.116	388.667
556.698	378.667
552.275	394.667
547.85	383
543.421	369
538.988	375
534.553	379.667
530.113	365.333
525.67	366.667
521.224	384
516.774	383.667
512.321	379
507.863	369.667
503.403	380.333
498.939	373
494.472	369.667
490.001	366
485.526	368.667
481.047	372.333
476.565	386.667
472.08	376.333
467.591	388.333
463.099	384
458.604	395.667
454.103	396
449.601	402.333
445.094	413.667
440.584	424.333
436.07	412.667
431.553	421.667
427.032	429.667
422.507	447.667
417.979	445
413.448	452.333
408.912	451
404.373	455.333
399.83	458
395.285	455.333
390.734	457
386.181	467
381.624	470
377.064	478
372.5	475.667
367.932	474.667
363.36	485.333
358.785	492.667
354.207	495.667
349.624	502.333
345.038	518.667
340.448	507
335.855	500.333
331.257	500.667
326.657	494.667
322.053	493.667
317.444	522
312.833	526.667
308.217	531.333
303.599	529.667
298.976	545
294.349	545
289.719	571.667
285.085	573
280.448	584
275.807	600.333
271.161	636.667
266.513	643.333
261.861	644.667
257.205	673
252.544	679.667
247.881	694.333
243.214	706.667
238.543	736
233.869	754
229.19	783.333
224.508	815
219.822	836
215.132	859.333
210.439	869.333
205.741	927.667
201.04	925.667
196.336	983
191.627	948.333
186.915	1001.33
182.199	1013.33
177.478	1043.67
172.755	1059.33
168.028	1115
163.297	1116.67
158.561	1181
153.823	1225
149.08	1222.33
144.334	1259
139.584	1285.67
134.829	1332.33
130.071	1387
125.31	1458
120.545	1549.67
115.775	1584.67
111.001	1712
106.224	1847
101.444	2010.33
96.6594	2191
91.8705	2392.33
87.0781	2704.67
82.282	3066.33
77.4812	3635
72.6778	4635.33
67.8698	6937.33
63.0582	9091
58.2419	10620.3
53.4229	12109.7
48.5993	13723.3
43.772	15785
38.941	18800.7
34.1054	23611.3
29.2661	30877.3
24.4231	46069.3
19.5764	64524
14.7261	64524
9.87099	64524
5.01321	64524
0.14975	64524
-4.71644	64524
-9.58634	64524
-14.461	64524
-19.3393	64524
-24.2214	64524
-29.1072	64524
-33.9977	64524
-38.892	19743.7
-43.7901	13176
-48.6919	9886.33
-53.5974	7543.67
-58.5078	5775.67
-63.4218	4492.67
-68.3397	3457
-73.2613	2700
-78.1878	2141
-83.117	1748.67
-88.051	1443.67
-92.9888	1160.67
-97.9314	926.333
-102.877	746.333
-107.827	626.667
-112.781	540.667
-117.739	453.667
-122.701	375.333
-127.667	315.333
-132.637	271.667
-137.612	233.333
-142.59	200.333
-147.572	181
-152.558	160
-157.548	138.333
-162.542	136
-167.541	138.333
-172.544	121.667
-177.55	106
-182.561	115.667
-187.576	121.667
-192.595	110.333
-197.617	100.333
-202.645	95
-207.676	103
-212.711	98.6667
-217.75	94
-222.794	99
-227.842	80.6667
-232.893	76.6667
-237.949	80.6667
-243.009	84.6667
-248.073	85.3333
-253.142	74.3333
-258.214	78.6667
-263.291	80
-268.371	74
-273.456	76.3333
-278.545	79.6667
-283.639	72
-288.735	72
-293.837	68
-298.943	70.6667
-304.053	67
-309.166	68.6667
-314.285	65.3333
-319.408	62
-324.534	61.6667
-329.665	59.6667
-334.801	65.3333
-339.94	64.6667
-345.083	61.3333
-350.231	62.3333
-355.383	53.3333
-360.539	56.6667
-365.699	59.6667
-370.864	56.6667
-376.033	60
-381.206	58.3333
-386.384	53
-391.565	50.3333
-396.751	48
-401.941	51.6667
-407.136	47.6667
-412.334	52
-417.537	52.3333
-422.745	50
-427.956	48
-433.173	46.3333
-438.392	51.6667
-443.617	47
-448.846	46
-454.078	53
-459.317	54.3333
-464.558	45
-469.804	58
-475.055	50.6667
-480.309	43.3333
-485.568	55.3333
-490.832	36.6667
-496.099	49.3333
-501.372	51
-506.648	47
-511.929	46.3333
-517.215	54.6667
-522.504	48
-527.797	52.6667
-533.097	46.6667
-538.399	51.6667
-543.706	42
-549.018	46.6667
-554.334	43
-559.654	49
-564.979	48.3333
-570.308	48
-575.641	46
-580.98	51.6667
-586.322	50.3333
-591.669	47.6667
-597.02	47.6667
-602.376	44
-607.736	44.6667
-613.1	43.3333
-618.47	48.3333
-623.843	37
-629.222	42.3333
-634.603	51
-639.99	48.3333
-645.382	48.3333
-650.779	54.6667
-656.179	53
-661.583	49.3333
-666.993	50
-672.407	42.6667
-677.825	49.6667
-683.248	49.6667
-688.675	44.3333
-694.108	46.3333
-699.544	44.6667
-704.985	49.6667
-710.431	39.6667
-715.88	41.3333
-721.335	43.6667
-726.795	53.6667
-732.258	51.6667
-737.727	51
-743.2	49
-748.678	51
-754.159	42
-759.646	48.6667
-765.138	52.6667
-770.633	50.3333
-776.133	46
-781.638	39
-787.149	44
-792.663	52.3333
-798.181	45.6667
-803.705	41.6667
-809.233	48.3333
-814.766	44.6667
-820.304	43.6667
-825.846	44
-831.392	50
-836.944	46
-842.499	49.3333
-848.06	46
-853.626	53
-859.195	50.6667
-864.77	50
-870.35	49.3333
-875.934	53.6667
-881.522	41.6667
-887.116	49.6667
-892.714	44.3333
-898.317	42.6667
-903.924	55.6667
-909.537	48.3333
-915.153	38.3333
-920.776	53.3333
-926.401	42.3333
-932.033	47.3333
-937.669	47.6667
-943.31	54
-948.955	49
-954.605	40.6667
-960.26	47
-965.92	44.6667
-971.584	51.3333
-977.254	47.6667
-982.928	47.3333
-988.607	48.6667
-994.291	49.6667
-999.979	43.6667
-1005.67	47.6667
-1011.37	48.3333
-1017.07	49.3333
-1022.78	51
-1028.49	46
-1034.21	49.3333
-1039.93	46.3333
-1045.66	42.3333
-1051.39	49.3333
-1057.13	53
-1062.87	55
-1068.62	55.6667
-1074.37	55.6667
-1080.12	50.3333
-1085.89	47
-1091.65	53
-1097.42	56.6667
-1103.2	53.3333
-1108.98	53.3333
-1114.77	53.3333
-1120.56	51.3333
-1126.35	58.3333
-1132.15	51
-1137.96	54.6667
-1143.77	53.6667
-1149.58	54
-1155.4	57
-1161.23	60.6667
-1167.06	63.3333
-1172.89	73
-1178.73	83.3333
-1184.58	118
-1190.43	129.333
-1196.28	150.333
-1202.14	174.667
-1208.01	215.333
-1213.88	226.667
-1219.75	246
-1225.63	283
-1231.52	316.333
-1237.41	394.333
-1243.3	502
-1249.2	858
-1255.11	974.333
-1261.02	891
-1266.93	723.333
-1272.85	487.333
-1278.78	196.333
-1284.71	111
-1290.65	87.6667
-1296.59	84
-1302.53	74
-1308.48	72
-1314.44	64
-1320.4	63
-1326.37	60.3333
-1332.34	63.3333
-1338.31	64.6667
-1344.29	63.6667
-1350.28	60.6667
-1356.27	63.6667
-1362.27	55
-1368.27	53
-1374.28	50.3333
-1380.29	50.3333
-1386.31	46.6667
-1392.33	48.3333
-1054.26	48
-1060	50
-1065.74	52.3333
-1071.49	50.6667
-1077.25	53.6667
-1083.01	56.6667
-1088.77	44.6667
-1094.54	48.6667
-1100.31	51.6667
-1106.09	59.3333
-1111.87	53.3333
-1117.66	52.3333
-1123.45	51.3333
-1129.25	48
-1135.05	57
-1140.86	59.3333
-1146.67	49
-1152.49	46.3333
-1158.32	57
-1164.14	60.6667
-1169.98	64.6667
-1175.81	77.3333
-1181.66	108.333
-1187.5	130
-1193.35	135.333
-1199.21	156
-1205.08	197
-1210.94	219
-1216.82	244.667
-1222.69	267
-1228.58	308.333
-1234.46	340.667
-1240.35	444.667
-1246.25	714
-1252.16	1023.33
-1258.06	920.667
-1263.97	808
-1269.89	616
-1275.82	324.333
-1281.74	136
-1287.68	97.6667
-1293.62	95.6667
-1299.56	85
-1305.51	79.6667
-1311.46	71
-1317.42	65.3333
-1323.38	66
-1329.35	67
-1335.32	56.3333
-1341.3	73.6667
-1347.29	60.6667
-1353.28	62.6667
-1359.27	58.6667
-1365.27	52
-1371.27	57
-1377.28	54.3333
-1383.3	46.6667
-1389.32	42.6667
-1392.33	48.3333