File: projects/python/data/20231030/txt/bloodtip_600_785 nm_10 s_1_2023_10_30_15_53_50_01.txt
#Sample=bloodtip
#Laser=785 nm
#Gating=600
#Exposition=10 s
#Accumulation=1
#Acquired=30.10.2023 15:53:50
2745.96	76
2743.18	85.6667
2740.41	86.3333
2737.63	82
2734.85	87
2732.07	86
2729.29	90.6667
2726.5	78.6667
2723.72	84.3333
2720.93	84.6667
2718.14	81.3333
2715.34	88.3333
2712.55	82
2709.75	84.3333
2706.95	78.3333
2704.15	88
2701.35	84.3333
2698.55	80.6667
2695.74	91.3333
2692.93	82
2690.12	85.6667
2687.31	84
2684.49	74
2681.67	80.3333
2678.85	84.6667
2676.03	82.6667
2673.21	82
2670.38	79
2667.56	75.3333
2664.73	81.6667
2661.9	79.6667
2659.06	79.3333
2656.23	84
2653.39	81.3333
2650.55	81.3333
2647.71	91
2644.86	84.6667
2642.02	84
2639.17	82.6667
2636.32	84.3333
2633.47	80
2630.62	86.3333
2627.76	96.3333
2624.9	86
2622.04	81.3333
2619.18	86
2616.31	83.3333
2613.45	86.6667
2610.58	82.3333
2607.71	77
2604.84	81.3333
2601.96	85
2599.08	91.3333
2596.21	88
2593.32	72.3333
2590.44	85
2587.56	80.6667
2584.67	84.3333
2581.78	94
2578.89	84.6667
2575.99	85.6667
2573.1	86.3333
2570.2	88
2567.3	79.6667
2564.4	80.6667
2561.5	78.6667
2558.59	80.3333
2555.68	88.3333
2552.77	85.3333
2549.86	87.3333
2546.94	88.3333
2544.03	88.3333
2541.11	93.3333
2538.19	86.6667
2535.26	84.3333
2532.34	76.6667
2529.41	84.6667
2526.48	87
2523.55	86.6667
2520.62	89.3333
2517.68	91
2514.74	82
2511.8	88
2508.86	78.3333
2505.92	87.3333
2502.97	91.3333
2500.02	85
2497.07	81.3333
2494.12	96.6667
2491.16	89
2488.2	83.3333
2485.25	94.3333
2482.28	84.6667
2479.32	90.3333
2476.35	87.3333
2473.39	95.6667
2470.42	92
2467.44	86
2464.47	96.6667
2461.49	90.6667
2458.51	88.6667
2455.53	94.6667
2452.55	93.3333
2449.56	87.3333
2446.58	93.3333
2443.59	100
2440.59	100.667
2437.6	108.667
2434.6	102.667
2431.61	90
2428.61	102.667
2425.6	93.3333
2422.6	90.6667
2419.59	101.667
2416.58	93.6667
2413.57	89
2410.56	95
2407.54	91.6667
2404.52	89
2401.5	97.3333
2398.48	95
2395.45	89.3333
2392.43	97.3333
2389.4	100.667
2386.37	92
2383.33	93.3333
2380.3	93.3333
2377.26	94
2374.22	97.3333
2371.17	91.3333
2368.13	98.6667
2365.08	98.6667
2362.03	102.667
2358.98	85.3333
2355.93	102
2352.87	91
2349.81	104.333
2346.75	97
2343.69	93.3333
2340.63	82.6667
2337.56	99.3333
2334.49	104.333
2331.42	104
2328.35	95
2325.27	94.6667
2322.19	94.3333
2319.11	100
2316.03	100
2312.94	104.667
2309.85	110
2306.77	97.3333
2303.67	104
2300.58	94.6667
2297.48	96
2294.38	102.667
2291.28	96.6667
2288.18	98
2285.07	99
2281.97	100.333
2278.86	107
2275.74	103
2272.63	108.333
2269.51	103
2266.39	97.6667
2263.27	106
2260.15	107
2257.02	108.333
2253.89	102.333
2250.76	107.667
2247.63	110.667
2244.49	100.333
2241.36	96
2238.22	104.667
2235.08	96.6667
2231.93	100
2228.78	104
2225.63	106
2222.48	102
2219.33	114
2216.17	105
2213.01	112.333
2209.85	101
2206.69	104
2203.53	114
2200.36	110
2197.19	102.667
2194.02	109.667
2190.84	106
2187.66	112
2184.48	105
2181.3	116.667
2178.12	109.667
2174.93	110
2171.74	115
2168.55	120.667
2165.36	109
2162.16	112
2158.97	110.667
2155.76	122
2152.56	119.333
2149.36	106
2146.15	123
2142.94	110.333
2139.73	108.333
2136.51	111
2133.29	110.333
2130.08	110.333
2126.85	119.333
2123.63	123
2120.4	122
2117.17	117.333
2113.94	124
2110.71	118.667
2107.47	116.333
2104.23	121
2100.99	115.667
2097.75	117
2094.5	128.333
2091.26	127
2088.01	121.333
2084.75	118.333
2081.5	122
2078.24	128
2074.98	114.333
2071.72	127
2068.45	122.333
2065.18	121.333
2061.92	114.667
2058.64	129.333
2055.37	119
2052.09	130
2048.81	127
2045.53	122
2042.25	118.333
2038.96	124
2035.67	127
2032.38	129
2029.08	131
2025.79	125.333
2022.49	119.333
2019.19	124.667
2015.88	131
2012.58	127.333
2009.27	129.667
2005.96	126
2002.64	135.333
1999.33	130.333
1996.01	135.667
1992.69	137
1989.36	136.333
1986.04	142.333
1982.71	141
1979.38	140
1976.05	143
1972.71	144.333
1969.37	153
1966.03	153.667
1962.69	163
1959.34	165.333
1955.99	159
1952.64	154.333
1949.29	153.667
1945.93	167.667
1942.58	163.667
1939.21	164
1935.85	170.333
1932.49	170.333
1929.12	176.667
1925.75	173.333
1922.37	167.667
1919	171
1915.62	166
1912.24	174.667
1908.86	178.667
1905.47	179.667
1902.08	180.667
1898.69	172
1895.3	180.333
1891.9	174.667
1888.5	179.333
1885.1	184.333
1881.7	185.333
1878.29	176.667
1874.88	177
1871.47	178
1868.06	174.667
1864.64	175
1861.22	180
1857.8	177.333
1854.38	186
1850.95	185.667
1847.52	176
1844.09	179
1840.66	188.667
1837.22	191.667
1833.78	181
1830.34	173.667
1826.9	183.333
1823.45	182
1820	186
1816.55	196.667
1813.09	182.667
1809.64	185.333
1806.18	185.333
1802.71	198.667
1799.25	192.667
1795.78	198
1792.31	208.667
1788.84	206.667
1785.36	207.333
1781.88	222.667
1778.4	212.333
1774.92	207
1771.43	215.333
1767.95	208.333
1764.45	235
1760.96	229
1757.47	221.333
1753.97	230.333
1750.47	231
1746.96	225.667
1743.45	237
1739.94	228
1736.43	231.333
1732.92	231.333
1729.4	228.667
1725.88	230
1722.36	246
1718.83	244.667
1715.3	252.667
1711.77	260.667
1708.24	266.667
1704.71	267.333
1701.17	272.333
1697.63	279
1694.08	270.667
1690.54	289.333
1686.99	280.667
1683.44	283
1679.88	289.667
1676.32	290
1672.76	278
1669.2	276.333
1665.64	290.667
1662.07	295
1658.5	302.333
1654.92	281.667
1651.35	300.667
1647.77	308
1644.19	318.667
1640.61	313.333
1637.02	318
1633.43	328
1629.84	331.333
1626.24	328.667
1622.64	323.667
1619.04	322.333
1615.44	325.333
1611.84	329.667
1608.23	315.667
1604.62	322.333
1601	333.667
1597.39	327.333
1593.77	340.333
1590.15	332
1586.52	337.333
1582.89	343.667
1579.26	335.333
1575.63	343
1571.99	357.667
1568.36	347.667
1564.72	361.667
1561.07	370
1557.42	357.333
1553.78	370.667
1550.12	356.667
1546.47	357.333
1542.81	350.333
1539.15	359
1535.49	356.667
1531.82	363.333
1528.15	344
1524.48	340.333
1520.81	338.667
1517.13	348.333
1513.45	350
1509.77	337.667
1506.08	343.333
1502.39	343.333
1498.7	344.667
1495.01	343
1491.31	347.333
1487.61	336.333
1483.91	344
1480.21	356.333
1476.5	339
1472.79	341
1469.07	350.667
1465.36	364
1461.64	355.667
1457.92	358.333
1454.19	367.333
1450.46	372.333
1446.73	361.667
1443	361
1439.26	359.333
1435.52	364.333
1431.78	351.667
1428.04	355
1424.29	349
1420.54	350.667
1416.79	346.333
1413.03	358.333
1409.27	344.667
1405.51	345
1401.75	357
1397.98	360.333
1394.21	348
1390.44	343
1386.66	346.333
1382.88	361
1379.1	344.667
1375.31	347
1371.53	351.333
1367.74	346
1363.94	366
1360.15	355
1356.35	343.667
1352.55	357.333
1348.74	354.667
1344.93	361
1341.12	370
1337.31	351
1333.49	368.667
1329.67	358.667
1325.85	365.333
1322.03	376
1318.2	375.333
1314.37	383
1310.53	385
1306.7	372.667
1302.86	377.333
1299.01	387
1295.17	380.333
1291.32	376.667
1287.47	382.333
1283.61	388
1279.76	397.667
1275.9	390.333
1272.03	396.333
1268.17	387.333
1264.3	401.667
1260.42	396
1256.55	391.333
1252.67	391
1248.79	377.667
1244.91	394
1241.02	384.333
1237.13	386
1233.24	386
1229.34	381.667
1225.44	368.333
1221.54	357.333
1217.63	350.333
1213.73	337.333
1209.81	335.667
1205.9	336.667
1201.98	322.667
1198.06	323.667
1194.14	318.333
1190.21	316
1186.29	312.333
1182.35	319
1178.42	315.333
1174.48	319
1170.54	304
1166.6	324.667
1162.65	309.667
1158.7	309.333
1154.74	316
1150.79	311.667
1146.83	318
1142.87	308
1138.9	307
1134.93	318
1130.96	320.667
1126.99	337
1123.01	313.667
1119.03	319.667
1115.04	314.667
1111.06	306
1107.07	317
1103.08	310
1099.08	308
1095.08	306.667
1091.08	310.667
1087.07	306.667
1083.06	299
1079.05	303.333
1075.04	308
1071.02	301.333
1067	305.333
1062.98	291.333
1058.95	306
1054.92	294.667
1050.89	286.667
1046.85	280
1042.81	290
1038.77	283.333
1034.72	287.667
1030.67	286.333
1026.62	287.667
1022.57	289.667
1018.51	297.333
1014.45	282
1010.38	296
1006.32	283
1002.24	296
998.171	303.333
994.094	295.667
990.013	305.333
985.93	298.667
981.843	305.667
977.754	296
973.661	294
969.565	298
965.466	303.333
961.364	296
957.258	291.333
953.15	297.333
949.038	294
944.923	310.333
940.804	301
936.683	296.333
932.558	294.667
928.43	295.667
924.299	303.667
920.165	307.667
916.028	292.333
911.887	306.667
907.743	291.333
903.595	288.667
899.445	303.333
895.292	293.333
891.135	294.667
886.975	288.667
882.812	290.667
878.646	287
874.475	295.333
870.303	281.333
866.126	285.333
861.947	290.667
857.764	286.667
853.578	297.667
849.389	291
845.196	292.333
841	302.333
836.801	295.333
832.599	298.667
828.393	297
824.184	274.667
819.972	297
815.757	284.333
811.538	282.333
807.316	278
803.091	286
798.863	286
794.631	280.667
790.395	280
786.157	280.333
781.915	288
777.669	292
773.421	295.667
769.169	290
764.915	287.333
760.656	288.333
756.394	283.667
752.129	291
747.861	296.667
743.588	289
739.314	297
735.035	290.667
730.753	289.333
726.469	290.333
722.18	272.667
717.888	275
713.593	285.667
709.294	272.333
704.992	278.333
700.687	282.667
696.378	282
692.066	274.333
687.751	272
683.432	278.667
679.109	262
674.784	276.667
670.455	275.333
666.122	277.333
661.787	279.667
657.448	274.333
653.104	272.333
648.759	265.333
644.409	284.667
640.056	278
635.7	289
631.34	286
626.977	290
622.61	271
618.24	272.667
613.867	268.333
609.49	265.333
605.11	260.333
600.726	267
596.339	275.333
591.948	263.333
587.554	271.333
583.156	289
578.755	292.667
574.35	290
569.943	294.667
565.531	288.333
561.116	296.333
556.698	277.667
552.275	277.667
547.85	279
543.421	285
538.988	279.667
534.553	272.667
530.113	286.667
525.67	276.667
521.224	274
516.774	281
512.321	280.333
507.863	277
503.403	282
498.939	280.667
494.472	273.667
490.001	291
485.526	279
481.047	282
476.565	271.333
472.08	287.667
467.591	277
463.099	298.333
458.604	287
454.103	300.667
449.601	297.333
445.094	310
440.584	303.333
436.07	319.667
431.553	335.667
427.032	343
422.507	336.667
417.979	345
413.448	337.667
408.912	340.333
404.373	354.333
399.83	337
395.285	343.333
390.734	354.333
386.181	354.333
381.624	355
377.064	369
372.5	356.667
367.932	373.667
363.36	369
358.785	371.333
354.207	387
349.624	383.667
345.038	383
340.448	391.333
335.855	381
331.257	399
326.657	400.333
322.053	401
317.444	396
312.833	411.333
308.217	415
303.599	415.333
298.976	421.333
294.349	435
289.719	456
285.085	462.667
280.448	468.333
275.807	472
271.161	481.667
266.513	503.333
261.861	510.667
257.205	521.333
252.544	533.333
247.881	562
243.214	579
238.543	593.667
233.869	608.667
229.19	638.667
224.508	663.667
219.822	668.667
215.132	692.333
210.439	703.667
205.741	766.667
201.04	758
196.336	780
191.627	790.667
186.915	840
182.199	842
177.478	848
172.755	885.333
168.028	923
163.297	953.667
158.561	948
153.823	1009.67
149.08	1024.67
144.334	1046.67
139.584	1103.67
134.829	1113.67
130.071	1129.33
125.31	1218.33
120.545	1288.67
115.775	1356
111.001	1408.33
106.224	1544
101.444	1672.67
96.6594	1807.67
91.8705	2019.67
87.0781	2292
82.282	2597.33
77.4812	3187.33
72.6778	4104
67.8698	6359.33
63.0582	8521.67
58.2419	10063
53.4229	11472.7
48.5993	12934.7
43.772	14884.3
38.941	17760.7
34.1054	22262.7
29.2661	29043
24.4231	43244
19.5764	64524
14.7261	64524
9.87099	64524
5.01321	64524
0.14975	64524
-4.71644	64524
-9.58634	64524
-14.461	64524
-19.3393	64524
-24.2214	64524
-29.1072	64524
-33.9977	64524
-38.892	18376
-43.7901	12377
-48.6919	9205.67
-53.5974	7025.33
-58.5078	5377.67
-63.4218	4119.33
-68.3397	3224
-73.2613	2533.33
-78.1878	2016
-83.117	1645.33
-88.051	1340.67
-92.9888	1114
-97.9314	916
-102.877	720.667
-107.827	608.333
-112.781	510
-117.739	429.333
-122.701	345.667
-127.667	302.667
-132.637	253.667
-137.612	227.333
-142.59	190
-147.572	172.333
-152.558	153.333
-157.548	137
-162.542	129.333
-167.541	124.667
-172.544	113.667
-177.55	110.667
-182.561	96.3333
-187.576	99.3333
-192.595	104
-197.617	102
-202.645	95.3333
-207.676	94
-212.711	90.6667
-217.75	87
-222.794	95.3333
-227.842	86
-232.893	84
-237.949	80.6667
-243.009	80.3333
-248.073	78.3333
-253.142	88.6667
-258.214	72
-263.291	70
-268.371	83
-273.456	69.6667
-278.545	64.6667
-283.639	72.6667
-288.735	73.3333
-293.837	66.3333
-298.943	67
-304.053	74.6667
-309.166	59.6667
-314.285	54
-319.408	66.6667
-324.534	66
-329.665	61.6667
-334.801	59.3333
-339.94	62
-345.083	57
-350.231	60.6667
-355.383	62.3333
-360.539	57
-365.699	50.6667
-370.864	56.3333
-376.033	53.6667
-381.206	52.3333
-386.384	61.6667
-391.565	60
-396.751	57
-401.941	55
-407.136	49.6667
-412.334	55.6667
-417.537	53.3333
-422.745	60
-427.956	47.6667
-433.173	56.6667
-438.392	56.3333
-443.617	54.3333
-448.846	46.6667
-454.078	49.3333
-459.317	52
-464.558	46.6667
-469.804	45.6667
-475.055	51.3333
-480.309	54
-485.568	51.3333
-490.832	44
-496.099	47
-501.372	49.3333
-506.648	45.6667
-511.929	46.6667
-517.215	41.3333
-522.504	48.3333
-527.797	42
-533.097	44.3333
-538.399	45
-543.706	48
-549.018	42
-554.334	44.3333
-559.654	45.3333
-564.979	48.6667
-570.308	43
-575.641	46.3333
-580.98	48
-586.322	41.6667
-591.669	46
-597.02	39.3333
-602.376	47.6667
-607.736	49.3333
-613.1	59
-618.47	54
-623.843	42.3333
-629.222	41
-634.603	48
-639.99	49.3333
-645.382	56.6667
-650.779	41.6667
-656.179	45.3333
-661.583	42.6667
-666.993	42.3333
-672.407	49.3333
-677.825	57.3333
-683.248	49.3333
-688.675	49.3333
-694.108	49
-699.544	50
-704.985	49.3333
-710.431	52.3333
-715.88	52
-721.335	48.6667
-726.795	42
-732.258	48.3333
-737.727	49.6667
-743.2	49
-748.678	40
-754.159	47.3333
-759.646	50.3333
-765.138	39
-770.633	43
-776.133	46.6667
-781.638	44.6667
-787.149	52
-792.663	51.3333
-798.181	48.6667
-803.705	42.3333
-809.233	42.6667
-814.766	47
-820.304	38
-825.846	50.6667
-831.392	39.3333
-836.944	46.6667
-842.499	50
-848.06	51
-853.626	36.3333
-859.195	46.3333
-864.77	43
-870.35	41.6667
-875.934	43.6667
-881.522	45.3333
-887.116	41
-892.714	42.3333
-898.317	49.6667
-903.924	43.6667
-909.537	49
-915.153	48
-920.776	43.3333
-926.401	41
-932.033	50.6667
-937.669	35
-943.31	49.6667
-948.955	89.3333
-954.605	47.6667
-960.26	48.6667
-965.92	46
-971.584	43.6667
-977.254	44.3333
-982.928	47
-988.607	51.3333
-994.291	49.3333
-999.979	49.3333
-1005.67	49.6667
-1011.37	42
-1017.07	52
-1022.78	49
-1028.49	46.6667
-1034.21	44
-1039.93	45.6667
-1045.66	52.3333
-1051.39	50
-1057.13	46
-1062.87	51.6667
-1068.62	43.3333
-1074.37	48.6667
-1080.12	54.6667
-1085.89	54.3333
-1091.65	58.6667
-1097.42	61.3333
-1103.2	43.6667
-1108.98	47.6667
-1114.77	45
-1120.56	45.6667
-1126.35	56.3333
-1132.15	49
-1137.96	54
-1143.77	50.6667
-1149.58	51.3333
-1155.4	55.3333
-1161.23	56
-1167.06	58
-1172.89	73
-1178.73	85.3333
-1184.58	113
-1190.43	131.333
-1196.28	146
-1202.14	160
-1208.01	183.667
-1213.88	211.667
-1219.75	240.667
-1225.63	268
-1231.52	284
-1237.41	346.333
-1243.3	442.333
-1249.2	796.667
-1255.11	826
-1261.02	846
-1266.93	668.333
-1272.85	439
-1278.78	195.667
-1284.71	101.333
-1290.65	84
-1296.59	84
-1302.53	76.3333
-1308.48	66
-1314.44	63.6667
-1320.4	66.3333
-1326.37	60
-1332.34	62.3333
-1338.31	69
-1344.29	59
-1350.28	56.6667
-1356.27	62.3333
-1362.27	60.3333
-1368.27	55
-1374.28	51
-1380.29	40.6667
-1386.31	38.3333
-1392.33	47.6667
-1057.13	46
-1062.87	51.6667
-1068.62	43.3333
-1074.37	48.6667
-1080.12	54.6667
-1085.89	54.3333
-1091.65	58.6667
-1097.42	61.3333
-1103.2	43.6667
-1108.98	47.6667
-1114.77	45
-1120.56	45.6667
-1126.35	56.3333
-1132.15	49
-1137.96	54
-1143.77	50.6667
-1149.58	51.3333
-1155.4	55.3333
-1161.23	56
-1167.06	58
-1172.89	73
-1178.73	85.3333
-1184.58	113
-1190.43	131.333
-1196.28	146
-1202.14	160
-1208.01	183.667
-1213.88	211.667
-1219.75	240.667
-1225.63	268
-1231.52	284
-1237.41	346.333
-1243.3	442.333
-1249.2	796.667
-1255.11	826
-1261.02	846
-1266.93	668.333
-1272.85	439
-1278.78	195.667
-1284.71	101.333
-1290.65	84
-1296.59	84
-1302.53	76.3333
-1308.48	66
-1314.44	63.6667
-1320.4	66.3333
-1326.37	60
-1332.34	62.3333
-1338.31	69
-1344.29	59
-1350.28	56.6667
-1356.27	62.3333
-1362.27	60.3333
-1368.27	55
-1374.28	51
-1380.29	40.6667
-1386.31	38.3333
-1392.33	47.6667