File: projects/python/data/20231030/txt/bloodtip_600_785 nm_10 s_1_2023_10_30_15_53_15_01.txt
#Sample=bloodtip
#Laser=785 nm
#Gating=600
#Exposition=10 s
#Accumulation=1
#Acquired=30.10.2023 15:53:15
2745.96	78.3333
2743.18	74.6667
2740.41	75.6667
2737.63	87.3333
2734.85	82.6667
2732.07	85
2729.29	73.6667
2726.5	69.3333
2723.72	80
2720.93	80
2718.14	83.6667
2715.34	78.3333
2712.55	77.3333
2709.75	81.6667
2706.95	74.3333
2704.15	86.6667
2701.35	67
2698.55	83.3333
2695.74	79.3333
2692.93	83.6667
2690.12	80
2687.31	82
2684.49	75.6667
2681.67	79.3333
2678.85	79.3333
2676.03	84.3333
2673.21	82.6667
2670.38	85.3333
2667.56	81.6667
2664.73	85.3333
2661.9	73
2659.06	81
2656.23	75.6667
2653.39	73
2650.55	78
2647.71	78.6667
2644.86	87.3333
2642.02	86.6667
2639.17	81.3333
2636.32	84.3333
2633.47	82
2630.62	82
2627.76	78
2624.9	81.3333
2622.04	80
2619.18	82
2616.31	80
2613.45	87.3333
2610.58	84.6667
2607.71	85.3333
2604.84	74.6667
2601.96	80
2599.08	78.3333
2596.21	80.6667
2593.32	81.6667
2590.44	87.3333
2587.56	82.3333
2584.67	89.6667
2581.78	73
2578.89	81.3333
2575.99	80
2573.1	79
2570.2	84
2567.3	75.3333
2564.4	82.3333
2561.5	90
2558.59	84.6667
2555.68	88
2552.77	85.3333
2549.86	87.3333
2546.94	85.3333
2544.03	82
2541.11	81.3333
2538.19	78
2535.26	86.3333
2532.34	86
2529.41	79
2526.48	87
2523.55	83
2520.62	87.3333
2517.68	81
2514.74	89
2511.8	89
2508.86	85.3333
2505.92	72
2502.97	83.3333
2500.02	89.3333
2497.07	91.3333
2494.12	85.3333
2491.16	79.6667
2488.2	83.3333
2485.25	86.6667
2482.28	82.6667
2479.32	94
2476.35	88
2473.39	79.3333
2470.42	90.3333
2467.44	88
2464.47	90.3333
2461.49	81.3333
2458.51	93.6667
2455.53	99
2452.55	89.3333
2449.56	95.3333
2446.58	97.6667
2443.59	89.6667
2440.59	98.3333
2437.6	101
2434.6	100
2431.61	98
2428.61	94
2425.6	94.3333
2422.6	88
2419.59	97.3333
2416.58	95.6667
2413.57	97.3333
2410.56	95.3333
2407.54	94
2404.52	90.3333
2401.5	88.6667
2398.48	91.6667
2395.45	89.6667
2392.43	89
2389.4	100
2386.37	89.3333
2383.33	84.3333
2380.3	90.6667
2377.26	97.6667
2374.22	91
2371.17	88.6667
2368.13	96.3333
2365.08	97.6667
2362.03	94.3333
2358.98	101
2355.93	94
2352.87	101.333
2349.81	97.3333
2346.75	94.6667
2343.69	93.3333
2340.63	96.3333
2337.56	92.3333
2334.49	93.3333
2331.42	103.667
2328.35	95.3333
2325.27	95.6667
2322.19	89
2319.11	87
2316.03	86
2312.94	96.6667
2309.85	100.333
2306.77	91.3333
2303.67	103.333
2300.58	101.333
2297.48	102.667
2294.38	90.3333
2291.28	96
2288.18	94.3333
2285.07	105
2281.97	97
2278.86	92.6667
2275.74	99.3333
2272.63	106.333
2269.51	96.3333
2266.39	96
2263.27	97.3333
2260.15	98.3333
2257.02	103.667
2253.89	102.667
2250.76	99.6667
2247.63	105.667
2244.49	101.667
2241.36	104
2238.22	101.333
2235.08	100
2231.93	92.3333
2228.78	100.667
2225.63	103
2222.48	111.333
2219.33	94.3333
2216.17	108
2213.01	106.333
2209.85	111
2206.69	104.333
2203.53	100
2200.36	110.333
2197.19	98.6667
2194.02	105.667
2190.84	114
2187.66	109.667
2184.48	99.3333
2181.3	112.667
2178.12	110
2174.93	107
2171.74	102.333
2168.55	106.333
2165.36	104.333
2162.16	113
2158.97	106
2155.76	120.333
2152.56	112.333
2149.36	109
2146.15	109.667
2142.94	110.333
2139.73	110
2136.51	111.667
2133.29	111.667
2130.08	118.667
2126.85	114.333
2123.63	106.333
2120.4	116.333
2117.17	107
2113.94	118.333
2110.71	112
2107.47	117
2104.23	109
2100.99	121.667
2097.75	120.333
2094.5	121.333
2091.26	117.333
2088.01	115
2084.75	116
2081.5	112
2078.24	125.667
2074.98	110.667
2071.72	110.667
2068.45	117.667
2065.18	126
2061.92	125.333
2058.64	115.333
2055.37	123.333
2052.09	118.667
2048.81	117
2045.53	116.667
2042.25	124
2038.96	117
2035.67	120.667
2032.38	129.333
2029.08	127
2025.79	120
2022.49	127.667
2019.19	123.667
2015.88	130.667
2012.58	124
2009.27	134
2005.96	132
2002.64	138.667
1999.33	132.667
1996.01	130.667
1992.69	132.667
1989.36	138
1986.04	135.667
1982.71	135.333
1979.38	140.667
1976.05	137
1972.71	148.667
1969.37	149.333
1966.03	158
1962.69	148.667
1959.34	150
1955.99	154
1952.64	154.667
1949.29	158.333
1945.93	159.333
1942.58	156
1939.21	161
1935.85	172.333
1932.49	164
1929.12	169.333
1925.75	170.667
1922.37	168
1919	167.333
1915.62	178.667
1912.24	169
1908.86	174
1905.47	174.667
1902.08	165.333
1898.69	179.333
1895.3	170
1891.9	183
1888.5	183.333
1885.1	175.333
1881.7	182
1878.29	169.333
1874.88	183
1871.47	173.333
1868.06	180.667
1864.64	181.333
1861.22	177
1857.8	178.667
1854.38	182.333
1850.95	169.667
1847.52	180
1844.09	184.667
1840.66	174.667
1837.22	187.667
1833.78	188.667
1830.34	185.333
1826.9	181
1823.45	180
1820	184.667
1816.55	189.667
1813.09	191.333
1809.64	198.667
1806.18	195.667
1802.71	205.333
1799.25	191.667
1795.78	202
1792.31	208.667
1788.84	213
1785.36	203.667
1781.88	212
1778.4	210.333
1774.92	215.333
1771.43	218.667
1767.95	219.667
1764.45	213.667
1760.96	213
1757.47	215.333
1753.97	225.333
1750.47	226.667
1746.96	238
1743.45	215.333
1739.94	234
1736.43	215.333
1732.92	230
1729.4	238.667
1725.88	241.333
1722.36	247.667
1718.83	245.667
1715.3	242
1711.77	261.333
1708.24	265
1704.71	264.667
1701.17	265.333
1697.63	263
1694.08	279.333
1690.54	277.333
1686.99	271.667
1683.44	273
1679.88	269
1676.32	275
1672.76	289
1669.2	280.667
1665.64	274
1662.07	276.667
1658.5	283.333
1654.92	292
1651.35	287.333
1647.77	286.667
1644.19	285.667
1640.61	296.333
1637.02	298.667
1633.43	318.333
1629.84	310
1626.24	307.333
1622.64	309.333
1619.04	292.667
1615.44	307.333
1611.84	312.667
1608.23	311.333
1604.62	314.333
1601	311
1597.39	312.667
1593.77	319.333
1590.15	329.667
1586.52	315.667
1582.89	315
1579.26	327.333
1575.63	338
1571.99	340.667
1568.36	344.667
1564.72	347
1561.07	337
1557.42	350
1553.78	352
1550.12	341.667
1546.47	344.667
1542.81	347.667
1539.15	349.333
1535.49	332.667
1531.82	346
1528.15	342
1524.48	343.667
1520.81	326.333
1517.13	350.667
1513.45	333.667
1509.77	337.333
1506.08	344.333
1502.39	346.333
1498.7	337
1495.01	343
1491.31	335.667
1487.61	345.333
1483.91	350.333
1480.21	345.667
1476.5	345.333
1472.79	343.667
1469.07	348.667
1465.36	346.667
1461.64	352.333
1457.92	355
1454.19	364
1450.46	350.333
1446.73	366
1443	342.333
1439.26	353.667
1435.52	351.333
1431.78	348.667
1428.04	361
1424.29	340.333
1420.54	342
1416.79	339
1413.03	344
1409.27	343.333
1405.51	355.667
1401.75	344.667
1397.98	347.333
1394.21	350.667
1390.44	349.333
1386.66	345
1382.88	341.333
1379.1	354.667
1375.31	347.667
1371.53	352
1367.74	342
1363.94	350.333
1360.15	349.667
1356.35	338.667
1352.55	348
1348.74	349
1344.93	350
1341.12	357
1337.31	352.667
1333.49	362.667
1329.67	357.667
1325.85	355.333
1322.03	359.333
1318.2	366
1314.37	368
1310.53	362.333
1306.7	362
1302.86	380.333
1299.01	377.333
1295.17	382
1291.32	385.333
1287.47	377.333
1283.61	378
1279.76	398.667
1275.9	377.667
1272.03	388.667
1268.17	395.667
1264.3	384
1260.42	388.667
1256.55	383.667
1252.67	378.333
1248.79	382
1244.91	384.667
1241.02	366.667
1237.13	389.333
1233.24	369
1229.34	361.333
1225.44	367
1221.54	344
1217.63	343
1213.73	335.667
1209.81	338
1205.9	317.667
1201.98	317.333
1198.06	303.333
1194.14	316
1190.21	308.333
1186.29	303.333
1182.35	306.333
1178.42	313
1174.48	302.667
1170.54	313.333
1166.6	303
1162.65	320.667
1158.7	311
1154.74	302.333
1150.79	316
1146.83	304.333
1142.87	304
1138.9	310.333
1134.93	306.333
1130.96	291.667
1126.99	300.667
1123.01	306.667
1119.03	308
1115.04	298.333
1111.06	290
1107.07	309.667
1103.08	319
1099.08	314
1095.08	294.333
1091.08	301.333
1087.07	299.333
1083.06	306.333
1079.05	298
1075.04	295.333
1071.02	304.333
1067	293.333
1062.98	297.333
1058.95	292
1054.92	293.667
1050.89	280.333
1046.85	278.667
1042.81	289.667
1038.77	274.333
1034.72	293.667
1030.67	276.333
1026.62	271
1022.57	303.333
1018.51	285.667
1014.45	283.333
1010.38	296.667
1006.32	291.333
1002.24	293
998.171	280.667
994.094	304
990.013	287.333
985.93	294
981.843	288.667
977.754	286
973.661	284
969.565	287
965.466	301.667
961.364	286.333
957.258	291.333
953.15	282
949.038	291.333
944.923	295.667
940.804	288.667
936.683	292
932.558	293
928.43	298
924.299	287.667
920.165	280
916.028	291.667
911.887	290.333
907.743	282.667
903.595	279.333
899.445	285
895.292	288
891.135	287.333
886.975	296
882.812	284.667
878.646	283.667
874.475	297
870.303	283.667
866.126	286.333
861.947	289
857.764	281.667
853.578	284.333
849.389	288.667
845.196	298
841	292.667
836.801	280
832.599	301
828.393	288.333
824.184	293
819.972	282.667
815.757	284
811.538	278.333
807.316	271.333
803.091	278.667
798.863	277.333
794.631	270.333
790.395	283.333
786.157	283
781.915	286.333
777.669	273.667
773.421	278.667
769.169	291.333
764.915	283.333
760.656	282
756.394	269
752.129	291
747.861	286.333
743.588	278
739.314	288.333
735.035	271.667
730.753	283.667
726.469	283
722.18	274.333
717.888	278.667
713.593	277.333
709.294	273.333
704.992	266.333
700.687	262.333
696.378	260.667
692.066	277.667
687.751	259.333
683.432	259.667
679.109	259.667
674.784	273
670.455	269
666.122	260.667
661.787	271.667
657.448	265.667
653.104	271.667
648.759	267.667
644.409	269.333
640.056	281.333
635.7	271.667
631.34	285.333
626.977	281.333
622.61	274.333
618.24	271
613.867	259
609.49	263.667
605.11	260.333
600.726	252.667
596.339	253.333
591.948	246.333
587.554	272.333
583.156	278.667
578.755	273.667
574.35	278.667
569.943	273.667
565.531	280
561.116	282.667
556.698	273.667
552.275	270.667
547.85	271.667
543.421	271
538.988	275.333
534.553	271.333
530.113	267.333
525.67	266
521.224	271
516.774	263.667
512.321	269.333
507.863	277.333
503.403	279
498.939	273.667
494.472	274.667
490.001	271.667
485.526	276
481.047	274
476.565	263
472.08	269
467.591	273.667
463.099	288.667
458.604	282
454.103	288
449.601	289.667
445.094	304.667
440.584	303.333
436.07	311.667
431.553	321
427.032	318.667
422.507	331
417.979	327
413.448	332.667
408.912	335.667
404.373	338.667
399.83	335
395.285	335.333
390.734	350.667
386.181	355
381.624	357.333
377.064	355.333
372.5	357
367.932	366.333
363.36	369.667
358.785	365
354.207	371
349.624	375.667
345.038	384.667
340.448	378
335.855	377.333
331.257	381.667
326.657	375.333
322.053	387.333
317.444	394
312.833	387.333
308.217	400.667
303.599	412.333
298.976	411
294.349	417
289.719	429.333
285.085	440
280.448	456
275.807	463.333
271.161	482
266.513	491
261.861	490.333
257.205	508.667
252.544	534
247.881	552.667
243.214	562.333
238.543	579.667
233.869	598.333
229.19	624.333
224.508	629.333
219.822	654
215.132	683.667
210.439	708
205.741	730.667
201.04	754.333
196.336	756.333
191.627	788.333
186.915	805.667
182.199	811
177.478	829.667
172.755	875.333
168.028	890
163.297	924.333
158.561	949
153.823	972
149.08	993.667
144.334	979
139.584	1036.33
134.829	1049.67
130.071	1062.33
125.31	1143.33
120.545	1199.67
115.775	1273.67
111.001	1336
106.224	1424
101.444	1550
96.6594	1706.67
91.8705	1897.67
87.0781	2136.33
82.282	2463.33
77.4812	3038
72.6778	4027.33
67.8698	6282.33
63.0582	8505
58.2419	10180
53.4229	11711.7
48.5993	13231.3
43.772	15273.3
38.941	18156.7
34.1054	22761.7
29.2661	29597.3
24.4231	44140.7
19.5764	64524
14.7261	64524
9.87099	64524
5.01321	64524
0.14975	64524
-4.71644	64524
-9.58634	64524
-14.461	64524
-19.3393	64524
-24.2214	64524
-29.1072	64524
-33.9977	64524
-38.892	19027
-43.7901	12797
-48.6919	9489.33
-53.5974	7282.67
-58.5078	5589
-63.4218	4303.33
-68.3397	3347.67
-73.2613	2647.67
-78.1878	2070.67
-83.117	1679.33
-88.051	1366
-92.9888	1137.33
-97.9314	917.333
-102.877	733.667
-107.827	607
-112.781	507.667
-117.739	426
-122.701	373.333
-127.667	302.667
-132.637	250
-137.612	234
-142.59	195.333
-147.572	163.667
-152.558	156
-157.548	141
-162.542	133.667
-167.541	122.667
-172.544	116
-177.55	107
-182.561	106.667
-187.576	106
-192.595	106.333
-197.617	92.3333
-202.645	104
-207.676	96.6667
-212.711	91
-217.75	88.3333
-222.794	91.6667
-227.842	83.6667
-232.893	73.6667
-237.949	84.3333
-243.009	77.3333
-248.073	80
-253.142	78
-258.214	75
-263.291	78
-268.371	70.3333
-273.456	74
-278.545	73.3333
-283.639	68.3333
-288.735	66
-293.837	64
-298.943	57.3333
-304.053	68.6667
-309.166	63.6667
-314.285	62
-319.408	67.6667
-324.534	67.3333
-329.665	60.3333
-334.801	59
-339.94	62.6667
-345.083	58
-350.231	60
-355.383	65
-360.539	58.3333
-365.699	50.3333
-370.864	52.3333
-376.033	48.6667
-381.206	53.6667
-386.384	59.6667
-391.565	52.6667
-396.751	52
-401.941	50
-407.136	52.6667
-412.334	48.3333
-417.537	52
-422.745	52.3333
-427.956	51.3333
-433.173	53.6667
-438.392	49
-443.617	54.3333
-448.846	50
-454.078	45.3333
-459.317	47.6667
-464.558	39
-469.804	46.3333
-475.055	56.3333
-480.309	53.6667
-485.568	54
-490.832	43.6667
-496.099	51.3333
-501.372	44.6667
-506.648	48.6667
-511.929	53
-517.215	40.3333
-522.504	48.6667
-527.797	49.6667
-533.097	53.3333
-538.399	51
-543.706	41
-549.018	48.3333
-554.334	47.3333
-559.654	41.6667
-564.979	46.3333
-570.308	35
-575.641	46.6667
-580.98	49
-586.322	44.3333
-591.669	44.6667
-597.02	47.3333
-602.376	43
-607.736	50
-613.1	46.3333
-618.47	48
-623.843	53.6667
-629.222	41.6667
-634.603	43.6667
-639.99	44.6667
-645.382	46.6667
-650.779	47.6667
-656.179	38.3333
-661.583	56
-666.993	48.3333
-672.407	42.3333
-677.825	46
-683.248	43.3333
-688.675	42.3333
-694.108	50.3333
-699.544	48
-704.985	45.3333
-710.431	44.6667
-715.88	43
-721.335	46
-726.795	47.3333
-732.258	42.3333
-737.727	45.6667
-743.2	41
-748.678	49.3333
-754.159	47.6667
-759.646	39.6667
-765.138	42.3333
-770.633	38
-776.133	39
-781.638	40
-787.149	41.3333
-792.663	44
-798.181	42
-803.705	47.6667
-809.233	52
-814.766	45.6667
-820.304	44.6667
-825.846	45
-831.392	49.6667
-836.944	43
-842.499	46
-848.06	50.6667
-853.626	49.3333
-859.195	48.3333
-864.77	49
-870.35	40.3333
-875.934	46
-881.522	44.6667
-887.116	47
-892.714	43.6667
-898.317	42
-903.924	57
-909.537	41.3333
-915.153	38.3333
-920.776	43.3333
-926.401	45.6667
-932.033	49.3333
-937.669	48.3333
-943.31	48.3333
-948.955	42.3333
-954.605	46.6667
-960.26	46.3333
-965.92	50.3333
-971.584	44.3333
-977.254	50.3333
-982.928	43
-988.607	45.6667
-994.291	48.3333
-999.979	41
-1005.67	53
-1011.37	48.6667
-1017.07	52.3333
-1022.78	48
-1028.49	46.6667
-1034.21	50.3333
-1039.93	53.6667
-1045.66	55.6667
-1051.39	53.6667
-1057.13	49.6667
-1062.87	49.6667
-1068.62	51.3333
-1074.37	54.3333
-1080.12	53.6667
-1085.89	46.6667
-1091.65	48.6667
-1097.42	48.3333
-1103.2	48.6667
-1108.98	51.3333
-1114.77	50.6667
-1120.56	50
-1126.35	56
-1132.15	56.6667
-1137.96	47.6667
-1143.77	52
-1149.58	56.3333
-1155.4	52.6667
-1161.23	60.6667
-1167.06	59.6667
-1172.89	73.6667
-1178.73	82
-1184.58	107.333
-1190.43	125.333
-1196.28	138.333
-1202.14	167.333
-1208.01	188.667
-1213.88	209.333
-1219.75	252.333
-1225.63	281.333
-1231.52	304
-1237.41	357.333
-1243.3	489.667
-1249.2	846
-1255.11	866
-1261.02	844.667
-1266.93	681
-1272.85	450
-1278.78	218.333
-1284.71	103
-1290.65	92
-1296.59	76.6667
-1302.53	79.6667
-1308.48	68
-1314.44	69
-1320.4	69
-1326.37	61.6667
-1332.34	68.6667
-1338.31	64.6667
-1344.29	45.6667
-1350.28	59
-1356.27	62.6667
-1362.27	56.6667
-1368.27	59
-1374.28	43
-1380.29	54
-1386.31	44.6667
-1392.33	47.6667

-1051.39	53.6667
-1054.26	43.6667
-1057.13	49.6667
-1060	50.6667
-1062.87	49.6667
-1065.74	48
-1068.62	51.3333
-1071.49	47.6667
-1074.37	54.3333
-1077.25	45
-1080.12	53.6667
-1083.01	52
-1085.89	46.6667
-1088.77	47.6667
-1091.65	48.6667
-1094.54	57
-1097.42	48.3333
-1100.31	57
-1103.2	48.6667
-1106.09	54
-1108.98	51.3333
-1111.87	54
-1114.77	50.6667
-1117.66	55.3333
-1120.56	50
-1123.45	52.3333
-1126.35	56
-1129.25	55
-1132.15	56.6667
-1135.05	54
-1137.96	47.6667
-1140.86	57
-1143.77	52
-1146.67	57
-1149.58	56.3333
-1152.49	59.3333
-1155.4	52.6667
-1158.32	62.3333
-1161.23	60.6667
-1164.14	65
-1167.06	59.6667
-1169.98	66.3333
-1172.89	73.6667
-1175.81	87.3333
-1178.73	82
-1181.66	100
-1184.58	107.333
-1187.5	119.667
-1190.43	125.333
-1193.35	130.333
-1196.28	138.333
-1199.21	151.333
-1202.14	167.333
-1205.08	180.333
-1208.01	188.667
-1210.94	198
-1213.88	209.333
-1216.82	228.667
-1219.75	252.333
-1222.69	254
-1225.63	281.333
-1228.58	297.667
-1231.52	304
-1234.46	347
-1237.41	357.333
-1240.35	389
-1243.3	489.667
-1246.25	661.667
-1249.2	846
-1252.16	873.667
-1255.11	866
-1258.06	863.667
-1261.02	844.667
-1263.97	778.667
-1266.93	681
-1269.89	572
-1272.85	450
-1275.82	340.667
-1278.78	218.333
-1281.74	129.333
-1284.71	103
-1287.68	92
-1290.65	92
-1293.62	86
-1296.59	76.6667
-1299.56	72.3333
-1302.53	79.6667
-1305.51	72.3333
-1308.48	68
-1311.46	68.3333
-1314.44	69
-1317.42	60.6667
-1320.4	69
-1323.38	59
-1326.37	61.6667
-1329.35	56
-1332.34	68.6667
-1335.32	53.3333
-1338.31	64.6667
-1341.3	59.6667
-1344.29	45.6667
-1347.29	56.6667
-1350.28	59
-1353.28	56.3333
-1356.27	62.6667
-1359.27	63
-1362.27	56.6667
-1365.27	51.6667
-1368.27	59
-1371.27	49
-1374.28	43
-1377.28	45.3333
-1380.29	54
-1383.3	45.3333
-1386.31	44.6667
-1389.32	46
-1392.33	47.6667