File: projects/python/data/20231030/txt/blood_600_785 nm_10 s_1_2023_10_30_15_34_38_01.txt
#Sample=blood
#Laser=785 nm
#Gating=600
#Exposition=10 s
#Accumulation=1
#Acquired=30.10.2023 15:34:38
2745.96	126
2743.18	108.667
2740.41	121
2737.63	110
2734.85	116
2732.07	113
2729.29	113
2726.5	124.667
2723.72	118.667
2720.93	116.333
2718.14	117
2715.34	111.333
2712.55	112.333
2709.75	117
2706.95	118
2704.15	118
2701.35	117.667
2698.55	123.667
2695.74	122
2692.93	122.333
2690.12	124
2687.31	129
2684.49	124.667
2681.67	120.667
2678.85	127.667
2676.03	110
2673.21	114
2670.38	117.333
2667.56	121.667
2664.73	121.333
2661.9	125
2659.06	118
2656.23	125
2653.39	130
2650.55	121.333
2647.71	128.667
2644.86	137.333
2642.02	128.333
2639.17	136.667
2636.32	126.333
2633.47	146.667
2630.62	135.333
2627.76	132.333
2624.9	131.667
2622.04	128.333
2619.18	130.667
2616.31	135.333
2613.45	130.667
2610.58	140
2607.71	133
2604.84	137
2601.96	123.333
2599.08	128.333
2596.21	122.333
2593.32	143
2590.44	125.667
2587.56	129.333
2584.67	136.333
2581.78	143.333
2578.89	137
2575.99	130
2573.1	138.333
2570.2	141.667
2567.3	134.667
2564.4	137.333
2561.5	141
2558.59	138.333
2555.68	147
2552.77	139
2549.86	139
2546.94	134
2544.03	139
2541.11	123.667
2538.19	140
2535.26	132.667
2532.34	142
2529.41	140.333
2526.48	143.333
2523.55	141.667
2520.62	134.667
2517.68	137
2514.74	138.333
2511.8	139.667
2508.86	144.333
2505.92	144
2502.97	146
2500.02	139
2497.07	138.667
2494.12	146.333
2491.16	147
2488.2	140.667
2485.25	155.333
2482.28	150.333
2479.32	138.667
2476.35	150
2473.39	156
2470.42	144.333
2467.44	153.667
2464.47	155.667
2461.49	154
2458.51	169.667
2455.53	163.667
2452.55	163.667
2449.56	159.333
2446.58	157.667
2443.59	158.667
2440.59	169
2437.6	168.333
2434.6	163.333
2431.61	168.667
2428.61	163
2425.6	168.667
2422.6	172
2419.59	168.333
2416.58	166.667
2413.57	163.333
2410.56	160
2407.54	167
2404.52	174.333
2401.5	167.667
2398.48	159
2395.45	151
2392.43	166
2389.4	169.333
2386.37	167.667
2383.33	161.667
2380.3	152
2377.26	174.333
2374.22	169.667
2371.17	157.333
2368.13	171.333
2365.08	167.667
2362.03	162.667
2358.98	163.333
2355.93	166
2352.87	168
2349.81	181.333
2346.75	175.333
2343.69	167
2340.63	176.333
2337.56	168.333
2334.49	178.333
2331.42	177.333
2328.35	175.333
2325.27	182.333
2322.19	177.667
2319.11	184
2316.03	177.667
2312.94	181.333
2309.85	181.333
2306.77	188
2303.67	174
2300.58	185.667
2297.48	184.667
2294.38	188.667
2291.28	188
2288.18	180.333
2285.07	182.667
2281.97	180
2278.86	182.667
2275.74	184.333
2272.63	184.333
2269.51	194.333
2266.39	182
2263.27	191
2260.15	185
2257.02	191.333
2253.89	181.667
2250.76	191.333
2247.63	196.667
2244.49	200.333
2241.36	187.333
2238.22	199.667
2235.08	198.667
2231.93	192.333
2228.78	187.333
2225.63	196.667
2222.48	196.333
2219.33	205
2216.17	204.667
2213.01	206
2209.85	205
2206.69	208.333
2203.53	205
2200.36	215.667
2197.19	203.667
2194.02	206.667
2190.84	220
2187.66	206
2184.48	213.333
2181.3	210.333
2178.12	209.333
2174.93	212
2171.74	222
2168.55	221.667
2165.36	220.333
2162.16	225.667
2158.97	224.333
2155.76	227.333
2152.56	227.333
2149.36	236.333
2146.15	228.667
2142.94	223
2139.73	226.667
2136.51	233.667
2133.29	223.667
2130.08	232.667
2126.85	239.333
2123.63	237.667
2120.4	237
2117.17	247
2113.94	239.333
2110.71	251
2107.47	256
2104.23	237.333
2100.99	256.333
2097.75	263
2094.5	247.667
2091.26	260.333
2088.01	252
2084.75	255.667
2081.5	264.333
2078.24	280
2074.98	269.333
2071.72	275
2068.45	283
2065.18	285.667
2061.92	275.333
2058.64	292
2055.37	301.667
2052.09	295.333
2048.81	296.333
2045.53	303
2042.25	318.333
2038.96	311.333
2035.67	330.333
2032.38	328.667
2029.08	328
2025.79	336.333
2022.49	339.667
2019.19	346.667
2015.88	353.667
2012.58	354
2009.27	358
2005.96	374.667
2002.64	388.333
1999.33	387.333
1996.01	389.667
1992.69	403.667
1989.36	409
1986.04	431.667
1982.71	433.333
1979.38	438.667
1976.05	449
1972.71	462.667
1969.37	480.333
1966.03	489.667
1962.69	510
1959.34	519
1955.99	515.333
1952.64	525.333
1949.29	517.667
1945.93	544.667
1942.58	564
1939.21	546.333
1935.85	569.333
1932.49	569.667
1929.12	579.667
1925.75	590
1922.37	581.667
1919	609.333
1915.62	597
1912.24	602
1908.86	614.333
1905.47	603.667
1902.08	608.667
1898.69	618.667
1895.3	620.333
1891.9	637.333
1888.5	652.667
1885.1	638.667
1881.7	643.667
1878.29	658
1874.88	632
1871.47	649.333
1868.06	647.333
1864.64	664.667
1861.22	644.667
1857.8	647.667
1854.38	642.667
1850.95	639.333
1847.52	653.333
1844.09	634.333
1840.66	652.333
1837.22	643
1833.78	656.333
1830.34	646
1826.9	651.333
1823.45	647.667
1820	664.667
1816.55	660
1813.09	644.667
1809.64	652.333
1806.18	659
1802.71	664
1799.25	662.667
1795.78	679
1792.31	683.333
1788.84	697.333
1785.36	676.667
1781.88	681
1778.4	691.333
1774.92	684
1771.43	697
1767.95	697.667
1764.45	705
1760.96	684.333
1757.47	728
1753.97	707.667
1750.47	732.333
1746.96	724
1743.45	728.667
1739.94	732.667
1736.43	739
1732.92	745.667
1729.4	747
1725.88	764.667
1722.36	760.333
1718.83	764
1715.3	770.667
1711.77	802.667
1708.24	817.667
1704.71	823
1701.17	840.667
1697.63	836.667
1694.08	842
1690.54	859.667
1686.99	874.333
1683.44	875.333
1679.88	882.333
1676.32	884
1672.76	896.667
1669.2	882
1665.64	903.667
1662.07	893
1658.5	919.667
1654.92	925.667
1651.35	930.333
1647.77	943.667
1644.19	936.667
1640.61	959
1637.02	958.667
1633.43	957
1629.84	964.333
1626.24	975
1622.64	975.333
1619.04	977.667
1615.44	978.333
1611.84	967
1608.23	979
1604.62	980
1601	976.667
1597.39	983.667
1593.77	1010.67
1590.15	1014.33
1586.52	1036.33
1582.89	1037
1579.26	1028.33
1575.63	1028.67
1571.99	1028
1568.36	1053.33
1564.72	1054.33
1561.07	1083.33
1557.42	1087.67
1553.78	1090.33
1550.12	1078.67
1546.47	1081
1542.81	1080.33
1539.15	1088.67
1535.49	1098
1531.82	1095.67
1528.15	1090
1524.48	1093
1520.81	1122.33
1517.13	1101.33
1513.45	1112
1509.77	1113.67
1506.08	1122.67
1502.39	1104.33
1498.7	1142
1495.01	1141
1491.31	1140.33
1487.61	1164.33
1483.91	1163
1480.21	1196.67
1476.5	1181.67
1472.79	1208
1469.07	1227.33
1465.36	1223.33
1461.64	1252
1457.92	1260
1454.19	1264.33
1450.46	1298
1446.73	1311.33
1443	1325.67
1439.26	1332
1435.52	1340
1431.78	1354.33
1428.04	1335.33
1424.29	1368
1420.54	1356.33
1416.79	1365
1413.03	1389.67
1409.27	1370
1405.51	1395
1401.75	1403.33
1397.98	1393.67
1394.21	1400.67
1390.44	1403
1386.66	1390
1382.88	1372.33
1379.1	1386
1375.31	1369.33
1371.53	1339
1367.74	1328
1363.94	1310
1360.15	1294.67
1356.35	1272.67
1352.55	1261.33
1348.74	1238
1344.93	1207.33
1341.12	1181.33
1337.31	1160.67
1333.49	1132.33
1329.67	1096.33
1325.85	1067
1322.03	1034.67
1318.2	1013.67
1314.37	999.667
1310.53	978.333
1306.7	961
1302.86	928.333
1299.01	893
1295.17	893.667
1291.32	890.667
1287.47	866.667
1283.61	873.333
1279.76	859.333
1275.9	870.333
1272.03	839.333
1268.17	848.667
1264.3	842
1260.42	820
1256.55	824.667
1252.67	818.667
1248.79	797
1244.91	782.333
1241.02	783
1237.13	793.667
1233.24	775.333
1229.34	754
1225.44	729
1221.54	739.333
1217.63	718
1213.73	688
1209.81	700.667
1205.9	675.667
1201.98	670.333
1198.06	657.667
1194.14	642.667
1190.21	642.333
1186.29	632
1182.35	635.333
1178.42	606.333
1174.48	620.667
1170.54	602
1166.6	593.333
1162.65	590.333
1158.7	597.667
1154.74	614.333
1150.79	572.667
1146.83	591.667
1142.87	575
1138.9	564.667
1134.93	551.333
1130.96	568.667
1126.99	549
1123.01	542.667
1119.03	545
1115.04	537
1111.06	518.333
1107.07	535.667
1103.08	518.667
1099.08	527
1095.08	520.667
1091.08	515.333
1087.07	510.667
1083.06	514
1079.05	513.667
1075.04	493.667
1071.02	491.667
1067	493
1062.98	475
1058.95	474
1054.92	468
1050.89	472
1046.85	463
1042.81	455
1038.77	451
1034.72	448.667
1030.67	432.333
1026.62	466.667
1022.57	453
1018.51	448
1014.45	458.333
1010.38	454.667
1006.32	448.333
1002.24	466.667
998.171	457
994.094	449.333
990.013	450.333
985.93	458.333
981.843	458.333
977.754	458
973.661	455.333
969.565	462.333
965.466	461
961.364	477.667
957.258	467.667
953.15	481
949.038	451
944.923	463.667
940.804	465.333
936.683	465.667
932.558	454.333
928.43	463
924.299	462.333
920.165	457.667
916.028	448.333
911.887	468.333
907.743	459.667
903.595	460.333
899.445	445
895.292	436.667
891.135	448.333
886.975	461.667
882.812	469.667
878.646	457.333
874.475	435
870.303	445
866.126	447.333
861.947	442
857.764	449.333
853.578	457.333
849.389	460.333
845.196	464
841	436.667
836.801	462.333
832.599	456.667
828.393	457.333
824.184	440
819.972	440.667
815.757	438
811.538	453.333
807.316	434.667
803.091	435
798.863	450
794.631	440
790.395	438.333
786.157	432.333
781.915	445.333
777.669	434
773.421	438
769.169	439.667
764.915	446.333
760.656	447.333
756.394	439
752.129	450.667
747.861	456.667
743.588	450.667
739.314	444.667
735.035	444.667
730.753	435.667
726.469	436
722.18	436
717.888	437.333
713.593	445.333
709.294	427
704.992	432.667
700.687	430.667
696.378	418
692.066	427
687.751	430
683.432	425
679.109	430.333
674.784	420.333
670.455	427
666.122	418.667
661.787	430.667
657.448	425
653.104	436.667
648.759	447.667
644.409	434
640.056	453.333
635.7	452.333
631.34	452.667
626.977	448.667
622.61	446.333
618.24	456.667
613.867	425.667
609.49	431.333
605.11	437.333
600.726	425
596.339	424.333
591.948	422
587.554	433.667
583.156	439.333
578.755	442.333
574.35	456.667
569.943	445
565.531	450.333
561.116	454
556.698	448.667
552.275	451.667
547.85	447
543.421	450.667
538.988	439.333
534.553	430.667
530.113	436
525.67	433.333
521.224	435.333
516.774	438.333
512.321	439.667
507.863	441.333
503.403	442
498.939	441.667
494.472	436.667
490.001	446
485.526	448.333
481.047	441.667
476.565	459.667
472.08	455
467.591	452
463.099	472.667
458.604	476.333
454.103	478.667
449.601	478.333
445.094	490.667
440.584	493.667
436.07	503
431.553	515.333
427.032	534
422.507	529.333
417.979	541.667
413.448	525.667
408.912	545.333
404.373	543
399.83	546
395.285	544.667
390.734	556
386.181	552.667
381.624	567.667
377.064	568.333
372.5	571.333
367.932	585
363.36	581.667
358.785	577.333
354.207	582.667
349.624	579
345.038	595.667
340.448	580.333
335.855	594
331.257	588.667
326.657	597
322.053	592.333
317.444	589
312.833	591
308.217	592
303.599	589.333
298.976	606.333
294.349	628
289.719	647
285.085	640
280.448	657
275.807	660.333
271.161	676
266.513	686
261.861	694.667
257.205	718
252.544	735.667
247.881	753.333
243.214	779.667
238.543	799
233.869	835.667
229.19	852.333
224.508	858
219.822	891.667
215.132	931
210.439	922.667
205.741	951
201.04	981
196.336	986.667
191.627	1000
186.915	1055.67
182.199	1042.33
177.478	1085.67
172.755	1112
168.028	1140
163.297	1153.67
158.561	1182.33
153.823	1170
149.08	1211.67
144.334	1222.67
139.584	1277.67
134.829	1301.33
130.071	1390.33
125.31	1435.33
120.545	1487.67
115.775	1573.33
111.001	1633.33
106.224	1759.33
101.444	1936.67
96.6594	2083.33
91.8705	2266
87.0781	2545
82.282	2872.67
77.4812	3455.67
72.6778	4570.33
67.8698	7265
63.0582	10014.3
58.2419	12020
53.4229	13577
48.5993	15214
43.772	17048.7
38.941	19736.3
34.1054	24039.7
29.2661	30785
24.4231	45367.7
19.5764	64524
14.7261	64524
9.87099	64524
5.01321	64524
0.14975	64524
-4.71644	64524
-9.58634	64524
-14.461	64524
-19.3393	64524
-24.2214	64524
-29.1072	64524
-33.9977	64524
-38.892	18753
-43.7901	12794
-48.6919	9531
-53.5974	7245.33
-58.5078	5551
-63.4218	4354.67
-68.3397	3329.33
-73.2613	2599
-78.1878	2079
-83.117	1699.33
-88.051	1398.67
-92.9888	1155.33
-97.9314	940
-102.877	752.333
-107.827	584.667
-112.781	503
-117.739	432
-122.701	367.667
-127.667	302.333
-132.637	246
-137.612	225
-142.59	195
-147.572	167.667
-152.558	157
-157.548	153
-162.542	135.667
-167.541	120.333
-172.544	111.667
-177.55	112
-182.561	108
-187.576	101
-192.595	97.3333
-197.617	97.6667
-202.645	101.667
-207.676	84
-212.711	99
-217.75	81.3333
-222.794	84.3333
-227.842	83.6667
-232.893	81.6667
-237.949	85.3333
-243.009	87.3333
-248.073	83.3333
-253.142	81.3333
-258.214	81.6667
-263.291	71.3333
-268.371	83.3333
-273.456	72.6667
-278.545	71.3333
-283.639	72
-288.735	74.3333
-293.837	67
-298.943	72
-304.053	64.6667
-309.166	68.3333
-314.285	60
-319.408	68
-324.534	48
-329.665	65
-334.801	51
-339.94	66
-345.083	55.6667
-350.231	57.6667
-355.383	49
-360.539	56.3333
-365.699	54.6667
-370.864	56.3333
-376.033	52.6667
-381.206	57.3333
-386.384	60.3333
-391.565	48
-396.751	53.3333
-401.941	52.3333
-407.136	55.6667
-412.334	48
-417.537	59
-422.745	48
-427.956	52
-433.173	47.3333
-438.392	52.3333
-443.617	45
-448.846	47
-454.078	52.6667
-459.317	48.6667
-464.558	47.3333
-469.804	51.6667
-475.055	42.6667
-480.309	52.3333
-485.568	48
-490.832	51.6667
-496.099	56
-501.372	46
-506.648	40
-511.929	52.6667
-517.215	44.6667
-522.504	44.3333
-527.797	42
-533.097	50
-538.399	46.3333
-543.706	48.6667
-549.018	47.6667
-554.334	47
-559.654	51.6667
-564.979	53.6667
-570.308	51.6667
-575.641	45.6667
-580.98	51
-586.322	43.6667
-591.669	44
-597.02	43
-602.376	50.3333
-607.736	42.3333
-613.1	53
-618.47	48
-623.843	50.3333
-629.222	44
-634.603	46.6667
-639.99	49
-645.382	50.6667
-650.779	46
-656.179	50
-661.583	49.3333
-666.993	53.6667
-672.407	51.3333
-677.825	41
-683.248	46
-688.675	46.6667
-694.108	48
-699.544	47.3333
-704.985	44.6667
-710.431	46.3333
-715.88	47.3333
-721.335	50.6667
-726.795	44.3333
-732.258	48
-737.727	43.6667
-743.2	50
-748.678	43
-754.159	52
-759.646	44.6667
-765.138	48
-770.633	52.6667
-776.133	43.6667
-781.638	44
-787.149	39
-792.663	48.6667
-798.181	53
-803.705	43.6667
-809.233	48
-814.766	47
-820.304	46
-825.846	50.6667
-831.392	43
-836.944	42
-842.499	41.3333
-848.06	45.3333
-853.626	50.6667
-859.195	49.6667
-864.77	42.3333
-870.35	45
-875.934	54.3333
-881.522	48
-887.116	46.3333
-892.714	40.6667
-898.317	51.6667
-903.924	38.6667
-909.537	45.6667
-915.153	46.3333
-920.776	45
-926.401	51.3333
-932.033	48
-937.669	46.6667
-943.31	53.6667
-948.955	50.6667
-954.605	44.6667
-960.26	52
-965.92	44
-971.584	47.6667
-977.254	53.3333
-982.928	50.3333
-988.607	51.6667
-994.291	44.3333
-999.979	51.3333
-1005.67	54.3333
-1011.37	53.3333
-1017.07	45.6667
-1022.78	55.6667
-1028.49	49.6667
-1034.21	50.3333
-1039.93	54
-1045.66	48.3333
-1051.39	55
-1057.13	51
-1062.87	47
-1068.62	55.6667
-1074.37	40
-1080.12	51.3333
-1085.89	44.3333
-1091.65	50.6667
-1097.42	47.6667
-1103.2	52
-1108.98	51.6667
-1114.77	46
-1120.56	51.6667
-1126.35	45
-1132.15	52
-1137.96	55
-1143.77	55.6667
-1149.58	65.3333
-1155.4	57.6667
-1161.23	64.6667
-1167.06	65
-1172.89	82
-1178.73	90.6667
-1184.58	113.667
-1190.43	138
-1196.28	170
-1202.14	189
-1208.01	190.333
-1213.88	219.333
-1219.75	237.333
-1225.63	305.667
-1231.52	345
-1237.41	370.333
-1243.3	515
-1249.2	824.333
-1255.11	942
-1261.02	838.667
-1266.93	674.667
-1272.85	459.333
-1278.78	215.333
-1284.71	108.667
-1290.65	92.3333
-1296.59	76.3333
-1302.53	69.6667
-1308.48	68
-1314.44	63.3333
-1320.4	67.3333
-1326.37	61.3333
-1332.34	58
-1338.31	67.6667
-1344.29	58
-1350.28	59
-1356.27	57.3333
-1362.27	51.6667
-1368.27	47
-1374.28	49.3333
-1380.29	50.6667
-1386.31	50.3333
-1392.33	48.3333

-1057.13	51
-1060	50.3333
-1062.87	47
-1065.74	45
-1068.62	55.6667
-1071.49	55
-1074.37	40
-1077.25	52.3333
-1080.12	51.3333
-1083.01	57.6667
-1085.89	44.3333
-1088.77	57
-1091.65	50.6667
-1094.54	47
-1097.42	47.6667
-1100.31	45.6667
-1103.2	52
-1106.09	57.3333
-1108.98	51.6667
-1111.87	47.3333
-1114.77	46
-1117.66	53.6667
-1120.56	51.6667
-1123.45	57.3333
-1126.35	45
-1129.25	49.3333
-1132.15	52
-1135.05	56.6667
-1137.96	55
-1140.86	51.3333
-1143.77	55.6667
-1146.67	57
-1149.58	65.3333
-1152.49	53.6667
-1155.4	57.6667
-1158.32	54.6667
-1161.23	64.6667
-1164.14	65.6667
-1167.06	65
-1169.98	72.3333
-1172.89	82
-1175.81	82
-1178.73	90.6667
-1181.66	108.667
-1184.58	113.667
-1187.5	130.667
-1190.43	138
-1193.35	153.667
-1196.28	170
-1199.21	180.333
-1202.14	189
-1205.08	199.333
-1208.01	190.333
-1210.94	215.333
-1213.88	219.333
-1216.82	226.667
-1219.75	237.333
-1222.69	281.333
-1225.63	305.667
-1228.58	341.333
-1231.52	345
-1234.46	340.333
-1237.41	370.333
-1240.35	394.333
-1243.3	515
-1246.25	713.333
-1249.2	824.333
-1252.16	900.667
-1255.11	942
-1258.06	864.667
-1261.02	838.667
-1263.97	754.333
-1266.93	674.667
-1269.89	560.667
-1272.85	459.333
-1275.82	345.667
-1278.78	215.333
-1281.74	141.667
-1284.71	108.667
-1287.68	88.6667
-1290.65	92.3333
-1293.62	88.6667
-1296.59	76.3333
-1299.56	74.6667
-1302.53	69.6667
-1305.51	71.3333
-1308.48	68
-1311.46	69
-1314.44	63.3333
-1317.42	73
-1320.4	67.3333
-1323.38	57.6667
-1326.37	61.3333
-1329.35	66.3333
-1332.34	58
-1335.32	66
-1338.31	67.6667
-1341.3	57
-1344.29	58
-1347.29	59
-1350.28	59
-1353.28	64
-1356.27	57.3333
-1359.27	63.3333
-1362.27	51.6667
-1365.27	57.6667
-1368.27	47
-1371.27	50.3333
-1374.28	49.3333
-1377.28	48
-1380.29	50.6667
-1383.3	51.6667
-1386.31	50.3333
-1389.32	47.6667
-1392.33	48.3333