File: projects/python/data/20231030/txt/blood_600_785 nm_10 s_1_2023_10_30_15_37_45_01.txt
#Sample=blood
#Laser=785 nm
#Gating=600
#Exposition=10 s
#Accumulation=1
#Acquired=30.10.2023 15:37:45
2745.96	132.333
2743.18	124.333
2740.41	140.333
2737.63	137.667
2734.85	132.333
2732.07	134.667
2729.29	132.333
2726.5	130.667
2723.72	141.333
2720.93	132.667
2718.14	133.667
2715.34	142.333
2712.55	137
2709.75	126
2706.95	131.667
2704.15	132.667
2701.35	134.333
2698.55	128.667
2695.74	135.667
2692.93	145
2690.12	141
2687.31	140.333
2684.49	148.333
2681.67	143.333
2678.85	137.667
2676.03	130
2673.21	134
2670.38	143.667
2667.56	134.667
2664.73	147
2661.9	144.667
2659.06	143.667
2656.23	133.667
2653.39	136.333
2650.55	149.667
2647.71	144.333
2644.86	152.667
2642.02	145.667
2639.17	156.333
2636.32	152.333
2633.47	153.667
2630.62	144
2627.76	153
2624.9	151.333
2622.04	162
2619.18	157.667
2616.31	149.333
2613.45	151.667
2610.58	160
2607.71	164
2604.84	150.667
2601.96	155
2599.08	156.333
2596.21	153
2593.32	163.333
2590.44	155
2587.56	156.667
2584.67	160.667
2581.78	162.333
2578.89	158.667
2575.99	144
2573.1	155.667
2570.2	159.333
2567.3	167
2564.4	154
2561.5	153
2558.59	160.667
2555.68	162
2552.77	154.667
2549.86	163
2546.94	156.333
2544.03	159.333
2541.11	158.333
2538.19	160.333
2535.26	161.667
2532.34	163
2529.41	167
2526.48	165.333
2523.55	159.667
2520.62	156.667
2517.68	167.333
2514.74	167.333
2511.8	169.333
2508.86	174.667
2505.92	166
2502.97	171.667
2500.02	159
2497.07	168.333
2494.12	169
2491.16	169.333
2488.2	174.333
2485.25	167.667
2482.28	182.333
2479.32	177.333
2476.35	172
2473.39	174.667
2470.42	179
2467.44	176
2464.47	180.667
2461.49	181.667
2458.51	190
2455.53	188.333
2452.55	183.333
2449.56	191.667
2446.58	192.667
2443.59	200
2440.59	195.333
2437.6	186.333
2434.6	192.333
2431.61	198.333
2428.61	192.667
2425.6	197.667
2422.6	186
2419.59	197.333
2416.58	197
2413.57	201.667
2410.56	191
2407.54	183.667
2404.52	184.333
2401.5	185.333
2398.48	189.333
2395.45	184
2392.43	199.333
2389.4	201
2386.37	195.667
2383.33	200.333
2380.3	209
2377.26	204.667
2374.22	192.333
2371.17	196.333
2368.13	211.667
2365.08	201.667
2362.03	200.333
2358.98	200
2355.93	209.667
2352.87	208.667
2349.81	206
2346.75	209
2343.69	213.667
2340.63	201.333
2337.56	210.667
2334.49	201.667
2331.42	209
2328.35	205.667
2325.27	211.333
2322.19	218.333
2319.11	206.333
2316.03	215.667
2312.94	218.667
2309.85	216.333
2306.77	216
2303.67	210
2300.58	217
2297.48	220
2294.38	216
2291.28	227
2288.18	210.667
2285.07	231.667
2281.97	222
2278.86	223.333
2275.74	219
2272.63	231.333
2269.51	225
2266.39	230.667
2263.27	224.333
2260.15	225
2257.02	229.667
2253.89	236
2250.76	234
2247.63	233.667
2244.49	248.333
2241.36	233.333
2238.22	237
2235.08	235.333
2231.93	240
2228.78	218.667
2225.63	240.667
2222.48	238.667
2219.33	254.667
2216.17	245
2213.01	237
2209.85	243.333
2206.69	244.667
2203.53	252
2200.36	241.667
2197.19	251
2194.02	251.667
2190.84	256
2187.66	259
2184.48	245.667
2181.3	259
2178.12	258
2174.93	253.667
2171.74	246
2168.55	244.667
2165.36	251.667
2162.16	270.667
2158.97	270.333
2155.76	269.333
2152.56	278.667
2149.36	273.333
2146.15	285.667
2142.94	276.333
2139.73	283.333
2136.51	290.333
2133.29	277
2130.08	293
2126.85	286.333
2123.63	290.333
2120.4	283.667
2117.17	285.333
2113.94	298
2110.71	307
2107.47	296.333
2104.23	294
2100.99	306.333
2097.75	296
2094.5	308.667
2091.26	302
2088.01	321.667
2084.75	315.667
2081.5	324
2078.24	313
2074.98	324.333
2071.72	323
2068.45	327.333
2065.18	341.333
2061.92	341.333
2058.64	336.333
2055.37	358.667
2052.09	353.333
2048.81	364.667
2045.53	370.333
2042.25	359
2038.96	372.667
2035.67	384.333
2032.38	392
2029.08	391.333
2025.79	397
2022.49	398.667
2019.19	400.333
2015.88	413
2012.58	419
2009.27	414
2005.96	432.667
2002.64	444
1999.33	451
1996.01	453.667
1992.69	469
1989.36	490.333
1986.04	501
1982.71	492.667
1979.38	514.667
1976.05	527
1972.71	533
1969.37	552.333
1966.03	564.667
1962.69	575.333
1959.34	585
1955.99	612
1952.64	618.667
1949.29	612
1945.93	617
1942.58	632
1939.21	625
1935.85	642.333
1932.49	660.333
1929.12	649
1925.75	657.667
1922.37	673
1919	684.333
1915.62	684
1912.24	691.333
1908.86	693
1905.47	699
1902.08	701.333
1898.69	711.667
1895.3	711.667
1891.9	723
1888.5	721
1885.1	701.333
1881.7	737.333
1878.29	733.333
1874.88	718.333
1871.47	745.667
1868.06	740
1864.64	734.333
1861.22	738.667
1857.8	737.667
1854.38	722.667
1850.95	751.333
1847.52	729.333
1844.09	742
1840.66	738.333
1837.22	733.667
1833.78	740
1830.34	721
1826.9	763.333
1823.45	736
1820	747.333
1816.55	752.333
1813.09	753.333
1809.64	776.333
1806.18	735
1802.71	765
1799.25	771
1795.78	758.333
1792.31	767.333
1788.84	768.667
1785.36	779.667
1781.88	779.667
1778.4	785
1774.92	782.667
1771.43	802.333
1767.95	787.333
1764.45	806.333
1760.96	771.667
1757.47	810
1753.97	804.667
1750.47	803
1746.96	818.667
1743.45	828.333
1739.94	834.333
1736.43	832
1732.92	843.667
1729.4	857.333
1725.88	862.333
1722.36	876
1718.83	890
1715.3	903
1711.77	911
1708.24	930.667
1704.71	932.333
1701.17	942.333
1697.63	971.667
1694.08	976
1690.54	979
1686.99	1017.67
1683.44	1006
1679.88	1020
1676.32	1036.33
1672.76	1046.67
1669.2	1056.67
1665.64	1068.33
1662.07	1072
1658.5	1070.67
1654.92	1107.33
1651.35	1126.33
1647.77	1142.33
1644.19	1127.67
1640.61	1162
1637.02	1151.33
1633.43	1173.67
1629.84	1186
1626.24	1185.33
1622.64	1175.33
1619.04	1181
1615.44	1185.67
1611.84	1206.67
1608.23	1174
1604.62	1200.67
1601	1185
1597.39	1181.33
1593.77	1212
1590.15	1214
1586.52	1214.67
1582.89	1230.67
1579.26	1228.67
1575.63	1265
1571.99	1271
1568.36	1297
1564.72	1292.33
1561.07	1299.67
1557.42	1304.33
1553.78	1290.67
1550.12	1293.33
1546.47	1267.33
1542.81	1283.67
1539.15	1259
1535.49	1268.33
1531.82	1274
1528.15	1253.67
1524.48	1229
1520.81	1263.67
1517.13	1244.67
1513.45	1246.67
1509.77	1254.33
1506.08	1251.33
1502.39	1274.67
1498.7	1254.67
1495.01	1290.33
1491.31	1300.33
1487.61	1316.33
1483.91	1305.33
1480.21	1326.67
1476.5	1354.67
1472.79	1370.33
1469.07	1399.67
1465.36	1425
1461.64	1443
1457.92	1475
1454.19	1471.67
1450.46	1486.33
1446.73	1508.67
1443	1506.67
1439.26	1516.33
1435.52	1537
1431.78	1537.67
1428.04	1558.67
1424.29	1545.33
1420.54	1546
1416.79	1558.33
1413.03	1579
1409.27	1571.67
1405.51	1583
1401.75	1583.67
1397.98	1593
1394.21	1604.33
1390.44	1573.67
1386.66	1583
1382.88	1564.33
1379.1	1530.67
1375.31	1548
1371.53	1505.33
1367.74	1518
1363.94	1496.33
1360.15	1509.67
1356.35	1470.67
1352.55	1446.33
1348.74	1424.33
1344.93	1390.33
1341.12	1408.33
1337.31	1352.33
1333.49	1327.67
1329.67	1283
1325.85	1249
1322.03	1219.33
1318.2	1200.67
1314.37	1189.33
1310.53	1162.67
1306.7	1132
1302.86	1108
1299.01	1076.67
1295.17	1054.33
1291.32	1051.67
1287.47	1019
1283.61	1023.33
1279.76	1031.67
1275.9	983
1272.03	1006
1268.17	992
1264.3	988
1260.42	975.667
1256.55	978
1252.67	962.667
1248.79	946.667
1244.91	956
1241.02	969.333
1237.13	961.667
1233.24	947.667
1229.34	927.667
1225.44	918.667
1221.54	892.667
1217.63	877.333
1213.73	860
1209.81	854.333
1205.9	829.667
1201.98	799
1198.06	802.333
1194.14	787.333
1190.21	778.667
1186.29	774
1182.35	764.333
1178.42	776.333
1174.48	751
1170.54	727.333
1166.6	739.333
1162.65	742.333
1158.7	735.333
1154.74	716.667
1150.79	730.333
1146.83	722.333
1142.87	717.667
1138.9	717
1134.93	707
1130.96	705
1126.99	721.333
1123.01	680.333
1119.03	679.667
1115.04	671.667
1111.06	662.667
1107.07	679
1103.08	656.333
1099.08	647
1095.08	644.333
1091.08	653.667
1087.07	652.333
1083.06	641.667
1079.05	639.667
1075.04	622
1071.02	628.667
1067	632
1062.98	603.333
1058.95	616.333
1054.92	612.333
1050.89	610.667
1046.85	599.333
1042.81	594
1038.77	595.667
1034.72	582.667
1030.67	596
1026.62	587.667
1022.57	598.333
1018.51	607.333
1014.45	612
1010.38	615
1006.32	623.333
1002.24	614.667
998.171	604
994.094	625.333
990.013	622
985.93	625
981.843	633.667
977.754	635.667
973.661	617.333
969.565	629
965.466	625.667
961.364	638
957.258	643.667
953.15	643
949.038	639.667
944.923	640.667
940.804	631.333
936.683	634
932.558	621
928.43	636.667
924.299	632.333
920.165	620
916.028	624
911.887	614
907.743	603.667
903.595	615.333
899.445	607.333
895.292	589
891.135	604.333
886.975	607
882.812	599
878.646	602.667
874.475	601.333
870.303	596.667
866.126	601.333
861.947	610
857.764	601
853.578	624.333
849.389	607.667
845.196	595.667
841	625.667
836.801	601.333
832.599	608.333
828.393	597.667
824.184	601.333
819.972	605.667
815.757	589
811.538	586
807.316	593.333
803.091	581.333
798.863	587.667
794.631	585
790.395	586
786.157	578.333
781.915	595
777.669	602.333
773.421	596.667
769.169	595.333
764.915	601.667
760.656	621.667
756.394	618.333
752.129	631.333
747.861	616
743.588	616.333
739.314	616.667
735.035	606
730.753	610
726.469	602
722.18	598
717.888	596.667
713.593	598.333
709.294	587.667
704.992	591
700.687	578.333
696.378	580.667
692.066	585.333
687.751	588.667
683.432	589.667
679.109	567.667
674.784	566.333
670.455	583.333
666.122	589.667
661.787	588.333
657.448	585.667
653.104	590.333
648.759	584.667
644.409	582.667
640.056	606.667
635.7	607
631.34	597.333
626.977	612.667
622.61	600.667
618.24	608.333
613.867	609
609.49	575.667
605.11	587.333
600.726	581.667
596.339	585.667
591.948	593.667
587.554	593
583.156	605.667
578.755	624.333
574.35	615.667
569.943	642
565.531	630.667
561.116	630.333
556.698	618
552.275	625
547.85	622.333
543.421	625.667
538.988	607.667
534.553	618.667
530.113	626.667
525.67	606.333
521.224	617.667
516.774	611
512.321	607.667
507.863	618.333
503.403	601.333
498.939	590.667
494.472	597
490.001	619.333
485.526	596.667
481.047	598.667
476.565	609.333
472.08	615.667
467.591	635
463.099	606.667
458.604	632
454.103	641.667
449.601	656.667
445.094	651.667
440.584	652.667
436.07	677
431.553	697
427.032	716
422.507	727
417.979	729.667
413.448	749.333
408.912	741.333
404.373	741.667
399.83	745
395.285	754.667
390.734	737.333
386.181	769.333
381.624	769
377.064	767.333
372.5	769
367.932	775
363.36	785.333
358.785	803.667
354.207	798
349.624	804
345.038	787.667
340.448	800.333
335.855	807.667
331.257	787.333
326.657	808
322.053	798.667
317.444	801.333
312.833	820.667
308.217	827.667
303.599	826
298.976	845
294.349	880
289.719	879.667
285.085	891.667
280.448	897
275.807	929.333
271.161	954.333
266.513	964
261.861	990.667
257.205	1010
252.544	1039
247.881	1080.67
243.214	1101.33
238.543	1143.67
233.869	1143
229.19	1207.67
224.508	1195
219.822	1255.67
215.132	1294.67
210.439	1342
205.741	1369.67
201.04	1388.67
196.336	1427.67
191.627	1477.67
186.915	1475.67
182.199	1512.67
177.478	1555
172.755	1620.33
168.028	1652
163.297	1676.33
158.561	1778
153.823	1792.33
149.08	1847
144.334	1896.67
139.584	1950
134.829	2006
130.071	2055.67
125.31	2190.33
120.545	2338
115.775	2476.67
111.001	2586.33
106.224	2787.67
101.444	3003.33
96.6594	3252.67
91.8705	3577.67
87.0781	3938.67
82.282	4369.67
77.4812	5063.67
72.6778	6205.33
67.8698	8849.33
63.0582	11520
58.2419	13336
53.4229	14991
48.5993	16647.7
43.772	18557.3
38.941	21472
34.1054	26277
29.2661	33622.3
24.4231	49588.3
19.5764	64524
14.7261	64524
9.87099	64524
5.01321	64524
0.14975	64524
-4.71644	64524
-9.58634	64524
-14.461	64524
-19.3393	64524
-24.2214	64524
-29.1072	64524
-33.9977	64524
-38.892	21101
-43.7901	14283.7
-48.6919	10588
-53.5974	8070.33
-58.5078	6231.67
-63.4218	4822.67
-68.3397	3715.67
-73.2613	2880
-78.1878	2276.33
-83.117	1869.67
-88.051	1517.33
-92.9888	1226.33
-97.9314	1041.33
-102.877	824.333
-107.827	667
-112.781	544.333
-117.739	473.667
-122.701	409
-127.667	336.667
-132.637	282
-137.612	240
-142.59	211.333
-147.572	186.667
-152.558	167.667
-157.548	158.667
-162.542	153.333
-167.541	134.667
-172.544	136
-177.55	118.667
-182.561	110.333
-187.576	111.667
-192.595	104
-197.617	106.667
-202.645	102
-207.676	98.3333
-212.711	93
-217.75	98
-222.794	97.6667
-227.842	92
-232.893	82
-237.949	87.6667
-243.009	85
-248.073	89.6667
-253.142	81.3333
-258.214	84
-263.291	80.3333
-268.371	86
-273.456	82.6667
-278.545	81
-283.639	77.3333
-288.735	74.6667
-293.837	62.3333
-298.943	61.6667
-304.053	66.6667
-309.166	65
-314.285	66.3333
-319.408	69
-324.534	63.6667
-329.665	59.3333
-334.801	66
-339.94	55
-345.083	53.3333
-350.231	66
-355.383	63
-360.539	59.6667
-365.699	58.3333
-370.864	59
-376.033	62
-381.206	62
-386.384	48.6667
-391.565	57.3333
-396.751	55.3333
-401.941	60
-407.136	58
-412.334	51.6667
-417.537	56
-422.745	52
-427.956	54.6667
-433.173	53
-438.392	48.6667
-443.617	45.6667
-448.846	51
-454.078	56
-459.317	48
-464.558	58.6667
-469.804	57.3333
-475.055	47
-480.309	49.6667
-485.568	48
-490.832	53
-496.099	56.3333
-501.372	52.3333
-506.648	51.3333
-511.929	49.3333
-517.215	49.3333
-522.504	53.3333
-527.797	48.3333
-533.097	50
-538.399	44.6667
-543.706	49
-549.018	50.3333
-554.334	48.6667
-559.654	51
-564.979	52.6667
-570.308	47.3333
-575.641	44.3333
-580.98	53.6667
-586.322	48
-591.669	46.3333
-597.02	47
-602.376	52
-607.736	54.6667
-613.1	44
-618.47	48.3333
-623.843	47
-629.222	44.3333
-634.603	57.6667
-639.99	48.6667
-645.382	51.6667
-650.779	42
-656.179	49.3333
-661.583	50
-666.993	53.6667
-672.407	54
-677.825	40.6667
-683.248	49.6667
-688.675	52
-694.108	50
-699.544	49
-704.985	51.3333
-710.431	45.3333
-715.88	52
-721.335	52
-726.795	45.6667
-732.258	46.3333
-737.727	47
-743.2	45
-748.678	44.3333
-754.159	48
-759.646	35
-765.138	55.3333
-770.633	54.3333
-776.133	48
-781.638	42.3333
-787.149	50.3333
-792.663	44.6667
-798.181	49.3333
-803.705	45.3333
-809.233	45.3333
-814.766	46
-820.304	50
-825.846	44.6667
-831.392	52.6667
-836.944	50.3333
-842.499	47.3333
-848.06	41.6667
-853.626	49.6667
-859.195	37.6667
-864.77	46
-870.35	42.6667
-875.934	47
-881.522	47.3333
-887.116	48.3333
-892.714	53
-898.317	53
-903.924	51.6667
-909.537	44
-915.153	50
-920.776	46.3333
-926.401	51.6667
-932.033	46
-937.669	47.3333
-943.31	42
-948.955	52.6667
-954.605	53.3333
-960.26	45.6667
-965.92	48
-971.584	39.6667
-977.254	46.6667
-982.928	53
-988.607	53
-994.291	61
-999.979	49.3333
-1005.67	54.6667
-1011.37	53.6667
-1017.07	43.3333
-1022.78	47
-1028.49	51.3333
-1034.21	50.3333
-1039.93	55.6667
-1045.66	50
-1051.39	45
-1057.13	54.6667
-1062.87	55.6667
-1068.62	44.3333
-1074.37	56
-1080.12	50
-1085.89	57.6667
-1091.65	50
-1097.42	55.6667
-1103.2	57
-1108.98	54.3333
-1114.77	50.6667
-1120.56	62.3333
-1126.35	49
-1132.15	55.6667
-1137.96	60.6667
-1143.77	60.6667
-1149.58	61.6667
-1155.4	59.6667
-1161.23	67
-1167.06	61.3333
-1172.89	76
-1178.73	94.6667
-1184.58	119.667
-1190.43	154.333
-1196.28	170
-1202.14	185.333
-1208.01	220.333
-1213.88	238
-1219.75	283.333
-1225.63	300.333
-1231.52	355.333
-1237.41	407
-1243.3	583.667
-1249.2	956
-1255.11	962.667
-1261.02	921
-1266.93	785.667
-1272.85	481.667
-1278.78	222
-1284.71	111
-1290.65	90.3333
-1296.59	93
-1302.53	79.6667
-1308.48	72.3333
-1314.44	72.3333
-1320.4	68.3333
-1326.37	60.6667
-1332.34	70.3333
-1338.31	54.6667
-1344.29	57.3333
-1350.28	63.3333
-1356.27	58
-1362.27	61.3333
-1368.27	58.3333
-1374.28	47.3333
-1380.29	54
-1386.31	53.6667
-1392.33	46.6667
-1065.74	59.3333
-1071.49	53.3333
-1077.25	50
-1083.01	53.6667
-1088.77	48.6667
-1094.54	56.3333
-1100.31	50.3333
-1106.09	49.3333
-1111.87	57.3333
-1117.66	50.6667
-1123.45	49.6667
-1129.25	47.3333
-1135.05	57.6667
-1140.86	59
-1146.67	60.3333
-1152.49	57.3333
-1158.32	66
-1164.14	70.3333
-1169.98	77
-1175.81	82.3333
-1181.66	114.333
-1187.5	136.333
-1193.35	164.333
-1199.21	179.333
-1205.08	208.667
-1210.94	229.667
-1216.82	279.333
-1222.69	293.667
-1228.58	334.667
-1234.46	384.667
-1240.35	489
-1246.25	807
-1252.16	968.333
-1258.06	953.333
-1263.97	893.667
-1269.89	621.333
-1275.82	352.333
-1281.74	140.333
-1287.68	103
-1293.62	94.6667
-1299.56	78.3333
-1305.51	76.3333
-1311.46	74.6667
-1317.42	58
-1323.38	76.6667
-1329.35	65.6667
-1335.32	65
-1341.3	68.6667
-1347.29	63.3333
-1353.28	59.6667
-1359.27	53.6667
-1365.27	57.3333
-1371.27	64
-1377.28	50.3333
-1383.3	47.6667
-1389.32	41
-1392.33	46.6667