File: projects/python/data/20231030/txt/noise_600_785 nm_10 s_1_2023_10_30_15_03_32_01.txt
#Sample=noise
#Laser=785 nm
#Gating=600
#Exposition=10 s
#Accumulation=1
#Acquired=30.10.2023 15:03:32
2745.96	53.3333
2743.18	50
2740.41	48.6667
2737.63	54.3333
2734.85	51.3333
2732.07	52.3333
2729.29	57.3333
2726.5	52.6667
2723.72	52.6667
2720.93	55.6667
2718.14	55
2715.34	54
2712.55	49.3333
2709.75	57
2706.95	48.6667
2704.15	63.6667
2701.35	45.6667
2698.55	57.3333
2695.74	54.6667
2692.93	49.6667
2690.12	52.3333
2687.31	50.6667
2684.49	43.3333
2681.67	42.6667
2678.85	44.3333
2676.03	41.6667
2673.21	50.6667
2670.38	49
2667.56	51
2664.73	46.6667
2661.9	53
2659.06	52.3333
2656.23	48.3333
2653.39	46.6667
2650.55	46.3333
2647.71	43.3333
2644.86	54.6667
2642.02	41
2639.17	51.3333
2636.32	50.6667
2633.47	49
2630.62	46.6667
2627.76	42.3333
2624.9	46.6667
2622.04	50.3333
2619.18	31
2616.31	44.3333
2613.45	45
2610.58	45.3333
2607.71	48
2604.84	46
2601.96	47.3333
2599.08	46.6667
2596.21	54
2593.32	46.3333
2590.44	51.6667
2587.56	48
2584.67	43
2581.78	48.6667
2578.89	46
2575.99	44
2573.1	43.3333
2570.2	44
2567.3	46
2564.4	48.3333
2561.5	39
2558.59	41
2555.68	47.3333
2552.77	43
2549.86	44
2546.94	44.3333
2544.03	47
2541.11	46.3333
2538.19	42
2535.26	40
2532.34	40.6667
2529.41	46.3333
2526.48	43.6667
2523.55	36.6667
2520.62	42.6667
2517.68	37.6667
2514.74	46.6667
2511.8	42.3333
2508.86	48
2505.92	44.6667
2502.97	45.3333
2500.02	39.6667
2497.07	43
2494.12	40.3333
2491.16	48.3333
2488.2	39.3333
2485.25	49
2482.28	45
2479.32	43.3333
2476.35	43.6667
2473.39	47.6667
2470.42	40.3333
2467.44	39
2464.47	49
2461.49	51.6667
2458.51	40
2455.53	51
2452.55	42
2449.56	43.3333
2446.58	47.6667
2443.59	44.3333
2440.59	44
2437.6	42.3333
2434.6	39.6667
2431.61	35.6667
2428.61	42.3333
2425.6	40.6667
2422.6	36.3333
2419.59	44.6667
2416.58	42.6667
2413.57	44.6667
2410.56	36
2407.54	43.3333
2404.52	45
2401.5	35.3333
2398.48	36.6667
2395.45	35.3333
2392.43	35
2389.4	38
2386.37	39.6667
2383.33	39.3333
2380.3	38
2377.26	37
2374.22	38.6667
2371.17	32
2368.13	39.3333
2365.08	33
2362.03	40
2358.98	33.6667
2355.93	39.3333
2352.87	45
2349.81	38.6667
2346.75	34.3333
2343.69	36
2340.63	38.6667
2337.56	34.3333
2334.49	40.6667
2331.42	32.6667
2328.35	39.6667
2325.27	35.6667
2322.19	44
2319.11	38.3333
2316.03	39.6667
2312.94	41.3333
2309.85	33.3333
2306.77	40.6667
2303.67	43.3333
2300.58	40.3333
2297.48	35
2294.38	29.3333
2291.28	36.3333
2288.18	31.6667
2285.07	33.6667
2281.97	35.6667
2278.86	36.3333
2275.74	43
2272.63	38.6667
2269.51	34.6667
2266.39	40.6667
2263.27	41.3333
2260.15	34
2257.02	37.6667
2253.89	33.3333
2250.76	30.6667
2247.63	32
2244.49	39.3333
2241.36	45.6667
2238.22	33
2235.08	35.3333
2231.93	37
2228.78	40.3333
2225.63	34
2222.48	36.6667
2219.33	32
2216.17	37
2213.01	30.6667
2209.85	33.3333
2206.69	40
2203.53	35.6667
2200.36	38.3333
2197.19	37.6667
2194.02	36
2190.84	32
2187.66	35.6667
2184.48	36
2181.3	42
2178.12	37.6667
2174.93	33.3333
2171.74	37.6667
2168.55	33.6667
2165.36	40
2162.16	34
2158.97	43.3333
2155.76	44
2152.56	45
2149.36	33.6667
2146.15	35
2142.94	36.6667
2139.73	38.6667
2136.51	31.6667
2133.29	33.6667
2130.08	35
2126.85	40.3333
2123.63	40.3333
2120.4	39
2117.17	37.3333
2113.94	38.6667
2110.71	40
2107.47	38.6667
2104.23	38.6667
2100.99	35
2097.75	35.3333
2094.5	36.6667
2091.26	38.3333
2088.01	34.3333
2084.75	36
2081.5	36.3333
2078.24	30.3333
2074.98	36.3333
2071.72	36.3333
2068.45	32.3333
2065.18	39.3333
2061.92	33
2058.64	32.3333
2055.37	38
2052.09	36
2048.81	43.3333
2045.53	37
2042.25	27.6667
2038.96	33.6667
2035.67	37.3333
2032.38	36.6667
2029.08	33
2025.79	30
2022.49	33.3333
2019.19	40
2015.88	42.3333
2012.58	45.3333
2009.27	29.3333
2005.96	37.3333
2002.64	44.3333
1999.33	36
1996.01	42
1992.69	39.6667
1989.36	37.3333
1986.04	42.6667
1982.71	34.6667
1979.38	35.6667
1976.05	35
1972.71	47
1969.37	41
1966.03	49
1962.69	49
1959.34	48.3333
1955.99	55.3333
1952.64	46
1949.29	48.6667
1945.93	54.3333
1942.58	51
1939.21	48.6667
1935.85	53.3333
1932.49	47
1929.12	39
1925.75	52
1922.37	46
1919	46
1915.62	52
1912.24	44.6667
1908.86	51.6667
1905.47	47
1902.08	47.6667
1898.69	49.6667
1895.3	60.6667
1891.9	53.3333
1888.5	55.3333
1885.1	48.6667
1881.7	57.6667
1878.29	52.3333
1874.88	50.3333
1871.47	45.6667
1868.06	51.6667
1864.64	44
1861.22	47.6667
1857.8	48.6667
1854.38	51
1850.95	42.6667
1847.52	45.6667
1844.09	44.3333
1840.66	52
1837.22	54
1833.78	48.3333
1830.34	43.6667
1826.9	50.3333
1823.45	38.6667
1820	47
1816.55	44.3333
1813.09	50.3333
1809.64	43.3333
1806.18	40.3333
1802.71	49
1799.25	53.6667
1795.78	46.6667
1792.31	44
1788.84	43.6667
1785.36	55.3333
1781.88	43.6667
1778.4	43.6667
1774.92	46.3333
1771.43	39
1767.95	43.3333
1764.45	49.3333
1760.96	44.3333
1757.47	41.3333
1753.97	47.6667
1750.47	40.3333
1746.96	48.3333
1743.45	47.3333
1739.94	39.3333
1736.43	36.3333
1732.92	46.3333
1729.4	46
1725.88	45.3333
1722.36	44.3333
1718.83	51.6667
1715.3	57.6667
1711.77	52
1708.24	48.6667
1704.71	49
1701.17	58
1697.63	52.3333
1694.08	55.3333
1690.54	57.6667
1686.99	55.6667
1683.44	56.6667
1679.88	52
1676.32	55
1672.76	41.3333
1669.2	45
1665.64	55
1662.07	43.6667
1658.5	40.6667
1654.92	43
1651.35	41.3333
1647.77	48.3333
1644.19	47.3333
1640.61	50.3333
1637.02	41.6667
1633.43	49
1629.84	49.6667
1626.24	42
1622.64	36
1619.04	54.3333
1615.44	51
1611.84	54.3333
1608.23	46
1604.62	52
1601	52.3333
1597.39	47.3333
1593.77	44
1590.15	58.3333
1586.52	46
1582.89	49
1579.26	53
1575.63	50.6667
1571.99	58.3333
1568.36	53.6667
1564.72	55.6667
1561.07	59
1557.42	62.6667
1553.78	59.6667
1550.12	58.6667
1546.47	66.3333
1542.81	60.3333
1539.15	70
1535.49	66.3333
1531.82	67
1528.15	69.6667
1524.48	75
1520.81	67.3333
1517.13	68
1513.45	64.6667
1509.77	66
1506.08	71.3333
1502.39	79
1498.7	69.3333
1495.01	69.3333
1491.31	70.6667
1487.61	68.6667
1483.91	71
1480.21	74.6667
1476.5	71
1472.79	71.3333
1469.07	67.6667
1465.36	63.6667
1461.64	67.3333
1457.92	65.3333
1454.19	74.6667
1450.46	65.3333
1446.73	71.6667
1443	70
1439.26	67.6667
1435.52	71
1431.78	73.6667
1428.04	66.6667
1424.29	69.3333
1420.54	79
1416.79	66.6667
1413.03	74.6667
1409.27	79
1405.51	67.3333
1401.75	63
1397.98	80
1394.21	65
1390.44	70.3333
1386.66	69
1382.88	67.3333
1379.1	74.6667
1375.31	69
1371.53	71.6667
1367.74	67.3333
1363.94	69.6667
1360.15	76.6667
1356.35	74.3333
1352.55	72
1348.74	69
1344.93	72.3333
1341.12	71.6667
1337.31	69.3333
1333.49	70
1329.67	64
1325.85	70
1322.03	73.3333
1318.2	72.3333
1314.37	68.3333
1310.53	64.3333
1306.7	72.6667
1302.86	67.6667
1299.01	63
1295.17	75.6667
1291.32	69.3333
1287.47	61
1283.61	70
1279.76	74
1275.9	69.6667
1272.03	72.3333
1268.17	65.6667
1264.3	73
1260.42	70.6667
1256.55	64.3333
1252.67	79.6667
1248.79	75
1244.91	71.6667
1241.02	68.6667
1237.13	72
1233.24	69.6667
1229.34	61
1225.44	75
1221.54	74.3333
1217.63	67.3333
1213.73	64
1209.81	73.6667
1205.9	69
1201.98	68.6667
1198.06	67
1194.14	75.3333
1190.21	70
1186.29	79
1182.35	69
1178.42	75.3333
1174.48	69
1170.54	74.6667
1166.6	71.3333
1162.65	71
1158.7	65.3333
1154.74	73
1150.79	74.3333
1146.83	65.3333
1142.87	68.3333
1138.9	73
1134.93	71.3333
1130.96	69
1126.99	64.3333
1123.01	65.3333
1119.03	63
1115.04	62
1111.06	74.6667
1107.07	71.6667
1103.08	72
1099.08	68
1095.08	61.6667
1091.08	74.6667
1087.07	67.3333
1083.06	72.3333
1079.05	71.3333
1075.04	71.3333
1071.02	64.6667
1067	75
1062.98	63.3333
1058.95	67.3333
1054.92	67.3333
1050.89	65.3333
1046.85	62
1042.81	60.6667
1038.77	64
1034.72	71.3333
1030.67	67.3333
1026.62	68.3333
1022.57	74
1018.51	63.3333
1014.45	64.6667
1010.38	64.6667
1006.32	64.6667
1002.24	73.3333
998.171	63.3333
994.094	65.3333
990.013	64.6667
985.93	66.6667
981.843	69
977.754	69
973.661	66
969.565	66.6667
965.466	70.3333
961.364	70
957.258	67.3333
953.15	62
949.038	70.6667
944.923	74
940.804	64
936.683	74.3333
932.558	71.3333
928.43	66.6667
924.299	63
920.165	70
916.028	70.6667
911.887	70
907.743	67.3333
903.595	71.3333
899.445	67.3333
895.292	70
891.135	70.3333
886.975	65.6667
882.812	62.6667
878.646	58.3333
874.475	66
870.303	66
866.126	63.3333
861.947	66.3333
857.764	70.6667
853.578	68
849.389	68.6667
845.196	65.6667
841	66
836.801	73.3333
832.599	66
828.393	72
824.184	62.6667
819.972	65.6667
815.757	60
811.538	59.3333
807.316	58
803.091	56
798.863	57.6667
794.631	57
790.395	59.3333
786.157	57.3333
781.915	61
777.669	62.6667
773.421	60.3333
769.169	59.6667
764.915	62.6667
760.656	55.3333
756.394	53
752.129	53
747.861	54
743.588	55.3333
739.314	53
735.035	58
730.753	64
726.469	54.3333
722.18	53.3333
717.888	56.6667
713.593	49.6667
709.294	53.3333
704.992	59.6667
700.687	50.3333
696.378	58.6667
692.066	55
687.751	40.6667
683.432	52
679.109	55.6667
674.784	47.3333
670.455	50
666.122	57
661.787	53.3333
657.448	56.3333
653.104	51.3333
648.759	54.3333
644.409	63.3333
640.056	50.6667
635.7	60.6667
631.34	58.6667
626.977	54
622.61	60.6667
618.24	57.3333
613.867	46.6667
609.49	53.6667
605.11	46
600.726	52.6667
596.339	36.6667
591.948	38.3333
587.554	49.3333
583.156	47.3333
578.755	44.6667
574.35	46
569.943	45.3333
565.531	52.6667
561.116	52.3333
556.698	48.3333
552.275	50.3333
547.85	49
543.421	43.3333
538.988	50.3333
534.553	44.6667
530.113	52.6667
525.67	42.6667
521.224	44
516.774	44
512.321	41
507.863	42
503.403	45.3333
498.939	47.6667
494.472	44.3333
490.001	43.3333
485.526	42
481.047	43.6667
476.565	46
472.08	46
467.591	44.6667
463.099	42.3333
458.604	48.3333
454.103	52.3333
449.601	51.3333
445.094	45
440.584	55.3333
436.07	65.6667
431.553	58
427.032	55
422.507	56.6667
417.979	61.3333
413.448	57.6667
408.912	59.3333
404.373	56
399.83	60
395.285	61.6667
390.734	57.3333
386.181	61.6667
381.624	69.3333
377.064	57.3333
372.5	64
367.932	71
363.36	60.3333
358.785	66.3333
354.207	62.3333
349.624	59
345.038	68.6667
340.448	69
335.855	63
331.257	64.3333
326.657	59
322.053	59.6667
317.444	58.6667
312.833	67.3333
308.217	65.3333
303.599	60
298.976	59.6667
294.349	51.6667
289.719	65.3333
285.085	65
280.448	65.6667
275.807	51.3333
271.161	63
266.513	59
261.861	57.6667
257.205	58.3333
252.544	62
247.881	53.3333
243.214	64.3333
238.543	64.6667
233.869	64
229.19	65
224.508	62.6667
219.822	64
215.132	61
210.439	57.6667
205.741	61
201.04	70
196.336	59
191.627	67.6667
186.915	64
182.199	63.3333
177.478	67.3333
172.755	64
168.028	66
163.297	65.3333
158.561	63.6667
153.823	68.6667
149.08	68.3333
144.334	60.3333
139.584	64.6667
134.829	62
130.071	68.6667
125.31	56.6667
120.545	59.3333
115.775	64.6667
111.001	60.6667
106.224	60.3333
101.444	68.3333
96.6594	57
91.8705	56
87.0781	64.6667
82.282	58
77.4812	66.3333
72.6778	59
67.8698	64
63.0582	52.6667
58.2419	54
53.4229	55
48.5993	43.3333
43.772	39.6667
38.941	40
34.1054	41.3333
29.2661	37.6667
24.4231	37.6667
19.5764	37.3333
14.7261	33.3333
9.87099	30.6667
5.01321	34
0.14975	38.3333
-4.71644	37.6667
-9.58634	31
-14.461	31
-19.3393	29.6667
-24.2214	38.3333
-29.1072	33
-33.9977	34.3333
-38.892	32
-43.7901	35.6667
-48.6919	35.6667
-53.5974	33
-58.5078	34
-63.4218	33.6667
-68.3397	33.6667
-73.2613	36.6667
-78.1878	35.3333
-83.117	35.6667
-88.051	36
-92.9888	41
-97.9314	36.3333
-102.877	38
-107.827	31.6667
-112.781	41.6667
-117.739	38.3333
-122.701	32.6667
-127.667	42
-132.637	35.3333
-137.612	34
-142.59	40
-147.572	38.3333
-152.558	33.3333
-157.548	36
-162.542	41.6667
-167.541	43
-172.544	28.6667
-177.55	30
-182.561	43.3333
-187.576	30.3333
-192.595	32.6667
-197.617	35.3333
-202.645	31
-207.676	34.6667
-212.711	30
-217.75	35.3333
-222.794	31.3333
-227.842	31
-232.893	45
-237.949	33.6667
-243.009	33.6667
-248.073	32
-253.142	36.6667
-258.214	27
-263.291	34.6667
-268.371	36.6667
-273.456	32.6667
-278.545	33.6667
-283.639	38.6667
-288.735	37.6667
-293.837	30.3333
-298.943	32.3333
-304.053	43.3333
-309.166	38
-314.285	34.6667
-319.408	29.3333
-324.534	34
-329.665	31
-334.801	28.6667
-339.94	38.3333
-345.083	33.6667
-350.231	33
-355.383	30.6667
-360.539	34.3333
-365.699	41
-370.864	36
-376.033	32
-381.206	42.6667
-386.384	32.3333
-391.565	30.3333
-396.751	34.6667
-401.941	29.6667
-407.136	32
-412.334	33.6667
-417.537	29
-422.745	35.6667
-427.956	33.6667
-433.173	41.3333
-438.392	35.3333
-443.617	32.3333
-448.846	38
-454.078	31.6667
-459.317	37.3333
-464.558	31
-469.804	31.6667
-475.055	35.3333
-480.309	34.6667
-485.568	29.3333
-490.832	27
-496.099	33
-501.372	46.3333
-506.648	31
-511.929	39.3333
-517.215	29.3333
-522.504	30.3333
-527.797	35.6667
-533.097	36.6667
-538.399	41
-543.706	29.3333
-549.018	27.6667
-554.334	33.6667
-559.654	36
-564.979	38.6667
-570.308	35
-575.641	36.3333
-580.98	33
-586.322	32.6667
-591.669	29.3333
-597.02	41.6667
-602.376	38.3333
-607.736	32.3333
-613.1	37
-618.47	32.3333
-623.843	28.6667
-629.222	36.3333
-634.603	34.3333
-639.99	31.3333
-645.382	37
-650.779	32.6667
-656.179	36
-661.583	35.6667
-666.993	35.6667
-672.407	30
-677.825	32
-683.248	29.6667
-688.675	40
-694.108	27
-699.544	33.6667
-704.985	26.3333
-710.431	33
-715.88	36
-721.335	32.3333
-726.795	39.6667
-732.258	26
-737.727	31.3333
-743.2	41
-748.678	38.6667
-754.159	36
-759.646	31.3333
-765.138	34.6667
-770.633	39.6667
-776.133	38
-781.638	34
-787.149	35.6667
-792.663	35.3333
-798.181	36.3333
-803.705	36
-809.233	39.3333
-814.766	33.6667
-820.304	35.3333
-825.846	33
-831.392	31.3333
-836.944	32.3333
-842.499	30
-848.06	36
-853.626	26
-859.195	31.6667
-864.77	28
-870.35	35.3333
-875.934	34.6667
-881.522	45.6667
-887.116	30
-892.714	41
-898.317	32.6667
-903.924	37.3333
-909.537	39.3333
-915.153	30.6667
-920.776	37.6667
-926.401	33
-932.033	36
-937.669	36.6667
-943.31	36
-948.955	33.6667
-954.605	44.3333
-960.26	37
-965.92	36.3333
-971.584	40.6667
-977.254	38.3333
-982.928	31
-988.607	28
-994.291	30.6667
-999.979	43.6667
-1005.67	37
-1011.37	34
-1017.07	37
-1022.78	36.3333
-1028.49	38.6667
-1034.21	32.3333
-1039.93	32
-1045.66	33
-1051.39	44.3333
-1057.13	38.6667
-1062.87	35.6667
-1068.62	35.6667
-1074.37	35
-1080.12	37.6667
-1085.89	40.3333
-1091.65	29.3333
-1097.42	39
-1103.2	36.6667
-1108.98	38.6667
-1114.77	36.6667
-1120.56	27.6667
-1126.35	32.6667
-1132.15	39
-1137.96	30
-1143.77	45.3333
-1149.58	34.6667
-1155.4	35.3333
-1161.23	33.3333
-1167.06	29
-1172.89	33.6667
-1178.73	33.3333
-1184.58	35.3333
-1190.43	36
-1196.28	38
-1202.14	39.6667
-1208.01	36.6667
-1213.88	36
-1219.75	31
-1225.63	40
-1231.52	31
-1237.41	37.3333
-1243.3	37
-1249.2	35.6667
-1255.11	30.6667
-1261.02	37
-1266.93	45
-1272.85	39.3333
-1278.78	32.3333
-1284.71	32
-1290.65	38.6667
-1296.59	25.6667
-1302.53	31.6667
-1308.48	34.6667
-1314.44	35
-1320.4	34.3333
-1326.37	31.3333
-1332.34	39.6667
-1338.31	31.3333
-1344.29	36.6667
-1350.28	42.6667
-1356.27	42
-1362.27	33.6667
-1368.27	36.3333
-1374.28	33
-1380.29	34
-1386.31	38
-1392.33	35.3333
-1051.39	44.3333
-1057.13	38.6667
-1062.87	35.6667
-1068.62	35.6667
-1074.37	35
-1080.12	37.6667
-1085.89	40.3333
-1091.65	29.3333
-1097.42	39
-1103.2	36.6667
-1108.98	38.6667
-1114.77	36.6667
-1120.56	27.6667
-1126.35	32.6667
-1132.15	39
-1137.96	30
-1143.77	45.3333
-1149.58	34.6667
-1155.4	35.3333
-1161.23	33.3333
-1167.06	29
-1172.89	33.6667
-1178.73	33.3333
-1184.58	35.3333
-1190.43	36
-1196.28	38
-1202.14	39.6667
-1208.01	36.6667
-1213.88	36
-1219.75	31
-1225.63	40
-1231.52	31
-1237.41	37.3333
-1243.3	37
-1249.2	35.6667
-1255.11	30.6667
-1261.02	37
-1266.93	45
-1272.85	39.3333
-1278.78	32.3333
-1284.71	32
-1290.65	38.6667
-1296.59	25.6667
-1302.53	31.6667
-1308.48	34.6667
-1314.44	35
-1320.4	34.3333
-1326.37	31.3333
-1332.34	39.6667
-1338.31	31.3333
-1344.29	36.6667
-1350.28	42.6667
-1356.27	42
-1362.27	33.6667
-1368.27	36.3333
-1374.28	33
-1380.29	34
-1386.31	38
-1392.33	35.3333