File: projects/python/data/20231030/txt/tip_600_785 nm_10 s_1_2023_10_30_14_56_57_01.txt
#Sample=tip
#Laser=785 nm
#Gating=600
#Exposition=10 s
#Accumulation=1
#Acquired=30.10.2023 14:56:57
2745.96	156.333
2743.18	157
2740.41	157.667
2737.63	154.333
2734.85	161.667
2732.07	165.667
2729.29	165.667
2726.5	164.667
2723.72	167.333
2720.93	168.333
2718.14	158.667
2715.34	173
2712.55	153.667
2709.75	179.333
2706.95	165.333
2704.15	178
2701.35	165.667
2698.55	176.333
2695.74	171.667
2692.93	175.667
2690.12	177.667
2687.31	188.333
2684.49	176.333
2681.67	184
2678.85	188.333
2676.03	178
2673.21	189.333
2670.38	186.667
2667.56	183.333
2664.73	185.667
2661.9	178.333
2659.06	186
2656.23	183.333
2653.39	197.667
2650.55	197.333
2647.71	196.667
2644.86	190.333
2642.02	194.333
2639.17	199.667
2636.32	192.333
2633.47	197.667
2630.62	205.333
2627.76	189.333
2624.9	198.667
2622.04	208
2619.18	210.333
2616.31	206
2613.45	202.333
2610.58	206
2607.71	209.667
2604.84	202
2601.96	210.333
2599.08	202.333
2596.21	202
2593.32	209.667
2590.44	214
2587.56	222
2584.67	220
2581.78	219.333
2578.89	221
2575.99	225.667
2573.1	235.333
2570.2	231.333
2567.3	237.667
2564.4	227
2561.5	240.333
2558.59	233.333
2555.68	231.667
2552.77	235.333
2549.86	242.333
2546.94	249.667
2544.03	233.667
2541.11	251
2538.19	251
2535.26	244.667
2532.34	246
2529.41	251.333
2526.48	251
2523.55	247.333
2520.62	259.667
2517.68	265.333
2514.74	251
2511.8	263.667
2508.86	268
2505.92	264.333
2502.97	263.333
2500.02	270.333
2497.07	269
2494.12	276.333
2491.16	269.333
2488.2	259.667
2485.25	283.667
2482.28	280.667
2479.32	285
2476.35	290
2473.39	272
2470.42	288.333
2467.44	287
2464.47	289
2461.49	299
2458.51	298.667
2455.53	300.333
2452.55	299
2449.56	301.667
2446.58	306.667
2443.59	316
2440.59	297.333
2437.6	310.333
2434.6	307.667
2431.61	318
2428.61	321.667
2425.6	323
2422.6	321.333
2419.59	316
2416.58	317.333
2413.57	324.667
2410.56	327
2407.54	339.333
2404.52	326.667
2401.5	329
2398.48	325
2395.45	344.667
2392.43	339
2389.4	342
2386.37	336
2383.33	348.333
2380.3	340.333
2377.26	345.667
2374.22	346.333
2371.17	361
2368.13	367.667
2365.08	355.333
2362.03	352.667
2358.98	362.667
2355.93	372.667
2352.87	365.667
2349.81	371.667
2346.75	364.667
2343.69	373
2340.63	364
2337.56	374
2334.49	378.667
2331.42	380.333
2328.35	382
2325.27	378
2322.19	383
2319.11	401.333
2316.03	394.667
2312.94	399.667
2309.85	409
2306.77	404
2303.67	404
2300.58	396.667
2297.48	399
2294.38	407
2291.28	419.667
2288.18	416
2285.07	409
2281.97	426.333
2278.86	416.667
2275.74	408.667
2272.63	430.333
2269.51	416
2266.39	427.667
2263.27	413
2260.15	432
2257.02	428.667
2253.89	432.667
2250.76	436.667
2247.63	432.667
2244.49	447.333
2241.36	439
2238.22	442.667
2235.08	453
2231.93	461
2228.78	453
2225.63	449
2222.48	458.333
2219.33	453
2216.17	467.333
2213.01	476
2209.85	470.667
2206.69	467
2203.53	481.333
2200.36	470.667
2197.19	488.333
2194.02	477.333
2190.84	480
2187.66	488.333
2184.48	496.333
2181.3	480.667
2178.12	488
2174.93	502
2171.74	492.333
2168.55	486
2165.36	503.667
2162.16	484.667
2158.97	513.667
2155.76	536.667
2152.56	514
2149.36	526.667
2146.15	518.333
2142.94	515
2139.73	527.667
2136.51	528.333
2133.29	517.333
2130.08	520.667
2126.85	524
2123.63	541.333
2120.4	542
2117.17	544
2113.94	533.667
2110.71	554.667
2107.47	556.333
2104.23	538.333
2100.99	557.667
2097.75	560
2094.5	563
2091.26	566.333
2088.01	553.667
2084.75	575
2081.5	564
2078.24	561.667
2074.98	587.667
2071.72	559.667
2068.45	590.333
2065.18	592.667
2061.92	599.667
2058.64	608.333
2055.37	589.667
2052.09	596.667
2048.81	617.333
2045.53	584
2042.25	603
2038.96	614
2035.67	616.333
2032.38	614.667
2029.08	637.667
2025.79	617.667
2022.49	647.333
2019.19	634.667
2015.88	631
2012.58	640
2009.27	637.667
2005.96	631.333
2002.64	630
1999.33	646.333
1996.01	655.333
1992.69	656.333
1989.36	652
1986.04	663.333
1982.71	655.667
1979.38	648.333
1976.05	665.667
1972.71	677.667
1969.37	673
1966.03	684.667
1962.69	705.667
1959.34	715
1955.99	701
1952.64	712
1949.29	696
1945.93	705.667
1942.58	706.667
1939.21	718
1935.85	719.667
1932.49	718.333
1929.12	728.667
1925.75	736
1922.37	731.333
1919	747.667
1915.62	731
1912.24	752
1908.86	754.667
1905.47	753.667
1902.08	762.333
1898.69	760.667
1895.3	784.667
1891.9	767.667
1888.5	773.333
1885.1	768
1881.7	788.333
1878.29	783
1874.88	781
1871.47	804.667
1868.06	797.333
1864.64	806.667
1861.22	813.333
1857.8	796.333
1854.38	807.333
1850.95	818.333
1847.52	827.667
1844.09	827
1840.66	827.667
1837.22	847.333
1833.78	835.667
1830.34	839.333
1826.9	825
1823.45	854
1820	857
1816.55	862.667
1813.09	872.667
1809.64	877.333
1806.18	875.333
1802.71	903.667
1799.25	891
1795.78	889
1792.31	893.667
1788.84	905.667
1785.36	938.667
1781.88	908.333
1778.4	908
1774.92	922.333
1771.43	924.667
1767.95	951
1764.45	944
1760.96	962.333
1757.47	946.667
1753.97	956.333
1750.47	959
1746.96	973.667
1743.45	973.667
1739.94	987.667
1736.43	978
1732.92	1003.67
1729.4	1006
1725.88	1023.67
1722.36	1027
1718.83	1023.67
1715.3	1006.67
1711.77	1046
1708.24	1049.67
1704.71	1068.67
1701.17	1078.33
1697.63	1085.67
1694.08	1105
1690.54	1107
1686.99	1125.67
1683.44	1117.67
1679.88	1126.33
1676.32	1152.33
1672.76	1166.67
1669.2	1165.67
1665.64	1169.33
1662.07	1168
1658.5	1197
1654.92	1205.33
1651.35	1189.67
1647.77	1195.67
1644.19	1203.33
1640.61	1204.33
1637.02	1187
1633.43	1199.67
1629.84	1205.33
1626.24	1198
1622.64	1201
1619.04	1187.33
1615.44	1206.33
1611.84	1191.33
1608.23	1202
1604.62	1182.67
1601	1203.33
1597.39	1198
1593.77	1203.67
1590.15	1206.67
1586.52	1193.67
1582.89	1222
1579.26	1196
1575.63	1199.33
1571.99	1207.67
1568.36	1212.67
1564.72	1233.33
1561.07	1235.33
1557.42	1221.33
1553.78	1230.33
1550.12	1237
1546.47	1235.67
1542.81	1266
1539.15	1221.33
1535.49	1240.33
1531.82	1255.67
1528.15	1252.67
1524.48	1258.33
1520.81	1257.33
1517.13	1234.67
1513.45	1235.67
1509.77	1258.67
1506.08	1261
1502.39	1256.33
1498.7	1254.67
1495.01	1250.33
1491.31	1275
1487.61	1256.67
1483.91	1254.67
1480.21	1286.33
1476.5	1284.67
1472.79	1317
1469.07	1327.67
1465.36	1329.67
1461.64	1335.67
1457.92	1359.67
1454.19	1357.33
1450.46	1358.33
1446.73	1340
1443	1340.67
1439.26	1354.33
1435.52	1331.33
1431.78	1312
1428.04	1341.33
1424.29	1323.67
1420.54	1307.33
1416.79	1313.33
1413.03	1314.67
1409.27	1317.33
1405.51	1316.67
1401.75	1319
1397.98	1306
1394.21	1305.33
1390.44	1294.33
1386.66	1316.67
1382.88	1303.67
1379.1	1281.33
1375.31	1302.67
1371.53	1317.67
1367.74	1320.67
1363.94	1313
1360.15	1317.33
1356.35	1336.67
1352.55	1337.33
1348.74	1346
1344.93	1353.67
1341.12	1362.33
1337.31	1363.33
1333.49	1393.33
1329.67	1371.67
1325.85	1351.33
1322.03	1386
1318.2	1400.33
1314.37	1408.67
1310.53	1388.67
1306.7	1408
1302.86	1395.33
1299.01	1417
1295.17	1433
1291.32	1448
1287.47	1443.33
1283.61	1452
1279.76	1462.33
1275.9	1465.67
1272.03	1462.67
1268.17	1448.33
1264.3	1453.33
1260.42	1434.33
1256.55	1475
1252.67	1429.33
1248.79	1423
1244.91	1431.33
1241.02	1416
1237.13	1419.33
1233.24	1440
1229.34	1397.33
1225.44	1376
1221.54	1379.67
1217.63	1368.67
1213.73	1351
1209.81	1326.33
1205.9	1321.33
1201.98	1312.33
1198.06	1306.33
1194.14	1302.33
1190.21	1289.67
1186.29	1305.33
1182.35	1302
1178.42	1293
1174.48	1286.33
1170.54	1300
1166.6	1282
1162.65	1302
1158.7	1301
1154.74	1312
1150.79	1311
1146.83	1316
1142.87	1301.33
1138.9	1312.67
1134.93	1318.33
1130.96	1309.33
1126.99	1316.33
1123.01	1310
1119.03	1324.67
1115.04	1330.67
1111.06	1340.67
1107.07	1327
1103.08	1360
1099.08	1343.67
1095.08	1347.67
1091.08	1368.67
1087.07	1350.33
1083.06	1364.67
1079.05	1381
1075.04	1367
1071.02	1354.33
1067	1400
1062.98	1349.67
1058.95	1377
1054.92	1359.33
1050.89	1357
1046.85	1386.33
1042.81	1392.67
1038.77	1377
1034.72	1379
1030.67	1358
1026.62	1368.33
1022.57	1386
1018.51	1387.67
1014.45	1379.33
1010.38	1389.67
1006.32	1399.33
1002.24	1403.33
998.171	1414.67
994.094	1431.67
990.013	1420.33
985.93	1426.67
981.843	1440.33
977.754	1449
973.661	1456.67
969.565	1474.67
965.466	1488.67
961.364	1488
957.258	1500
953.15	1492
949.038	1494.67
944.923	1504
940.804	1523.33
936.683	1518
932.558	1509.67
928.43	1519
924.299	1512.33
920.165	1529.67
916.028	1533.67
911.887	1520.67
907.743	1523.67
903.595	1528.33
899.445	1519
895.292	1514
891.135	1512
886.975	1526
882.812	1540.67
878.646	1533
874.475	1560.33
870.303	1553.33
866.126	1568
861.947	1586
857.764	1591.33
853.578	1585.33
849.389	1590
845.196	1586.67
841	1588.33
836.801	1591.67
832.599	1617.67
828.393	1588.67
824.184	1602.67
819.972	1596.33
815.757	1609.33
811.538	1567.33
807.316	1571
803.091	1597.67
798.863	1611.67
794.631	1583
790.395	1574.67
786.157	1579.67
781.915	1565
777.669	1578
773.421	1608.33
769.169	1625
764.915	1600.67
760.656	1626
756.394	1644
752.129	1636
747.861	1655
743.588	1643
739.314	1655
735.035	1675.67
730.753	1664.33
726.469	1661.33
722.18	1653.33
717.888	1673.33
713.593	1647.33
709.294	1668.33
704.992	1665.67
700.687	1649.33
696.378	1651
692.066	1642.67
687.751	1657.33
683.432	1617.33
679.109	1662
674.784	1642.67
670.455	1657.33
666.122	1647.67
661.787	1665
657.448	1663.33
653.104	1687
648.759	1680.33
644.409	1689.67
640.056	1694.67
635.7	1705.33
631.34	1707
626.977	1705.67
622.61	1727.67
618.24	1720.67
613.867	1731.67
609.49	1728.33
605.11	1727.33
600.726	1726
596.339	1716.33
591.948	1724
587.554	1731.67
583.156	1724.67
578.755	1704.67
574.35	1736.67
569.943	1732.33
565.531	1703
561.116	1737.33
556.698	1756.67
552.275	1731.33
547.85	1742.33
543.421	1754.33
538.988	1773
534.553	1778.67
530.113	1765
525.67	1788.33
521.224	1793
516.774	1812
512.321	1774.67
507.863	1765.33
503.403	1798.33
498.939	1786
494.472	1798.67
490.001	1800.33
485.526	1757
481.047	1796
476.565	1787.67
472.08	1769
467.591	1807.67
463.099	1795.33
458.604	1801.67
454.103	1794.33
449.601	1815.67
445.094	1837
440.584	1840.33
436.07	1871.67
431.553	1875.33
427.032	1882.67
422.507	1892.33
417.979	1888.33
413.448	1915.67
408.912	1931.67
404.373	1935
399.83	1921.33
395.285	1888
390.734	1900.67
386.181	1933
381.624	1903.33
377.064	1934
372.5	1941.33
367.932	1953
363.36	1972.33
358.785	1938.67
354.207	1969.33
349.624	1961.67
345.038	2009.33
340.448	1998
335.855	2000.67
331.257	1976.33
326.657	2031.67
322.053	2020
317.444	2033.67
312.833	2072.33
308.217	2064
303.599	2098
298.976	2112.33
294.349	2139
289.719	2179
285.085	2207.67
280.448	2224
275.807	2268
271.161	2271.67
266.513	2306.33
261.861	2325
257.205	2352
252.544	2371
247.881	2404.67
243.214	2446.67
238.543	2487.33
233.869	2507
229.19	2597.67
224.508	2636.33
219.822	2656.67
215.132	2750.67
210.439	2739.33
205.741	2854
201.04	2907
196.336	2967.33
191.627	3007.67
186.915	3082.33
182.199	3094
177.478	3125
172.755	3200.33
168.028	3260
163.297	3336.33
158.561	3385
153.823	3449
149.08	3490.67
144.334	3515
139.584	3616
134.829	3665.67
130.071	3729.67
125.31	3900.33
120.545	4011
115.775	4171.67
111.001	4375
106.224	4671.67
101.444	4841.33
96.6594	5146.33
91.8705	5550.67
87.0781	6175.67
82.282	6802
77.4812	7843.33
72.6778	9364.67
67.8698	12579.3
63.0582	15976
58.2419	18724
53.4229	21602
48.5993	25025
43.772	29693
38.941	36412.7
34.1054	46565
29.2661	61491
24.4231	64524
19.5764	64524
14.7261	64524
9.87099	64524
5.01321	64524
0.14975	64524
-4.71644	64524
-9.58634	64524
-14.461	64524
-19.3393	64524
-24.2214	64524
-29.1072	64524
-33.9977	64524
-38.892	42148.7
-43.7901	27865.3
-48.6919	20641.3
-53.5974	15645.3
-58.5078	12052.3
-63.4218	9329.67
-68.3397	7286.67
-73.2613	5702.67
-78.1878	4491.33
-83.117	3526
-88.051	2883.33
-92.9888	2348.33
-97.9314	1937.33
-102.877	1612.33
-107.827	1297.33
-112.781	1047
-117.739	860
-122.701	711.667
-127.667	598.667
-132.637	505
-137.612	421.667
-142.59	375.333
-147.572	320.333
-152.558	278.667
-157.548	259
-162.542	235.333
-167.541	209.667
-172.544	201
-177.55	182.667
-182.561	173.667
-187.576	165.667
-192.595	171.333
-197.617	162
-202.645	147.667
-207.676	148.667
-212.711	151.667
-217.75	147
-222.794	137.667
-227.842	137
-232.893	131
-237.949	127
-243.009	127.667
-248.073	120.667
-253.142	124.667
-258.214	114
-263.291	111
-268.371	107.667
-273.456	109
-278.545	113.667
-283.639	98.6667
-288.735	103.333
-293.837	98.6667
-298.943	98
-304.053	106
-309.166	87
-314.285	97.3333
-319.408	90.6667
-324.534	85.6667
-329.665	87.3333
-334.801	87.6667
-339.94	76
-345.083	82
-350.231	82.6667
-355.383	81.3333
-360.539	73.6667
-365.699	77
-370.864	69.6667
-376.033	86.3333
-381.206	64.3333
-386.384	67.6667
-391.565	62.6667
-396.751	69.6667
-401.941	69.6667
-407.136	68.3333
-412.334	68.6667
-417.537	73.3333
-422.745	71.6667
-427.956	74
-433.173	66
-438.392	64.6667
-443.617	62
-448.846	71.6667
-454.078	58.3333
-459.317	58.6667
-464.558	65
-469.804	54.6667
-475.055	60.3333
-480.309	62.3333
-485.568	69
-490.832	60
-496.099	59.3333
-501.372	58.6667
-506.648	62.3333
-511.929	56.6667
-517.215	63.3333
-522.504	56.3333
-527.797	57.6667
-533.097	61.6667
-538.399	56
-543.706	59.3333
-549.018	58
-554.334	59.6667
-559.654	64
-564.979	61.6667
-570.308	53
-575.641	54
-580.98	56
-586.322	63.6667
-591.669	50.3333
-597.02	62.6667
-602.376	61
-607.736	60.3333
-613.1	67
-618.47	61
-623.843	61.6667
-629.222	56.6667
-634.603	54.6667
-639.99	62.6667
-645.382	65.6667
-650.779	51.6667
-656.179	59.6667
-661.583	72.3333
-666.993	66.3333
-672.407	69
-677.825	62
-683.248	57
-688.675	63.3333
-694.108	59.3333
-699.544	68.3333
-704.985	52.6667
-710.431	67
-715.88	64
-721.335	52.6667
-726.795	64.6667
-732.258	60.3333
-737.727	58.6667
-743.2	64
-748.678	61
-754.159	61
-759.646	57.6667
-765.138	53
-770.633	65.6667
-776.133	63
-781.638	62
-787.149	62.6667
-792.663	53.3333
-798.181	65.6667
-803.705	66.6667
-809.233	59
-814.766	52
-820.304	62
-825.846	54.6667
-831.392	66.3333
-836.944	64.3333
-842.499	56
-848.06	63.6667
-853.626	65.6667
-859.195	62.6667
-864.77	66
-870.35	61.3333
-875.934	56.3333
-881.522	57.6667
-887.116	61.3333
-892.714	58.6667
-898.317	64
-903.924	64.3333
-909.537	57
-915.153	61
-920.776	53
-926.401	58.6667
-932.033	57
-937.669	61
-943.31	64.6667
-948.955	56.3333
-954.605	56.3333
-960.26	65
-965.92	56
-971.584	57.3333
-977.254	72
-982.928	62.6667
-988.607	68.3333
-994.291	64.3333
-999.979	66.3333
-1005.67	57
-1011.37	66
-1017.07	60.3333
-1022.78	66.3333
-1028.49	66.3333
-1034.21	67
-1039.93	69.6667
-1045.66	68.6667
-1051.39	65.6667
-1057.13	65.3333
-1062.87	68
-1068.62	71.3333
-1074.37	62.6667
-1080.12	70.6667
-1085.89	67
-1091.65	76.3333
-1097.42	65
-1103.2	78.3333
-1108.98	85.3333
-1114.77	68.3333
-1120.56	81
-1126.35	75
-1132.15	79.3333
-1137.96	83
-1143.77	83.3333
-1149.58	71.3333
-1155.4	86.3333
-1161.23	86.6667
-1167.06	98
-1172.89	119.667
-1178.73	162.667
-1184.58	217.667
-1190.43	264
-1196.28	279
-1202.14	326.667
-1208.01	359.333
-1213.88	413.667
-1219.75	493
-1225.63	573
-1231.52	676.667
-1237.41	797
-1243.3	1025.33
-1249.2	1744
-1255.11	1927.67
-1261.02	1695.67
-1266.93	1436.67
-1272.85	1016.33
-1278.78	448.667
-1284.71	192.667
-1290.65	156.667
-1296.59	136
-1302.53	122.667
-1308.48	122.667
-1314.44	114.333
-1320.4	103.667
-1326.37	97.6667
-1332.34	101.667
-1338.31	96
-1344.29	86.6667
-1350.28	91
-1356.27	87
-1362.27	83
-1368.27	82
-1374.28	73
-1380.29	61.3333
-1386.31	56
-1392.33	51.6667
-1060	71.3333
-1065.74	73
-1071.49	66.6667
-1077.25	72.3333
-1083.01	74
-1088.77	71
-1094.54	76.3333
-1100.31	80.3333
-1106.09	75
-1111.87	70.6667
-1117.66	75
-1123.45	73
-1129.25	78.3333
-1135.05	80
-1140.86	84.3333
-1146.67	76.6667
-1152.49	89
-1158.32	89.3333
-1164.14	92.6667
-1169.98	110.667
-1175.81	135.667
-1181.66	197.667
-1187.5	244.667
-1193.35	272.667
-1199.21	296.333
-1205.08	348.333
-1210.94	392.333
-1216.82	465.667
-1222.69	540
-1228.58	603.667
-1234.46	705.333
-1240.35	868.333
-1246.25	1436
-1252.16	1888.67
-1258.06	1862.33
-1263.97	1548.33
-1269.89	1252.67
-1275.82	707.667
-1281.74	259.667
-1287.68	165.667
-1293.62	155.333
-1299.56	127.667
-1305.51	116.333
-1311.46	103.667
-1317.42	109.333
-1323.38	95.6667
-1329.35	99.3333
-1335.32	95
-1341.3	92.3333
-1347.29	85.3333
-1353.28	83.6667
-1359.27	81.3333
-1365.27	80.3333
-1371.27	79
-1377.28	71.6667
-1383.3	64.6667
-1389.32	60.6667
-1392.33	51.6667