File: projects/python/data/20231030/txt/tip_600_785 nm_10 s_1_2023_10_30_14_55_47_01.txt
#Sample=tip
#Laser=785 nm
#Gating=600
#Exposition=10 s
#Accumulation=1
#Acquired=30.10.2023 14:55:47
2745.96	136
2743.18	137.333
2740.41	130.333
2737.63	147
2734.85	142
2732.07	144.667
2729.29	143.667
2726.5	152
2723.72	144
2720.93	152.667
2718.14	140.667
2715.34	148
2712.55	145.667
2709.75	148.333
2706.95	135.667
2704.15	150.333
2701.35	146
2698.55	153
2695.74	150
2692.93	157.333
2690.12	147.667
2687.31	156.667
2684.49	156
2681.67	156.667
2678.85	155
2676.03	155
2673.21	163.333
2670.38	153.667
2667.56	159.333
2664.73	155.333
2661.9	160.667
2659.06	163.667
2656.23	164.667
2653.39	164
2650.55	176.333
2647.71	167.667
2644.86	167
2642.02	169.333
2639.17	176.333
2636.32	162
2633.47	163.667
2630.62	178.667
2627.76	171.333
2624.9	174.667
2622.04	184
2619.18	170.333
2616.31	179.667
2613.45	168.333
2610.58	178.667
2607.71	174.667
2604.84	174.333
2601.96	177.333
2599.08	180.333
2596.21	185
2593.32	189.333
2590.44	186
2587.56	187.333
2584.67	187
2581.78	188.333
2578.89	187.667
2575.99	188.667
2573.1	187.667
2570.2	197.667
2567.3	195.667
2564.4	195.333
2561.5	199.667
2558.59	206
2555.68	209.667
2552.77	203.667
2549.86	202.333
2546.94	209
2544.03	207.667
2541.11	219.333
2538.19	208
2535.26	206.333
2532.34	205.333
2529.41	214.667
2526.48	223
2523.55	217.667
2520.62	217.667
2517.68	223
2514.74	216.333
2511.8	228.333
2508.86	220.667
2505.92	216
2502.97	230.333
2500.02	224.333
2497.07	224
2494.12	244.333
2491.16	229
2488.2	247.333
2485.25	233.667
2482.28	244.667
2479.32	248
2476.35	235.667
2473.39	234.333
2470.42	240
2467.44	238.667
2464.47	250.667
2461.49	248
2458.51	247
2455.53	253.667
2452.55	259.333
2449.56	262
2446.58	263.333
2443.59	261.667
2440.59	259.667
2437.6	256
2434.6	259
2431.61	269.333
2428.61	264.667
2425.6	266
2422.6	261.333
2419.59	277.333
2416.58	334.333
2413.57	269.333
2410.56	278
2407.54	277.667
2404.52	272.667
2401.5	293.667
2398.48	290.333
2395.45	279.333
2392.43	279
2389.4	288.333
2386.37	285.333
2383.33	290.333
2380.3	295
2377.26	290.333
2374.22	289.667
2371.17	304.667
2368.13	300.667
2365.08	301
2362.03	298.667
2358.98	303.667
2355.93	305.333
2352.87	307.333
2349.81	319
2346.75	309.333
2343.69	308.667
2340.63	314
2337.56	317.333
2334.49	331
2331.42	311.333
2328.35	327.333
2325.27	326
2322.19	317.333
2319.11	320.667
2316.03	326
2312.94	315.333
2309.85	331.667
2306.77	332.667
2303.67	334.333
2300.58	341.667
2297.48	336.667
2294.38	346
2291.28	342.333
2288.18	339
2285.07	348
2281.97	352
2278.86	350.667
2275.74	350
2272.63	351.667
2269.51	352
2266.39	360.333
2263.27	340.667
2260.15	358.667
2257.02	363
2253.89	356
2250.76	365.333
2247.63	361.333
2244.49	366
2241.36	368.333
2238.22	376
2235.08	375.667
2231.93	378
2228.78	377.333
2225.63	384.333
2222.48	394.667
2219.33	384.333
2216.17	384
2213.01	394.333
2209.85	395.667
2206.69	392
2203.53	391.667
2200.36	399.333
2197.19	389.667
2194.02	397.667
2190.84	404.667
2187.66	401.333
2184.48	410
2181.3	399.333
2178.12	409
2174.93	414
2171.74	419.667
2168.55	423.333
2165.36	419
2162.16	429
2158.97	420
2155.76	430
2152.56	434
2149.36	429.667
2146.15	451
2142.94	435.667
2139.73	438.667
2136.51	424
2133.29	457.333
2130.08	435
2126.85	451.667
2123.63	447.333
2120.4	439.333
2117.17	451
2113.94	442.333
2110.71	455.333
2107.47	451.667
2104.23	452
2100.99	463.667
2097.75	443.667
2094.5	462.333
2091.26	459.333
2088.01	458.667
2084.75	473
2081.5	463.667
2078.24	467.667
2074.98	483.667
2071.72	473.667
2068.45	493
2065.18	477.667
2061.92	499
2058.64	488.333
2055.37	493
2052.09	508.667
2048.81	505
2045.53	501.333
2042.25	503
2038.96	507.333
2035.67	506.667
2032.38	494.333
2029.08	522.333
2025.79	518
2022.49	519.667
2019.19	512.333
2015.88	514.333
2012.58	533.333
2009.27	525.667
2005.96	522.333
2002.64	522.667
1999.33	538
1996.01	543.333
1992.69	548.667
1989.36	546.667
1986.04	541.333
1982.71	534.667
1979.38	547
1976.05	562
1972.71	547
1969.37	562.333
1966.03	569
1962.69	576
1959.34	586
1955.99	578.333
1952.64	574
1949.29	584
1945.93	584.667
1942.58	589.667
1939.21	597
1935.85	620
1932.49	602.667
1929.12	618.667
1925.75	610.333
1922.37	632.333
1919	603.333
1915.62	629.333
1912.24	624.667
1908.86	621.333
1905.47	638.333
1902.08	640.667
1898.69	620.333
1895.3	627.333
1891.9	640.333
1888.5	644.333
1885.1	636.333
1881.7	648
1878.29	631.333
1874.88	650
1871.47	659.667
1868.06	659.667
1864.64	654.333
1861.22	654
1857.8	663
1854.38	671.667
1850.95	670.333
1847.52	684.333
1844.09	692.667
1840.66	697.667
1837.22	681
1833.78	692
1830.34	696.333
1826.9	692
1823.45	700.333
1820	723.667
1816.55	733.667
1813.09	729.333
1809.64	723
1806.18	737.667
1802.71	741
1799.25	769
1795.78	745
1792.31	745.667
1788.84	765.667
1785.36	782.333
1781.88	776.667
1778.4	757.333
1774.92	789
1771.43	788
1767.95	796.333
1764.45	793.333
1760.96	796.667
1757.47	802.667
1753.97	798.667
1750.47	807.667
1746.96	835.667
1743.45	824.667
1739.94	831.667
1736.43	839.667
1732.92	843.333
1729.4	839.333
1725.88	857
1722.36	845.333
1718.83	853.333
1715.3	866.667
1711.77	870
1708.24	910
1704.71	894.333
1701.17	904.333
1697.63	924
1694.08	923.333
1690.54	953.667
1686.99	947.667
1683.44	956.667
1679.88	977.667
1676.32	969.333
1672.76	995
1669.2	979
1665.64	1007.33
1662.07	997.333
1658.5	1014.67
1654.92	1014.67
1651.35	1014.33
1647.77	1000
1644.19	1020.67
1640.61	1024
1637.02	1042.33
1633.43	1024
1629.84	1026
1626.24	1009.67
1622.64	1030.33
1619.04	1018
1615.44	1008.33
1611.84	1008
1608.23	1005
1604.62	1022.67
1601	1015.33
1597.39	1015.67
1593.77	1021
1590.15	1019.33
1586.52	1034
1582.89	1036.33
1579.26	1024.33
1575.63	1036.67
1571.99	1039
1568.36	1033.33
1564.72	1043.33
1561.07	1057.67
1557.42	1065.67
1553.78	1056
1550.12	1048.67
1546.47	1060
1542.81	1074.33
1539.15	1056
1535.49	1051.33
1531.82	1055.67
1528.15	1056.33
1524.48	1073.67
1520.81	1074
1517.13	1069.33
1513.45	1070.33
1509.77	1076.67
1506.08	1069.67
1502.39	1072.67
1498.7	1067
1495.01	1080
1491.31	1075.33
1487.61	1103.67
1483.91	1092
1480.21	1104
1476.5	1105
1472.79	1126.67
1469.07	1125.67
1465.36	1130.33
1461.64	1127
1457.92	1149.33
1454.19	1154.67
1450.46	1150.67
1446.73	1141.67
1443	1144.33
1439.26	1148.33
1435.52	1155.67
1431.78	1150
1428.04	1118
1424.29	1147
1420.54	1109.67
1416.79	1122.33
1413.03	1113.67
1409.27	1124.67
1405.51	1114
1401.75	1122.67
1397.98	1120.67
1394.21	1121.33
1390.44	1103.33
1386.66	1103
1382.88	1109.33
1379.1	1117
1375.31	1102.33
1371.53	1104.33
1367.74	1094.33
1363.94	1115
1360.15	1140.33
1356.35	1124.33
1352.55	1119.33
1348.74	1145.67
1344.93	1167
1341.12	1164
1337.31	1145.67
1333.49	1160.33
1329.67	1168
1325.85	1176.33
1322.03	1176.33
1318.2	1187
1314.37	1176.67
1310.53	1199.33
1306.7	1215.33
1302.86	1237
1299.01	1210.67
1295.17	1199
1291.32	1252
1287.47	1233.67
1283.61	1246.67
1279.76	1249.33
1275.9	1265.33
1272.03	1262
1268.17	1246.33
1264.3	1268
1260.42	1246.67
1256.55	1228
1252.67	1247.33
1248.79	1227.33
1244.91	1236
1241.02	1193.33
1237.13	1214.67
1233.24	1187
1229.34	1200.33
1225.44	1165
1221.54	1183
1217.63	1131
1213.73	1159.33
1209.81	1111.67
1205.9	1115.67
1201.98	1124.33
1198.06	1097.67
1194.14	1092.67
1190.21	1088.33
1186.29	1087.33
1182.35	1101
1178.42	1094
1174.48	1102.67
1170.54	1079.67
1166.6	1093.33
1162.65	1102.67
1158.7	1098
1154.74	1090
1150.79	1101.33
1146.83	1093
1142.87	1100.33
1138.9	1098.33
1134.93	1103.33
1130.96	1098
1126.99	1103
1123.01	1112
1119.03	1109.33
1115.04	1127.67
1111.06	1119.33
1107.07	1118.33
1103.08	1126.67
1099.08	1126.33
1095.08	1118.33
1091.08	1126.33
1087.07	1132
1083.06	1140.67
1079.05	1144.67
1075.04	1156.67
1071.02	1122.33
1067	1132
1062.98	1155.33
1058.95	1151
1054.92	1135.67
1050.89	1137.67
1046.85	1140.33
1042.81	1132.33
1038.77	1139.33
1034.72	1136
1030.67	1146
1026.62	1135.33
1022.57	1129.33
1018.51	1149
1014.45	1157
1010.38	1169.67
1006.32	1148.67
1002.24	1160.33
998.171	1165.67
994.094	1151
990.013	1164.33
985.93	1178
981.843	1197
977.754	1188.67
973.661	1199.33
969.565	1211.33
965.466	1229
961.364	1227.67
957.258	1240
953.15	1231.33
949.038	1235
944.923	1256.33
940.804	1237
936.683	1256
932.558	1237.33
928.43	1228.33
924.299	1249.67
920.165	1271
916.028	1240.33
911.887	1250
907.743	1245.33
903.595	1270.33
899.445	1239.33
895.292	1259.67
891.135	1248.67
886.975	1257.67
882.812	1285.33
878.646	1259.67
874.475	1264.33
870.303	1308.33
866.126	1303.33
861.947	1289.67
857.764	1302
853.578	1301.67
849.389	1293.67
845.196	1295
841	1315
836.801	1328.67
832.599	1337.67
828.393	1319
824.184	1328
819.972	1307
815.757	1303
811.538	1295.33
807.316	1304.67
803.091	1303.67
798.863	1311
794.631	1271.67
790.395	1291
786.157	1309
781.915	1289.33
777.669	1291
773.421	1307.67
769.169	1346.67
764.915	1325.67
760.656	1322.33
756.394	1342.67
752.129	1334.33
747.861	1338.67
743.588	1366.33
739.314	1335.33
735.035	1360
730.753	1367.33
726.469	1362
722.18	1357.33
717.888	1379.33
713.593	1371.67
709.294	1399.33
704.992	1458.33
700.687	1351
696.378	1371.33
692.066	1350
687.751	1358.33
683.432	1364
679.109	1335.33
674.784	1333.33
670.455	1358.67
666.122	1352
661.787	1356
657.448	1367.33
653.104	1346.33
648.759	1385
644.409	1371
640.056	1386.67
635.7	1417.67
631.34	1423.33
626.977	1413.33
622.61	1422.67
618.24	1407
613.867	1419.33
609.49	1399
605.11	1407.33
600.726	1406.67
596.339	1400.33
591.948	1420
587.554	1415.33
583.156	1394
578.755	1418.33
574.35	1403.33
569.943	1412
565.531	1425.33
561.116	1427.33
556.698	1427.67
552.275	1406.33
547.85	1411.67
543.421	1405
538.988	1427.33
534.553	1441.67
530.113	1458.67
525.67	1457.67
521.224	1465.67
516.774	1458
512.321	1457.67
507.863	1457.67
503.403	1469.33
498.939	1458
494.472	1441.33
490.001	1450
485.526	1439
481.047	1469
476.565	1444
472.08	1461.33
467.591	1457
463.099	1474.67
458.604	1480.33
454.103	1495
449.601	1521.67
445.094	1501.33
440.584	1519
436.07	1520.67
431.553	1517
427.032	1549
422.507	1564.67
417.979	1574
413.448	1572
408.912	1558
404.373	1567.33
399.83	1551.67
395.285	1553.67
390.734	1557.33
386.181	1578.33
381.624	1568.33
377.064	1582.67
372.5	1585.67
367.932	1588.67
363.36	1598.67
358.785	1633.67
354.207	1616
349.624	1620.33
345.038	1623.67
340.448	1639.33
335.855	1631.67
331.257	1637.67
326.657	1644.67
322.053	1663.33
317.444	1680.33
312.833	1718.33
308.217	1723.33
303.599	1739.33
298.976	1742.33
294.349	1797
289.719	1806.67
285.085	1822.67
280.448	1841.33
275.807	1846.67
271.161	1874
266.513	1906.33
261.861	1920
257.205	1941.33
252.544	1993.33
247.881	2009.67
243.214	2068.67
238.543	2100
233.869	2156
229.19	2188
224.508	2252.67
219.822	2273
215.132	2336
210.439	2369.67
205.741	2446.67
201.04	2479.67
196.336	2574.67
191.627	2570.33
186.915	2662
182.199	2697
177.478	2684.33
172.755	2789.33
168.028	2847.33
163.297	2857
158.561	3008
153.823	3083.33
149.08	3106.33
144.334	3110.33
139.584	3188.67
134.829	3235.33
130.071	3358.33
125.31	3512
120.545	3635.33
115.775	3745.67
111.001	3918
106.224	4173.67
101.444	4430.33
96.6594	4720.33
91.8705	5149
87.0781	5650.33
82.282	6355
77.4812	7369
72.6778	9006
67.8698	12115.3
63.0582	15639
58.2419	18468
53.4229	21523.3
48.5993	24916
43.772	29726
38.941	36505.7
34.1054	46854.7
29.2661	62081
24.4231	64524
19.5764	64524
14.7261	64524
9.87099	64524
5.01321	64524
0.14975	64524
-4.71644	64524
-9.58634	64524
-14.461	64524
-19.3393	64524
-24.2214	64524
-29.1072	64524
-33.9977	64524
-38.892	42258.3
-43.7901	27810
-48.6919	20791.3
-53.5974	15728.7
-58.5078	12128.3
-63.4218	9383.33
-68.3397	7350.33
-73.2613	5751.33
-78.1878	4501
-83.117	3579
-88.051	2852.67
-92.9888	2357.67
-97.9314	1955.33
-102.877	1592
-107.827	1261.67
-112.781	1026
-117.739	842.333
-122.701	736.333
-127.667	614.667
-132.637	495
-137.612	435.333
-142.59	365.667
-147.572	320.333
-152.558	264
-157.548	252.333
-162.542	237.667
-167.541	198.333
-172.544	193.333
-177.55	188.333
-182.561	170.333
-187.576	161.667
-192.595	164.667
-197.617	154
-202.645	146
-207.676	150.333
-212.711	146
-217.75	144.667
-222.794	140
-227.842	145
-232.893	133.333
-237.949	138
-243.009	137.333
-248.073	122.333
-253.142	133
-258.214	117.333
-263.291	115.333
-268.371	108.667
-273.456	108.667
-278.545	111.667
-283.639	105
-288.735	101.333
-293.837	102.667
-298.943	97
-304.053	99
-309.166	98.3333
-314.285	79.6667
-319.408	83
-324.534	83.3333
-329.665	86.6667
-334.801	85.6667
-339.94	75.6667
-345.083	76.6667
-350.231	79.3333
-355.383	79
-360.539	74.3333
-365.699	69.6667
-370.864	69.3333
-376.033	73
-381.206	71
-386.384	70
-391.565	73.6667
-396.751	74.3333
-401.941	80.6667
-407.136	78.3333
-412.334	64.6667
-417.537	69.6667
-422.745	72.3333
-427.956	62
-433.173	66.6667
-438.392	62.3333
-443.617	61.6667
-448.846	62.6667
-454.078	70.3333
-459.317	63.3333
-464.558	57.6667
-469.804	52
-475.055	58.3333
-480.309	63
-485.568	61
-490.832	68.6667
-496.099	72
-501.372	62.6667
-506.648	63.3333
-511.929	58
-517.215	65.3333
-522.504	64.6667
-527.797	59.6667
-533.097	71.6667
-538.399	59.3333
-543.706	61.3333
-549.018	65.6667
-554.334	52.6667
-559.654	63
-564.979	60
-570.308	58
-575.641	55.6667
-580.98	57
-586.322	59
-591.669	55
-597.02	62.6667
-602.376	54.3333
-607.736	62.3333
-613.1	55.6667
-618.47	60.3333
-623.843	64.6667
-629.222	66.6667
-634.603	68
-639.99	62.6667
-645.382	62.3333
-650.779	53
-656.179	62.6667
-661.583	63.6667
-666.993	59.3333
-672.407	62.6667
-677.825	59
-683.248	63
-688.675	61.3333
-694.108	62.6667
-699.544	65
-704.985	65.6667
-710.431	57.3333
-715.88	59.6667
-721.335	60.6667
-726.795	54.6667
-732.258	61
-737.727	58
-743.2	61.6667
-748.678	53.6667
-754.159	54.3333
-759.646	57.3333
-765.138	59
-770.633	58.3333
-776.133	62
-781.638	59.3333
-787.149	59
-792.663	60
-798.181	62
-803.705	67.6667
-809.233	59.3333
-814.766	69
-820.304	62
-825.846	55.6667
-831.392	58.6667
-836.944	58.6667
-842.499	64.3333
-848.06	61.3333
-853.626	64
-859.195	69.3333
-864.77	61.6667
-870.35	64
-875.934	55.6667
-881.522	52.3333
-887.116	66
-892.714	58
-898.317	58
-903.924	59.6667
-909.537	54
-915.153	63.3333
-920.776	58.6667
-926.401	56.6667
-932.033	60.6667
-937.669	55
-943.31	57.6667
-948.955	57
-954.605	67.6667
-960.26	58
-965.92	66.6667
-971.584	58.6667
-977.254	64
-982.928	60.3333
-988.607	59
-994.291	66.6667
-999.979	61
-1005.67	66.6667
-1011.37	62
-1017.07	69
-1022.78	75.6667
-1028.49	64.3333
-1034.21	68.6667
-1039.93	69.3333
-1045.66	61
-1051.39	65.3333
-1057.13	72.6667
-1062.87	69.6667
-1068.62	69
-1074.37	75.6667
-1080.12	71.3333
-1085.89	77
-1091.65	73.6667
-1097.42	70.3333
-1103.2	83.3333
-1108.98	77
-1114.77	76.3333
-1120.56	77.3333
-1126.35	72
-1132.15	69.6667
-1137.96	75.3333
-1143.77	82
-1149.58	85
-1155.4	89
-1161.23	87
-1167.06	90.3333
-1172.89	116
-1178.73	156
-1184.58	201.333
-1190.43	239.333
-1196.28	269.667
-1202.14	317.667
-1208.01	359.667
-1213.88	420
-1219.75	508.667
-1225.63	589.667
-1231.52	676.333
-1237.41	816.667
-1243.3	1028
-1249.2	1682.67
-1255.11	1869
-1261.02	1760
-1266.93	1404.67
-1272.85	1040.67
-1278.78	447.333
-1284.71	187
-1290.65	157
-1296.59	142.667
-1302.53	123
-1308.48	107
-1314.44	109
-1320.4	104
-1326.37	109
-1332.34	93.6667
-1338.31	91
-1344.29	95.6667
-1350.28	83.6667
-1356.27	82
-1362.27	79
-1368.27	76
-1374.28	71.6667
-1380.29	58.3333
-1386.31	55
-1392.33	58.6667

-1051.39	65.3333
-1054.26	64.3333
-1057.13	72.6667
-1060	73.3333
-1062.87	69.6667
-1065.74	78.3333
-1068.62	69
-1071.49	70.6667
-1074.37	75.6667
-1077.25	72
-1080.12	71.3333
-1083.01	76
-1085.89	77
-1088.77	70
-1091.65	73.6667
-1094.54	72.3333
-1097.42	70.3333
-1100.31	72.3333
-1103.2	83.3333
-1106.09	73
-1108.98	77
-1111.87	74.6667
-1114.77	76.3333
-1117.66	80.6667
-1120.56	77.3333
-1123.45	86.6667
-1126.35	72
-1129.25	78.3333
-1132.15	69.6667
-1135.05	79
-1137.96	75.3333
-1140.86	85.6667
-1143.77	82
-1146.67	79
-1149.58	85
-1152.49	84
-1155.4	89
-1158.32	88.6667
-1161.23	87
-1164.14	94
-1167.06	90.3333
-1169.98	103.333
-1172.89	116
-1175.81	134
-1178.73	156
-1181.66	177.667
-1184.58	201.333
-1187.5	235
-1190.43	239.333
-1193.35	273
-1196.28	269.667
-1199.21	292.333
-1202.14	317.667
-1205.08	351.333
-1208.01	359.667
-1210.94	391.667
-1213.88	420
-1216.82	471.333
-1219.75	508.667
-1222.69	561
-1225.63	589.667
-1228.58	614.333
-1231.52	676.333
-1234.46	723.667
-1237.41	816.667
-1240.35	896.333
-1243.3	1028
-1246.25	1397
-1249.2	1682.67
-1252.16	1847.67
-1255.11	1869
-1258.06	1849
-1261.02	1760
-1263.97	1589
-1266.93	1404.67
-1269.89	1257.67
-1272.85	1040.67
-1275.82	723.333
-1278.78	447.333
-1281.74	248.333
-1284.71	187
-1287.68	164.333
-1290.65	157
-1293.62	157.667
-1296.59	142.667
-1299.56	136
-1302.53	123
-1305.51	114.667
-1308.48	107
-1311.46	108.333
-1314.44	109
-1317.42	97
-1320.4	104
-1323.38	101.667
-1326.37	109
-1329.35	97.3333
-1332.34	93.6667
-1335.32	88.3333
-1338.31	91
-1341.3	98.6667
-1344.29	95.6667
-1347.29	94.3333
-1350.28	83.6667
-1353.28	91.6667
-1356.27	82
-1359.27	77.3333
-1362.27	79
-1365.27	79
-1368.27	76
-1371.27	80
-1374.28	71.6667
-1377.28	72.6667
-1380.29	58.3333
-1383.3	60.6667
-1386.31	55
-1389.32	58.6667
-1392.33	58.6667