File: projects/python/data/20231030/txt/wristback_600_785 nm_10 s_1_2023_10_30_15_21_49_01.txt
#Sample=wristback
#Laser=785 nm
#Gating=600
#Exposition=10 s
#Accumulation=1
#Acquired=30.10.2023 15:21:49
2745.96	898.333
2743.18	898.667
2740.41	897.667
2737.63	938.667
2734.85	951.667
2732.07	968
2729.29	974
2726.5	967.667
2723.72	969.667
2720.93	974.333
2718.14	991.333
2715.34	999.333
2712.55	1003.67
2709.75	1019.33
2706.95	1023
2704.15	1017.67
2701.35	1033
2698.55	1045.67
2695.74	1081.33
2692.93	1090
2690.12	1103.33
2687.31	1105.33
2684.49	1116
2681.67	1120.67
2678.85	1136.67
2676.03	1145
2673.21	1142.33
2670.38	1146.33
2667.56	1150.67
2664.73	1162.67
2661.9	1139.67
2659.06	1173
2656.23	1187.67
2653.39	1201.67
2650.55	1224.67
2647.71	1241.33
2644.86	1262.33
2642.02	1259.33
2639.17	1285.67
2636.32	1268
2633.47	1296.33
2630.62	1317.67
2627.76	1306.33
2624.9	1361.33
2622.04	1358.67
2619.18	1354
2616.31	1352.67
2613.45	1375.67
2610.58	1383.67
2607.71	1379.67
2604.84	1403.67
2601.96	1395
2599.08	1400.67
2596.21	1403
2593.32	1435
2590.44	1456.67
2587.56	1448.33
2584.67	1468.33
2581.78	1493.33
2578.89	1504
2575.99	1507
2573.1	1528.33
2570.2	1547.67
2567.3	1548
2564.4	1541
2561.5	1585.67
2558.59	1594.33
2555.68	1617.67
2552.77	1608.67
2549.86	1623
2546.94	1659.67
2544.03	1667.67
2541.11	1705.33
2538.19	1715.33
2535.26	1709
2532.34	1718.67
2529.41	1720.67
2526.48	1725.33
2523.55	1757.33
2520.62	1767.33
2517.68	1764.67
2514.74	1804.33
2511.8	1806
2508.86	1797.67
2505.92	1838.33
2502.97	1814.33
2500.02	1828
2497.07	1831.33
2494.12	1857.67
2491.16	1882.67
2488.2	1858.33
2485.25	1893.33
2482.28	1902.67
2479.32	1919
2476.35	1920.33
2473.39	1941.67
2470.42	1941.33
2467.44	1976
2464.47	1978.67
2461.49	2024.33
2458.51	2052.67
2455.53	2048.67
2452.55	2064
2449.56	2055.67
2446.58	2096
2443.59	2102.33
2440.59	2132.67
2437.6	2150.33
2434.6	2153.67
2431.61	2167.67
2428.61	2189.33
2425.6	2192.67
2422.6	2219
2419.59	2215
2416.58	2260.67
2413.57	2276
2410.56	2267.67
2407.54	2317
2404.52	2272.33
2401.5	2319
2398.48	2331
2395.45	2341.67
2392.43	2340
2389.4	2382.67
2386.37	2380.33
2383.33	2403
2380.3	2412.67
2377.26	2419
2374.22	2480.33
2371.17	2489
2368.13	2482.67
2365.08	2487
2362.03	2509.67
2358.98	2509.67
2355.93	2519.33
2352.87	2576.33
2349.81	2582
2346.75	2563
2343.69	2574
2340.63	2604.33
2337.56	2595.67
2334.49	2644.67
2331.42	2636.67
2328.35	2686
2325.27	2647
2322.19	2671
2319.11	2670.67
2316.03	2707
2312.94	2716
2309.85	2740
2306.77	2756
2303.67	2763
2300.58	2787.67
2297.48	2800
2294.38	2816
2291.28	2851.67
2288.18	2841
2285.07	2843.33
2281.97	2903.67
2278.86	2875
2275.74	2859
2272.63	2934.33
2269.51	2933.33
2266.39	2966.67
2263.27	2933
2260.15	2980.33
2257.02	2957.67
2253.89	3001.67
2250.76	3006.67
2247.63	3058.67
2244.49	3038.33
2241.36	3042
2238.22	3061
2235.08	3104.33
2231.93	3096.33
2228.78	3141.33
2225.63	3077.67
2222.48	3144.67
2219.33	3158.33
2216.17	3188
2213.01	3202.67
2209.85	3175.33
2206.69	3182.33
2203.53	3200
2200.36	3214.33
2197.19	3229.67
2194.02	3238
2190.84	3260.33
2187.66	3281.67
2184.48	3286.67
2181.3	3315
2178.12	3317.67
2174.93	3346.67
2171.74	3370
2168.55	3385
2165.36	3357.33
2162.16	3437.67
2158.97	3447
2155.76	3499.33
2152.56	3505
2149.36	3491.67
2146.15	3549
2142.94	3532
2139.73	3540.33
2136.51	3550.33
2133.29	3540.67
2130.08	3574.33
2126.85	3572.67
2123.63	3609.33
2120.4	3616
2117.17	3592.67
2113.94	3655.33
2110.71	3626.67
2107.47	3664
2104.23	3674.67
2100.99	3662.33
2097.75	3696.67
2094.5	3744
2091.26	3713
2088.01	3758.67
2084.75	3741.33
2081.5	3819.33
2078.24	3801.33
2074.98	3817.67
2071.72	3838.33
2068.45	3893.33
2065.18	3903.33
2061.92	3926.67
2058.64	3933.33
2055.37	3949
2052.09	3962.67
2048.81	3989.67
2045.53	4018
2042.25	4027.33
2038.96	4040
2035.67	4040.67
2032.38	4067.33
2029.08	4067.67
2025.79	4058
2022.49	4065.33
2019.19	4098
2015.88	4112.67
2012.58	4120
2009.27	4080.33
2005.96	4138
2002.64	4161.67
1999.33	4171.67
1996.01	4178.67
1992.69	4235.67
1989.36	4252.33
1986.04	4232
1982.71	4259
1979.38	4300.67
1976.05	4303
1972.71	4323
1969.37	4385.33
1966.03	4407.67
1962.69	4444.67
1959.34	4458.67
1955.99	4437.67
1952.64	4450.67
1949.29	4498
1945.93	4478.33
1942.58	4537.33
1939.21	4553.33
1935.85	4567.67
1932.49	4616.67
1929.12	4611
1925.75	4574
1922.37	4647.33
1919	4620
1915.62	4607.33
1912.24	4610.67
1908.86	4614
1905.47	4657
1902.08	4677.67
1898.69	4661.33
1895.3	4666
1891.9	4719.33
1888.5	4705
1885.1	4738
1881.7	4725.33
1878.29	4720
1874.88	4752.67
1871.47	4784
1868.06	4785.33
1864.64	4791.33
1861.22	4803.33
1857.8	4793.33
1854.38	4853.67
1850.95	4876.33
1847.52	4854
1844.09	4879
1840.66	4940
1837.22	4936.67
1833.78	4948
1830.34	4951
1826.9	4983
1823.45	4996.67
1820	4985.67
1816.55	5001
1813.09	5015.67
1809.64	5026.67
1806.18	5078.67
1802.71	5072.33
1799.25	5080.67
1795.78	5108.67
1792.31	5161.33
1788.84	5136.67
1785.36	5155.33
1781.88	5146.67
1778.4	5155.67
1774.92	5137
1771.43	5141.33
1767.95	5184.67
1764.45	5179
1760.96	5160.67
1757.47	5234.33
1753.97	5207
1750.47	5231.67
1746.96	5244
1743.45	5250.67
1739.94	5276.67
1736.43	5299.67
1732.92	5359
1729.4	5305.67
1725.88	5384
1722.36	5416
1718.83	5402
1715.3	5387.67
1711.77	5422.67
1708.24	5449.33
1704.71	5511.33
1701.17	5496.33
1697.63	5551
1694.08	5538
1690.54	5547
1686.99	5616
1683.44	5578
1679.88	5629.67
1676.32	5596
1672.76	5645
1669.2	5673.67
1665.64	5653.67
1662.07	5713
1658.5	5688.33
1654.92	5688.33
1651.35	5731
1647.77	5747
1644.19	5734.33
1640.61	5738.33
1637.02	5809.67
1633.43	5749.33
1629.84	5742
1626.24	5765
1622.64	5752.33
1619.04	5751.67
1615.44	5717.33
1611.84	5741.33
1608.23	5766.33
1604.62	5777.33
1601	5785.33
1597.39	5773.33
1593.77	5807
1590.15	5812
1586.52	5783
1582.89	5843.33
1579.26	5799.33
1575.63	5856.67
1571.99	5860.67
1568.36	5867.33
1564.72	5857.33
1561.07	5905.33
1557.42	5900.67
1553.78	5911
1550.12	5926.33
1546.47	5922.67
1542.81	5910.33
1539.15	5925
1535.49	5909
1531.82	5903
1528.15	5931.33
1524.48	5878.67
1520.81	5922.67
1517.13	5904.33
1513.45	5915
1509.77	5927.33
1506.08	5961
1502.39	5952.33
1498.7	5897.33
1495.01	5931
1491.31	5873.33
1487.61	5891.33
1483.91	5935.33
1480.21	5956.67
1476.5	5954
1472.79	5990.33
1469.07	5958.33
1465.36	6006.67
1461.64	6046
1457.92	6064
1454.19	6016.33
1450.46	6080
1446.73	6040.33
1443	6048.33
1439.26	6013.67
1435.52	6009
1431.78	5981.67
1428.04	5998.67
1424.29	5946
1420.54	5973.33
1416.79	6044
1413.03	5994
1409.27	5927.67
1405.51	5988.67
1401.75	5974.33
1397.98	6000
1394.21	5955.33
1390.44	5941.67
1386.66	5944.33
1382.88	5933.33
1379.1	5912.33
1375.31	5913
1371.53	5885.67
1367.74	5915.33
1363.94	5913.67
1360.15	5970
1356.35	5976.33
1352.55	6016.67
1348.74	6034
1344.93	5976.33
1341.12	6015
1337.31	5957
1333.49	5986.67
1329.67	6012
1325.85	6015
1322.03	6011.33
1318.2	6004.33
1314.37	6011
1310.53	6026.67
1306.7	6050.67
1302.86	6038.33
1299.01	6002.67
1295.17	6016
1291.32	6039.33
1287.47	6053.67
1283.61	6039
1279.76	6083.33
1275.9	6109
1272.03	6059.67
1268.17	6070.33
1264.3	6026.67
1260.42	6118
1256.55	6057
1252.67	6059.67
1248.79	6053.67
1244.91	6108.33
1241.02	6047.33
1237.13	6036.67
1233.24	6024.33
1229.34	6024
1225.44	6024.67
1221.54	5999.67
1217.63	5975.33
1213.73	5972.67
1209.81	5938.67
1205.9	5933
1201.98	5933
1198.06	5937.67
1194.14	5936
1190.21	5910
1186.29	5931.33
1182.35	5941.67
1178.42	5935.67
1174.48	5901.67
1170.54	5890.67
1166.6	5873
1162.65	5923
1158.7	5883.33
1154.74	5913.67
1150.79	5877
1146.83	5861.33
1142.87	5910
1138.9	5900
1134.93	5892
1130.96	5924.67
1126.99	5889.33
1123.01	5916.33
1119.03	5935
1115.04	5963.67
1111.06	5989
1107.07	6012.33
1103.08	6047
1099.08	6089
1095.08	6053.67
1091.08	6124.33
1087.07	6115
1083.06	6167
1079.05	6139.33
1075.04	6204.67
1071.02	6183.33
1067	6174
1062.98	6215.33
1058.95	6235.33
1054.92	6245
1050.89	6221
1046.85	6175.33
1042.81	6217.33
1038.77	6232.67
1034.72	6257
1030.67	6290.33
1026.62	6263
1022.57	6240
1018.51	6324.67
1014.45	6338.67
1010.38	6376
1006.32	6315.33
1002.24	6386
998.171	6447.33
994.094	6462.67
990.013	6503
985.93	6535
981.843	6574.33
977.754	6612
973.661	6668.67
969.565	6645.33
965.466	6704.33
961.364	6751.67
957.258	6786
953.15	6783.67
949.038	6766.33
944.923	6789.67
940.804	6818.33
936.683	6807
932.558	6835
928.43	6783.67
924.299	6786.33
920.165	6800.67
916.028	6822
911.887	6770.67
907.743	6778.67
903.595	6733.33
899.445	6741.67
895.292	6745.67
891.135	6749
886.975	6741
882.812	6802.33
878.646	6839.67
874.475	6814.33
870.303	6893.67
866.126	6920
861.947	6918
857.764	6933.33
853.578	6958.33
849.389	6975.33
845.196	6940.67
841	6996
836.801	7031.33
832.599	7034.67
828.393	6990.33
824.184	7024.33
819.972	6983
815.757	6960.67
811.538	6940.67
807.316	6949
803.091	6952.33
798.863	6967
794.631	6947.33
790.395	6955.33
786.157	6882.67
781.915	6878.67
777.669	6858
773.421	6877.67
769.169	6895
764.915	6991
760.656	6988.33
756.394	7013.33
752.129	6976.67
747.861	7047
743.588	7078
739.314	7088.67
735.035	7138.33
730.753	7145
726.469	7151.67
722.18	7177.67
717.888	7182.33
713.593	7089.33
709.294	7074.33
704.992	7083.67
700.687	7089.67
696.378	7010.33
692.066	7004.33
687.751	6908.67
683.432	6958.67
679.109	6917.67
674.784	6948.33
670.455	6951.67
666.122	6887.33
661.787	6954.33
657.448	6917
653.104	6999.33
648.759	7014.67
644.409	7033.33
640.056	7022.67
635.7	7102.33
631.34	7103.67
626.977	7115.33
622.61	7089.33
618.24	7137.67
613.867	7090
609.49	7037.33
605.11	7034.33
600.726	6992
596.339	7002
591.948	6982.33
587.554	6925
583.156	6912.67
578.755	6898.33
574.35	6961
569.943	6885.67
565.531	6929.33
561.116	6845.33
556.698	6862
552.275	6849
547.85	6879.67
543.421	6844.67
538.988	7049.67
534.553	6956.33
530.113	6912
525.67	6968.33
521.224	6972.67
516.774	6964
512.321	6999.33
507.863	6967.33
503.403	6962
498.939	6912.67
494.472	6898
490.001	6829
485.526	6789.33
481.047	6803.33
476.565	6856
472.08	6789
467.591	6841.67
463.099	6839.67
458.604	6805
454.103	6879.67
449.601	6859.67
445.094	6884
440.584	6935.33
436.07	6937.33
431.553	7032.67
427.032	7021.33
422.507	6979.67
417.979	7035.33
413.448	7012.33
408.912	7017.33
404.373	6991.33
399.83	6990
395.285	6928
390.734	6963
386.181	7012
381.624	6965.33
377.064	6961
372.5	6949
367.932	6951.67
363.36	6971.67
358.785	6964
354.207	6944
349.624	6984
345.038	6958.33
340.448	6969
335.855	6888.33
331.257	6970.67
326.657	6956.67
322.053	6988.33
317.444	7012.67
312.833	7029.67
308.217	7066.33
303.599	7094.67
298.976	7082.33
294.349	7142.67
289.719	7142.33
285.085	7157.33
280.448	7178.67
275.807	7166
271.161	7212.33
266.513	7207.67
261.861	7184
257.205	7217
252.544	7282.33
247.881	7249
243.214	7289
238.543	7301.67
233.869	7384.33
229.19	7429.67
224.508	7462.33
219.822	7490
215.132	7529.33
210.439	7609.67
205.741	7670.67
201.04	7726.67
196.336	7824.67
191.627	7911
186.915	7911.67
182.199	7929
177.478	8092
172.755	8103
168.028	8149.67
163.297	8193
158.561	8267.33
153.823	8318.67
149.08	8285.33
144.334	8379.67
139.584	8432
134.829	8464
130.071	8634
125.31	8764
120.545	8915.33
115.775	9073.67
111.001	9291
106.224	9519.33
101.444	9811.33
96.6594	10309.3
91.8705	10749.7
87.0781	11412.3
82.282	12167
77.4812	13117
72.6778	14668.3
67.8698	17955.3
63.0582	21031.3
58.2419	23561
53.4229	26158.3
48.5993	29601.7
43.772	34303
38.941	41335
34.1054	52304
29.2661	64524
24.4231	64524
19.5764	64524
14.7261	64524
9.87099	64524
5.01321	64524
0.14975	64524
-4.71644	64524
-9.58634	64524
-14.461	64524
-19.3393	64524
-24.2214	64524
-29.1072	64524
-33.9977	64524
-38.892	44620.3
-43.7901	29983.7
-48.6919	22405.3
-53.5974	16963
-58.5078	13120.3
-63.4218	10166.7
-68.3397	7884.67
-73.2613	6167
-78.1878	4859.67
-83.117	3836
-88.051	3097.33
-92.9888	2524.67
-97.9314	2128.67
-102.877	1719
-107.827	1376.67
-112.781	1088
-117.739	898.667
-122.701	790.333
-127.667	674.667
-132.637	542.667
-137.612	456.333
-142.59	385
-147.572	354
-152.558	303.667
-157.548	264.667
-162.542	247.333
-167.541	223.333
-172.544	214
-177.55	219.667
-182.561	189.333
-187.576	189
-192.595	182
-197.617	179
-202.645	175
-207.676	182.667
-212.711	172.333
-217.75	170
-222.794	165.333
-227.842	148.333
-232.893	150.333
-237.949	146
-243.009	140.667
-248.073	137.333
-253.142	139
-258.214	130.667
-263.291	138
-268.371	138.333
-273.456	127.333
-278.545	125.667
-283.639	116
-288.735	117
-293.837	111.333
-298.943	113
-304.053	113.667
-309.166	109.667
-314.285	96.6667
-319.408	109.333
-324.534	105.333
-329.665	97.6667
-334.801	101.333
-339.94	96
-345.083	96.3333
-350.231	99.3333
-355.383	95
-360.539	96.3333
-365.699	88.3333
-370.864	88.6667
-376.033	92
-381.206	86
-386.384	90
-391.565	82.3333
-396.751	87.6667
-401.941	81.6667
-407.136	66.3333
-412.334	79.6667
-417.537	84.6667
-422.745	78.3333
-427.956	88.3333
-433.173	77.6667
-438.392	77.6667
-443.617	87.6667
-448.846	77.3333
-454.078	77.3333
-459.317	76
-464.558	75.3333
-469.804	70.3333
-475.055	65.3333
-480.309	67.6667
-485.568	71.6667
-490.832	68.3333
-496.099	71.6667
-501.372	72
-506.648	80.3333
-511.929	77.6667
-517.215	74.3333
-522.504	83.3333
-527.797	70.6667
-533.097	77
-538.399	76
-543.706	67.3333
-549.018	76.3333
-554.334	75.3333
-559.654	78.6667
-564.979	64.3333
-570.308	81
-575.641	71.6667
-580.98	64.6667
-586.322	65.6667
-591.669	68.6667
-597.02	75
-602.376	71.3333
-607.736	72.3333
-613.1	78.6667
-618.47	74.3333
-623.843	72
-629.222	66.6667
-634.603	75.6667
-639.99	76.3333
-645.382	69.6667
-650.779	72
-656.179	78.6667
-661.583	72.6667
-666.993	73.3333
-672.407	75.3333
-677.825	72.6667
-683.248	74.6667
-688.675	71.6667
-694.108	66.3333
-699.544	65
-704.985	69.3333
-710.431	76.3333
-715.88	75.6667
-721.335	77.6667
-726.795	73.6667
-732.258	71
-737.727	66.3333
-743.2	77
-748.678	76
-754.159	74.6667
-759.646	78.3333
-765.138	71.6667
-770.633	74.3333
-776.133	76.3333
-781.638	62.3333
-787.149	74
-792.663	74
-798.181	66.6667
-803.705	75.3333
-809.233	77.6667
-814.766	68.3333
-820.304	80.3333
-825.846	75.6667
-831.392	66.6667
-836.944	72
-842.499	70.3333
-848.06	79.3333
-853.626	71.3333
-859.195	72.6667
-864.77	65.3333
-870.35	73
-875.934	79
-881.522	70
-887.116	69.6667
-892.714	77.6667
-898.317	70
-903.924	72.6667
-909.537	74.3333
-915.153	65
-920.776	67
-926.401	76.6667
-932.033	74.3333
-937.669	64.3333
-943.31	66.3333
-948.955	75.3333
-954.605	69.6667
-960.26	78.3333
-965.92	73.3333
-971.584	77.3333
-977.254	78
-982.928	75
-988.607	87.3333
-994.291	69
-999.979	78.3333
-1005.67	74.6667
-1011.37	70
-1017.07	80
-1022.78	86
-1028.49	77.6667
-1034.21	73.3333
-1039.93	79.6667
-1045.66	85.6667
-1051.39	79
-1057.13	76
-1062.87	86
-1068.62	80.3333
-1074.37	81.6667
-1080.12	76.6667
-1085.89	80
-1091.65	82.6667
-1097.42	82.3333
-1103.2	77.6667
-1108.98	84.3333
-1114.77	90
-1120.56	83
-1126.35	89.3333
-1132.15	90
-1137.96	92.3333
-1143.77	97
-1149.58	96.6667
-1155.4	94.3333
-1161.23	104
-1167.06	113
-1172.89	130
-1178.73	173.667
-1184.58	220.333
-1190.43	273
-1196.28	316
-1202.14	369.667
-1208.01	446.667
-1213.88	503.667
-1219.75	563.667
-1225.63	671.667
-1231.52	749.667
-1237.41	895
-1243.3	1115.67
-1249.2	1931.33
-1255.11	2061.67
-1261.02	1928
-1266.93	1637.33
-1272.85	1012.33
-1278.78	424
-1284.71	209.333
-1290.65	175
-1296.59	149.667
-1302.53	126.333
-1308.48	123
-1314.44	119.333
-1320.4	121.667
-1326.37	106.333
-1332.34	108
-1338.31	101
-1344.29	101.667
-1350.28	95.3333
-1356.27	99.6667
-1362.27	83.3333
-1368.27	76
-1374.28	78.6667
-1380.29	77
-1386.31	69.3333
-1392.33	58.3333
-1057.13	76
-1062.87	86
-1068.62	80.3333
-1074.37	81.6667
-1080.12	76.6667
-1085.89	80
-1091.65	82.6667
-1097.42	82.3333
-1103.2	77.6667
-1108.98	84.3333
-1114.77	90
-1120.56	83
-1126.35	89.3333
-1132.15	90
-1137.96	92.3333
-1143.77	97
-1149.58	96.6667
-1155.4	94.3333
-1161.23	104
-1167.06	113
-1172.89	130
-1178.73	173.667
-1184.58	220.333
-1190.43	273
-1196.28	316
-1202.14	369.667
-1208.01	446.667
-1213.88	503.667
-1219.75	563.667
-1225.63	671.667
-1231.52	749.667
-1237.41	895
-1243.3	1115.67
-1249.2	1931.33
-1255.11	2061.67
-1261.02	1928
-1266.93	1637.33
-1272.85	1012.33
-1278.78	424
-1284.71	209.333
-1290.65	175
-1296.59	149.667
-1302.53	126.333
-1308.48	123
-1314.44	119.333
-1320.4	121.667
-1326.37	106.333
-1332.34	108
-1338.31	101
-1344.29	101.667
-1350.28	95.3333
-1356.27	99.6667
-1362.27	83.3333
-1368.27	76
-1374.28	78.6667
-1380.29	77
-1386.31	69.3333
-1392.33	58.3333