File: projects/python/data/20231113-stretch/indexblood_600_785 nm_120 s_1_2023_11_13_18_40_10_01.txt
#Sample=indexblood
#Laser=785 nm
#Grating=600
#Exposition=120
#Accumulation=1
#Acquired=13.11.2023 18:40:10
1568.96	1163
1567.14	1166
1565.32	1228
1563.5	1203
1561.68	1200
1559.85	1202
1558.03	1181
1556.21	1204
1554.38	1200
1552.56	1182
1550.73	1223
1548.9	1223
1547.08	1232
1545.25	1214
1543.42	1207
1541.59	1240
1539.76	1232
1537.93	1218
1536.1	1231
1534.26	1202
1532.43	1228
1530.6	1204
1528.76	1207
1526.93	1212
1525.09	1219
1523.25	1220
1521.42	1222
1519.58	1254
1517.74	1210
1515.9	1232
1514.06	1234
1512.22	1223
1510.38	1227
1508.54	1211
1506.69	1238
1504.85	1229
1503.01	1216
1501.16	1232
1499.32	1194
1497.47	1213
1495.62	1239
1493.77	1214
1491.93	1246
1490.08	1239
1488.23	1245
1486.38	1244
1484.53	1251
1482.67	1227
1480.82	1226
1478.97	1221
1477.11	1250
1475.26	1274
1473.4	1260
1471.55	1273
1469.69	1223
1467.83	1249
1465.98	1285
1464.12	1294
1462.26	1303
1460.4	1282
1458.54	1319
1456.67	1289
1454.81	1307
1452.95	1284
1451.08	1295
1449.22	1280
1447.35	1291
1445.49	1306
1443.62	1308
1441.75	1302
1439.89	1294
1438.02	1282
1436.15	1293
1434.28	1288
1432.41	1281
1430.53	1303
1428.66	1293
1426.79	1245
1424.92	1248
1423.04	1261
1421.17	1270
1419.29	1267
1417.41	1225
1415.54	1266
1413.66	1253
1411.78	1323
1409.9	1270
1408.02	1251
1406.14	1263
1404.26	1265
1402.37	1236
1400.49	1257
1398.61	1228
1396.72	1262
1394.84	1247
1392.95	1254
1391.07	1243
1389.18	1266
1387.29	1265
1385.4	1244
1383.51	1239
1381.62	1268
1379.73	1239
1377.84	1231
1375.95	1236
1374.05	1236
1372.16	1246
1370.26	1254
1368.37	1264
1366.47	1230
1364.58	1272
1362.68	1227
1360.78	1259
1358.88	1266
1356.98	1257
1355.08	1302
1353.18	1286
1351.28	1298
1349.38	1277
1347.47	1249
1345.57	1295
1343.66	1275
1341.76	1277
1339.85	1277
1337.95	1307
1336.04	1300
1334.13	1316
1332.22	1295
1330.31	1277
1328.4	1278
1326.49	1324
1324.58	1304
1322.66	1266
1320.75	1315
1318.84	1281
1316.92	1326
1315.01	1326
1313.09	1309
1311.17	1332
1309.25	1363
1307.34	1339
1305.42	1335
1303.5	1325
1301.58	1386
1299.65	1380
1297.73	1338
1295.81	1388
1293.89	1437
1291.96	1385
1290.04	1392
1288.11	1429
1286.18	1382
1284.26	1395
1282.33	1377
1280.4	1396
1278.47	1407
1276.54	1413
1274.61	1464
1272.68	1425
1270.74	1372
1268.81	1414
1266.88	1413
1264.94	1386
1263.01	1379
1261.07	1418
1259.13	1405
1257.2	1379
1255.26	1423
1253.32	1394
1251.38	1417
1249.44	1367
1247.5	1416
1245.55	1388
1243.61	1399
1241.67	1371
1239.72	1352
1237.78	1374
1235.83	1396
1233.89	1336
1231.94	1368
1229.99	1342
1228.04	1297
1226.09	1338
1224.14	1312
1222.19	1270
1220.24	1265
1218.29	1299
1216.33	1319
1214.38	1272
1212.42	1289
1210.47	1219
1208.51	1262
1206.55	1252
1204.6	1250
1202.64	1221
1200.68	1232
1198.72	1203
1196.76	1244
1194.8	1257
1192.83	1271
1190.87	1244
1188.91	1206
1186.94	1218
1184.98	1209
1183.01	1206
1181.04	1238
1179.08	1203
1177.11	1219
1175.14	1195
1173.17	1241
1171.2	1209
1169.23	1198
1167.25	1192
1165.28	1206
1163.31	1217
1161.33	1285
1159.36	1227
1157.38	1196
1155.41	1209
1153.43	1233
1151.45	1205
1149.47	1204
1147.49	1208
1145.51	1235
1143.53	1217
1141.55	1257
1139.56	1228
1137.58	1208
1135.6	1238
1133.61	1241
1131.63	1201
1129.64	1234
1127.65	1274
1125.66	1245
1123.67	1265
1121.68	1259
1119.69	1219
1117.7	1217
1115.71	1253
1113.72	1233
1111.72	1212
1109.73	1226
1107.74	1253
1105.74	1221
1103.74	1233
1101.75	1234
1099.75	1245
1097.75	1297
1095.75	1275
1093.75	1257
1091.75	1271
1089.75	1253
1087.74	1277
1085.74	1240
1083.73	1279
1081.73	1260
1079.72	1255
1077.72	1253
1075.71	1278
1073.7	1248
1071.69	1258
1069.68	1254
1067.67	1269
1065.66	1287
1063.65	1268
1061.64	1273
1059.62	1251
1057.61	1255
1055.59	1268
1053.58	1256
1051.56	1297
1049.54	1244
1047.53	1302
1045.51	1290
1043.49	1284
1041.47	1291
1039.44	1278
1037.42	1281
1035.4	1287
1033.38	1286
1031.35	1242
1029.33	1259
1027.3	1267
1025.27	1228
1023.25	1257
1021.22	1245
1019.19	1278
1017.16	1280
1015.13	1268
1013.1	1267
1011.06	1273
1009.03	1299
1007	1270
1004.96	1248
1002.93	1262
1000.89	1271
998.852	1292
996.815	1281
994.776	1296
992.737	1293
990.697	1276
988.656	1296
986.614	1307
984.572	1320
982.528	1361
980.484	1330
978.439	1334
976.393	1350
974.347	1346
972.299	1361
970.251	1353
968.202	1329
966.153	1349
964.102	1363
962.051	1349
959.999	1357
957.946	1345
955.892	1385
953.838	1348
951.783	1367
949.727	1351
947.67	1381
945.612	1389
943.554	1352
941.495	1390
939.434	1352
937.374	1377
935.311	1377
933.25	1402
931.186	1375
929.122	1364
927.057	1351
924.991	1403
922.925	1411
920.858	1380
918.79	1402
916.721	1380
914.651	1372
912.58	1382
910.51	1432
908.437	1437
906.364	1390
904.291	1378
902.216	1417
900.141	1362
898.065	1367
895.988	1379
893.91	1417
891.832	1381
889.752	1379
887.673	1410
885.591	1366
883.51	1413
881.427	1385
879.344	1416
877.26	1407
875.175	1435
873.088	1429
871.002	1439
868.915	1424
866.826	1440
864.737	1468
862.648	1457
860.557	1440
858.465	1418
856.373	1444
854.28	1436
852.186	1457
850.091	1446
847.996	1443
845.899	1466
843.802	1436
841.704	1451
839.605	1463
837.506	1470
835.405	1495
833.304	1486
831.202	1478
829.098	1470
826.995	1461
824.891	1500
822.785	1467
820.679	1485
818.572	1471
816.463	1505
814.355	1484
812.246	1466
810.136	1489
808.024	1456
805.913	1431
803.799	1462
801.686	1459
799.572	1479
797.456	1478
795.341	1712
793.223	1705
791.105	1494
788.987	1496
786.867	1481
784.747	1476
782.626	1453
780.504	1463
778.382	1466
776.258	1489
774.134	1508
772.008	1495
769.883	1478
767.756	1513
765.628	1533
763.499	1508
761.37	1556
759.24	1525
757.109	1539
754.977	1551
752.844	1508
750.711	1556
748.577	1543
746.441	1526
744.305	1484
742.169	1536
740.031	1580
737.892	1578
735.753	1557
733.613	1530
731.472	1566
729.33	1540
727.187	1595
725.043	1561
722.899	1583
720.754	1585
718.608	1586
716.461	1558
714.313	1569
712.164	1568
710.015	1535
707.865	1559
705.714	1557
703.562	1535
701.409	1576
699.256	1574
697.101	1544
694.946	1543
692.789	1522
690.632	1546
688.474	1525
686.315	1530
684.156	1540
681.995	1541
679.834	1529
677.673	1539
675.51	1503
673.346	1518
671.181	1559
669.016	1509
666.849	1552
664.682	1546
662.514	1521
660.345	1514
658.175	1553
656.005	1552
653.834	1563
651.661	1579
649.488	1575
647.314	1575
645.139	1572
642.964	1578
640.787	1586
638.609	1540
636.43	1638
634.251	1596
632.072	1623
629.89	1603
627.709	1606
625.526	1663
623.343	1644
621.158	1622
618.974	1646
616.787	1637
614.601	1668
612.413	1650
610.224	1607
608.035	1629
605.845	1641
603.654	1622
601.462	1623
599.268	1616
597.075	1603
594.88	1629
592.684	1629
590.488	1596
588.291	1632
586.093	1650
583.894	1667
581.694	1597
579.493	1618
577.292	1656
575.089	1619
572.886	1612
570.682	1613
568.477	1657
566.271	1658
564.065	1636
561.856	1638
559.648	1617
557.439	1667
555.229	1641
553.018	1634
550.806	1645
548.593	1649
546.379	1666
544.165	1657
541.949	1647
539.732	1677
537.515	1647
535.297	1651
533.078	1677
530.858	1660
528.638	1707
526.416	1694
524.193	1686
521.97	1713
519.746	1694
517.521	1690
515.295	1689
513.068	1747
510.84	1747
508.611	1735
506.382	1687
504.152	1719
501.92	1738
499.688	1712
497.455	1748
495.221	1712
492.986	1742
490.751	1683
488.514	1730
486.277	1672
484.038	1704
481.799	1687
479.559	1732
477.318	1703
475.076	1714
472.833	1714
470.589	1712
468.345	1708
466.099	1688
463.853	1717
461.606	1709
459.358	1734
457.109	1688
454.859	1724
452.608	1753
450.357	1731
448.103	1779
445.85	1746
443.596	1754
441.341	1763
439.084	1758
436.828	1790
434.57	1795
432.311	1801
430.051	1816
427.79	1779
425.529	1817
423.267	1830
421.003	1811
418.739	1870
416.474	1878
414.208	1825
411.941	1841
409.673	1854
407.404	1829
405.134	1821
402.865	1803
400.593	1867
398.321	1819
396.047	1827
393.773	1821
391.498	1872
389.223	1844
386.945	1800
384.668	1828
382.389	1815
380.109	1830
377.829	1864
375.548	1804
373.265	1850
370.983	1812
368.698	1807
366.413	1864
364.127	1862
361.841	1843
359.553	1864
357.265	1872
354.974	1912
352.684	1833
350.393	1870
348.1	1882
345.808	1880
343.513	1898
341.219	1891
338.923	1919
336.625	1941
334.328	1892
332.029	1883
329.729	1966
327.429	1892
325.128	1891
322.825	1912
320.522	1928
318.218	1907
315.913	1978
313.606	1962
311.3	1984
308.992	1992
306.684	1970
304.374	1963
302.063	1953
299.751	2010
297.439	1978
295.125	2029
292.811	2044
290.496	2041
288.18	2023
285.863	2039
283.545	2063
281.226	2060
278.907	2095
276.585	2040
274.263	2072
271.941	2054
269.617	2104
267.293	2096
264.967	2130
262.641	2126
260.314	2167
257.985	2138
255.656	2164
253.327	2171
250.996	2225
248.664	2264
246.331	2249
243.997	2280
241.662	2282
239.327	2279
236.99	2322
234.652	2347
232.315	2378
229.975	2343
227.635	2360
225.293	2335
222.951	2408
220.608	2381
218.264	2476
215.919	2448
213.573	2536
211.226	2610
208.879	2615
206.529	2656
204.18	2670
201.829	2748
199.477	2751
197.125	2764
194.772	2814
192.417	2937
190.062	2934
187.705	2942
185.348	2902
182.99	2969
180.631	3017
178.271	3013
175.909	3015
173.548	3129
171.185	3159
168.821	3137
166.456	3095
164.09	3208
161.723	3329
159.356	3378
156.987	3323
154.618	3308
152.247	3340
149.875	3463
147.503	3511
145.13	3442
142.755	3466
140.38	3506
138.004	3590
135.627	3696
133.249	3731
130.87	3671
128.489	3735
126.109	3895
123.727	3978
121.343	4112
118.96	4062
116.575	3998
114.189	4086
111.802	4271
109.415	4404
107.026	4657
104.636	4751
102.246	4793
99.8545	4870
97.4613	5064
95.0681	5315
92.674	5590
90.278	5877
87.8821	6205
85.4843	6432
83.0866	6846
80.687	7329
78.2865	7825
75.8851	8375
73.4827	8988
71.0805	9917
68.6763	11431
66.2712	13901
63.8643	17976
61.4574	25002
59.0496	36657
56.6409	48782
54.2312	57327
51.8197	61816
49.4082	64253
46.9948	64524
44.5815	64524
42.1663	64524
39.7512	64448
37.3342	63701
34.9162	64354
32.4973	64524
30.0775	64524
27.6568	64524
25.2361	64524
22.8126	64524
20.3891	64524
17.9647	64524
15.5393	64524
13.1131	64524
10.6849	64524
8.25676	64524
5.82772	64524
3.39677	64524
0.965873	64524