File: projects/python/data/20231113-stretch/nothing_600_785 nm_120 s_1_2023_11_13_18_58_03_01.txt
#Sample=nothing
#Laser=785 nm
#Grating=600
#Exposition=120
#Accumulation=1
#Acquired=13.11.2023 18:58:03
1568.96	547
1567.14	547
1565.32	589
1563.5	575
1561.68	593
1559.85	556
1558.03	580
1556.21	583
1554.38	574
1552.56	565
1550.73	576
1548.9	572
1547.08	580
1545.25	539
1543.42	553
1541.59	588
1539.76	546
1537.93	560
1536.1	588
1534.26	569
1532.43	568
1530.6	555
1528.76	578
1526.93	554
1525.09	571
1523.25	540
1521.42	570
1519.58	569
1517.74	571
1515.9	522
1514.06	574
1512.22	577
1510.38	551
1508.54	590
1506.69	541
1504.85	567
1503.01	577
1501.16	580
1499.32	529
1497.47	557
1495.62	548
1493.77	535
1491.93	568
1490.08	551
1488.23	591
1486.38	562
1484.53	556
1482.67	554
1480.82	568
1478.97	526
1477.11	535
1475.26	560
1473.4	567
1471.55	586
1469.69	557
1467.83	544
1465.98	568
1464.12	576
1462.26	571
1460.4	553
1458.54	558
1456.67	568
1454.81	564
1452.95	566
1451.08	549
1449.22	555
1447.35	584
1445.49	570
1443.62	539
1441.75	541
1439.89	566
1438.02	550
1436.15	549
1434.28	544
1432.41	569
1430.53	545
1428.66	561
1426.79	555
1424.92	546
1423.04	545
1421.17	519
1419.29	545
1417.41	554
1415.54	543
1413.66	553
1411.78	560
1409.9	545
1408.02	531
1406.14	574
1404.26	535
1402.37	544
1400.49	525
1398.61	508
1396.72	537
1394.84	532
1392.95	550
1391.07	555
1389.18	540
1387.29	537
1385.4	526
1383.51	535
1381.62	528
1379.73	544
1377.84	539
1375.95	511
1374.05	524
1372.16	536
1370.26	518
1368.37	522
1366.47	534
1364.58	530
1362.68	502
1360.78	507
1358.88	527
1356.98	531
1355.08	501
1353.18	541
1351.28	542
1349.38	542
1347.47	544
1345.57	559
1343.66	533
1341.76	547
1339.85	561
1337.95	514
1336.04	532
1334.13	543
1332.22	556
1330.31	519
1328.4	521
1326.49	522
1324.58	558
1322.66	552
1320.75	564
1318.84	549
1316.92	581
1315.01	569
1313.09	570
1311.17	578
1309.25	573
1307.34	591
1305.42	569
1303.5	569
1301.58	571
1299.65	599
1297.73	630
1295.81	587
1293.89	639
1291.96	622
1290.04	618
1288.11	615
1286.18	630
1284.26	622
1282.33	633
1280.4	661
1278.47	638
1276.54	635
1274.61	645
1272.68	641
1270.74	659
1268.81	635
1266.88	632
1264.94	633
1263.01	655
1261.07	644
1259.13	632
1257.2	614
1255.26	631
1253.32	628
1251.38	616
1249.44	636
1247.5	621
1245.55	612
1243.61	592
1241.67	600
1239.72	622
1237.78	583
1235.83	604
1233.89	578
1231.94	560
1229.99	583
1228.04	564
1226.09	554
1224.14	529
1222.19	534
1220.24	532
1218.29	536
1216.33	537
1214.38	517
1212.42	491
1210.47	504
1208.51	482
1206.55	487
1204.6	445
1202.64	448
1200.68	476
1198.72	453
1196.76	430
1194.8	455
1192.83	448
1190.87	424
1188.91	423
1186.94	427
1184.98	418
1183.01	426
1181.04	410
1179.08	418
1177.11	422
1175.14	397
1173.17	399
1171.2	409
1169.23	435
1167.25	401
1165.28	427
1163.31	396
1161.33	409
1159.36	422
1157.38	415
1155.41	408
1153.43	390
1151.45	415
1149.47	413
1147.49	418
1145.51	420
1143.53	407
1141.55	414
1139.56	413
1137.58	425
1135.6	432
1133.61	416
1131.63	407
1129.64	417
1127.65	395
1125.66	418
1123.67	414
1121.68	402
1119.69	399
1117.7	408
1115.71	409
1113.72	427
1111.72	397
1109.73	420
1107.74	412
1105.74	381
1103.74	400
1101.75	407
1099.75	398
1097.75	400
1095.75	401
1093.75	406
1091.75	402
1089.75	409
1087.74	378
1085.74	361
1083.73	399
1081.73	393
1079.72	379
1077.72	385
1075.71	365
1073.7	386
1071.69	363
1069.68	372
1067.67	365
1065.66	349
1063.65	359
1061.64	360
1059.62	380
1057.61	363
1055.59	375
1053.58	364
1051.56	350
1049.54	368
1047.53	386
1045.51	360
1043.49	364
1041.47	339
1039.44	342
1037.42	355
1035.4	346
1033.38	346
1031.35	336
1029.33	325
1027.3	330
1025.27	333
1023.25	319
1021.22	322
1019.19	319
1017.16	321
1015.13	301
1013.1	328
1011.06	327
1009.03	312
1007	293
1004.96	299
1002.93	310
1000.89	298
998.852	300
996.815	317
994.776	302
992.737	311
990.697	297
988.656	304
986.614	295
984.572	323
982.528	304
980.484	309
978.439	302
976.393	312
974.347	294
972.299	282
970.251	291
968.202	303
966.153	290
964.102	305
962.051	297
959.999	296
957.946	302
955.892	287
953.838	287
951.783	295
949.727	296
947.67	299
945.612	296
943.554	306
941.495	292
939.434	290
937.374	264
935.311	286
933.25	301
931.186	292
929.122	295
927.057	288
924.991	303
922.925	297
920.858	292
918.79	306
916.721	294
914.651	290
912.58	283
910.51	310
908.437	303
906.364	289
904.291	295
902.216	272
900.141	283
898.065	314
895.988	283
893.91	298
891.832	286
889.752	290
887.673	295
885.591	304
883.51	289
881.427	277
879.344	279
877.26	302
875.175	316
873.088	289
871.002	307
868.915	318
866.826	281
864.737	288
862.648	297
860.557	302
858.465	285
856.373	295
854.28	278
852.186	293
850.091	259
847.996	297
845.899	284
843.802	293
841.704	309
839.605	298
837.506	291
835.405	314
833.304	315
831.202	327
829.098	277
826.995	286
824.891	301
822.785	286
820.679	300
818.572	287
816.463	291
814.355	271
812.246	317
810.136	282
808.024	296
805.913	292
803.799	276
801.686	299
799.572	293
797.456	306
795.341	284
793.223	314
791.105	310
788.987	299
786.867	293
784.747	292
782.626	291
780.504	309
778.382	310
776.258	303
774.134	322
772.008	322
769.883	293
767.756	311
765.628	290
763.499	321
761.37	327
759.24	305
757.109	302
754.977	311
752.844	285
750.711	298
748.577	291
746.441	303
744.305	304
742.169	331
740.031	303
737.892	314
735.753	316
733.613	308
731.472	310
729.33	308
727.187	327
725.043	324
722.899	302
720.754	293
718.608	296
716.461	320
714.313	308
712.164	283
710.015	279
707.865	288
705.714	268
703.562	316
701.409	276
699.256	286
697.101	290
694.946	276
692.789	292
690.632	278
688.474	279
686.315	279
684.156	268
681.995	292
679.834	259
677.673	262
675.51	262
673.346	274
671.181	264
669.016	274
666.849	269
664.682	271
662.514	275
660.345	288
658.175	259
656.005	259
653.834	276
651.661	242
649.488	278
647.314	268
645.139	274
642.964	268
640.787	271
638.609	283
636.43	290
634.251	275
632.072	284
629.89	270
627.709	290
625.526	281
623.343	278
621.158	292
618.974	303
616.787	279
614.601	273
612.413	265
610.224	284
608.035	288
605.845	272
603.654	289
601.462	293
599.268	284
597.075	284
594.88	298
592.684	291
590.488	289
588.291	286
586.093	300
583.894	283
581.694	296
579.493	297
577.292	297
575.089	288
572.886	294
570.682	282
568.477	297
566.271	301
564.065	306
561.856	279
559.648	313
557.439	289
555.229	289
553.018	305
550.806	300
548.593	297
546.379	295
544.165	295
541.949	293
539.732	292
537.515	291
535.297	290
533.078	290
530.858	301
528.638	306
526.416	288
524.193	303
521.97	299
519.746	297
517.521	299
515.295	308
513.068	318
510.84	296
508.611	291
506.382	322
504.152	304
501.92	305
499.688	308
497.455	318
495.221	311
492.986	316
490.751	311
488.514	324
486.277	319
484.038	314
481.799	302
479.559	304
477.318	298
475.076	326
472.833	313
470.589	313
468.345	288
466.099	315
463.853	307
461.606	307
459.358	291
457.109	316
454.859	316
452.608	318
450.357	302
448.103	330
445.85	306
443.596	320
441.341	329
439.084	307
436.828	303
434.57	329
432.311	318
430.051	311
427.79	328
425.529	324
423.267	337
421.003	315
418.739	338
416.474	330
414.208	354
411.941	339
409.673	332
407.404	323
405.134	339
402.865	333
400.593	326
398.321	342
396.047	340
393.773	350
391.498	343
389.223	329
386.945	355
384.668	348
382.389	361
380.109	344
377.829	381
375.548	382
373.265	350
370.983	363
368.698	346
366.413	359
364.127	357
361.841	369
359.553	350
357.265	361
354.974	356
352.684	365
350.393	389
348.1	377
345.808	389
343.513	368
341.219	381
338.923	369
336.625	381
334.328	379
332.029	380
329.729	395
327.429	361
325.128	379
322.825	386
320.522	402
318.218	408
315.913	401
313.606	362
311.3	391
308.992	413
306.684	388
304.374	409
302.063	415
299.751	424
297.439	417
295.125	416
292.811	413
290.496	416
288.18	424
285.863	429
283.545	426
281.226	453
278.907	434
276.585	458
274.263	463
271.941	441
269.617	471
267.293	479
264.967	503
262.641	500
260.314	515
257.985	504
255.656	526
253.327	530
250.996	534
248.664	548
246.331	608
243.997	599
241.662	629
239.327	677
236.99	688
234.652	712
232.315	754
229.975	749
227.635	743
225.293	828
222.951	878
220.608	843
218.264	853
215.919	948
213.573	902
211.226	931
208.879	984
206.529	1055
204.18	970
201.829	977
199.477	1106
197.125	1098
194.772	1078
192.417	1117
190.062	1225
187.705	1273
185.348	1163
182.99	1281
180.631	1371
178.271	1341
175.909	1283
173.548	1414
171.185	1511
168.821	1440
166.456	1449
164.09	1638
161.723	1693
159.356	1682
156.987	1608
154.618	1565
152.247	1769
149.875	1857
147.503	1749
145.13	1664
142.755	1619
140.38	1631
138.004	1679
135.627	1719
133.249	1818
130.87	1812
128.489	1866
126.109	1978
123.727	2130
121.343	2177
118.96	2098
116.575	1987
114.189	2087
111.802	2289
109.415	2465
107.026	2495
104.636	2502
102.246	2548
99.8545	2703
97.4613	2889
95.0681	3120
92.674	3217
90.278	3534
87.8821	3834
85.4843	4251
83.0866	4704
80.687	5125
78.2865	5611
75.8851	6025
73.4827	6648
71.0805	7530
68.6763	9035
66.2712	11384
63.8643	15285
61.4574	21998
59.0496	32871
56.6409	44454
54.2312	52604
51.8197	57155
49.4082	59929
46.9948	61112
44.5815	62043
42.1663	62044
39.7512	61754
37.3342	61819
34.9162	63006
32.4973	64458
30.0775	64524
27.6568	64524
25.2361	64524
22.8126	64524
20.3891	64524
17.9647	64524
15.5393	64524
13.1131	64524
10.6849	64524
8.25676	64524
5.82772	64524
3.39677	64524
0.965873	64524