File: projects/python/data/20231109-finger/2nailfold_600_785 nm_120 s_1_2023_11_09_18_08_11_01.txt
#Sample=2nailfold
#Laser=785 nm
#Grating=600
#Exposition=120
#Accumulation=1
#Acquired=09.11.2023 18:08:11
1568.38	2907
1566.56	2942
1564.74	2868
1562.92	2894
1561.1	2975
1559.27	2974
1557.45	2919
1555.62	2912
1553.8	2967
1551.97	2972
1550.15	2953
1548.32	2940
1546.49	2984
1544.66	2950
1542.84	2934
1541.01	2961
1539.18	2972
1537.34	2952
1535.51	2905
1533.68	2943
1531.85	2977
1530.01	2922
1528.18	2960
1526.34	2969
1524.51	2954
1522.67	2925
1520.83	2893
1518.99	2938
1517.15	2921
1515.31	2927
1513.47	2949
1511.63	2935
1509.79	2985
1507.95	2971
1506.11	2924
1504.26	2955
1502.42	2942
1500.57	2993
1498.73	2942
1496.88	2934
1495.03	2928
1493.19	3003
1491.34	2953
1489.49	2943
1487.64	2987
1485.79	2940
1483.94	2980
1482.08	2981
1480.23	2948
1478.38	2964
1476.52	2952
1474.67	2938
1472.81	2939
1470.96	2954
1469.1	2942
1467.24	2998
1465.38	2955
1463.52	2974
1461.66	3041
1459.8	3065
1457.94	3089
1456.08	3044
1454.22	3033
1452.35	3045
1450.49	3039
1448.62	3051
1446.76	3024
1444.89	2997
1443.03	3011
1441.16	3010
1439.29	3028
1437.42	3000
1435.55	3001
1433.68	3014
1431.81	3035
1429.94	3010
1428.06	3068
1426.19	3017
1424.32	2997
1422.44	3004
1420.57	2979
1418.69	2974
1416.81	2983
1414.94	3001
1413.06	2988
1411.18	3048
1409.3	3007
1407.42	2942
1405.54	2941
1403.65	2906
1401.77	3004
1399.89	2970
1398.01	2989
1396.12	2983
1394.23	3003
1392.35	3010
1390.46	2983
1388.57	2999
1386.69	2978
1384.8	3010
1382.91	2959
1381.02	2988
1379.13	2954
1377.23	2891
1375.34	2971
1373.45	2958
1371.55	2958
1369.66	2995
1367.76	2978
1365.87	2938
1363.97	2989
1362.07	2965
1360.17	2970
1358.27	2991
1356.37	2999
1354.47	2967
1352.57	3037
1350.67	3083
1348.77	3016
1346.86	3024
1344.96	3012
1343.05	2981
1341.15	3020
1339.24	2990
1337.34	3040
1335.43	2976
1333.52	3019
1331.61	3004
1329.7	3009
1327.79	2984
1325.88	2992
1323.97	3004
1322.05	2982
1320.14	3039
1318.22	3056
1316.31	3058
1314.39	3046
1312.48	3037
1310.56	3010
1308.64	3036
1306.72	3055
1304.8	3033
1302.88	3119
1300.96	3033
1299.04	3040
1297.12	3086
1295.19	3013
1293.27	3088
1291.35	3069
1289.42	3056
1287.49	3085
1285.57	3067
1283.64	3044
1281.71	3097
1279.78	3078
1277.85	3107
1275.92	3048
1273.99	3132
1272.06	3077
1270.12	3129
1268.19	3144
1266.26	3130
1264.32	3050
1262.39	3123
1260.45	3131
1258.51	3158
1256.58	3129
1254.64	3061
1252.7	3152
1250.76	3128
1248.82	3083
1246.87	3117
1244.93	3089
1242.99	3034
1241.04	3104
1239.1	3072
1237.15	3033
1235.21	3075
1233.26	3049
1231.31	3078
1229.37	3090
1227.42	3037
1225.47	3004
1223.52	3015
1221.56	2967
1219.61	3019
1217.66	2969
1215.71	2944
1213.75	2946
1211.8	3002
1209.84	2954
1207.88	2929
1205.93	2942
1203.97	2897
1202.01	2921
1200.05	2949
1198.09	2917
1196.13	2929
1194.17	2919
1192.2	2931
1190.24	2905
1188.28	2943
1186.31	2941
1184.35	2912
1182.38	2930
1180.41	2909
1178.45	2870
1176.48	2927
1174.51	2874
1172.54	2915
1170.57	2925
1168.59	2955
1166.62	2938
1164.65	2915
1162.67	2908
1160.7	2867
1158.72	2908
1156.75	2907
1154.77	2872
1152.79	2936
1150.82	2890
1148.84	2902
1146.86	2888
1144.87	2900
1142.89	2914
1140.91	2925
1138.93	2921
1136.94	2948
1134.96	2862
1132.97	2929
1130.99	2911
1129	2909
1127.01	2910
1125.02	2933
1123.04	2921
1121.05	2906
1119.06	2947
1117.06	2937
1115.07	2903
1113.08	2919
1111.08	2943
1109.09	3012
1107.1	2973
1105.1	3002
1103.1	2936
1101.1	2958
1099.11	2952
1097.11	2973
1095.11	2949
1093.11	3010
1091.11	3031
1089.1	2944
1087.1	3023
1085.1	2991
1083.09	3015
1081.09	3006
1079.08	3020
1077.07	3016
1075.07	3062
1073.06	3020
1071.05	2985
1069.04	3064
1067.03	3046
1065.02	3031
1063	3022
1060.99	3109
1058.98	3020
1056.96	3063
1054.95	3018
1052.93	3045
1050.91	2979
1048.9	3010
1046.88	3034
1044.86	3029
1042.84	3045
1040.82	3040
1038.79	3075
1036.77	3049
1034.75	3047
1032.73	3079
1030.7	3036
1028.68	3104
1026.65	3037
1024.62	3086
1022.59	3050
1020.57	3054
1018.54	3038
1016.51	3099
1014.47	3099
1012.44	3057
1010.41	3079
1008.38	3081
1006.34	3080
1004.31	3128
1002.27	3183
1000.24	3190
998.198	3155
996.16	3130
994.121	3158
992.082	3192
990.041	3151
988	3156
985.958	3221
983.915	3195
981.871	3226
979.827	3262
977.782	3210
975.735	3203
973.689	3252
971.642	3245
969.593	3245
967.544	3207
965.493	3288
963.443	3294
961.392	3241
959.339	3287
957.286	3322
955.232	3286
953.178	3299
951.122	3289
949.066	3316
947.008	3311
944.951	3221
942.892	3270
940.832	3309
938.772	3316
936.71	3346
934.649	3291
932.586	3329
930.522	3285
928.459	3338
926.393	3347
924.328	3342
922.261	3331
920.193	3321
918.125	3287
916.056	3298
913.986	3367
911.915	3356
909.844	3323
907.771	3320
905.698	3327
903.624	3278
901.549	3340
899.474	3272
897.397	3314
895.32	3302
893.242	3337
891.164	3304
889.084	3314
887.003	3337
884.922	3363
882.84	3329
880.758	3334
878.674	3351
876.589	3329
874.504	3342
872.418	3385
870.331	3345
868.243	3322
866.154	3407
864.066	3421
861.975	3423
859.884	3415
857.792	3417
855.7	3416
853.607	3419
851.513	3384
849.417	3398
847.322	3413
845.224	3526
843.128	3436
841.029	3412
838.93	3415
836.83	3479
834.729	3463
832.627	3468
830.525	3444
828.422	3468
826.318	3454
824.213	3480
822.108	3440
820.001	3454
817.894	3456
815.786	3413
813.677	3460
811.567	3452
809.456	3415
807.345	3460
805.233	3381
803.12	3482
801.006	3454
798.891	3458
796.775	3438
794.66	3361
792.542	3417
790.424	3439
788.305	3399
786.185	3419
784.065	3395
781.944	3431
779.822	3458
777.698	3464
775.575	3388
773.45	3364
771.325	3432
769.198	3441
767.071	3450
764.944	3424
762.815	3442
760.685	3456
758.555	3529
756.423	3525
754.291	3478
752.158	3579
750.024	3516
747.89	3491
745.754	3547
743.617	3549
741.481	3558
739.343	3598
737.204	3552
735.065	3564
732.924	3525
730.782	3543
728.64	3551
726.498	3558
724.353	3568
722.209	3593
720.063	3622
717.917	3556
715.77	3591
713.622	3570
711.473	3561
709.323	3547
707.173	3522
705.021	3514
702.869	3561
700.716	3521
698.562	3508
696.408	3497
694.252	3461
692.095	3497
689.938	3461
687.78	3466
685.621	3467
683.461	3431
681.301	3419
679.138	3483
676.976	3455
674.813	3466
672.649	3428
670.484	3456
668.318	3462
666.151	3432
663.985	3461
661.816	3476
659.647	3472
657.477	3439
655.306	3502
653.134	3471
650.961	3482
648.788	3548
646.613	3520
644.439	3497
642.262	3508
640.085	3483
637.908	3506
635.73	3614
633.55	3593
631.37	3584
629.189	3660
627.007	3565
624.823	3535
622.64	3607
620.456	3632
618.27	3584
616.084	3573
613.896	3614
611.708	3564
609.52	3590
607.33	3606
605.14	3539
602.948	3601
600.756	3546
598.562	3567
596.368	3547
594.174	3492
591.977	3543
589.781	3527
587.583	3514
585.385	3546
583.186	3566
580.986	3522
578.785	3564
576.583	3567
574.38	3503
572.177	3525
569.973	3543
567.767	3554
565.561	3454
563.353	3516
561.146	3471
558.937	3480
556.728	3511
554.517	3483
552.305	3528
550.093	3528
547.88	3514
545.666	3530
543.451	3500
541.236	3560
539.018	3506
536.801	3601
534.583	3561
532.363	3600
530.144	3602
527.923	3601
525.7	3545
523.477	3561
521.254	3612
519.029	3605
516.804	3639
514.578	3583
512.351	3641
510.123	3614
507.893	3635
505.664	3584
503.433	3584
501.202	3559
498.969	3533
496.735	3590
494.502	3512
492.267	3522
490.031	3508
487.794	3573
485.556	3497
483.317	3494
481.078	3551
478.837	3476
476.597	3497
474.354	3503
472.11	3521
469.867	3544
467.622	3518
465.376	3567
463.13	3464
460.882	3557
458.634	3576
456.385	3541
454.134	3538
451.883	3604
449.631	3533
447.379	3554
445.124	3547
442.87	3579
440.614	3686
438.358	3633
436.101	3635
433.842	3638
431.583	3638
429.323	3641
427.062	3659
424.8	3616
422.538	3669
420.274	3681
418.009	3709
415.744	3654
413.478	3704
411.211	3731
408.943	3707
406.674	3641
404.404	3683
402.133	3648
399.862	3656
397.589	3624
395.316	3651
393.041	3638
390.765	3644
388.489	3666
386.212	3676
383.935	3684
381.655	3575
379.376	3622
377.095	3713
374.813	3658
372.531	3628
370.247	3674
367.962	3561
365.677	3687
363.391	3673
361.104	3654
358.816	3649
356.527	3637
354.238	3696
351.946	3647
349.655	3689
347.363	3695
345.069	3695
342.774	3706
340.479	3700
338.183	3653
335.886	3638
333.587	3672
331.288	3649
328.989	3674
326.688	3681
324.386	3653
322.084	3738
319.781	3703
317.476	3707
315.171	3691
312.864	3743
310.557	3759
308.249	3738
305.94	3788
303.63	3786
301.319	3738
299.007	3804
296.694	3807
294.38	3856
292.066	3795
289.751	3751
287.434	3774
285.116	3832
282.798	3880
280.48	3928
278.159	3880
275.838	3849
273.516	3880
271.193	3848
268.87	3882
266.545	3838
264.219	3865
261.892	3924
259.565	3892
257.236	3905
254.907	4039
252.577	4029
250.245	3944
247.913	3992
245.58	4085
243.245	4102
240.911	4071
238.575	4132
236.237	4106
233.9	4075
231.561	4155
229.221	4190
226.881	4176
224.539	4193
222.197	4268
219.853	4356
217.509	4323
215.164	4326
212.817	4341
210.47	4374
208.123	4434
205.773	4496
203.423	4563
201.072	4509
198.72	4625
196.368	4655
194.014	4692
191.659	4734
189.303	4863
186.947	4857
184.589	4900
182.231	4876
179.871	4987
177.511	5100
175.149	5155
172.787	5050
170.424	4990
168.06	5144
165.695	5146
163.329	5230
160.961	5133
158.594	5189
156.225	5296
153.855	5385
151.484	5369
149.112	5411
146.739	5421
144.366	5660
141.991	5797
139.616	5783
137.239	5648
134.862	5717
132.483	5802
130.103	5771
127.724	5758
125.342	5892
122.96	6039
120.577	6285
118.192	6494
115.807	6591
113.422	6512
111.034	6604
108.646	6789
106.257	7003
103.868	7170
101.476	7212
99.0842	7412
96.6916	7567
94.2982	7956
91.9028	8333
89.5075	8666
87.1103	8978
84.7132	9368
82.3143	9784
79.9144	10165
77.5145	10931
75.1128	11779
72.7102	13126
70.3066	15188
67.9022	18323
65.4968	23314
63.0906	32368
60.6834	44885
58.2753	55514
55.8653	62150
53.4553	64524
51.0445	64524
48.6317	64524
46.2191	64524
43.8045	64524
41.39	64524
38.9735	64524
36.5562	64524
34.1379	64524
31.7198	64524
29.2997	64524
26.8786	64524
24.4567	64524
22.0338	64524
19.61	64524
17.1843	64524
14.7587	64524
12.3321	64524
9.90466	64524
7.47525	64524
5.04592	64524
2.61466	64524
0.183468	64524