File: projects/python/data/20231109-finger/2noise_600_785 nm_120 s_1_2023_11_09_18_12_57_01.txt
#Sample=2noise
#Laser=785 nm
#Grating=600
#Exposition=120
#Accumulation=1
#Acquired=09.11.2023 18:12:57
1568.38	36
1566.56	46
1564.74	37
1562.92	43
1561.1	41
1559.27	50
1557.45	43
1555.62	41
1553.8	44
1551.97	39
1550.15	45
1548.32	40
1546.49	47
1544.66	36
1542.84	48
1541.01	41
1539.18	46
1537.34	48
1535.51	54
1533.68	44
1531.85	33
1530.01	37
1528.18	38
1526.34	47
1524.51	32
1522.67	59
1520.83	31
1518.99	39
1517.15	52
1515.31	44
1513.47	54
1511.63	32
1509.79	36
1507.95	44
1506.11	48
1504.26	53
1502.42	44
1500.57	50
1498.73	38
1496.88	48
1495.03	43
1493.19	46
1491.34	37
1489.49	55
1487.64	50
1485.79	42
1483.94	41
1482.08	57
1480.23	40
1478.38	39
1476.52	39
1474.67	59
1472.81	41
1470.96	44
1469.1	36
1467.24	34
1465.38	36
1463.52	69
1461.66	32
1459.8	46
1457.94	31
1456.08	40
1454.22	41
1452.35	44
1450.49	53
1448.62	44
1446.76	44
1444.89	43
1443.03	50
1441.16	43
1439.29	54
1437.42	38
1435.55	54
1433.68	59
1431.81	46
1429.94	27
1428.06	47
1426.19	47
1424.32	44
1422.44	37
1420.57	34
1418.69	62
1416.81	42
1414.94	60
1413.06	43
1411.18	43
1409.3	45
1407.42	53
1405.54	52
1403.65	38
1401.77	46
1399.89	43
1398.01	49
1396.12	44
1394.23	37
1392.35	45
1390.46	40
1388.57	37
1386.69	44
1384.8	49
1382.91	47
1381.02	46
1379.13	45
1377.23	38
1375.34	43
1373.45	30
1371.55	37
1369.66	45
1367.76	49
1365.87	42
1363.97	43
1362.07	51
1360.17	35
1358.27	39
1356.37	47
1354.47	38
1352.57	46
1350.67	32
1348.77	40
1346.86	44
1344.96	37
1343.05	57
1341.15	46
1339.24	42
1337.34	36
1335.43	45
1333.52	41
1331.61	47
1329.7	35
1327.79	50
1325.88	27
1323.97	35
1322.05	46
1320.14	50
1318.22	45
1316.31	36
1314.39	44
1312.48	37
1310.56	53
1308.64	39
1306.72	46
1304.8	42
1302.88	37
1300.96	41
1299.04	34
1297.12	47
1295.19	41
1293.27	39
1291.35	47
1289.42	43
1287.49	46
1285.57	35
1283.64	40
1281.71	48
1279.78	40
1277.85	53
1275.92	50
1273.99	38
1272.06	50
1270.12	48
1268.19	45
1266.26	55
1264.32	55
1262.39	35
1260.45	46
1258.51	47
1256.58	40
1254.64	30
1252.7	40
1250.76	61
1248.82	28
1246.87	38
1244.93	41
1242.99	52
1241.04	51
1239.1	42
1237.15	47
1235.21	53
1233.26	46
1231.31	26
1229.37	47
1227.42	42
1225.47	35
1223.52	45
1221.56	31
1219.61	54
1217.66	45
1215.71	32
1213.75	43
1211.8	44
1209.84	35
1207.88	33
1205.93	38
1203.97	38
1202.01	36
1200.05	40
1198.09	33
1196.13	39
1194.17	39
1192.2	46
1190.24	40
1188.28	45
1186.31	58
1184.35	40
1182.38	49
1180.41	46
1178.45	45
1176.48	37
1174.51	52
1172.54	31
1170.57	49
1168.59	45
1166.62	35
1164.65	34
1162.67	46
1160.7	41
1158.72	45
1156.75	34
1154.77	43
1152.79	51
1150.82	31
1148.84	51
1146.86	43
1144.87	46
1142.89	60
1140.91	36
1138.93	48
1136.94	40
1134.96	45
1132.97	40
1130.99	38
1129	58
1127.01	44
1125.02	41
1123.04	48
1121.05	47
1119.06	59
1117.06	50
1115.07	43
1113.08	44
1111.08	46
1109.09	42
1107.1	45
1105.1	28
1103.1	44
1101.1	41
1099.11	47
1097.11	51
1095.11	50
1093.11	44
1091.11	53
1089.1	40
1087.1	42
1085.1	55
1083.09	52
1081.09	51
1079.08	46
1077.07	39
1075.07	38
1073.06	50
1071.05	40
1069.04	39
1067.03	44
1065.02	49
1063	29
1060.99	50
1058.98	54
1056.96	48
1054.95	51
1052.93	39
1050.91	31
1048.9	51
1046.88	30
1044.86	54
1042.84	38
1040.82	42
1038.79	52
1036.77	41
1034.75	45
1032.73	55
1030.7	37
1028.68	40
1026.65	47
1024.62	49
1022.59	50
1020.57	45
1018.54	42
1016.51	34
1014.47	43
1012.44	53
1010.41	37
1008.38	45
1006.34	43
1004.31	52
1002.27	45
1000.24	37
998.198	45
996.16	48
994.121	46
992.082	31
990.041	47
988	43
985.958	32
983.915	49
981.871	36
979.827	40
977.782	42
975.735	38
973.689	35
971.642	40
969.593	42
967.544	43
965.493	55
963.443	34
961.392	30
959.339	37
957.286	48
955.232	50
953.178	49
951.122	57
949.066	47
947.008	50
944.951	43
942.892	37
940.832	39
938.772	38
936.71	47
934.649	52
932.586	39
930.522	42
928.459	51
926.393	46
924.328	40
922.261	36
920.193	43
918.125	52
916.056	41
913.986	38
911.915	50
909.844	32
907.771	36
905.698	49
903.624	37
901.549	39
899.474	38
897.397	46
895.32	45
893.242	37
891.164	38
889.084	51
887.003	49
884.922	37
882.84	35
880.758	49
878.674	46
876.589	55
874.504	45
872.418	52
870.331	45
868.243	45
866.154	38
864.066	45
861.975	38
859.884	47
857.792	41
855.7	39
853.607	39
851.513	23
849.417	46
847.322	43
845.224	40
843.128	30
841.029	40
838.93	35
836.83	36
834.729	48
832.627	43
830.525	40
828.422	44
826.318	34
824.213	34
822.108	36
820.001	50
817.894	48
815.786	39
813.677	53
811.567	36
809.456	45
807.345	44
805.233	50
803.12	33
801.006	48
798.891	35
796.775	44
794.66	59
792.542	51
790.424	42
788.305	36
786.185	32
784.065	60
781.944	40
779.822	49
777.698	54
775.575	40
773.45	60
771.325	46
769.198	47
767.071	35
764.944	48
762.815	46
760.685	49
758.555	58
756.423	32
754.291	52
752.158	29
750.024	49
747.89	23
745.754	24
743.617	50
741.481	39
739.343	51
737.204	30
735.065	48
732.924	33
730.782	46
728.64	32
726.498	41
724.353	48
722.209	43
720.063	43
717.917	58
715.77	41
713.622	54
711.473	38
709.323	50
707.173	49
705.021	51
702.869	49
700.716	43
698.562	53
696.408	47
694.252	40
692.095	35
689.938	48
687.78	39
685.621	38
683.461	40
681.301	40
679.138	36
676.976	42
674.813	51
672.649	50
670.484	46
668.318	42
666.151	49
663.985	40
661.816	47
659.647	39
657.477	53
655.306	43
653.134	34
650.961	54
648.788	50
646.613	51
644.439	50
642.262	47
640.085	35
637.908	49
635.73	52
633.55	51
631.37	34
629.189	46
627.007	51
624.823	46
622.64	44
620.456	53
618.27	31
616.084	42
613.896	49
611.708	38
609.52	37
607.33	36
605.14	37
602.948	55
600.756	61
598.562	33
596.368	48
594.174	53
591.977	52
589.781	43
587.583	63
585.385	36
583.186	47
580.986	62
578.785	40
576.583	36
574.38	42
572.177	38
569.973	37
567.767	38
565.561	52
563.353	37
561.146	39
558.937	41
556.728	35
554.517	42
552.305	37
550.093	44
547.88	39
545.666	44
543.451	33
541.236	39
539.018	42
536.801	40
534.583	36
532.363	37
530.144	44
527.923	51
525.7	52
523.477	38
521.254	41
519.029	28
516.804	42
514.578	40
512.351	45
510.123	33
507.893	58
505.664	49
503.433	52
501.202	43
498.969	45
496.735	33
494.502	49
492.267	44
490.031	58
487.794	41
485.556	31
483.317	51
481.078	32
478.837	43
476.597	57
474.354	46
472.11	30
469.867	40
467.622	52
465.376	57
463.13	37
460.882	35
458.634	58
456.385	48
454.134	53
451.883	41
449.631	40
447.379	57
445.124	42
442.87	29
440.614	51
438.358	40
436.101	47
433.842	53
431.583	45
429.323	48
427.062	38
424.8	38
422.538	41
420.274	45
418.009	46
415.744	47
413.478	37
411.211	39
408.943	39
406.674	49
404.404	38
402.133	47
399.862	48
397.589	40
395.316	47
393.041	45
390.765	54
388.489	38
386.212	38
383.935	58
381.655	37
379.376	51
377.095	43
374.813	43
372.531	33
370.247	47
367.962	36
365.677	46
363.391	44
361.104	41
358.816	56
356.527	32
354.238	41
351.946	44
349.655	41
347.363	54
345.069	44
342.774	53
340.479	54
338.183	33
335.886	39
333.587	44
331.288	43
328.989	45
326.688	37
324.386	54
322.084	46
319.781	52
317.476	43
315.171	43
312.864	31
310.557	45
308.249	54
305.94	36
303.63	40
301.319	48
299.007	37
296.694	35
294.38	56
292.066	32
289.751	40
287.434	45
285.116	42
282.798	50
280.48	50
278.159	26
275.838	37
273.516	37
271.193	47
268.87	37
266.545	45
264.219	37
261.892	47
259.565	42
257.236	45
254.907	55
252.577	49
250.245	38
247.913	45
245.58	39
243.245	44
240.911	45
238.575	39
236.237	45
233.9	42
231.561	42
229.221	43
226.881	36
224.539	39
222.197	39
219.853	45
217.509	40
215.164	36
212.817	42
210.47	50
208.123	47
205.773	40
203.423	36
201.072	39
198.72	31
196.368	46
194.014	42
191.659	42
189.303	40
186.947	28
184.589	53
182.231	47
179.871	57
177.511	54
175.149	50
172.787	53
170.424	40
168.06	53
165.695	43
163.329	47
160.961	51
158.594	42
156.225	43
153.855	38
151.484	50
149.112	56
146.739	35
144.366	42
141.991	37
139.616	45
137.239	38
134.862	54
132.483	35
130.103	35
127.724	37
125.342	43
122.96	29
120.577	28
118.192	46
115.807	43
113.422	54
111.034	43
108.646	54
106.257	41
103.868	48
101.476	37
99.0842	44
96.6916	51
94.2982	37
91.9028	44
89.5075	45
87.1103	30
84.7132	40
82.3143	43
79.9144	42
77.5145	37
75.1128	43
72.7102	32
70.3066	54
67.9022	37
65.4968	45
63.0906	50
60.6834	314
58.2753	405
55.8653	161
53.4553	71
51.0445	39
48.6317	35
46.2191	49
43.8045	55
41.39	48
38.9735	40
36.5562	34
34.1379	59
31.7198	40
29.2997	46
26.8786	40
24.4567	45
22.0338	48
19.61	58
17.1843	51
14.7587	62
12.3321	45
9.90466	52
7.47525	47
5.04592	48
2.61466	43
0.183468	45