File: projects/python/data/20231109-finger/2nothing_600_785 nm_120 s_1_2023_11_09_17_52_45_01.txt
#Sample=2nothing
#Laser=785 nm
#Grating=600
#Exposition=120
#Accumulation=1
#Acquired=09.11.2023 17:52:45
1568.38	545
1566.56	530
1564.74	512
1562.92	538
1561.1	552
1559.27	541
1557.45	533
1555.62	522
1553.8	527
1551.97	536
1550.15	523
1548.32	543
1546.49	533
1544.66	558
1542.84	564
1541.01	526
1539.18	536
1537.34	545
1535.51	521
1533.68	516
1531.85	529
1530.01	540
1528.18	525
1526.34	525
1524.51	528
1522.67	535
1520.83	542
1518.99	521
1517.15	539
1515.31	522
1513.47	550
1511.63	525
1509.79	549
1507.95	524
1506.11	537
1504.26	537
1502.42	535
1500.57	519
1498.73	554
1496.88	493
1495.03	535
1493.19	532
1491.34	532
1489.49	525
1487.64	541
1485.79	504
1483.94	532
1482.08	514
1480.23	527
1478.38	517
1476.52	532
1474.67	532
1472.81	519
1470.96	502
1469.1	531
1467.24	542
1465.38	528
1463.52	524
1461.66	511
1459.8	526
1457.94	543
1456.08	510
1454.22	528
1452.35	554
1450.49	529
1448.62	534
1446.76	533
1444.89	512
1443.03	509
1441.16	539
1439.29	531
1437.42	521
1435.55	518
1433.68	511
1431.81	546
1429.94	502
1428.06	511
1426.19	501
1424.32	522
1422.44	535
1420.57	505
1418.69	526
1416.81	503
1414.94	537
1413.06	550
1411.18	513
1409.3	539
1407.42	530
1405.54	523
1403.65	529
1401.77	519
1399.89	534
1398.01	503
1396.12	480
1394.23	517
1392.35	480
1390.46	487
1388.57	508
1386.69	508
1384.8	511
1382.91	512
1381.02	508
1379.13	492
1377.23	520
1375.34	504
1373.45	476
1371.55	500
1369.66	510
1367.76	506
1365.87	480
1363.97	518
1362.07	518
1360.17	509
1358.27	525
1356.37	506
1354.47	519
1352.57	515
1350.67	499
1348.77	495
1346.86	497
1344.96	496
1343.05	508
1341.15	500
1339.24	508
1337.34	535
1335.43	524
1333.52	528
1331.61	512
1329.7	484
1327.79	522
1325.88	514
1323.97	524
1322.05	524
1320.14	504
1318.22	521
1316.31	511
1314.39	556
1312.48	538
1310.56	530
1308.64	541
1306.72	544
1304.8	562
1302.88	527
1300.96	575
1299.04	585
1297.12	564
1295.19	575
1293.27	576
1291.35	604
1289.42	595
1287.49	600
1285.57	610
1283.64	578
1281.71	600
1279.78	630
1277.85	598
1275.92	617
1273.99	623
1272.06	620
1270.12	627
1268.19	645
1266.26	637
1264.32	614
1262.39	612
1260.45	586
1258.51	623
1256.58	615
1254.64	603
1252.7	608
1250.76	613
1248.82	592
1246.87	552
1244.93	560
1242.99	578
1241.04	557
1239.1	536
1237.15	572
1235.21	556
1233.26	561
1231.31	545
1229.37	506
1227.42	538
1225.47	514
1223.52	521
1221.56	485
1219.61	485
1217.66	491
1215.71	477
1213.75	491
1211.8	449
1209.84	471
1207.88	450
1205.93	459
1203.97	452
1202.01	405
1200.05	430
1198.09	409
1196.13	416
1194.17	426
1192.2	397
1190.24	409
1188.28	405
1186.31	402
1184.35	415
1182.38	379
1180.41	379
1178.45	395
1176.48	399
1174.51	422
1172.54	396
1170.57	402
1168.59	374
1166.62	386
1164.65	393
1162.67	398
1160.7	403
1158.72	399
1156.75	389
1154.77	389
1152.79	405
1150.82	396
1148.84	380
1146.86	393
1144.87	375
1142.89	391
1140.91	378
1138.93	382
1136.94	409
1134.96	396
1132.97	416
1130.99	385
1129	387
1127.01	381
1125.02	400
1123.04	382
1121.05	371
1119.06	392
1117.06	373
1115.07	374
1113.08	387
1111.08	362
1109.09	382
1107.1	361
1105.1	385
1103.1	384
1101.1	379
1099.11	363
1097.11	387
1095.11	397
1093.11	370
1091.11	366
1089.1	366
1087.1	360
1085.1	379
1083.09	357
1081.09	349
1079.08	365
1077.07	350
1075.07	352
1073.06	355
1071.05	341
1069.04	363
1067.03	363
1065.02	340
1063	366
1060.99	339
1058.98	334
1056.96	358
1054.95	334
1052.93	351
1050.91	350
1048.9	333
1046.88	329
1044.86	347
1042.84	338
1040.82	345
1038.79	343
1036.77	321
1034.75	334
1032.73	331
1030.7	297
1028.68	318
1026.65	323
1024.62	335
1022.59	316
1020.57	317
1018.54	309
1016.51	284
1014.47	302
1012.44	276
1010.41	285
1008.38	285
1006.34	300
1004.31	295
1002.27	326
1000.24	269
998.198	287
996.16	308
994.121	292
992.082	291
990.041	283
988	284
985.958	292
983.915	276
981.871	288
979.827	290
977.782	278
975.735	270
973.689	286
971.642	296
969.593	275
967.544	297
965.493	285
963.443	279
961.392	292
959.339	274
957.286	275
955.232	297
953.178	288
951.122	290
949.066	297
947.008	260
944.951	307
942.892	292
940.832	283
938.772	279
936.71	280
934.649	282
932.586	258
930.522	282
928.459	264
926.393	266
924.328	269
922.261	283
920.193	289
918.125	284
916.056	289
913.986	271
911.915	284
909.844	289
907.771	274
905.698	285
903.624	296
901.549	260
899.474	281
897.397	269
895.32	295
893.242	296
891.164	284
889.084	305
887.003	277
884.922	278
882.84	294
880.758	288
878.674	295
876.589	287
874.504	275
872.418	289
870.331	274
868.243	258
866.154	276
864.066	280
861.975	281
859.884	289
857.792	273
855.7	282
853.607	284
851.513	269
849.417	291
847.322	269
845.224	305
843.128	274
841.029	273
838.93	274
836.83	287
834.729	289
832.627	281
830.525	285
828.422	299
826.318	282
824.213	293
822.108	261
820.001	277
817.894	294
815.786	271
813.677	293
811.567	273
809.456	279
807.345	273
805.233	296
803.12	281
801.006	285
798.891	272
796.775	289
794.66	280
792.542	279
790.424	305
788.305	284
786.185	287
784.065	302
781.944	294
779.822	279
777.698	276
775.575	282
773.45	303
771.325	279
769.198	294
767.071	300
764.944	303
762.815	304
760.685	300
758.555	297
756.423	286
754.291	300
752.158	292
750.024	284
747.89	301
745.754	299
743.617	276
741.481	292
739.343	292
737.204	291
735.065	278
732.924	304
730.782	302
728.64	268
726.498	264
724.353	279
722.209	288
720.063	299
717.917	300
715.77	282
713.622	284
711.473	290
709.323	286
707.173	260
705.021	261
702.869	266
700.716	269
698.562	275
696.408	292
694.252	261
692.095	271
689.938	291
687.78	270
685.621	256
683.461	257
681.301	262
679.138	256
676.976	261
674.813	252
672.649	259
670.484	251
668.318	262
666.151	247
663.985	258
661.816	268
659.647	248
657.477	271
655.306	248
653.134	261
650.961	250
648.788	258
646.613	248
644.439	276
642.262	267
640.085	263
637.908	259
635.73	250
633.55	276
631.37	264
629.189	260
627.007	258
624.823	259
622.64	254
620.456	302
618.27	248
616.084	257
613.896	278
611.708	247
609.52	261
607.33	284
605.14	257
602.948	269
600.756	286
598.562	261
596.368	298
594.174	261
591.977	255
589.781	267
587.583	289
585.385	271
583.186	283
580.986	294
578.785	278
576.583	267
574.38	282
572.177	276
569.973	263
567.767	291
565.561	264
563.353	263
561.146	264
558.937	290
556.728	266
554.517	272
552.305	278
550.093	276
547.88	287
545.666	291
543.451	286
541.236	285
539.018	276
536.801	260
534.583	288
532.363	271
530.144	285
527.923	284
525.7	280
523.477	262
521.254	312
519.029	309
516.804	292
514.578	272
512.351	275
510.123	314
507.893	293
505.664	292
503.433	288
501.202	298
498.969	299
496.735	285
494.502	286
492.267	294
490.031	295
487.794	306
485.556	297
483.317	271
481.078	269
478.837	292
476.597	307
474.354	295
472.11	276
469.867	297
467.622	290
465.376	296
463.13	306
460.882	310
458.634	281
456.385	299
454.134	278
451.883	307
449.631	319
447.379	285
445.124	304
442.87	305
440.614	330
438.358	308
436.101	295
433.842	308
431.583	311
429.323	301
427.062	320
424.8	302
422.538	312
420.274	330
418.009	325
415.744	312
413.478	323
411.211	304
408.943	329
406.674	309
404.404	328
402.133	306
399.862	340
397.589	303
395.316	311
393.041	314
390.765	347
388.489	328
386.212	314
383.935	330
381.655	335
379.376	330
377.095	324
374.813	329
372.531	329
370.247	334
367.962	343
365.677	332
363.391	345
361.104	345
358.816	329
356.527	342
354.238	348
351.946	339
349.655	349
347.363	347
345.069	349
342.774	342
340.479	352
338.183	363
335.886	340
333.587	365
331.288	347
328.989	372
326.688	362
324.386	350
322.084	351
319.781	370
317.476	374
315.171	389
312.864	371
310.557	374
308.249	369
305.94	391
303.63	357
301.319	374
299.007	363
296.694	395
294.38	378
292.066	383
289.751	407
287.434	434
285.116	410
282.798	405
280.48	416
278.159	436
275.838	447
273.516	433
271.193	451
268.87	452
266.545	468
264.219	478
261.892	481
259.565	484
257.236	524
254.907	512
252.577	519
250.245	539
247.913	552
245.58	538
243.245	552
240.911	544
238.575	592
236.237	588
233.9	585
231.561	630
229.221	622
226.881	642
224.539	646
222.197	673
219.853	675
217.509	675
215.164	733
212.817	757
210.47	737
208.123	776
205.773	834
203.423	825
201.072	843
198.72	903
196.368	940
194.014	977
191.659	935
189.303	912
186.947	974
184.589	1016
182.231	1013
179.871	966
177.511	1030
175.149	1031
172.787	1060
170.424	1055
168.06	1105
165.695	1217
163.329	1212
160.961	1194
158.594	1246
156.225	1341
153.855	1427
151.484	1336
149.112	1279
146.739	1345
144.366	1465
141.991	1458
139.616	1412
137.239	1444
134.862	1531
132.483	1627
130.103	1729
127.724	1752
125.342	1734
122.96	1818
120.577	1838
118.192	1833
115.807	1886
113.422	2017
111.034	2247
108.646	2315
106.257	2367
103.868	2397
101.476	2521
99.0842	2814
96.6916	2958
94.2982	2978
91.9028	3089
89.5075	3421
87.1103	3749
84.7132	4141
82.3143	4505
79.9144	4823
77.5145	5321
75.1128	5907
72.7102	6857
70.3066	8531
67.9022	11026
65.4968	15195
63.0906	22588
60.6834	33763
58.2753	44474
55.8653	51493
53.4553	55462
51.0445	57490
48.6317	58430
46.2191	58109
43.8045	57543
41.39	56811
38.9735	56871
36.5562	57223
34.1379	57979
31.7198	57964
29.2997	58864
26.8786	62898
24.4567	64524
22.0338	64524
19.61	64524
17.1843	64524
14.7587	64524
12.3321	64524
9.90466	64524
7.47525	64524
5.04592	64524
2.61466	64524
0.183468	64524