File: projects/python/data/20231109-blood/blood_600_785 nm_120 s_1_2023_11_09_12_34_53_01.txt
#Sample=blood
#Laser=785 nm
#Grating=600
#Exposition=120
#Accumulation=1
#Acquired=09.11.2023 12:34:53
1568.38	2046
1566.56	2083
1564.74	2104
1562.92	2118
1561.1	2084
1559.27	2103
1557.45	2068
1555.62	2072
1553.8	2071
1551.97	2030
1550.15	2032
1548.32	2058
1546.49	1976
1544.66	1984
1542.84	1961
1541.01	1898
1539.18	1917
1537.34	1862
1535.51	1822
1533.68	1771
1531.85	1791
1530.01	1765
1528.18	1713
1526.34	1715
1524.51	1692
1522.67	1652
1520.83	1671
1518.99	1659
1517.15	1626
1515.31	1664
1513.47	1620
1511.63	1594
1509.79	1644
1507.95	1605
1506.11	1626
1504.26	1636
1502.42	1611
1500.57	1614
1498.73	1625
1496.88	1583
1495.03	1608
1493.19	1582
1491.34	1609
1489.49	1603
1487.64	1618
1485.79	1592
1483.94	1665
1482.08	1673
1480.23	1668
1478.38	1703
1476.52	1758
1474.67	1743
1472.81	1755
1470.96	1744
1469.1	1804
1467.24	1829
1465.38	1796
1463.52	1864
1461.66	1862
1459.8	1904
1457.94	1901
1456.08	1904
1454.22	1918
1452.35	1939
1450.49	1958
1448.62	2007
1446.76	1992
1444.89	1953
1443.03	1970
1441.16	1943
1439.29	1940
1437.42	1930
1435.55	1923
1433.68	1867
1431.81	1924
1429.94	1870
1428.06	1855
1426.19	1854
1424.32	1880
1422.44	1784
1420.57	1819
1418.69	1800
1416.81	1781
1414.94	1790
1413.06	1766
1411.18	1790
1409.3	1786
1407.42	1793
1405.54	1807
1403.65	1807
1401.77	1765
1399.89	1807
1398.01	1777
1396.12	1820
1394.23	1764
1392.35	1815
1390.46	1778
1388.57	1801
1386.69	1808
1384.8	1778
1382.91	1802
1381.02	1795
1379.13	1813
1377.23	1796
1375.34	1765
1373.45	1789
1371.55	1778
1369.66	1835
1367.76	1772
1365.87	1763
1363.97	1781
1362.07	1801
1360.17	1820
1358.27	1800
1356.37	1850
1354.47	1833
1352.57	1827
1350.67	1882
1348.77	1910
1346.86	1885
1344.96	1919
1343.05	1924
1341.15	1939
1339.24	1947
1337.34	1895
1335.43	1950
1333.52	1926
1331.61	1892
1329.7	1974
1327.79	1934
1325.88	1921
1323.97	1909
1322.05	1950
1320.14	1965
1318.22	1951
1316.31	1973
1314.39	1947
1312.48	1913
1310.56	1959
1308.64	1972
1306.72	1971
1304.8	1926
1302.88	1925
1300.96	1962
1299.04	1910
1297.12	1936
1295.19	1919
1293.27	1937
1291.35	1949
1289.42	1943
1287.49	1924
1285.57	1900
1283.64	1945
1281.71	1939
1279.78	1904
1277.85	1896
1275.92	1938
1273.99	1967
1272.06	1950
1270.12	1906
1268.19	1910
1266.26	1935
1264.32	1910
1262.39	1889
1260.45	1921
1258.51	1981
1256.58	1956
1254.64	1941
1252.7	1917
1250.76	1963
1248.82	1949
1246.87	1928
1244.93	1909
1242.99	1941
1241.04	1966
1239.1	1931
1237.15	1960
1235.21	1981
1233.26	1953
1231.31	1995
1229.37	1978
1227.42	1992
1225.47	1993
1223.52	1981
1221.56	1892
1219.61	1923
1217.66	1862
1215.71	1823
1213.75	1845
1211.8	1804
1209.84	1720
1207.88	1719
1205.93	1668
1203.97	1693
1202.01	1634
1200.05	1624
1198.09	1622
1196.13	1614
1194.17	1621
1192.2	1583
1190.24	1574
1188.28	1595
1186.31	1591
1184.35	1609
1182.38	1638
1180.41	1623
1178.45	1600
1176.48	1618
1174.51	1615
1172.54	1631
1170.57	1586
1168.59	1610
1166.62	1635
1164.65	1670
1162.67	1652
1160.7	1641
1158.72	1673
1156.75	1576
1154.77	1619
1152.79	1616
1150.82	1629
1148.84	1589
1146.86	1656
1144.87	1634
1142.89	1636
1140.91	1635
1138.93	1657
1136.94	1664
1134.96	1665
1132.97	1664
1130.99	1684
1129	1691
1127.01	1712
1125.02	1689
1123.04	1736
1121.05	1692
1119.06	1714
1117.06	1678
1115.07	1695
1113.08	1684
1111.08	1694
1109.09	1645
1107.1	1677
1105.1	1682
1103.1	1648
1101.1	1667
1099.11	1621
1097.11	1647
1095.11	1655
1093.11	1684
1091.11	1634
1089.1	1665
1087.1	1620
1085.1	1646
1083.09	1664
1081.09	1613
1079.08	1635
1077.07	1628
1075.07	1627
1073.06	1634
1071.05	1587
1069.04	1594
1067.03	1568
1065.02	1614
1063	1597
1060.99	1576
1058.98	1613
1056.96	1594
1054.95	1591
1052.93	1607
1050.91	1560
1048.9	1541
1046.88	1537
1044.86	1522
1042.84	1524
1040.82	1560
1038.79	1565
1036.77	1541
1034.75	1517
1032.73	1568
1030.7	1538
1028.68	1573
1026.65	1583
1024.62	1541
1022.59	1546
1020.57	1565
1018.54	1611
1016.51	1620
1014.47	1683
1012.44	1703
1010.41	1751
1008.38	1742
1006.34	1758
1004.31	1794
1002.27	1762
1000.24	1762
998.198	1793
996.16	1777
994.121	1775
992.082	1781
990.041	1761
988	1757
985.958	1731
983.915	1760
981.871	1727
979.827	1759
977.782	1767
975.735	1742
973.689	1730
971.642	1738
969.593	1754
967.544	1772
965.493	1743
963.443	1753
961.392	1789
959.339	1769
957.286	1800
955.232	1840
953.178	1783
951.122	1819
949.066	1785
947.008	1816
944.951	1824
942.892	1834
940.832	1794
938.772	1805
936.71	1794
934.649	1784
932.586	1799
930.522	1817
928.459	1801
926.393	1805
924.328	1764
922.261	1790
920.193	1777
918.125	1759
916.056	1713
913.986	1778
911.915	1733
909.844	1705
907.771	1722
905.698	1783
903.624	1701
901.549	1735
899.474	1687
897.397	1679
895.32	1710
893.242	1693
891.164	1716
889.084	1706
887.003	1678
884.922	1695
882.84	1689
880.758	1694
878.674	1709
876.589	1659
874.504	1668
872.418	1675
870.331	1659
868.243	1663
866.154	1662
864.066	1676
861.975	1644
859.884	1650
857.792	1692
855.7	1693
853.607	1724
851.513	1690
849.417	1705
847.322	1690
845.224	1691
843.128	1660
841.029	1711
838.93	1667
836.83	1711
834.729	1664
832.627	1730
830.525	1694
828.422	1666
826.318	1690
824.213	1700
822.108	1671
820.001	1661
817.894	1667
815.786	1655
813.677	1652
811.567	1584
809.456	1621
807.345	1594
805.233	1602
803.12	1636
801.006	1598
798.891	1637
796.775	1597
794.66	1593
792.542	1616
790.424	1603
788.305	1591
786.185	1577
784.065	1573
781.944	1614
779.822	1596
777.698	1598
775.575	1597
773.45	1679
771.325	1639
769.198	1616
767.071	1637
764.944	1675
762.815	1758
760.685	1718
758.555	1754
756.423	1789
754.291	1804
752.158	1807
750.024	1777
747.89	1775
745.754	1741
743.617	1806
741.481	1746
739.343	1717
737.204	1694
735.065	1693
732.924	1693
730.782	1723
728.64	1687
726.498	1667
724.353	1605
722.209	1629
720.063	1630
717.917	1640
715.77	1626
713.622	1591
711.473	1621
709.323	1639
707.173	1606
705.021	1621
702.869	1612
700.716	1611
698.562	1590
696.408	1579
694.252	1613
692.095	1596
689.938	1632
687.78	1587
685.621	1584
683.461	1625
681.301	1594
679.138	1574
676.976	1610
674.813	1602
672.649	1589
670.484	1537
668.318	1583
666.151	1533
663.985	1545
661.816	1577
659.647	1585
657.477	1604
655.306	1583
653.134	1577
650.961	1587
648.788	1595
646.613	1562
644.439	1522
642.262	1571
640.085	1562
637.908	1588
635.73	1617
633.55	1633
631.37	1674
629.189	1619
627.007	1648
624.823	1631
622.64	1631
620.456	1665
618.27	1628
616.084	1640
613.896	1622
611.708	1612
609.52	1589
607.33	1626
605.14	1528
602.948	1531
600.756	1532
598.562	1515
596.368	1497
594.174	1520
591.977	1516
589.781	1502
587.583	1546
585.385	1535
583.186	1602
580.986	1630
578.785	1629
576.583	1625
574.38	1640
572.177	1693
569.973	1691
567.767	1787
565.561	1775
563.353	1744
561.146	1757
558.937	1736
556.728	1684
554.517	1730
552.305	1758
550.093	1663
547.88	1714
545.666	1672
543.451	1647
541.236	1679
539.018	1674
536.801	1731
534.583	1668
532.363	1660
530.144	1678
527.923	1683
525.7	1658
523.477	1652
521.254	1694
519.029	1719
516.804	1650
514.578	1683
512.351	1706
510.123	1687
507.893	1656
505.664	1643
503.433	1682
501.202	1655
498.969	1640
496.735	1666
494.502	1608
492.267	1625
490.031	1630
487.794	1648
485.556	1619
483.317	1602
481.078	1581
478.837	1587
476.597	1578
474.354	1622
472.11	1641
469.867	1653
467.622	1654
465.376	1641
463.13	1657
460.882	1637
458.634	1655
456.385	1681
454.134	1673
451.883	1691
449.631	1679
447.379	1724
445.124	1735
442.87	1777
440.614	1768
438.358	1784
436.101	1798
433.842	1812
431.583	1837
429.323	1892
427.062	1928
424.8	1935
422.538	2006
420.274	1995
418.009	1984
415.744	2004
413.478	2000
411.211	2019
408.943	2022
406.674	2056
404.404	1996
402.133	1992
399.862	1978
397.589	1997
395.316	2020
393.041	2006
390.765	2064
388.489	2007
386.212	2071
383.935	2052
381.655	2021
379.376	2026
377.095	2056
374.813	2018
372.531	2086
370.247	2083
367.962	2075
365.677	2094
363.391	2107
361.104	2083
358.816	2150
356.527	2164
354.238	2155
351.946	2194
349.655	2182
347.363	2201
345.069	2224
342.774	2260
340.479	2181
338.183	2235
335.886	2213
333.587	2252
331.288	2214
328.989	2241
326.688	2208
324.386	2279
322.084	2200
319.781	2239
317.476	2297
315.171	2264
312.864	2268
310.557	2284
308.249	2288
305.94	2343
303.63	2352
301.319	2368
299.007	2386
296.694	2450
294.38	2470
292.066	2418
289.751	2472
287.434	2503
285.116	2517
282.798	2593
280.48	2641
278.159	2636
275.838	2676
273.516	2701
271.193	2697
268.87	2803
266.545	2850
264.219	2872
261.892	2931
259.565	2905
257.236	3000
254.907	3055
252.577	3068
250.245	3128
247.913	3169
245.58	3218
243.245	3310
240.911	3324
238.575	3394
236.237	3413
233.9	3543
231.561	3621
229.221	3574
226.881	3677
224.539	3733
222.197	3764
219.853	3809
217.509	3931
215.164	4015
212.817	4013
210.47	4028
208.123	4151
205.773	4244
203.423	4460
201.072	4441
198.72	4452
196.368	4614
194.014	4842
191.659	5018
189.303	4893
186.947	4904
184.589	5223
182.231	5399
179.871	5335
177.511	5195
175.149	5358
172.787	5544
170.424	5634
168.06	5524
165.695	5746
163.329	5907
160.961	5944
158.594	6159
156.225	6496
153.855	6505
151.484	6372
149.112	6614
146.739	6968
144.366	7178
141.991	7055
139.616	7046
137.239	7003
134.862	7238
132.483	7389
130.103	7830
127.724	7903
125.342	8112
122.96	8165
120.577	8251
118.192	8497
115.807	8646
113.422	9010
111.034	9437
108.646	9692
106.257	10061
103.868	10391
101.476	10905
99.0842	11219
96.6916	11762
94.2982	12217
91.9028	12662
89.5075	13185
87.1103	14138
84.7132	14725
82.3143	15593
79.9144	16339
77.5145	17289
75.1128	18357
72.7102	19837
70.3066	21763
67.9022	24432
65.4968	28309
63.0906	34843
60.6834	46749
58.2753	61960
55.8653	64524
53.4553	64524
51.0445	64524
48.6317	64524
46.2191	64524
43.8045	64524
41.39	64524
38.9735	64524
36.5562	64524
34.1379	64524
31.7198	64524
29.2997	64524
26.8786	64524
24.4567	64524
22.0338	64524
19.61	64524
17.1843	64524
14.7587	64524
12.3321	64524
9.90466	64524
7.47525	64524
5.04592	64524
2.61466	64524
0.183468	64524