File: projects/python/data/20231114-noslide/thirdnoblood_600_785 nm_30 s_1_2023_11_14_20_37_37_01.txt
#Sample=thirdnoblood
#Laser=785 nm
#Grating=600
#Exposition=30
#Accumulation=1
#Acquired=14.11.2023 20:37:37
1568.95	3328
1567.13	3341
1565.31	3367
1563.49	3400
1561.66	3335
1559.84	3370
1558.02	3383
1556.19	3360
1554.37	3356
1552.54	3388
1550.72	3367
1548.89	3338
1547.06	3336
1545.23	3374
1543.41	3338
1541.58	3350
1539.75	3319
1537.92	3362
1536.08	3341
1534.25	3409
1532.42	3319
1530.58	3356
1528.75	3361
1526.91	3357
1525.08	3313
1523.24	3328
1521.4	3306
1519.57	3341
1517.73	3275
1515.89	3379
1514.05	3346
1512.21	3327
1510.37	3335
1508.52	3370
1506.68	3380
1504.84	3357
1502.99	3344
1501.15	3334
1499.3	3333
1497.46	3356
1495.61	3383
1493.76	3318
1491.91	3381
1490.07	3337
1488.22	3356
1486.36	3418
1484.51	3453
1482.66	3445
1480.81	3423
1478.96	3420
1477.1	3451
1475.25	3457
1473.39	3555
1471.54	3588
1469.68	3536
1467.82	3640
1465.96	3595
1464.1	3622
1462.24	3646
1460.38	3762
1458.52	3700
1456.66	3704
1454.8	3733
1452.94	3715
1451.07	3709
1449.21	3702
1447.34	3666
1445.48	3695
1443.61	3736
1441.74	3677
1439.87	3677
1438	3629
1436.14	3670
1434.26	3670
1432.39	3627
1430.52	3639
1428.65	3589
1426.78	3591
1424.9	3623
1423.03	3606
1421.15	3574
1419.28	3561
1417.4	3538
1415.52	3534
1413.65	3531
1411.77	3555
1409.89	3513
1408.01	3551
1406.13	3537
1404.24	3498
1402.36	3558
1400.48	3495
1398.59	3514
1396.71	3505
1394.82	3499
1392.94	3455
1391.05	3438
1389.16	3501
1387.28	3447
1385.39	3424
1383.5	3456
1381.61	3407
1379.72	3413
1377.83	3418
1375.93	3440
1374.04	3428
1372.15	3398
1370.25	3473
1368.36	3447
1366.46	3444
1364.56	3498
1362.67	3391
1360.77	3505
1358.87	3514
1356.97	3516
1355.07	3555
1353.17	3496
1351.27	3553
1349.36	3579
1347.46	3570
1345.56	3644
1343.65	3610
1341.75	3605
1339.84	3632
1337.93	3597
1336.03	3602
1334.12	3615
1332.21	3637
1330.3	3660
1328.39	3673
1326.48	3667
1324.56	3638
1322.65	3651
1320.74	3724
1318.82	3765
1316.91	3676
1314.99	3727
1313.08	3750
1311.16	3718
1309.24	3685
1307.32	3764
1305.4	3770
1303.48	3797
1301.56	3773
1299.64	3759
1297.72	3856
1295.8	3879
1293.87	3823
1291.95	3791
1290.02	3832
1288.1	3842
1286.17	3862
1284.24	3902
1282.32	3910
1280.39	3918
1278.46	3907
1276.53	3903
1274.6	3895
1272.66	3959
1270.73	3971
1268.8	3934
1266.86	3990
1264.93	3966
1262.99	3912
1261.06	3968
1259.12	3913
1257.18	3913
1255.24	3957
1253.31	3858
1251.36	3920
1249.42	3883
1247.48	3907
1245.54	3917
1243.6	3845
1241.65	3850
1239.71	3828
1237.76	3764
1235.82	3773
1233.87	3785
1231.93	3721
1229.98	3692
1228.03	3672
1226.08	3701
1224.13	3689
1222.18	3629
1220.23	3634
1218.27	3590
1216.32	3583
1214.36	3537
1212.41	3505
1210.45	3475
1208.5	3521
1206.54	3450
1204.58	3377
1202.62	3421
1200.67	3402
1198.7	3449
1196.74	3353
1194.78	3385
1192.82	3351
1190.86	3333
1188.89	3297
1186.93	3337
1184.96	3357
1183	3284
1181.03	3297
1179.06	3285
1177.09	3319
1175.13	3263
1173.16	3286
1171.18	3319
1169.21	3287
1167.24	3280
1165.27	3212
1163.29	3275
1161.32	3250
1159.34	3232
1157.37	3220
1155.39	3260
1153.41	3264
1151.44	3243
1149.46	3258
1147.48	3296
1145.5	3272
1143.52	3258
1141.53	3256
1139.55	3285
1137.57	3256
1135.58	3256
1133.6	3263
1131.61	3294
1129.62	3283
1127.64	3320
1125.65	3308
1123.66	3342
1121.67	3251
1119.68	3316
1117.69	3314
1115.7	3328
1113.7	3319
1111.71	3330
1109.72	3352
1107.72	3335
1105.73	3314
1103.73	3364
1101.73	3399
1099.73	3372
1097.74	3448
1095.74	3409
1093.73	3350
1091.73	3384
1089.73	3426
1087.73	3378
1085.73	3351
1083.72	3439
1081.72	3378
1079.71	3437
1077.7	3371
1075.7	3404
1073.69	3380
1071.68	3323
1069.67	3419
1067.66	3432
1065.65	3380
1063.64	3412
1061.62	3452
1059.61	3384
1057.59	3424
1055.58	3410
1053.56	3376
1051.55	3422
1049.53	3426
1047.51	3392
1045.49	3383
1043.47	3452
1041.45	3387
1039.43	3417
1037.41	3372
1035.39	3394
1033.36	3328
1031.34	3346
1029.31	3369
1027.29	3352
1025.26	3343
1023.23	3388
1021.2	3379
1019.17	3415
1017.14	3352
1015.11	3400
1013.08	3368
1011.05	3382
1009.02	3392
1006.98	3346
1004.95	3416
1002.91	3372
1000.88	3417
998.839	3410
996.801	3407
994.763	3398
992.723	3404
990.683	3401
988.642	3405
986.601	3430
984.557	3395
982.514	3376
980.47	3497
978.425	3449
976.379	3463
974.333	3436
972.286	3548
970.237	3467
968.189	3531
966.139	3514
964.089	3524
962.037	3578
959.985	3562
957.932	3688
955.878	3575
953.824	3610
951.768	3619
949.712	3635
947.656	3594
945.598	3634
943.539	3639
941.48	3594
939.42	3678
937.359	3649
935.298	3639
933.235	3678
931.172	3659
929.108	3617
927.043	3661
924.978	3648
922.911	3623
920.844	3602
918.775	3627
916.707	3649
914.637	3612
912.567	3636
910.495	3681
908.424	3680
906.351	3647
904.277	3608
902.202	3624
900.127	3641
898.05	3616
895.974	3644
893.896	3672
891.817	3634
889.739	3601
887.658	3628
885.577	3642
883.496	3634
881.413	3647
879.33	3699
877.245	3666
875.16	3703
873.075	3675
870.988	3738
868.9	3754
866.813	3723
864.723	3732
862.633	3748
860.542	3791
858.451	3769
856.358	3792
854.265	3746
852.172	3812
850.077	3812
847.981	3789
845.885	3814
843.787	3773
841.69	3756
839.591	3812
837.491	3811
835.391	3843
833.289	3813
831.187	3796
829.084	3800
826.981	3800
824.876	3852
822.771	3793
820.664	3828
818.558	3802
816.45	3774
814.341	3716
812.231	3757
810.121	3696
808.01	3717
805.898	3657
803.785	3700
801.672	3699
799.557	3722
797.442	3729
795.326	3661
793.208	3666
791.091	3666
788.973	3719
786.853	3689
784.733	3695
782.612	3747
780.49	3681
778.367	3740
776.244	3781
774.119	3692
771.994	3734
769.868	3791
767.741	3740
765.614	3771
763.485	3818
761.356	3821
759.226	3828
757.095	3864
754.962	3830
752.83	3851
750.697	3841
748.562	3890
746.426	3848
744.291	3903
742.154	3906
740.016	3955
737.878	3865
735.738	3888
733.598	3972
731.457	3879
729.315	3870
727.172	3941
725.029	3930
722.885	3934
720.74	3932
718.593	3889
716.446	3897
714.299	3913
712.15	3915
710.001	3902
707.851	3867
705.699	3895
703.547	3889
701.395	3856
699.241	3839
697.086	3810
694.931	3832
692.775	3791
690.618	3854
688.46	3838
686.301	3751
684.142	3810
681.981	3814
679.82	3817
677.657	3769
675.495	3800
673.331	3853
671.166	3835
669.001	3855
666.835	3813
664.667	3874
662.499	3835
660.33	3778
658.16	3828
655.99	3819
653.818	3799
651.646	3828
649.473	3907
647.299	3932
645.124	3880
642.948	3868
640.771	3930
638.595	3928
636.416	3892
634.237	3916
632.057	3942
629.876	3951
627.694	3954
625.512	3960
623.328	3998
621.144	3991
618.958	3988
616.773	3989
614.586	3972
612.398	3967
610.21	4018
608.02	4016
605.83	3981
603.639	3996
601.447	4024
599.254	3967
597.06	4092
594.865	3963
592.67	4010
590.473	4032
588.276	3952
586.078	3970
583.879	3958
581.68	3983
579.479	3978
577.277	4018
575.075	4001
572.872	3993
570.667	3996
568.462	3991
566.256	3979
564.049	3963
561.842	4003
559.633	3980
557.424	3950
555.214	4014
553.002	3968
550.79	4034
548.577	3996
546.364	4131
544.149	3993
541.934	4076
539.718	4035
537.5	4076
535.282	4086
533.063	4099
530.843	4124
528.622	4148
526.401	4226
524.179	4115
521.955	4142
519.731	4174
517.506	4146
515.28	4223
513.053	4196
510.825	4207
508.596	4217
506.367	4165
504.136	4200
501.906	4232
499.673	4182
497.44	4215
495.206	4195
492.972	4176
490.736	4100
488.499	4129
486.262	4142
484.023	4140
481.784	4156
479.544	4194
477.302	4169
475.061	4155
472.818	4134
470.574	4160
468.33	4137
466.084	4133
463.838	4170
461.591	4205
459.343	4166
457.094	4177
454.844	4267
452.592	4229
450.341	4247
448.089	4207
445.835	4307
443.581	4222
441.325	4231
439.069	4306
436.812	4278
434.554	4280
432.296	4361
430.036	4268
427.775	4393
425.514	4371
423.251	4436
420.988	4461
418.724	4466
416.459	4439
414.192	4470
411.926	4364
409.658	4451
407.389	4431
405.12	4462
402.849	4475
400.577	4478
398.305	4424
396.032	4418
393.758	4453
391.483	4480
389.207	4409
386.93	4484
384.652	4415
382.374	4503
380.094	4450
377.814	4473
375.532	4510
373.25	4508
370.967	4500
368.683	4493
366.397	4515
364.112	4547
361.825	4562
359.537	4536
357.249	4537
354.959	4506
352.669	4608
350.377	4561
348.085	4582
345.792	4613
343.498	4675
341.203	4668
338.907	4679
336.61	4577
334.313	4759
332.014	4590
329.714	4670
327.414	4682
325.112	4733
322.809	4738
320.506	4753
318.202	4783
315.897	4759
313.591	4863
311.284	4863
308.977	4831
306.667	4934
304.358	4964
302.048	4932
299.736	4992
297.424	4996
295.11	5013
292.796	5086
290.481	5082
288.164	5182
285.847	5222
283.529	5267
281.21	5269
278.89	5283
276.569	5281
274.248	5375
271.925	5428
269.601	5447
267.278	5474
264.952	5629
262.626	5690
260.298	5632
257.97	5688
255.641	5785
253.311	5843
250.98	5855
248.648	5882
246.315	5968
243.981	5981
241.647	6042
239.311	6058
236.974	6175
234.637	6368
232.298	6341
229.959	6479
227.618	6565
225.277	6598
222.935	6666
220.592	6731
218.248	6866
215.903	6997
213.557	6949
211.21	7177
208.862	7338
206.513	7457
204.164	7359
201.813	7619
199.462	7787
197.109	7935
194.755	8019
192.401	8078
190.045	8252
187.69	8246
185.333	8326
182.974	8386
180.615	8627
178.255	8712
175.894	8781
173.531	8735
171.169	8905
168.805	9018
166.44	9252
164.075	9367
161.708	9410
159.34	9463
156.971	9563
154.602	9768
152.231	9962
149.86	10033
147.487	10146
145.114	10272
142.74	10308
140.364	10353
137.988	10575
135.611	10797
133.232	11028
130.854	11046
128.473	11109
126.092	11262
123.71	11563
121.328	11872
118.944	12125
116.559	12347
114.173	12659
111.786	13018
109.398	13268
107.009	13659
104.62	14000
102.229	14422
99.8379	14957
97.4456	15606
95.0515	16038
92.6574	16746
90.2624	17481
87.8655	18363
85.4677	19415
83.07	20453
80.6704	21737
78.2698	23173
75.8694	24692
73.467	26494
71.0638	28945
68.6596	31753
66.2546	35911
63.8486	41992
61.4417	48755
59.0339	54987
56.6241	60063
54.2145	64524
51.8039	64524
49.3915	64524
46.9791	64524
44.5648	64524
42.1506	64524
39.7344	64524
37.3174	64524
34.8994	64524
32.4815	64524
30.0617	64524
27.641	64524
25.2193	64524
22.7968	64524
20.3733	64524
17.9488	64524
15.5225	64524
13.0962	64524
10.669	64524
8.23993	64524
5.81088	64524
3.37992	64524
0.949017	64524