File: projects/python/data/20231030/bloodtip_600_785 nm_10 s_1_2023_10_30_15_52_23_01.txt
#Sample=bloodtip
#Laser=785 nm
#Grating=600
#Exposition=10
#Accumulation=1
#Acquired=30.10.2023 15:52:23
2745.96	81
2743.18	76.6667
2740.41	75
2737.63	74
2734.85	78.6667
2732.07	81.6667
2729.29	83.6667
2726.5	74.6667
2723.72	73
2720.93	78.6667
2718.14	79
2715.34	80.6667
2712.55	80
2709.75	73.3333
2706.95	82.6667
2704.15	66.6667
2701.35	82.3333
2698.55	75.3333
2695.74	75.3333
2692.93	83
2690.12	75.6667
2687.31	73.6667
2684.49	75.6667
2681.67	80.3333
2678.85	77.6667
2676.03	74.3333
2673.21	76.6667
2670.38	77.3333
2667.56	71.6667
2664.73	78.6667
2661.9	83.3333
2659.06	78.3333
2656.23	70.3333
2653.39	81.6667
2650.55	74
2647.71	80.3333
2644.86	68.6667
2642.02	72
2639.17	75
2636.32	78
2633.47	70.6667
2630.62	72
2627.76	77
2624.9	73.6667
2622.04	78.6667
2619.18	77.3333
2616.31	78
2613.45	75.3333
2610.58	81
2607.71	72.3333
2604.84	82
2601.96	82.6667
2599.08	76.6667
2596.21	84
2593.32	71
2590.44	72.3333
2587.56	79
2584.67	74
2581.78	90.3333
2578.89	80.6667
2575.99	85.3333
2573.1	78.6667
2570.2	78.6667
2567.3	73
2564.4	78.3333
2561.5	75
2558.59	84
2555.68	79.6667
2552.77	78.3333
2549.86	73.3333
2546.94	81
2544.03	81.6667
2541.11	74
2538.19	73
2535.26	77.6667
2532.34	77.3333
2529.41	77
2526.48	80.3333
2523.55	79.6667
2520.62	77.6667
2517.68	75.3333
2514.74	71.6667
2511.8	81.3333
2508.86	75.6667
2505.92	78
2502.97	69.6667
2500.02	69
2497.07	75
2494.12	73
2491.16	74.6667
2488.2	82
2485.25	72
2482.28	76
2479.32	76.6667
2476.35	77.3333
2473.39	76.6667
2470.42	78.6667
2467.44	80.6667
2464.47	82
2461.49	86
2458.51	74.3333
2455.53	76.6667
2452.55	76.3333
2449.56	78.6667
2446.58	83.6667
2443.59	85.6667
2440.59	81.6667
2437.6	76.3333
2434.6	73.3333
2431.61	79.6667
2428.61	86.6667
2425.6	89
2422.6	71.6667
2419.59	81
2416.58	83.3333
2413.57	80
2410.56	78
2407.54	88
2404.52	88.6667
2401.5	80.6667
2398.48	80
2395.45	79.3333
2392.43	79
2389.4	77.3333
2386.37	73
2383.33	73
2380.3	80.3333
2377.26	78
2374.22	77.6667
2371.17	76.6667
2368.13	77
2365.08	86
2362.03	72.3333
2358.98	81
2355.93	78.6667
2352.87	79.6667
2349.81	84.3333
2346.75	83
2343.69	81.6667
2340.63	76
2337.56	78
2334.49	84.6667
2331.42	81.3333
2328.35	79.3333
2325.27	79.6667
2322.19	74.6667
2319.11	73.6667
2316.03	76.6667
2312.94	74.3333
2309.85	83
2306.77	79.3333
2303.67	87.6667
2300.58	81.6667
2297.48	88.3333
2294.38	83
2291.28	84.6667
2288.18	82
2285.07	82
2281.97	73.3333
2278.86	85.6667
2275.74	81.3333
2272.63	90.3333
2269.51	82.3333
2266.39	89.6667
2263.27	82
2260.15	82.6667
2257.02	82.3333
2253.89	72.6667
2250.76	91
2247.63	83.6667
2244.49	87
2241.36	91.3333
2238.22	88
2235.08	84
2231.93	89.3333
2228.78	86.3333
2225.63	82
2222.48	87.6667
2219.33	83
2216.17	83.6667
2213.01	95.3333
2209.85	91
2206.69	88.6667
2203.53	85.6667
2200.36	83.3333
2197.19	93
2194.02	86.3333
2190.84	79.6667
2187.66	86.6667
2184.48	87.3333
2181.3	86.3333
2178.12	91.3333
2174.93	96.3333
2171.74	87.6667
2168.55	92.3333
2165.36	91.6667
2162.16	86.6667
2158.97	95
2155.76	101.333
2152.56	88.3333
2149.36	89.3333
2146.15	85.6667
2142.94	96.3333
2139.73	100.667
2136.51	97
2133.29	99.6667
2130.08	98.3333
2126.85	97
2123.63	92
2120.4	95
2117.17	97.6667
2113.94	97
2110.71	98.6667
2107.47	101.333
2104.23	104.333
2100.99	94.6667
2097.75	93
2094.5	94
2091.26	102.333
2088.01	96.6667
2084.75	103
2081.5	97.6667
2078.24	92.3333
2074.98	91
2071.72	100.667
2068.45	106
2065.18	96.6667
2061.92	105.333
2058.64	90.3333
2055.37	101.333
2052.09	104.333
2048.81	95.3333
2045.53	102
2042.25	91
2038.96	103
2035.67	99.6667
2032.38	102.667
2029.08	96
2025.79	99.6667
2022.49	102.333
2019.19	98.3333
2015.88	100.333
2012.58	99.6667
2009.27	99.3333
2005.96	111.667
2002.64	104.667
1999.33	101
1996.01	107.667
1992.69	112.333
1989.36	108
1986.04	104.333
1982.71	108.667
1979.38	133
1976.05	130.333
1972.71	111.333
1969.37	125.333
1966.03	127
1962.69	123
1959.34	129
1955.99	133.667
1952.64	128.667
1949.29	133.667
1945.93	134.333
1942.58	134
1939.21	129.333
1935.85	133.667
1932.49	143.333
1929.12	141
1925.75	141
1922.37	150.667
1919	153
1915.62	143
1912.24	155.333
1908.86	141.667
1905.47	143
1902.08	145.333
1898.69	153.333
1895.3	150.333
1891.9	152
1888.5	155.667
1885.1	151.667
1881.7	155.333
1878.29	151
1874.88	158
1871.47	164.667
1868.06	152
1864.64	144.333
1861.22	151.333
1857.8	148
1854.38	145
1850.95	142.667
1847.52	142
1844.09	144
1840.66	146.667
1837.22	144.667
1833.78	147.333
1830.34	154.667
1826.9	156
1823.45	143.667
1820	153.333
1816.55	161.333
1813.09	144.333
1809.64	158.667
1806.18	154
1802.71	153.333
1799.25	161.667
1795.78	167.333
1792.31	173
1788.84	171.667
1785.36	164
1781.88	172
1778.4	170.667
1774.92	168
1771.43	167.333
1767.95	174.333
1764.45	168
1760.96	176
1757.47	170
1753.97	173.333
1750.47	180.667
1746.96	173
1743.45	186.667
1739.94	181.333
1736.43	176.667
1732.92	184
1729.4	178
1725.88	185
1722.36	200.333
1718.83	190.667
1715.3	197.667
1711.77	194
1708.24	195.333
1704.71	217.667
1701.17	213.667
1697.63	212
1694.08	220
1690.54	213
1686.99	221.333
1683.44	218
1679.88	217.667
1676.32	221.333
1672.76	225.333
1669.2	227
1665.64	230
1662.07	231.333
1658.5	225.667
1654.92	228
1651.35	240.667
1647.77	243
1644.19	238.333
1640.61	256.667
1637.02	253.333
1633.43	251.667
1629.84	251.333
1626.24	257.333
1622.64	251.667
1619.04	257.333
1615.44	257
1611.84	266.667
1608.23	268
1604.62	246
1601	260.667
1597.39	262
1593.77	255.333
1590.15	261.333
1586.52	256
1582.89	259.333
1579.26	277.333
1575.63	282
1571.99	288
1568.36	295.333
1564.72	294.333
1561.07	286
1557.42	294.333
1553.78	308.667
1550.12	281.333
1546.47	292
1542.81	282
1539.15	291.333
1535.49	275.667
1531.82	275
1528.15	286.667
1524.48	275.667
1520.81	281.333
1517.13	276.667
1513.45	276.667
1509.77	267.333
1506.08	265.333
1502.39	273.333
1498.7	277.333
1495.01	278.667
1491.31	269.333
1487.61	284.667
1483.91	283
1480.21	266.667
1476.5	277.667
1472.79	275.667
1469.07	296
1465.36	284.333
1461.64	292
1457.92	300
1454.19	301
1450.46	293
1446.73	295.333
1443	282
1439.26	305
1435.52	287.333
1431.78	284.333
1428.04	292.667
1424.29	281.333
1420.54	287.333
1416.79	290
1413.03	282.667
1409.27	282.667
1405.51	289.333
1401.75	288.333
1397.98	273.333
1394.21	275.667
1390.44	279.333
1386.66	280.667
1382.88	292
1379.1	287.667
1375.31	284.667
1371.53	287.333
1367.74	299.667
1363.94	282
1360.15	293.667
1356.35	293.333
1352.55	286.667
1348.74	301
1344.93	303.667
1341.12	304.667
1337.31	293
1333.49	306
1329.67	313.333
1325.85	308.667
1322.03	306.667
1318.2	301.667
1314.37	297.333
1310.53	313.667
1306.7	305
1302.86	294
1299.01	311
1295.17	315
1291.32	316.667
1287.47	310
1283.61	320
1279.76	306
1275.9	319.667
1272.03	318.333
1268.17	324.667
1264.3	300.667
1260.42	313.667
1256.55	314
1252.67	306
1248.79	313
1244.91	310
1241.02	305.667
1237.13	304.667
1233.24	315.667
1229.34	306
1225.44	307.667
1221.54	292.667
1217.63	289.333
1213.73	286.667
1209.81	280.667
1205.9	276.667
1201.98	275.667
1198.06	269.667
1194.14	264
1190.21	261.667
1186.29	270.333
1182.35	263.333
1178.42	271
1174.48	278.667
1170.54	274.667
1166.6	272
1162.65	263.333
1158.7	266.667
1154.74	267
1150.79	269.667
1146.83	269.667
1142.87	261
1138.9	271
1134.93	275.667
1130.96	278.667
1126.99	275.667
1123.01	274.667
1119.03	278.667
1115.04	269
1111.06	266.333
1107.07	272.667
1103.08	267.333
1099.08	278
1095.08	272.667
1091.08	277.333
1087.07	271.667
1083.06	275.333
1079.05	275
1075.04	268.667
1071.02	258.667
1067	269
1062.98	258.333
1058.95	247.667
1054.92	259.333
1050.89	253.333
1046.85	257.333
1042.81	250.333
1038.77	255.333
1034.72	251
1030.67	254.667
1026.62	266
1022.57	257
1018.51	262.667
1014.45	269.667
1010.38	268.333
1006.32	269.333
1002.24	278
998.171	269
994.094	272
990.013	263
985.93	277.667
981.843	269.333
977.754	276
973.661	274.333
969.565	268.333
965.466	277
961.364	286.333
957.258	278.333
953.15	298.333
949.038	286
944.923	281
940.804	279.667
936.683	289.333
932.558	298
928.43	286.667
924.299	285
920.165	284.667
916.028	272
911.887	270.333
907.743	274
903.595	268
899.445	267.667
895.292	275.333
891.135	278.667
886.975	269
882.812	275.333
878.646	265.667
874.475	263
870.303	270
866.126	271.333
861.947	272.667
857.764	264.333
853.578	276
849.389	275.333
845.196	268.667
841	294.333
836.801	280.333
832.599	279.667
828.393	265.333
824.184	272
819.972	267.333
815.757	264
811.538	256
807.316	270.667
803.091	256
798.863	266.667
794.631	274.667
790.395	259.333
786.157	260.333
781.915	251.333
777.669	259.333
773.421	265
769.169	261.667
764.915	273.667
760.656	272
756.394	265.333
752.129	261.667
747.861	256.333
743.588	260.333
739.314	268.333
735.035	257.667
730.753	255
726.469	245.667
722.18	258.667
717.888	266.667
713.593	257.333
709.294	249.333
704.992	242.667
700.687	254
696.378	248.667
692.066	253.667
687.751	246
683.432	240.667
679.109	247.333
674.784	239.667
670.455	245.667
666.122	251
661.787	247
657.448	248.667
653.104	250.333
648.759	239
644.409	259.333
640.056	260.667
635.7	255.333
631.34	268.667
626.977	268.333
622.61	258.333
618.24	259.667
613.867	252
609.49	237.333
605.11	244
600.726	246.667
596.339	239
591.948	232.667
587.554	244.667
583.156	258.333
578.755	251.667
574.35	277.667
569.943	265
565.531	256.667
561.116	259
556.698	263.333
552.275	261.333
547.85	249.333
543.421	257
538.988	256.333
534.553	252.667
530.113	252.333
525.67	253
521.224	255
516.774	245
512.321	253.667
507.863	257
503.403	250
498.939	245.667
494.472	252.667
490.001	250.667
485.526	258
481.047	251.667
476.565	262.333
472.08	244
467.591	256.333
463.099	260.667
458.604	265.667
454.103	274
449.601	276.333
445.094	281.667
440.584	285.667
436.07	291.333
431.553	298
427.032	303.333
422.507	294.333
417.979	313.333
413.448	306
408.912	319.333
404.373	319.667
399.83	314
395.285	312.333
390.734	315.333
386.181	326.333
381.624	323
377.064	343.667
372.5	327.333
367.932	346.667
363.36	341.667
358.785	341.667
354.207	341
349.624	353.667
345.038	351.333
340.448	369
335.855	349
331.257	350.333
326.657	358.333
322.053	348.333
317.444	363.333
312.833	360
308.217	357.667
303.599	361.667
298.976	382.667
294.349	389
289.719	392.333
285.085	399.667
280.448	405.333
275.807	419
271.161	429
266.513	442.333
261.861	430
257.205	459.667
252.544	480.333
247.881	495.333
243.214	503.667
238.543	508.667
233.869	530
229.19	527.667
224.508	556
219.822	575.333
215.132	583.667
210.439	595.667
205.741	601.333
201.04	633.667
196.336	637.333
191.627	651.333
186.915	654
182.199	685.667
177.478	707.667
172.755	719.333
168.028	753.333
163.297	761.667
158.561	775.667
153.823	791.333
149.08	817.333
144.334	833.333
139.584	866
134.829	883
130.071	919.333
125.31	932.667
120.545	988.667
115.775	1089.33
111.001	1131.33
106.224	1183.67
101.444	1284.67
96.6594	1382.67
91.8705	1548.33
87.0781	1707.33
82.282	1920.33
77.4812	2303.67
72.6778	2997.67
67.8698	4726
63.0582	6264.33
58.2419	7374.67
53.4229	8191.67
48.5993	9008.67
43.772	9996.33
38.941	11355
34.1054	13828
29.2661	17471.7
24.4231	25378.7
19.5764	64524
14.7261	64524
9.87099	64524
5.01321	64524
0.14975	64524
-4.71644	64524
-9.58634	64524
-14.461	64524
-19.3393	64524
-24.2214	64524
-29.1072	64524
-33.9977	22113
-38.892	11097.7
-43.7901	7362.67
-48.6919	5513.67
-53.5974	4149.67
-58.5078	3222.33
-63.4218	2491
-68.3397	1971.33
-73.2613	1555.33
-78.1878	1230
-83.117	996.333
-88.051	825.333
-92.9888	682
-97.9314	559.333
-102.877	476
-107.827	400
-112.781	342
-117.739	280
-122.701	237.667
-127.667	208.667
-132.637	188.333
-137.612	148
-142.59	141
-147.572	128
-152.558	113.333
-157.548	104.667
-162.542	97.3333
-167.541	83.6667
-172.544	90.6667
-177.55	81
-182.561	80.3333
-187.576	87
-192.595	77
-197.617	72.6667
-202.645	81.3333
-207.676	85
-212.711	80
-217.75	71.3333
-222.794	75.3333
-227.842	66.6667
-232.893	65
-237.949	70.6667
-243.009	70.3333
-248.073	65.6667
-253.142	46.3333
-258.214	57
-263.291	65.3333
-268.371	55.6667
-273.456	64.6667
-278.545	53
-283.639	64.6667
-288.735	62.3333
-293.837	58.6667
-298.943	53.6667
-304.053	49.3333
-309.166	57
-314.285	55.6667
-319.408	56
-324.534	52.6667
-329.665	52
-334.801	51.6667
-339.94	49.3333
-345.083	49
-350.231	50
-355.383	47
-360.539	44
-365.699	49
-370.864	42.6667
-376.033	41.6667
-381.206	49.3333
-386.384	52.3333
-391.565	51.6667
-396.751	47.6667
-401.941	38.3333
-407.136	48.3333
-412.334	43
-417.537	47.6667
-422.745	45
-427.956	38.6667
-433.173	45.3333
-438.392	40.3333
-443.617	47.6667
-448.846	48.3333
-454.078	38.6667
-459.317	43
-464.558	45
-469.804	42.3333
-475.055	37.6667
-480.309	42.3333
-485.568	45.6667
-490.832	45
-496.099	34.3333
-501.372	40.3333
-506.648	44
-511.929	38.3333
-517.215	51.3333
-522.504	40
-527.797	46
-533.097	44.6667
-538.399	34.6667
-543.706	36.3333
-549.018	41
-554.334	45.3333
-559.654	42.3333
-564.979	47.6667
-570.308	37
-575.641	38
-580.98	42.6667
-586.322	45.6667
-591.669	40.6667
-597.02	38
-602.376	41.3333
-607.736	43.3333
-613.1	51.3333
-618.47	44
-623.843	43.6667
-629.222	46
-634.603	39.6667
-639.99	42
-645.382	40.3333
-650.779	31.3333
-656.179	38
-661.583	46.3333
-666.993	44.3333
-672.407	45.3333
-677.825	46
-683.248	45.3333
-688.675	40.3333
-694.108	43.6667
-699.544	37
-704.985	47.3333
-710.431	46
-715.88	48
-721.335	43
-726.795	38.6667
-732.258	33.3333
-737.727	40.6667
-743.2	45.6667
-748.678	40.6667
-754.159	39
-759.646	37.6667
-765.138	32.3333
-770.633	38.3333
-776.133	42
-781.638	35.3333
-787.149	47
-792.663	42
-798.181	47
-803.705	41.6667
-809.233	45.6667
-814.766	49
-820.304	45
-825.846	43.6667
-831.392	37.6667
-836.944	34.3333
-842.499	43.6667
-848.06	41.3333
-853.626	42.6667
-859.195	50.3333
-864.77	43
-870.35	44.6667
-875.934	47.6667
-881.522	42.6667
-887.116	45
-892.714	40.6667
-898.317	36.3333
-903.924	45.6667
-909.537	44
-915.153	47.3333
-920.776	39.6667
-926.401	40
-932.033	42.3333
-937.669	38.6667
-943.31	36.6667
-948.955	47.3333
-954.605	40.6667
-960.26	50
-965.92	33.3333
-971.584	35
-977.254	42.3333
-982.928	46.6667
-988.607	34.3333
-994.291	40.6667
-999.979	50.6667
-1005.67	39.6667
-1011.37	39
-1017.07	43
-1022.78	46.3333
-1028.49	43.3333
-1034.21	46
-1039.93	45.6667
-1045.66	44.6667
-1051.39	43.3333
-1057.13	43
-1062.87	43.6667
-1068.62	50.6667
-1074.37	43
-1080.12	41.3333
-1085.89	42
-1091.65	46
-1097.42	49
-1103.2	43
-1108.98	41.3333
-1114.77	49.3333
-1120.56	43
-1126.35	50.6667
-1132.15	46.6667
-1137.96	43.6667
-1143.77	48.3333
-1149.58	38
-1155.4	43
-1161.23	50.3333
-1167.06	47.3333
-1172.89	56
-1178.73	64.6667
-1184.58	82
-1190.43	93.6667
-1196.28	98.6667
-1202.14	106.667
-1208.01	124.333
-1213.88	160.667
-1219.75	170.333
-1225.63	171.667
-1231.52	199
-1237.41	280.667
-1243.3	333
-1249.2	474.667
-1255.11	533.333
-1261.02	448
-1266.93	404.667
-1272.85	259
-1278.78	114
-1284.71	76
-1290.65	69.3333
-1296.59	65.3333
-1302.53	48.3333
-1308.48	50.3333
-1314.44	54.6667
-1320.4	57.6667
-1326.37	47.3333
-1332.34	45.3333
-1338.31	48
-1344.29	51.3333
-1350.28	49.6667
-1356.27	45.3333
-1362.27	51.6667
-1368.27	44.3333
-1374.28	42.6667
-1380.29	39.6667
-1386.31	40.6667
-1392.33	34.3333
-1054.26	42.3333
-1060	42.6667
-1065.74	39.3333
-1071.49	41
-1077.25	44
-1083.01	43
-1088.77	45.3333
-1094.54	42.3333
-1100.31	48
-1106.09	48.6667
-1111.87	37
-1117.66	40.3333
-1123.45	46.6667
-1129.25	42.3333
-1135.05	47.3333
-1140.86	49.3333
-1146.67	41.3333
-1152.49	46
-1158.32	43.6667
-1164.14	50
-1169.98	52.3333
-1175.81	61.3333
-1181.66	77.6667
-1187.5	94.6667
-1193.35	91.3333
-1199.21	103.333
-1205.08	114.667
-1210.94	137
-1216.82	165
-1222.69	169
-1228.58	177.667
-1234.46	232.667
-1240.35	312.667
-1246.25	383
-1252.16	498
-1258.06	490.667
-1263.97	425
-1269.89	368.667
-1275.82	189
-1281.74	84.6667
-1287.68	65.6667
-1293.62	60
-1299.56	61
-1305.51	56.3333
-1311.46	53
-1317.42	44.3333
-1323.38	51.3333
-1329.35	54.3333
-1335.32	56
-1341.3	56.3333
-1347.29	51
-1353.28	52.3333
-1359.27	38
-1365.27	44.3333
-1371.27	42.3333
-1377.28	44
-1383.3	50
-1389.32	42.6667
-1392.33	34.3333