File: projects/python/data/20231030/blood_600_785 nm_10 s_1_2023_10_30_15_38_25_01.txt
#Sample=blood
#Laser=785 nm
#Grating=600
#Exposition=10
#Accumulation=1
#Acquired=30.10.2023 15:38:25
2745.96	130.667
2743.18	137.333
2740.41	129
2737.63	128
2734.85	139.667
2732.07	144
2729.29	141.667
2726.5	136.667
2723.72	136
2720.93	145.333
2718.14	148
2715.34	141.667
2712.55	134
2709.75	132.667
2706.95	135.667
2704.15	140
2701.35	134.333
2698.55	140.333
2695.74	143.667
2692.93	148.333
2690.12	137.667
2687.31	141
2684.49	151
2681.67	142.333
2678.85	144.333
2676.03	150
2673.21	146.333
2670.38	140.333
2667.56	150.333
2664.73	145.667
2661.9	146
2659.06	145
2656.23	149.333
2653.39	145.667
2650.55	158.667
2647.71	151.333
2644.86	145.333
2642.02	152
2639.17	153
2636.32	150.667
2633.47	158.333
2630.62	152
2627.76	152.667
2624.9	162
2622.04	150
2619.18	168
2616.31	154.667
2613.45	157
2610.58	152.667
2607.71	152.667
2604.84	165
2601.96	146
2599.08	152.333
2596.21	150
2593.32	147.667
2590.44	158.333
2587.56	152.333
2584.67	152.667
2581.78	153.667
2578.89	167.333
2575.99	160.333
2573.1	155.333
2570.2	155.667
2567.3	165.667
2564.4	160
2561.5	159
2558.59	160
2555.68	158.667
2552.77	162
2549.86	168.333
2546.94	159.333
2544.03	158
2541.11	169.333
2538.19	168
2535.26	166.333
2532.34	167.667
2529.41	169.667
2526.48	162.667
2523.55	168.333
2520.62	181
2517.68	172.667
2514.74	172.333
2511.8	170.333
2508.86	167
2505.92	170.333
2502.97	164.667
2500.02	180
2497.07	171.333
2494.12	179.667
2491.16	168.667
2488.2	177
2485.25	174.333
2482.28	167.333
2479.32	160
2476.35	181.667
2473.39	167.333
2470.42	179
2467.44	187
2464.47	177.667
2461.49	178.333
2458.51	184
2455.53	181.333
2452.55	200.667
2449.56	190
2446.58	197.333
2443.59	194.333
2440.59	195.333
2437.6	196.333
2434.6	196.333
2431.61	192.333
2428.61	196.333
2425.6	197.333
2422.6	199
2419.59	202.667
2416.58	203.333
2413.57	203.667
2410.56	199.333
2407.54	186
2404.52	199
2401.5	196
2398.48	186.333
2395.45	198
2392.43	183
2389.4	187
2386.37	196.333
2383.33	198.667
2380.3	198
2377.26	199
2374.22	189.333
2371.17	203.667
2368.13	199.333
2365.08	209
2362.03	216
2358.98	205.667
2355.93	206
2352.87	199
2349.81	199.333
2346.75	212.667
2343.69	203.333
2340.63	215.333
2337.56	198
2334.49	207.333
2331.42	205
2328.35	211.667
2325.27	213.667
2322.19	209.333
2319.11	205
2316.03	207
2312.94	208.333
2309.85	222.667
2306.77	222
2303.67	214.333
2300.58	226.333
2297.48	223
2294.38	225.667
2291.28	224.333
2288.18	223.667
2285.07	212.333
2281.97	218.333
2278.86	216
2275.74	225
2272.63	210.667
2269.51	221.333
2266.39	232
2263.27	217.667
2260.15	225
2257.02	225
2253.89	231.667
2250.76	228
2247.63	228.667
2244.49	229.667
2241.36	238.333
2238.22	236.333
2235.08	234
2231.93	239.667
2228.78	239
2225.63	246
2222.48	241.333
2219.33	237.333
2216.17	232.667
2213.01	238.667
2209.85	236.333
2206.69	246
2203.53	245.667
2200.36	246
2197.19	247.667
2194.02	244.333
2190.84	248.333
2187.66	249
2184.48	243.333
2181.3	251.667
2178.12	246.333
2174.93	246
2171.74	253
2168.55	265
2165.36	267.667
2162.16	260
2158.97	268
2155.76	258.667
2152.56	265.667
2149.36	266.333
2146.15	253.333
2142.94	272.667
2139.73	273.667
2136.51	269.333
2133.29	275.667
2130.08	270.333
2126.85	283
2123.63	287.333
2120.4	280.333
2117.17	286.667
2113.94	298.333
2110.71	292
2107.47	294.667
2104.23	292
2100.99	302
2097.75	297.333
2094.5	291
2091.26	305
2088.01	307.667
2084.75	309
2081.5	319
2078.24	311.667
2074.98	317.333
2071.72	310.333
2068.45	323.333
2065.18	321.333
2061.92	338.333
2058.64	334
2055.37	352.333
2052.09	349.667
2048.81	351.333
2045.53	361.667
2042.25	357
2038.96	365.667
2035.67	378.667
2032.38	378.333
2029.08	378
2025.79	381.333
2022.49	399
2019.19	393
2015.88	407.667
2012.58	408.667
2009.27	417.333
2005.96	417.333
2002.64	434.333
1999.33	436.667
1996.01	460.333
1992.69	469.333
1989.36	468
1986.04	484
1982.71	503
1979.38	491.333
1976.05	506.667
1972.71	513.333
1969.37	528.667
1966.03	538.333
1962.69	568.333
1959.34	570
1955.99	587.667
1952.64	576
1949.29	603.333
1945.93	596.333
1942.58	607.667
1939.21	633
1935.85	626.333
1932.49	637
1929.12	667
1925.75	656
1922.37	660.333
1919	679.667
1915.62	660
1912.24	681.667
1908.86	685.667
1905.47	680.667
1902.08	694
1898.69	707
1895.3	695.333
1891.9	698.333
1888.5	707.667
1885.1	727.333
1881.7	729.333
1878.29	716.333
1874.88	710
1871.47	703.333
1868.06	710.333
1864.64	723
1861.22	731.333
1857.8	713.333
1854.38	714
1850.95	723.667
1847.52	726
1844.09	735.333
1840.66	722
1837.22	717.333
1833.78	722
1830.34	708.667
1826.9	736.333
1823.45	720
1820	738.667
1816.55	729.667
1813.09	728.667
1809.64	735.333
1806.18	734.333
1802.71	731.333
1799.25	735.333
1795.78	749.333
1792.31	762
1788.84	745.667
1785.36	765.333
1781.88	769
1778.4	768.333
1774.92	773
1771.43	786
1767.95	765.333
1764.45	782.333
1760.96	775.333
1757.47	789.333
1753.97	798
1750.47	791
1746.96	807.333
1743.45	790
1739.94	819.333
1736.43	834
1732.92	812
1729.4	845.333
1725.88	860
1722.36	852.667
1718.83	871
1715.3	872
1711.77	901
1708.24	897.333
1704.71	905.667
1701.17	936
1697.63	954.333
1694.08	967
1690.54	971
1686.99	963.333
1683.44	990.667
1679.88	988
1676.32	1017
1672.76	1021.67
1669.2	1028.67
1665.64	1034.67
1662.07	1052.33
1658.5	1065.33
1654.92	1080.67
1651.35	1106
1647.77	1111.33
1644.19	1139.33
1640.61	1130.33
1637.02	1169.33
1633.43	1179
1629.84	1161
1626.24	1190.33
1622.64	1186.33
1619.04	1192.33
1615.44	1181.33
1611.84	1175
1608.23	1174.33
1604.62	1181.67
1601	1177
1597.39	1174.33
1593.77	1187.67
1590.15	1212.67
1586.52	1231
1582.89	1224
1579.26	1233.33
1575.63	1247.33
1571.99	1262.33
1568.36	1267.33
1564.72	1293.33
1561.07	1304.33
1557.42	1298
1553.78	1271.67
1550.12	1296
1546.47	1277.67
1542.81	1275.33
1539.15	1246.67
1535.49	1265
1531.82	1242
1528.15	1250
1524.48	1252.33
1520.81	1238.67
1517.13	1232
1513.45	1236.67
1509.77	1233.67
1506.08	1251.33
1502.39	1257
1498.7	1271.33
1495.01	1273
1491.31	1295.67
1487.61	1304.67
1483.91	1304.67
1480.21	1326.67
1476.5	1336
1472.79	1353
1469.07	1369.67
1465.36	1402.33
1461.64	1427
1457.92	1434.67
1454.19	1441.33
1450.46	1487.33
1446.73	1487.33
1443	1486
1439.26	1504
1435.52	1515.33
1431.78	1506.33
1428.04	1519.67
1424.29	1506
1420.54	1523
1416.79	1535.67
1413.03	1541.67
1409.27	1536.67
1405.51	1564
1401.75	1555.67
1397.98	1559
1394.21	1566
1390.44	1572.33
1386.66	1533
1382.88	1570.33
1379.1	1523.33
1375.31	1507.67
1371.53	1493.67
1367.74	1481
1363.94	1486
1360.15	1462.67
1356.35	1464
1352.55	1420
1348.74	1409.67
1344.93	1400.33
1341.12	1350.67
1337.31	1319.33
1333.49	1294.67
1329.67	1259.67
1325.85	1262.33
1322.03	1203.67
1318.2	1192
1314.37	1160.33
1310.53	1135.33
1306.7	1109.33
1302.86	1092
1299.01	1067
1295.17	1065
1291.32	1044
1287.47	1054.67
1283.61	1020.33
1279.76	1003
1275.9	1002.33
1272.03	1021.67
1268.17	999.333
1264.3	981.667
1260.42	1001
1256.55	988
1252.67	978.333
1248.79	961
1244.91	957
1241.02	961
1237.13	962.333
1233.24	944.333
1229.34	942.667
1225.44	920.333
1221.54	914
1217.63	891.667
1213.73	862.333
1209.81	840.333
1205.9	830.667
1201.98	811
1198.06	800
1194.14	811
1190.21	802.333
1186.29	784.667
1182.35	771
1178.42	766.667
1174.48	759.333
1170.54	747.333
1166.6	760
1162.65	734.667
1158.7	744.333
1154.74	730
1150.79	736.667
1146.83	698.667
1142.87	721.667
1138.9	714.667
1134.93	723.667
1130.96	710.333
1126.99	715.333
1123.01	706.333
1119.03	699
1115.04	692
1111.06	685
1107.07	698.333
1103.08	680.667
1099.08	682
1095.08	679.333
1091.08	662.333
1087.07	654.667
1083.06	655.667
1079.05	647.333
1075.04	632.667
1071.02	638.333
1067	632
1062.98	631.333
1058.95	615.667
1054.92	610.333
1050.89	599.333
1046.85	597
1042.81	602
1038.77	604.667
1034.72	592
1030.67	620.667
1026.62	603.333
1022.57	617.333
1018.51	614.667
1014.45	630.667
1010.38	627
1006.32	645
1002.24	642.333
998.171	638
994.094	646.333
990.013	633
985.93	654
981.843	644
977.754	629.333
973.661	634.667
969.565	638
965.466	643.667
961.364	644
957.258	643.333
953.15	648.333
949.038	666.667
944.923	662.333
940.804	655.333
936.683	648
932.558	658.667
928.43	656
924.299	640
920.165	653.667
916.028	633.667
911.887	631.667
907.743	631
903.595	618.667
899.445	615.333
895.292	636
891.135	621
886.975	607.667
882.812	621.333
878.646	608.667
874.475	621.667
870.303	624
866.126	615.333
861.947	629.333
857.764	632
853.578	622.333
849.389	623
845.196	624
841	635.667
836.801	631.333
832.599	618.667
828.393	620.333
824.184	600.333
819.972	607.667
815.757	617.333
811.538	609.667
807.316	604.333
803.091	603
798.863	599.667
794.631	601.667
790.395	608
786.157	602.333
781.915	591.333
777.669	609.333
773.421	620.667
769.169	630.333
764.915	644
760.656	627
756.394	636.333
752.129	636
747.861	630.667
743.588	641
739.314	620.667
735.035	628.667
730.753	617
726.469	607.667
722.18	614.333
717.888	613.333
713.593	602.667
709.294	603
704.992	596
700.687	608
696.378	595.667
692.066	599.333
687.751	599
683.432	593.333
679.109	583
674.784	599.667
670.455	588
666.122	582.333
661.787	598
657.448	601.333
653.104	599
648.759	594
644.409	610.667
640.056	618.667
635.7	621.333
631.34	620.333
626.977	629
622.61	627.667
618.24	618.333
613.867	603.333
609.49	590
605.11	602.667
600.726	590
596.339	586
591.948	591
587.554	591.667
583.156	603.667
578.755	620.667
574.35	632
569.943	624.667
565.531	647.667
561.116	636.667
556.698	625.333
552.275	622
547.85	615.333
543.421	635.667
538.988	622
534.553	611.667
530.113	610.333
525.67	616.333
521.224	622
516.774	625
512.321	622.333
507.863	633
503.403	617.333
498.939	610.667
494.472	618.333
490.001	613.667
485.526	621.667
481.047	623.667
476.565	616.333
472.08	606.333
467.591	621.667
463.099	632
458.604	638.667
454.103	663
449.601	658
445.094	667.667
440.584	694.667
436.07	697
431.553	700
427.032	723.667
422.507	747
417.979	741.333
413.448	755.333
408.912	737.667
404.373	754.333
399.83	755
395.285	756
390.734	756.333
386.181	769
381.624	780.667
377.064	777.333
372.5	804
367.932	774.667
363.36	797.667
358.785	802.333
354.207	812
349.624	831.333
345.038	817
340.448	831
335.855	814.333
331.257	830.333
326.657	819.667
322.053	820
317.444	841.333
312.833	823
308.217	837.333
303.599	861
298.976	865
294.349	869.667
289.719	914
285.085	915.333
280.448	936
275.807	955
271.161	974.333
266.513	1002.67
261.861	1011
257.205	1035.67
252.544	1068.67
247.881	1057
243.214	1121.33
238.543	1116.33
233.869	1199
229.19	1223.33
224.508	1267.33
219.822	1293
215.132	1334.33
210.439	1363.33
205.741	1370
201.04	1430.33
196.336	1449.33
191.627	1491
186.915	1507
182.199	1555
177.478	1618.33
172.755	1619
168.028	1667
163.297	1717.33
158.561	1814.67
153.823	1812
149.08	1892.67
144.334	1879.33
139.584	1960.33
134.829	2038.33
130.071	2118
125.31	2268
120.545	2389
115.775	2468.67
111.001	2623.67
106.224	2852
101.444	3060.33
96.6594	3337.33
91.8705	3656
87.0781	3965
82.282	4422
77.4812	5095.67
72.6778	6210
67.8698	8762
63.0582	11224
58.2419	12969
53.4229	14508.3
48.5993	16143
43.772	18206
38.941	21200.7
34.1054	26277
29.2661	33652.3
24.4231	49943.3
19.5764	64524
14.7261	64524
9.87099	64524
5.01321	64524
0.14975	64524
-4.71644	64524
-9.58634	64524
-14.461	64524
-19.3393	64524
-24.2214	64524
-29.1072	64524
-33.9977	64524
-38.892	20984.7
-43.7901	14127
-48.6919	10557.7
-53.5974	8037.67
-58.5078	6191
-63.4218	4768.33
-68.3397	3653.67
-73.2613	2860
-78.1878	2246.33
-83.117	1832.67
-88.051	1516.67
-92.9888	1245.67
-97.9314	1038
-102.877	832
-107.827	670.333
-112.781	552.333
-117.739	472
-122.701	395
-127.667	321
-132.637	278.333
-137.612	239.667
-142.59	217.667
-147.572	184
-152.558	169.333
-157.548	160.667
-162.542	149.667
-167.541	138.667
-172.544	117.333
-177.55	128
-182.561	120.333
-187.576	117.333
-192.595	114.333
-197.617	101.333
-202.645	102.667
-207.676	106
-212.711	98.6667
-217.75	96
-222.794	101.667
-227.842	92
-232.893	87.3333
-237.949	88.6667
-243.009	86.3333
-248.073	84
-253.142	78
-258.214	84.3333
-263.291	82.3333
-268.371	94.3333
-273.456	79.6667
-278.545	74.6667
-283.639	70.6667
-288.735	73.6667
-293.837	69
-298.943	70
-304.053	71.6667
-309.166	69
-314.285	66.6667
-319.408	63
-324.534	68.6667
-329.665	60
-334.801	64.3333
-339.94	60.6667
-345.083	64.6667
-350.231	65
-355.383	67.6667
-360.539	62
-365.699	53.3333
-370.864	68
-376.033	56.3333
-381.206	60.3333
-386.384	55.3333
-391.565	57.6667
-396.751	55.6667
-401.941	52
-407.136	51
-412.334	56.6667
-417.537	48.6667
-422.745	48.6667
-427.956	50
-433.173	59.3333
-438.392	44.3333
-443.617	46.6667
-448.846	48.6667
-454.078	56
-459.317	51.3333
-464.558	54.6667
-469.804	51
-475.055	52
-480.309	53
-485.568	50.3333
-490.832	52.3333
-496.099	60.3333
-501.372	54
-506.648	40.6667
-511.929	52.6667
-517.215	52.6667
-522.504	52.6667
-527.797	51
-533.097	42.6667
-538.399	51.6667
-543.706	45.3333
-549.018	48
-554.334	51.6667
-559.654	44.6667
-564.979	48.6667
-570.308	49.6667
-575.641	51.3333
-580.98	48
-586.322	49.6667
-591.669	43.3333
-597.02	41.6667
-602.376	50
-607.736	45.6667
-613.1	50
-618.47	51
-623.843	51.6667
-629.222	45
-634.603	54.6667
-639.99	46
-645.382	51.6667
-650.779	44
-656.179	55
-661.583	47
-666.993	49.3333
-672.407	49.3333
-677.825	46
-683.248	51.3333
-688.675	51.3333
-694.108	44.6667
-699.544	47.3333
-704.985	46.6667
-710.431	48
-715.88	48.3333
-721.335	49
-726.795	44.3333
-732.258	47
-737.727	38.3333
-743.2	47.3333
-748.678	51.6667
-754.159	48.3333
-759.646	48.3333
-765.138	45.3333
-770.633	48
-776.133	48.3333
-781.638	48.6667
-787.149	48.6667
-792.663	37
-798.181	43.6667
-803.705	46.6667
-809.233	50
-814.766	45.3333
-820.304	52
-825.846	53.3333
-831.392	43.3333
-836.944	50.3333
-842.499	50.3333
-848.06	47
-853.626	46.6667
-859.195	49.3333
-864.77	48.3333
-870.35	47.3333
-875.934	50
-881.522	44.3333
-887.116	47
-892.714	49.6667
-898.317	50
-903.924	47.3333
-909.537	52
-915.153	46.6667
-920.776	51
-926.401	49.3333
-932.033	52.3333
-937.669	47.6667
-943.31	62
-948.955	46
-954.605	48.6667
-960.26	38.3333
-965.92	57
-971.584	51
-977.254	57
-982.928	51.6667
-988.607	54
-994.291	50
-999.979	51.3333
-1005.67	51.3333
-1011.37	51.6667
-1017.07	43.6667
-1022.78	51.6667
-1028.49	47
-1034.21	58.3333
-1039.93	58
-1045.66	46.3333
-1051.39	50.6667
-1057.13	55.6667
-1062.87	46
-1068.62	47.3333
-1074.37	55.6667
-1080.12	43
-1085.89	55.6667
-1091.65	48.3333
-1097.42	50.3333
-1103.2	59.3333
-1108.98	59.3333
-1114.77	48.3333
-1120.56	59
-1126.35	45.6667
-1132.15	56
-1137.96	50.3333
-1143.77	59.6667
-1149.58	72.3333
-1155.4	57.3333
-1161.23	59.3333
-1167.06	76.3333
-1172.89	78.6667
-1178.73	101
-1184.58	123
-1190.43	137
-1196.28	156.667
-1202.14	194.667
-1208.01	225
-1213.88	243
-1219.75	278
-1225.63	320
-1231.52	383.667
-1237.41	422.333
-1243.3	540
-1249.2	927.667
-1255.11	1006.33
-1261.02	879
-1266.93	747.333
-1272.85	478
-1278.78	209.667
-1284.71	103.667
-1290.65	91
-1296.59	81.3333
-1302.53	76.6667
-1308.48	70.3333
-1314.44	72
-1320.4	64.3333
-1326.37	61.6667
-1332.34	56.3333
-1338.31	66.6667
-1344.29	58.3333
-1350.28	55.3333
-1356.27	65
-1362.27	60
-1368.27	52.3333
-1374.28	55.3333
-1380.29	51.3333
-1386.31	46.6667
-1392.33	49
-1057.13	55.6667
-1062.87	46
-1068.62	47.3333
-1074.37	55.6667
-1080.12	43
-1085.89	55.6667
-1091.65	48.3333
-1097.42	50.3333
-1103.2	59.3333
-1108.98	59.3333
-1114.77	48.3333
-1120.56	59
-1126.35	45.6667
-1132.15	56
-1137.96	50.3333
-1143.77	59.6667
-1149.58	72.3333
-1155.4	57.3333
-1161.23	59.3333
-1167.06	76.3333
-1172.89	78.6667
-1178.73	101
-1184.58	123
-1190.43	137
-1196.28	156.667
-1202.14	194.667
-1208.01	225
-1213.88	243
-1219.75	278
-1225.63	320
-1231.52	383.667
-1237.41	422.333
-1243.3	540
-1249.2	927.667
-1255.11	1006.33
-1261.02	879
-1266.93	747.333
-1272.85	478
-1278.78	209.667
-1284.71	103.667
-1290.65	91
-1296.59	81.3333
-1302.53	76.6667
-1308.48	70.3333
-1314.44	72
-1320.4	64.3333
-1326.37	61.6667
-1332.34	56.3333
-1338.31	66.6667
-1344.29	58.3333
-1350.28	55.3333
-1356.27	65
-1362.27	60
-1368.27	52.3333
-1374.28	55.3333
-1380.29	51.3333
-1386.31	46.6667
-1392.33	49