File: projects/python/data/20231030/blood_600_785 nm_10 s_3_2023_10_30_15_32_31.txt
#Sample=blood
#Laser=785 nm
#Grating=600
#Exposition=10
#Accumulation=3
#Acquired=30.10.2023 15:32:31
2745.96	61
2743.18	68
2740.41	78
2737.63	85
2734.85	66
2732.07	67
2729.29	90
2726.5	74
2723.72	91
2720.93	77
2718.14	60
2715.34	66
2712.55	79
2709.75	79
2706.95	78
2704.15	59
2701.35	83
2698.55	69
2695.74	71
2692.93	82
2690.12	81
2687.31	67
2684.49	67
2681.67	65
2678.85	72
2676.03	76
2673.21	74
2670.38	81
2667.56	71
2664.73	68
2661.9	76
2659.06	75
2656.23	82
2653.39	69
2650.55	86
2647.71	87
2644.86	64
2642.02	68
2639.17	72
2636.32	55
2633.47	76
2630.62	73
2627.76	84
2624.9	88
2622.04	77
2619.18	68
2616.31	71
2613.45	67
2610.58	67
2607.71	77
2604.84	79
2601.96	62
2599.08	89
2596.21	80
2593.32	74
2590.44	73
2587.56	65
2584.67	69
2581.78	69
2578.89	78
2575.99	63
2573.1	71
2570.2	72
2567.3	81
2564.4	71
2561.5	64
2558.59	64
2555.68	64
2552.77	59
2549.86	62
2546.94	79
2544.03	78
2541.11	72
2538.19	49
2535.26	56
2532.34	71
2529.41	72
2526.48	64
2523.55	65
2520.62	67
2517.68	68
2514.74	59
2511.8	66
2508.86	74
2505.92	70
2502.97	62
2500.02	72
2497.07	72
2494.12	53
2491.16	55
2488.2	59
2485.25	66
2482.28	63
2479.32	69
2476.35	62
2473.39	70
2470.42	66
2467.44	71
2464.47	85
2461.49	84
2458.51	74
2455.53	79
2452.55	68
2449.56	70
2446.58	81
2443.59	78
2440.59	77
2437.6	72
2434.6	70
2431.61	66
2428.61	67
2425.6	83
2422.6	75
2419.59	79
2416.58	72
2413.57	54
2410.56	76
2407.54	73
2404.52	71
2401.5	65
2398.48	63
2395.45	62
2392.43	61
2389.4	70
2386.37	60
2383.33	64
2380.3	58
2377.26	58
2374.22	71
2371.17	61
2368.13	72
2365.08	71
2362.03	71
2358.98	69
2355.93	53
2352.87	60
2349.81	71
2346.75	65
2343.69	67
2340.63	69
2337.56	73
2334.49	53
2331.42	46
2328.35	69
2325.27	68
2322.19	65
2319.11	62
2316.03	61
2312.94	72
2309.85	62
2306.77	67
2303.67	55
2300.58	78
2297.48	68
2294.38	54
2291.28	57
2288.18	58
2285.07	67
2281.97	62
2278.86	60
2275.74	71
2272.63	66
2269.51	56
2266.39	58
2263.27	59
2260.15	64
2257.02	61
2253.89	51
2250.76	67
2247.63	61
2244.49	61
2241.36	64
2238.22	58
2235.08	59
2231.93	52
2228.78	75
2225.63	61
2222.48	59
2219.33	62
2216.17	69
2213.01	59
2209.85	70
2206.69	52
2203.53	76
2200.36	60
2197.19	65
2194.02	69
2190.84	52
2187.66	71
2184.48	56
2181.3	71
2178.12	68
2174.93	62
2171.74	71
2168.55	59
2165.36	66
2162.16	68
2158.97	69
2155.76	66
2152.56	59
2149.36	69
2146.15	80
2142.94	76
2139.73	84
2136.51	65
2133.29	79
2130.08	78
2126.85	93
2123.63	73
2120.4	76
2117.17	66
2113.94	81
2110.71	63
2107.47	75
2104.23	62
2100.99	76
2097.75	79
2094.5	84
2091.26	75
2088.01	86
2084.75	72
2081.5	59
2078.24	80
2074.98	70
2071.72	75
2068.45	81
2065.18	69
2061.92	83
2058.64	82
2055.37	84
2052.09	78
2048.81	74
2045.53	75
2042.25	92
2038.96	79
2035.67	77
2032.38	79
2029.08	95
2025.79	76
2022.49	86
2019.19	103
2015.88	105
2012.58	88
2009.27	96
2005.96	94
2002.64	86
1999.33	104
1996.01	109
1992.69	103
1989.36	112
1986.04	111
1982.71	109
1979.38	109
1976.05	116
1972.71	115
1969.37	110
1966.03	133
1962.69	138
1959.34	131
1955.99	136
1952.64	137
1949.29	149
1945.93	152
1942.58	145
1939.21	162
1935.85	167
1932.49	139
1929.12	142
1925.75	148
1922.37	163
1919	169
1915.62	160
1912.24	142
1908.86	182
1905.47	169
1902.08	167
1898.69	166
1895.3	159
1891.9	165
1888.5	181
1885.1	169
1881.7	169
1878.29	167
1874.88	154
1871.47	148
1868.06	172
1864.64	159
1861.22	167
1857.8	166
1854.38	164
1850.95	151
1847.52	164
1844.09	155
1840.66	164
1837.22	157
1833.78	143
1830.34	153
1826.9	169
1823.45	152
1820	158
1816.55	158
1813.09	155
1809.64	162
1806.18	156
1802.71	158
1799.25	167
1795.78	149
1792.31	151
1788.84	153
1785.36	175
1781.88	162
1778.4	159
1774.92	168
1771.43	178
1767.95	159
1764.45	183
1760.96	189
1757.47	160
1753.97	161
1750.47	172
1746.96	183
1743.45	167
1739.94	163
1736.43	163
1732.92	168
1729.4	186
1725.88	169
1722.36	193
1718.83	189
1715.3	201
1711.77	186
1708.24	194
1704.71	197
1701.17	198
1697.63	195
1694.08	224
1690.54	196
1686.99	211
1683.44	219
1679.88	207
1676.32	222
1672.76	201
1669.2	203
1665.64	178
1662.07	215
1658.5	184
1654.92	199
1651.35	197
1647.77	206
1644.19	197
1640.61	215
1637.02	208
1633.43	215
1629.84	211
1626.24	220
1622.64	208
1619.04	205
1615.44	205
1611.84	202
1608.23	208
1604.62	211
1601	227
1597.39	209
1593.77	210
1590.15	220
1586.52	228
1582.89	238
1579.26	239
1575.63	233
1571.99	246
1568.36	246
1564.72	250
1561.07	262
1557.42	262
1553.78	274
1550.12	256
1546.47	276
1542.81	251
1539.15	274
1535.49	281
1531.82	262
1528.15	285
1524.48	274
1520.81	281
1517.13	289
1513.45	269
1509.77	283
1506.08	289
1502.39	256
1498.7	291
1495.01	273
1491.31	280
1487.61	277
1483.91	283
1480.21	300
1476.5	296
1472.79	272
1469.07	294
1465.36	294
1461.64	301
1457.92	310
1454.19	309
1450.46	333
1446.73	315
1443	315
1439.26	315
1435.52	348
1431.78	323
1428.04	322
1424.29	308
1420.54	333
1416.79	312
1413.03	336
1409.27	348
1405.51	314
1401.75	314
1397.98	316
1394.21	301
1390.44	339
1386.66	346
1382.88	334
1379.1	321
1375.31	324
1371.53	319
1367.74	316
1363.94	321
1360.15	318
1356.35	314
1352.55	315
1348.74	316
1344.93	309
1341.12	292
1337.31	290
1333.49	310
1329.67	268
1325.85	261
1322.03	274
1318.2	290
1314.37	260
1310.53	283
1306.7	249
1302.86	266
1299.01	243
1295.17	262
1291.32	250
1287.47	249
1283.61	261
1279.76	237
1275.9	245
1272.03	246
1268.17	250
1264.3	242
1260.42	251
1256.55	235
1252.67	254
1248.79	247
1244.91	244
1241.02	247
1237.13	252
1233.24	234
1229.34	221
1225.44	241
1221.54	227
1217.63	230
1213.73	216
1209.81	207
1205.9	224
1201.98	218
1198.06	211
1194.14	199
1190.21	212
1186.29	219
1182.35	203
1178.42	199
1174.48	201
1170.54	209
1166.6	204
1162.65	196
1158.7	183
1154.74	209
1150.79	191
1146.83	198
1142.87	206
1138.9	213
1134.93	205
1130.96	211
1126.99	209
1123.01	196
1119.03	194
1115.04	194
1111.06	192
1107.07	211
1103.08	186
1099.08	200
1095.08	188
1091.08	187
1087.07	186
1083.06	194
1079.05	199
1075.04	177
1071.02	182
1067	189
1062.98	187
1058.95	173
1054.92	187
1050.89	182
1046.85	191
1042.81	177
1038.77	176
1034.72	177
1030.67	181
1026.62	171
1022.57	180
1018.51	165
1014.45	172
1010.38	180
1006.32	195
1002.24	193
998.171	186
994.094	182
990.013	184
985.93	171
981.843	204
977.754	206
973.661	178
969.565	199
965.466	190
961.364	193
957.258	186
953.15	186
949.038	202
944.923	198
940.804	188
936.683	195
932.558	197
928.43	200
924.299	183
920.165	172
916.028	170
911.887	193
907.743	194
903.595	185
899.445	169
895.292	185
891.135	194
886.975	194
882.812	205
878.646	187
874.475	196
870.303	183
866.126	185
861.947	180
857.764	183
853.578	192
849.389	174
845.196	193
841	183
836.801	196
832.599	184
828.393	193
824.184	186
819.972	186
815.757	174
811.538	191
807.316	176
803.091	191
798.863	175
794.631	163
790.395	160
786.157	185
781.915	174
777.669	190
773.421	174
769.169	180
764.915	168
760.656	173
756.394	170
752.129	174
747.861	179
743.588	170
739.314	177
735.035	158
730.753	166
726.469	166
722.18	167
717.888	165
713.593	170
709.294	165
704.992	160
700.687	163
696.378	147
692.066	170
687.751	165
683.432	150
679.109	147
674.784	162
670.455	142
666.122	155
661.787	162
657.448	150
653.104	158
648.759	152
644.409	159
640.056	149
635.7	164
631.34	175
626.977	181
622.61	175
618.24	160
613.867	146
609.49	149
605.11	141
600.726	150
596.339	150
591.948	146
587.554	133
583.156	157
578.755	159
574.35	152
569.943	180
565.531	172
561.116	172
556.698	161
552.275	150
547.85	153
543.421	151
538.988	140
534.553	144
530.113	140
525.67	143
521.224	135
516.774	151
512.321	150
507.863	153
503.403	152
498.939	135
494.472	147
490.001	147
485.526	127
481.047	145
476.565	141
472.08	161
467.591	167
463.099	164
458.604	165
454.103	162
449.601	157
445.094	182
440.584	174
436.07	189
431.553	191
427.032	175
422.507	199
417.979	191
413.448	173
408.912	194
404.373	199
399.83	217
395.285	230
390.734	227
386.181	216
381.624	222
377.064	226
372.5	246
367.932	222
363.36	217
358.785	236
354.207	245
349.624	237
345.038	219
340.448	236
335.855	240
331.257	233
326.657	233
322.053	230
317.444	216
312.833	230
308.217	237
303.599	236
298.976	228
294.349	232
289.719	244
285.085	229
280.448	228
275.807	241
271.161	242
266.513	248
261.861	235
257.205	278
252.544	239
247.881	252
243.214	243
238.543	261
233.869	273
229.19	278
224.508	257
219.822	270
215.132	289
210.439	299
205.741	311
201.04	292
196.336	294
191.627	305
186.915	312
182.199	293
177.478	308
172.755	285
168.028	315
163.297	332
158.561	350
153.823	336
149.08	343
144.334	355
139.584	317
134.829	366
130.071	349
125.31	345
120.545	352
115.775	395
111.001	407
106.224	418
101.444	449
96.6594	465
91.8705	533
87.0781	582
82.282	660
77.4812	875
72.6778	1945
67.8698	2813
63.0582	4398
58.2419	5260
53.4229	5679
48.5993	5723
43.772	5635
38.941	5529
34.1054	5729
29.2661	6333
24.4231	8214
19.5764	44020
14.7261	64524
9.87099	64524
5.01321	64524
0.14975	64524
-4.71644	64524
-9.58634	64524
-14.461	61327
-19.3393	46199
-24.2214	41913
-29.1072	26146
-33.9977	4679
-38.892	2545
-43.7901	1705
-48.6919	1277
-53.5974	958
-58.5078	733
-63.4218	591
-68.3397	474
-73.2613	386
-78.1878	314
-83.117	279
-88.051	209
-92.9888	159
-97.9314	132
-102.877	142
-107.827	116
-112.781	92
-117.739	88
-122.701	73
-127.667	65
-132.637	67
-137.612	57
-142.59	52
-147.572	60
-152.558	47
-157.548	38
-162.542	47
-167.541	52
-172.544	34
-177.55	40
-182.561	31
-187.576	37
-192.595	57
-197.617	47
-202.645	37
-207.676	51
-212.711	39
-217.75	47
-222.794	40
-227.842	50
-232.893	41
-237.949	41
-243.009	47
-248.073	44
-253.142	41
-258.214	23
-263.291	38
-268.371	34
-273.456	39
-278.545	39
-283.639	44
-288.735	43
-293.837	31
-298.943	31
-304.053	37
-309.166	52
-314.285	32
-319.408	46
-324.534	32
-329.665	38
-334.801	43
-339.94	33
-345.083	34
-350.231	25
-355.383	49
-360.539	21
-365.699	28
-370.864	24
-376.033	38
-381.206	31
-386.384	44
-391.565	37
-396.751	30
-401.941	32
-407.136	32
-412.334	23
-417.537	38
-422.745	31
-427.956	43
-433.173	43
-438.392	40
-443.617	50
-448.846	37
-454.078	33
-459.317	40
-464.558	38
-469.804	32
-475.055	35
-480.309	49
-485.568	41
-490.832	31
-496.099	35
-501.372	44
-506.648	47
-511.929	29
-517.215	20
-522.504	33
-527.797	45
-533.097	42
-538.399	43
-543.706	28
-549.018	45
-554.334	43
-559.654	29
-564.979	30
-570.308	25
-575.641	34
-580.98	31
-586.322	41
-591.669	35
-597.02	35
-602.376	33
-607.736	28
-613.1	38
-618.47	49
-623.843	48
-629.222	26
-634.603	36
-639.99	22
-645.382	36
-650.779	42
-656.179	30
-661.583	45
-666.993	35
-672.407	32
-677.825	37
-683.248	39
-688.675	42
-694.108	43
-699.544	37
-704.985	40
-710.431	33
-715.88	28
-721.335	28
-726.795	43
-732.258	41
-737.727	32
-743.2	32
-748.678	24
-754.159	33
-759.646	34
-765.138	38
-770.633	38
-776.133	28
-781.638	53
-787.149	41
-792.663	34
-798.181	32
-803.705	32
-809.233	34
-814.766	34
-820.304	30
-825.846	34
-831.392	30
-836.944	37
-842.499	28
-848.06	38
-853.626	41
-859.195	28
-864.77	31
-870.35	33
-875.934	29
-881.522	26
-887.116	34
-892.714	35
-898.317	22
-903.924	27
-909.537	35
-915.153	34
-920.776	33
-926.401	41
-932.033	28
-937.669	38
-943.31	26
-948.955	28
-954.605	28
-960.26	35
-965.92	22
-971.584	36
-977.254	36
-982.928	28
-988.607	25
-994.291	32
-999.979	29
-1005.67	29
-1011.37	27
-1017.07	42
-1022.78	32
-1028.49	41
-1034.21	20
-1039.93	36
-1045.66	42
-1051.39	22
-1057.13	42
-1062.87	31
-1068.62	35
-1074.37	40
-1080.12	34
-1085.89	49
-1091.65	38
-1097.42	36
-1103.2	35
-1108.98	38
-1114.77	41
-1120.56	36
-1126.35	45
-1132.15	32
-1137.96	27
-1143.77	39
-1149.58	49
-1155.4	30
-1161.23	14
-1167.06	28
-1172.89	39
-1178.73	46
-1184.58	46
-1190.43	69
-1196.28	57
-1202.14	66
-1208.01	45
-1213.88	70
-1219.75	74
-1225.63	54
-1231.52	82
-1237.41	76
-1243.3	97
-1249.2	155
-1255.11	167
-1261.02	149
-1266.93	123
-1272.85	86
-1278.78	57
-1284.71	37
-1290.65	41
-1296.59	49
-1302.53	29
-1308.48	40
-1314.44	30
-1320.4	30
-1326.37	43
-1332.34	28
-1338.31	40
-1344.29	47
-1350.28	36
-1356.27	47
-1362.27	32
-1368.27	38
-1374.28	27
-1380.29	25
-1386.31	39
-1392.33	36
-968.751	32
-974.419	46
-980.09	35
-985.767	38
-991.448	26
-997.135	30
-1002.82	39
-1008.52	32
-1014.22	33
-1019.93	23
-1025.64	36
-1031.35	27
-1037.07	36
-1042.8	35
-1048.53	30
-1054.26	42
-1060	31
-1065.74	27
-1071.49	25
-1077.25	20
-1083.01	28
-1088.77	42
-1094.54	35
-1100.31	29
-1106.09	51
-1111.87	30
-1117.66	28
-1123.45	41
-1129.25	41
-1135.05	42
-1140.86	35
-1146.67	24
-1152.49	32
-1158.32	38
-1164.14	47
-1169.98	51
-1175.81	49
-1181.66	42
-1187.5	56
-1193.35	61
-1199.21	51
-1205.08	47
-1210.94	59
-1216.82	63
-1222.69	63
-1228.58	61
-1234.46	81
-1240.35	93
-1246.25	121
-1252.16	142
-1258.06	155
-1263.97	146
-1269.89	118
-1275.82	65
-1281.74	50
-1287.68	61
-1293.62	51
-1299.56	31
-1305.51	43
-1311.46	37
-1317.42	35
-1323.38	44
-1329.35	49
-1335.32	47
-1341.3	34
-1347.29	40
-1353.28	28
-1359.27	46
-1365.27	34
-1371.27	26
-1377.28	40
-1383.3	23
-1389.32	34
-1392.33	36