File: projects/python/data/20231030/blood_600_785 nm_10 s_1_2023_10_30_15_33_44_01.txt
#Sample=blood
#Laser=785 nm
#Grating=600
#Exposition=10
#Accumulation=1
#Acquired=30.10.2023 15:33:44
2745.96	96.6667
2743.18	95.3333
2740.41	94.3333
2737.63	98.3333
2734.85	104
2732.07	97.3333
2729.29	99
2726.5	96
2723.72	102.667
2720.93	107
2718.14	100
2715.34	101.667
2712.55	105
2709.75	94.6667
2706.95	99.3333
2704.15	95.3333
2701.35	113.667
2698.55	103.667
2695.74	104
2692.93	104.333
2690.12	102.333
2687.31	107
2684.49	96.3333
2681.67	104
2678.85	105.333
2676.03	104.333
2673.21	104.667
2670.38	103.667
2667.56	109.333
2664.73	105.333
2661.9	106.667
2659.06	104
2656.23	106.667
2653.39	104.333
2650.55	103.333
2647.71	106.667
2644.86	105
2642.02	100.333
2639.17	110.333
2636.32	112.333
2633.47	100.667
2630.62	106.667
2627.76	110.667
2624.9	107
2622.04	114.667
2619.18	105
2616.31	108.333
2613.45	100
2610.58	102
2607.71	107
2604.84	107
2601.96	108.667
2599.08	109.667
2596.21	104.667
2593.32	103.333
2590.44	107
2587.56	107.333
2584.67	96
2581.78	106.667
2578.89	107.667
2575.99	103.667
2573.1	112.667
2570.2	102.333
2567.3	113.667
2564.4	111.667
2561.5	109
2558.59	118.667
2555.68	110.333
2552.77	113.333
2549.86	108
2546.94	107.667
2544.03	114
2541.11	109.667
2538.19	102.667
2535.26	108.667
2532.34	99
2529.41	114.667
2526.48	104
2523.55	113.333
2520.62	106.667
2517.68	107
2514.74	115
2511.8	100.333
2508.86	95.3333
2505.92	112
2502.97	113.333
2500.02	115
2497.07	114.667
2494.12	105.667
2491.16	106.667
2488.2	109
2485.25	109.333
2482.28	108
2479.32	112
2476.35	107
2473.39	117.667
2470.42	121.333
2467.44	117.333
2464.47	119.333
2461.49	112
2458.51	121
2455.53	119.333
2452.55	115.667
2449.56	115
2446.58	121
2443.59	109
2440.59	119
2437.6	123
2434.6	125.667
2431.61	128
2428.61	123.667
2425.6	131
2422.6	127
2419.59	123
2416.58	124
2413.57	124.333
2410.56	131
2407.54	114.333
2404.52	118.667
2401.5	116.333
2398.48	115
2395.45	122.667
2392.43	113.667
2389.4	124
2386.37	123.667
2383.33	110.667
2380.3	123
2377.26	122.667
2374.22	118
2371.17	122
2368.13	116.667
2365.08	123
2362.03	118
2358.98	132
2355.93	128.333
2352.87	125.333
2349.81	131
2346.75	130.667
2343.69	125.333
2340.63	122.333
2337.56	117
2334.49	120
2331.42	122
2328.35	122.667
2325.27	122
2322.19	127
2319.11	130.333
2316.03	130.333
2312.94	137.667
2309.85	122.333
2306.77	124
2303.67	139.667
2300.58	132
2297.48	131
2294.38	127.333
2291.28	126
2288.18	135.333
2285.07	130.667
2281.97	127
2278.86	123
2275.74	126
2272.63	136.667
2269.51	121
2266.39	122.667
2263.27	131
2260.15	141
2257.02	136
2253.89	133
2250.76	131.667
2247.63	133.667
2244.49	134.667
2241.36	128
2238.22	133.667
2235.08	138
2231.93	140.333
2228.78	140.333
2225.63	139.667
2222.48	143.333
2219.33	153
2216.17	142.667
2213.01	139.667
2209.85	141.667
2206.69	137.333
2203.53	138.333
2200.36	142.667
2197.19	147.333
2194.02	146.333
2190.84	153.333
2187.66	144
2184.48	143.333
2181.3	150
2178.12	153.667
2174.93	155.667
2171.74	146.333
2168.55	152
2165.36	150.667
2162.16	140.333
2158.97	157.333
2155.76	151.667
2152.56	140.333
2149.36	151.333
2146.15	161
2142.94	163.667
2139.73	160.667
2136.51	158
2133.29	158.667
2130.08	155
2126.85	168
2123.63	162.667
2120.4	166.667
2117.17	168.667
2113.94	159
2110.71	164.667
2107.47	173.667
2104.23	175
2100.99	181
2097.75	171.667
2094.5	170.333
2091.26	184
2088.01	174.667
2084.75	186.333
2081.5	184.667
2078.24	182
2074.98	192
2071.72	195.333
2068.45	185.333
2065.18	193.667
2061.92	187
2058.64	203.667
2055.37	192.667
2052.09	196
2048.81	205.667
2045.53	202
2042.25	201.667
2038.96	209.333
2035.67	209
2032.38	213.333
2029.08	225
2025.79	231.333
2022.49	227.333
2019.19	224.333
2015.88	238.333
2012.58	237.333
2009.27	238
2005.96	247.333
2002.64	259.667
1999.33	266.667
1996.01	260.667
1992.69	269
1989.36	273
1986.04	285
1982.71	295.667
1979.38	282.333
1976.05	316.667
1972.71	308
1969.37	313.667
1966.03	341
1962.69	336.333
1959.34	341.667
1955.99	345.667
1952.64	351
1949.29	370
1945.93	376.667
1942.58	379
1939.21	374
1935.85	374.333
1932.49	369
1929.12	390.333
1925.75	395.333
1922.37	397.333
1919	399.333
1915.62	407.667
1912.24	407
1908.86	427.333
1905.47	412.667
1902.08	421.667
1898.69	431.667
1895.3	438.667
1891.9	431
1888.5	439
1885.1	444
1881.7	439.333
1878.29	430
1874.88	434.333
1871.47	435.667
1868.06	442.667
1864.64	438.667
1861.22	419
1857.8	431.333
1854.38	432.333
1850.95	430.333
1847.52	427
1844.09	429.667
1840.66	435
1837.22	435
1833.78	427.333
1830.34	431
1826.9	424
1823.45	429.667
1820	425.333
1816.55	437.333
1813.09	448.667
1809.64	426
1806.18	438.333
1802.71	431.667
1799.25	448.333
1795.78	447
1792.31	449.333
1788.84	442.333
1785.36	454.667
1781.88	465.333
1778.4	468.333
1774.92	450.667
1771.43	449.667
1767.95	465.333
1764.45	453.333
1760.96	456.667
1757.47	465.667
1753.97	468.667
1750.47	472.333
1746.96	473.667
1743.45	490.333
1739.94	485.333
1736.43	494.333
1732.92	491.333
1729.4	503.667
1725.88	499
1722.36	515.667
1718.83	515.333
1715.3	523
1711.77	522
1708.24	533
1704.71	537.333
1701.17	552.667
1697.63	562
1694.08	568.333
1690.54	558.333
1686.99	567.333
1683.44	567
1679.88	575.667
1676.32	575.333
1672.76	579
1669.2	575.333
1665.64	589
1662.07	582.333
1658.5	585.333
1654.92	589.667
1651.35	607.667
1647.77	609.333
1644.19	605.667
1640.61	608.333
1637.02	608.667
1633.43	625.667
1629.84	615
1626.24	603
1622.64	622
1619.04	627
1615.44	623
1611.84	634.333
1608.23	635.333
1604.62	622.667
1601	632
1597.39	648
1593.77	645.333
1590.15	655
1586.52	653.667
1582.89	664
1579.26	671.333
1575.63	684
1571.99	684.667
1568.36	694
1564.72	681.333
1561.07	708.667
1557.42	707.333
1553.78	713.333
1550.12	710.667
1546.47	723
1542.81	723
1539.15	713.333
1535.49	718.667
1531.82	723.667
1528.15	723.667
1524.48	721.667
1520.81	743.667
1517.13	726.667
1513.45	726.667
1509.77	743
1506.08	768.333
1502.39	754.667
1498.7	755.667
1495.01	755.667
1491.31	758
1487.61	758.667
1483.91	770
1480.21	788.667
1476.5	793.333
1472.79	819.333
1469.07	805.333
1465.36	817
1461.64	819.667
1457.92	842.667
1454.19	847.667
1450.46	859.333
1446.73	863
1443	876.333
1439.26	862
1435.52	900.333
1431.78	905.667
1428.04	888.667
1424.29	900.333
1420.54	906
1416.79	914
1413.03	907.333
1409.27	914
1405.51	914.333
1401.75	938.333
1397.98	929.333
1394.21	936
1390.44	917.333
1386.66	918
1382.88	917.667
1379.1	920.333
1375.31	894.667
1371.53	891.333
1367.74	880.333
1363.94	887
1360.15	852.667
1356.35	852
1352.55	832
1348.74	829.333
1344.93	808.667
1341.12	788.667
1337.31	751.667
1333.49	738.667
1329.67	739
1325.85	699.333
1322.03	700.333
1318.2	687.667
1314.37	654.667
1310.53	657
1306.7	641
1302.86	626
1299.01	625.667
1295.17	607
1291.32	603.333
1287.47	580.333
1283.61	584
1279.76	573.667
1275.9	576.667
1272.03	587
1268.17	553.667
1264.3	563.333
1260.42	560
1256.55	563.333
1252.67	538.333
1248.79	538.667
1244.91	540.333
1241.02	550.333
1237.13	538.333
1233.24	518
1229.34	510
1225.44	512.667
1221.54	499.333
1217.63	492
1213.73	484
1209.81	474
1205.9	461.333
1201.98	455.333
1198.06	440.333
1194.14	435.667
1190.21	439.667
1186.29	424.333
1182.35	440
1178.42	436.667
1174.48	432.333
1170.54	420.333
1166.6	425
1162.65	430
1158.7	415
1154.74	400.667
1150.79	410.333
1146.83	411.667
1142.87	407
1138.9	403
1134.93	390.667
1130.96	396.667
1126.99	382
1123.01	398
1119.03	392
1115.04	384
1111.06	384.333
1107.07	373
1103.08	368.333
1099.08	378.667
1095.08	373
1091.08	369.667
1087.07	360.667
1083.06	357
1079.05	360.333
1075.04	360.333
1071.02	348.667
1067	349.667
1062.98	343
1058.95	345.333
1054.92	336.333
1050.89	328.667
1046.85	333.667
1042.81	329
1038.77	326.333
1034.72	325.333
1030.67	330
1026.62	329.333
1022.57	331
1018.51	331
1014.45	329
1010.38	324.333
1006.32	325.333
1002.24	324
998.171	334
994.094	342.667
990.013	326.667
985.93	331
981.843	335
977.754	337.333
973.661	332.667
969.565	332.667
965.466	341.333
961.364	337.667
957.258	334.333
953.15	334
949.038	345.667
944.923	349
940.804	344.333
936.683	341
932.558	345.667
928.43	342.333
924.299	339
920.165	348.667
916.028	339.667
911.887	343.667
907.743	330.333
903.595	334
899.445	334.667
895.292	337.667
891.135	323
886.975	334.667
882.812	325
878.646	353
874.475	336
870.303	333
866.126	320.333
861.947	320.667
857.764	326
853.578	340.667
849.389	342.333
845.196	334.667
841	336.667
836.801	334
832.599	334.667
828.393	327.667
824.184	331.333
819.972	330.667
815.757	321.667
811.538	321.667
807.316	319
803.091	330
798.863	321.667
794.631	330.667
790.395	316.667
786.157	320.667
781.915	314
777.669	320
773.421	324.667
769.169	327.333
764.915	323
760.656	317.667
756.394	331
752.129	322.667
747.861	319.333
743.588	322.333
739.314	322
735.035	314.333
730.753	315.333
726.469	312.667
722.18	311.333
717.888	313
713.593	311.667
709.294	310.333
704.992	310.667
700.687	297.667
696.378	304
692.066	316.333
687.751	299.333
683.432	310
679.109	310
674.784	302
670.455	288.333
666.122	297.667
661.787	311.667
657.448	313
653.104	309.667
648.759	314.667
644.409	312
640.056	317.667
635.7	320.333
631.34	330
626.977	339
622.61	337
618.24	321
613.867	313.667
609.49	297
605.11	290.667
600.726	298.333
596.339	310.333
591.948	298.333
587.554	314
583.156	296.333
578.755	319.333
574.35	328.333
569.943	327.667
565.531	323
561.116	328
556.698	329.333
552.275	326.333
547.85	315.667
543.421	320
538.988	315
534.553	302.667
530.113	304
525.67	320.667
521.224	318.333
516.774	314.667
512.321	306.667
507.863	310.333
503.403	304.667
498.939	308
494.472	305
490.001	307
485.526	310
481.047	307
476.565	323
472.08	311.333
467.591	317.667
463.099	326.333
458.604	333
454.103	336.667
449.601	333
445.094	346.667
440.584	359.333
436.07	359.667
431.553	354
427.032	367.667
422.507	369.667
417.979	389.333
413.448	380.667
408.912	386.667
404.373	400.667
399.83	392
395.285	404
390.734	402.333
386.181	399.333
381.624	414.667
377.064	400.667
372.5	398.667
367.932	411.333
363.36	431.333
358.785	417.667
354.207	425
349.624	432.667
345.038	445
340.448	428
335.855	431.333
331.257	425.333
326.657	413.667
322.053	430.667
317.444	428.667
312.833	421.667
308.217	422.333
303.599	442
298.976	430
294.349	450
289.719	449
285.085	456.667
280.448	466
275.807	466.333
271.161	478
266.513	484
261.861	504
257.205	493.667
252.544	505
247.881	522.667
243.214	518.667
238.543	533
233.869	560
229.19	540.333
224.508	585.667
219.822	591.333
215.132	582.667
210.439	621.333
205.741	612.333
201.04	643.333
196.336	641
191.627	657
186.915	666.333
182.199	681.333
177.478	692
172.755	690.667
168.028	705.333
163.297	752.667
158.561	749.667
153.823	781
149.08	789
144.334	784
139.584	812.333
134.829	824.667
130.071	836
125.31	883.667
120.545	904.667
115.775	931.333
111.001	1017
106.224	1049.67
101.444	1103.67
96.6594	1214
91.8705	1306.33
87.0781	1460
82.282	1664.33
77.4812	2038.33
72.6778	2839.67
67.8698	4926.33
63.0582	7024
58.2419	8327.33
53.4229	9364.33
48.5993	10178.3
43.772	10872.3
38.941	11969.7
34.1054	13944.7
29.2661	17343
24.4231	24597.3
19.5764	64524
14.7261	64524
9.87099	64524
5.01321	64524
0.14975	64524
-4.71644	64524
-9.58634	64524
-14.461	64524
-19.3393	64524
-24.2214	64524
-29.1072	64524
-33.9977	18941.7
-38.892	9860.67
-43.7901	6613
-48.6919	4909.67
-53.5974	3751.33
-58.5078	2890.33
-63.4218	2245
-68.3397	1777.33
-73.2613	1410.33
-78.1878	1149.33
-83.117	929
-88.051	744
-92.9888	612.333
-97.9314	503.333
-102.877	454
-107.827	391.667
-112.781	297.667
-117.739	239
-122.701	209.667
-127.667	191.333
-132.637	176.667
-137.612	138
-142.59	128.667
-147.572	109.667
-152.558	106.333
-157.548	98
-162.542	90.6667
-167.541	97.3333
-172.544	87.3333
-177.55	84.6667
-182.561	76.6667
-187.576	65
-192.595	74.3333
-197.617	77
-202.645	69
-207.676	69.6667
-212.711	64.6667
-217.75	68
-222.794	67.6667
-227.842	69
-232.893	68
-237.949	65
-243.009	67
-248.073	57.6667
-253.142	68
-258.214	61.6667
-263.291	59
-268.371	64
-273.456	64.3333
-278.545	50.3333
-283.639	58
-288.735	58
-293.837	51.3333
-298.943	51.6667
-304.053	57.6667
-309.166	57.6667
-314.285	59.3333
-319.408	56.6667
-324.534	48.3333
-329.665	53
-334.801	51.3333
-339.94	56.3333
-345.083	49.3333
-350.231	54.6667
-355.383	45.3333
-360.539	52.3333
-365.699	42.3333
-370.864	54.6667
-376.033	51.3333
-381.206	49.3333
-386.384	45.3333
-391.565	46
-396.751	42
-401.941	50.3333
-407.136	47
-412.334	48.3333
-417.537	48.3333
-422.745	39.6667
-427.956	55.6667
-433.173	50.3333
-438.392	50
-443.617	35
-448.846	46.6667
-454.078	44
-459.317	45
-464.558	43.3333
-469.804	47
-475.055	49.6667
-480.309	47.6667
-485.568	50.6667
-490.832	51.6667
-496.099	49
-501.372	42.6667
-506.648	38
-511.929	50
-517.215	44.3333
-522.504	43
-527.797	54.3333
-533.097	50.6667
-538.399	43.3333
-543.706	47.3333
-549.018	38.6667
-554.334	39
-559.654	45.3333
-564.979	41
-570.308	45.3333
-575.641	44.6667
-580.98	46
-586.322	49
-591.669	44.6667
-597.02	36.3333
-602.376	44.3333
-607.736	42
-613.1	46.6667
-618.47	39.3333
-623.843	39.6667
-629.222	43
-634.603	47.6667
-639.99	45
-645.382	37.6667
-650.779	46.3333
-656.179	44.3333
-661.583	42.3333
-666.993	44.6667
-672.407	45.6667
-677.825	36
-683.248	44.3333
-688.675	47.6667
-694.108	37.3333
-699.544	49.6667
-704.985	43
-710.431	41.3333
-715.88	53
-721.335	43.3333
-726.795	38.6667
-732.258	41.6667
-737.727	41
-743.2	39.6667
-748.678	55.6667
-754.159	41.6667
-759.646	41.3333
-765.138	46.6667
-770.633	44
-776.133	42
-781.638	47.3333
-787.149	37
-792.663	43.3333
-798.181	41
-803.705	45
-809.233	43.3333
-814.766	38
-820.304	41.3333
-825.846	51.3333
-831.392	51.3333
-836.944	39.3333
-842.499	48.3333
-848.06	42.6667
-853.626	35.3333
-859.195	50.3333
-864.77	48.3333
-870.35	41.3333
-875.934	35.3333
-881.522	48.3333
-887.116	37.6667
-892.714	39
-898.317	40.6667
-903.924	48
-909.537	38.3333
-915.153	38
-920.776	44.3333
-926.401	48
-932.033	34.6667
-937.669	43
-943.31	43.6667
-948.955	38.6667
-954.605	38.6667
-960.26	36
-965.92	47.6667
-971.584	40.6667
-977.254	38.6667
-982.928	43.3333
-988.607	40.3333
-994.291	47.3333
-999.979	43.6667
-1005.67	48.6667
-1011.37	37
-1017.07	38.3333
-1022.78	45
-1028.49	40.3333
-1034.21	40.6667
-1039.93	49.3333
-1045.66	43.6667
-1051.39	50.3333
-1057.13	34.6667
-1062.87	43.3333
-1068.62	47
-1074.37	38.6667
-1080.12	40.3333
-1085.89	40.3333
-1091.65	43.6667
-1097.42	43.3333
-1103.2	40.6667
-1108.98	41.6667
-1114.77	49.6667
-1120.56	50.6667
-1126.35	55
-1132.15	49.6667
-1137.96	46.3333
-1143.77	46
-1149.58	53
-1155.4	44.6667
-1161.23	47.6667
-1167.06	52.3333
-1172.89	58
-1178.73	67
-1184.58	71.3333
-1190.43	93
-1196.28	106
-1202.14	106
-1208.01	113.667
-1213.88	130
-1219.75	138.333
-1225.63	154.333
-1231.52	192.333
-1237.41	215.333
-1243.3	292.333
-1249.2	495.333
-1255.11	550
-1261.02	413.333
-1266.93	412.333
-1272.85	279
-1278.78	117.333
-1284.71	66.3333
-1290.65	60.3333
-1296.59	55.3333
-1302.53	50
-1308.48	52
-1314.44	56.3333
-1320.4	53
-1326.37	48.3333
-1332.34	44.6667
-1338.31	50
-1344.29	46
-1350.28	51
-1356.27	38
-1362.27	37.6667
-1368.27	43
-1374.28	39.3333
-1380.29	45
-1386.31	41.3333
-1392.33	41.6667

-1057.13	34.6667
-1060	55.3333
-1062.87	43.3333
-1065.74	41.6667
-1068.62	47
-1071.49	48.3333
-1074.37	38.6667
-1077.25	40.6667
-1080.12	40.3333
-1083.01	44.3333
-1085.89	40.3333
-1088.77	45
-1091.65	43.6667
-1094.54	41.6667
-1097.42	43.3333
-1100.31	44.3333
-1103.2	40.6667
-1106.09	44.6667
-1108.98	41.6667
-1111.87	51.3333
-1114.77	49.6667
-1117.66	37.3333
-1120.56	50.6667
-1123.45	41.6667
-1126.35	55
-1129.25	47.6667
-1132.15	49.6667
-1135.05	43.6667
-1137.96	46.3333
-1140.86	54.3333
-1143.77	46
-1146.67	51
-1149.58	53
-1152.49	48
-1155.4	44.6667
-1158.32	44.6667
-1161.23	47.6667
-1164.14	53.3333
-1167.06	52.3333
-1169.98	49.3333
-1172.89	58
-1175.81	54.6667
-1178.73	67
-1181.66	66.3333
-1184.58	71.3333
-1187.5	83.3333
-1190.43	93
-1193.35	94.3333
-1196.28	106
-1199.21	114
-1202.14	106
-1205.08	113.333
-1208.01	113.667
-1210.94	120
-1213.88	130
-1216.82	135.333
-1219.75	138.333
-1222.69	147.667
-1225.63	154.333
-1228.58	169.333
-1231.52	192.333
-1234.46	195.667
-1237.41	215.333
-1240.35	255.667
-1243.3	292.333
-1246.25	399.667
-1249.2	495.333
-1252.16	557.667
-1255.11	550
-1258.06	461.667
-1261.02	413.333
-1263.97	402.333
-1266.93	412.333
-1269.89	358.667
-1272.85	279
-1275.82	192.667
-1278.78	117.333
-1281.74	87.6667
-1284.71	66.3333
-1287.68	65
-1290.65	60.3333
-1293.62	63.6667
-1296.59	55.3333
-1299.56	60
-1302.53	50
-1305.51	48.6667
-1308.48	52
-1311.46	59
-1314.44	56.3333
-1317.42	50
-1320.4	53
-1323.38	57
-1326.37	48.3333
-1329.35	48.3333
-1332.34	44.6667
-1335.32	49.3333
-1338.31	50
-1341.3	49
-1344.29	46
-1347.29	49.3333
-1350.28	51
-1353.28	41.6667
-1356.27	38
-1359.27	48.6667
-1362.27	37.6667
-1365.27	40.3333
-1368.27	43
-1371.27	44
-1374.28	39.3333
-1377.28	45.6667
-1380.29	45
-1383.3	39.3333
-1386.31	41.3333
-1389.32	36
-1392.33	41.6667