File: projects/python/data/20231030/blood_600_785 nm_10 s_1_2023_10_30_15_38_25_01.txt
#Sample=blood
#Laser=785 nm
#Grating=600
#Exposition=10
#Accumulation=1
#Acquired=30.10.2023 15:38:25
1599.2	1191.33
1597.39	1174.33
1595.58	1195.33
1593.77	1187.67
1591.96	1194
1590.15	1212.67
1588.33	1214
1586.52	1231
1584.71	1216
1582.89	1224
1581.08	1220.33
1579.26	1233.33
1577.45	1229.67
1575.63	1247.33
1573.81	1264
1571.99	1262.33
1570.18	1280.33
1568.36	1267.33
1566.54	1271
1564.72	1293.33
1562.89	1294
1561.07	1304.33
1559.25	1275.67
1557.42	1298
1555.6	1295
1553.78	1271.67
1551.95	1294.33
1550.12	1296
1548.3	1294.33
1546.47	1277.67
1544.64	1279.33
1542.81	1275.33
1540.98	1275.33
1539.15	1246.67
1537.32	1279
1535.49	1265
1533.65	1232
1531.82	1242
1529.99	1246.33
1528.15	1250
1526.32	1236.67
1524.48	1252.33
1522.64	1226.67
1520.81	1238.67
1518.97	1237.67
1517.13	1232
1515.29	1232.67
1513.45	1236.67
1511.61	1244.33
1509.77	1233.67
1507.92	1240.67
1506.08	1251.33
1504.24	1234
1502.39	1257
1500.55	1265
1498.7	1271.33
1496.86	1253
1495.01	1273
1493.16	1278.67
1491.31	1295.67
1489.46	1306
1487.61	1304.67
1485.76	1320
1483.91	1304.67
1482.06	1303.33
1480.21	1326.67
1478.35	1316
1476.5	1336
1474.64	1334.67
1472.79	1353
1470.93	1367
1469.07	1369.67
1467.22	1406.67
1465.36	1402.33
1463.5	1403.67
1461.64	1427
1459.78	1451
1457.92	1434.67
1456.05	1455.33
1454.19	1441.33
1452.33	1460.67
1450.46	1487.33
1448.6	1483
1446.73	1487.33
1444.87	1486.33
1443	1486
1441.13	1500
1439.26	1504
1437.39	1488
1435.52	1515.33
1433.65	1512
1431.78	1506.33
1429.91	1511
1428.04	1519.67
1426.17	1502.33
1424.29	1506
1422.42	1522.67
1420.54	1523
1418.66	1526
1416.79	1535.67
1414.91	1533
1413.03	1541.67
1411.15	1547.33
1409.27	1536.67
1407.39	1560.33
1405.51	1564
1403.63	1563.67
1401.75	1555.67
1399.86	1572.67
1397.98	1559
1396.09	1576
1394.21	1566
1392.32	1556
1390.44	1572.33
1388.55	1571.67
1386.66	1533
1384.77	1564
1382.88	1570.33
1380.99	1521
1379.1	1523.33
1377.21	1548
1375.31	1507.67
1373.42	1522
1371.53	1493.67
1369.63	1505.67
1367.74	1481
1365.84	1494.67
1363.94	1486
1362.05	1480.33
1360.15	1462.67
1358.25	1466
1356.35	1464
1354.45	1452.33
1352.55	1420
1350.64	1431.67
1348.74	1409.67
1346.84	1412.33
1344.93	1400.33
1343.03	1373
1341.12	1350.67
1339.22	1346.67
1337.31	1319.33
1335.4	1318.33
1333.49	1294.67
1331.58	1273.33
1329.67	1259.67
1327.76	1268.67
1325.85	1262.33
1323.94	1237.67
1322.03	1203.67
1320.11	1204.67
1318.2	1192
1316.28	1173.33
1314.37	1160.33
1312.45	1159.67
1310.53	1135.33
1308.62	1137
1306.7	1109.33
1304.78	1109.67
1302.86	1092
1300.94	1082
1299.01	1067
1297.09	1069
1295.17	1065
1293.24	1073
1291.32	1044
1289.39	1066.67
1287.47	1054.67
1285.54	1007.33
1283.61	1020.33
1281.68	1030.67
1279.76	1003
1277.83	1027.67
1275.9	1002.33
1273.96	1013
1272.03	1021.67
1270.1	985.667
1268.17	999.333
1266.23	991.333
1264.3	981.667
1262.36	991.667
1260.42	1001
1258.49	987.333
1256.55	988
1254.61	957
1252.67	978.333
1250.73	970
1248.79	961
1246.85	946.333
1244.91	957
1242.96	958
1241.02	961
1239.07	966
1237.13	962.333
1235.18	968
1233.24	944.333
1231.29	952.667
1229.34	942.667
1227.39	943.333
1225.44	920.333
1223.49	920.333
1221.54	914
1219.59	889.667
1217.63	891.667
1215.68	874.333
1213.73	862.333
1211.77	850.667
1209.81	840.333
1207.86	855.333
1205.9	830.667
1203.94	818.667
1201.98	811
1200.02	813.667
1198.06	800
1196.1	802.333
1194.14	811
1192.18	793.667
1190.21	802.333
1188.25	785.667
1186.29	784.667
1184.32	778.333
1182.35	771
1180.39	776.333
1178.42	766.667
1176.45	768
1174.48	759.333
1172.51	754.333
1170.54	747.333
1168.57	756.333
1166.6	760
1164.62	767
1162.65	734.667
1160.67	737.667
1158.7	744.333
1156.72	752.333
1154.74	730
1152.77	738.667
1150.79	736.667
1148.81	747.667
1146.83	698.667
1144.85	714.667
1142.87	721.667
1140.88	729.333
1138.9	714.667
1136.92	727.667
1134.93	723.667
1132.95	715
1130.96	710.333
1128.97	720.333
1126.99	715.333
1125	713
1123.01	706.333
1121.02	691.667
1119.03	699
1117.04	692.333
1115.04	692
1113.05	689.667
1111.06	685
1109.06	671
1107.07	698.333
1105.07	677.667
1103.08	680.667
1101.08	690.667
1099.08	682
1097.08	670
1095.08	679.333
1093.08	658.667
1091.08	662.333
1089.08	668.333
1087.07	654.667
1085.07	658
1083.06	655.667
1081.06	650.667
1079.05	647.333
1077.05	655
1075.04	632.667
1073.03	646
1071.02	638.333
1069.01	649.333
1067	632
1064.99	636.333
1062.98	631.333
1060.96	623.333
1058.95	615.667
1056.93	624.333
1054.92	610.333
1052.9	600
1050.89	599.333
1048.87	604.667
1046.85	597
1044.83	609
1042.81	602
1040.79	597
1038.77	604.667
1036.75	608
1034.72	592
1032.7	618
1030.67	620.667
1028.65	590
1026.62	603.333
1024.59	607.333
1022.57	617.333
1020.54	638
1018.51	614.667
1016.48	633.333
1014.45	630.667
1012.42	628.333
1010.38	627
1008.35	647.667
1006.32	645
1004.28	645.667
1002.24	642.333
1000.21	639
998.171	638
996.133	630
994.094	646.333
992.054	643.333
990.013	633
987.972	648
985.93	654
983.888	650
981.843	644
979.799	637.333
977.754	629.333
975.708	642.667
973.661	634.667
971.614	648.667
969.565	638
967.516	644.333
965.466	643.667
963.415	659
961.364	644
959.312	639.333
957.258	643.333
955.204	657.333
953.15	648.333
951.094	653
949.038	666.667
946.98	650
944.923	662.333
942.864	669
940.804	655.333
938.744	654.333
936.683	648
934.621	656.667
932.558	658.667
930.495	641.333
928.43	656
926.365	630.667
924.299	640
922.233	649.667
920.165	653.667
918.096	655
916.028	633.667
913.957	638.333
911.887	631.667
909.815	632
907.743	631
905.669	629
903.595	618.667
901.521	635
899.445	615.333
897.369	619
895.292	636
893.214	626.667
891.135	621
889.055	619.333
886.975	607.667
884.894	616
882.812	621.333
880.729	625.333
878.646	608.667
876.561	620.333
874.475	621.667
872.389	627
870.303	624
868.215	635.333
866.126	615.333
864.037	616.333
861.947	629.333
859.856	613.333
857.764	632
855.671	624.667
853.578	622.333
851.484	625.667
849.389	623
847.293	630
845.196	624
843.099	616.667
841	635.667
838.901	613.667
836.801	631.333
834.701	619.667
832.599	618.667
830.496	627
828.393	620.333
826.29	622.333
824.184	600.333
822.079	626.333
819.972	607.667
817.865	611
815.757	617.333
813.648	598.667
811.538	609.667
809.428	605.333
807.316	604.333
805.204	620.333
803.091	603
800.977	614.333
798.863	599.667
796.747	605.667
794.631	601.667
792.513	602.333
790.395	608
788.276	588
786.157	602.333
784.036	607.667
781.915	591.333
779.793	605.667
777.669	609.333
775.546	614
773.421	620.667
771.296	617.333
769.169	630.333
767.042	632.333
764.915	644
762.786	624
760.656	627
758.526	638
756.394	636.333
754.262	632
752.129	636
749.995	638.667
747.861	630.667
745.725	637.333
743.588	641
741.452	627
739.314	620.667
737.175	615.667
735.035	628.667
732.895	622
730.753	617
728.611	618.667
726.469	607.667
724.324	610
722.18	614.333
720.034	612.333
717.888	613.333
715.741	615.667
713.593	602.667
711.444	588.667
709.294	603
707.144	597.667
704.992	596
702.84	603
700.687	608
698.533	608
696.378	595.667
694.222	579.667
692.066	599.333
689.909	589.333
687.751	599
685.592	576
683.432	593.333
681.271	591.333
679.109	583
676.947	592.333
674.784	599.667
672.62	594
670.455	588
668.289	582
666.122	582.333
663.955	588
661.787	598
659.618	606.333
657.448	601.333
655.277	592
653.104	599
650.932	595.333
648.759	594
646.584	614.333
644.409	610.667
642.233	619.667
640.056	618.667
637.879	594
635.7	621.333
633.52	636.333
631.34	620.333
629.159	637.667
626.977	629
624.794	618.333
622.61	627.667
620.426	622.333
618.24	618.333
616.054	602.667
613.867	603.333
611.679	596
609.49	590
607.301	598
605.11	602.667
602.919	589.333
600.726	590
598.532	600
596.339	586
594.144	587
591.948	591
589.751	590
587.554	591.667
585.355	609.667
583.156	603.667
580.956	629.667
578.755	620.667
576.553	624
574.35	632
572.147	632
569.943	624.667
567.737	635.667
565.531	647.667
563.323	630.333
561.116	636.667
558.907	639.333
556.698	625.333
554.487	636
552.275	622
550.063	640.667
547.85	615.333
545.636	629
543.421	635.667
541.206	629.333
538.988	622
536.771	616
534.553	611.667
532.333	619.333
530.113	610.333
527.892	615
525.67	616.333
523.447	622
521.224	622
518.999	629.667
516.774	625
514.548	617
512.321	622.333
510.093	627
507.863	633
505.634	606.667
503.403	617.333
501.172	628
498.939	610.667
496.705	605.667
494.472	618.333
492.237	605.333
490.001	613.667
487.764	623
485.526	621.667
483.287	616
481.047	623.667
478.807	620
476.565	616.333
474.324	612.333
472.08	606.333
469.837	630
467.591	621.667
465.346	617.667
463.099	632
460.852	632.667
458.604	638.667
456.354	655.667
454.103	663
451.852	638.333
449.601	658
447.348	684.333
445.094	667.667
442.84	671.333
440.584	694.667
438.327	688.667
436.07	697
433.812	708.333
431.553	700
429.293	724.333
427.032	723.667
424.77	736.667
422.507	747
420.244	750.333
417.979	741.333
415.714	748.667
413.448	755.333
411.18	739.667
408.912	737.667
406.643	754.333
404.373	754.333
402.102	756.333
399.83	755
397.558	762.667
395.285	756
393.01	746
390.734	756.333
388.458	756.333
386.181	769
383.903	774.333
381.624	780.667
379.345	787.333
377.064	777.333
374.782	781.333
372.5	804
370.216	782.667
367.932	774.667
365.646	782.333
363.36	797.667
361.073	797
358.785	802.333
356.496	800.333
354.207	812
351.915	821.333
349.624	831.333
347.331	835.667
345.038	817
342.743	817.667
340.448	831
338.152	816.333
335.855	814.333
333.556	800.667
331.257	830.333
328.958	819.667
326.657	819.667
324.355	836
322.053	820
319.749	822
317.444	841.333
315.139	835.667
312.833	823
310.526	836.333
308.217	837.333
305.908	856
303.599	861
301.288	871.667
298.976	865
296.663	875.667
294.349	869.667
292.035	906.333
289.719	914
287.403	910.667
285.085	915.333
282.767	929.667
280.448	936
278.128	961.333
275.807	955
273.485	967
271.161	974.333
268.837	969.667
266.513	1002.67
264.187	986.333
261.861	1011
259.533	1004.33
257.205	1035.67
254.875	1046.33
252.544	1068.67
250.213	1075
247.881	1057
245.548	1098.67
243.214	1121.33
240.879	1144.67
238.543	1116.33
236.206	1162.33
233.869	1199
231.53	1211
229.19	1223.33
226.849	1234
224.508	1267.33
222.165	1278.33
219.822	1293
217.478	1320.67
215.132	1334.33
212.785	1366.67
210.439	1363.33
208.091	1371
205.741	1370
203.391	1398.67
201.04	1430.33
198.688	1417.33
196.336	1449.33
193.982	1421.33
191.627	1491
189.271	1505.67
186.915	1507
184.557	1527.67
182.199	1555
179.84	1558.67
177.478	1618.33
175.117	1619.67
172.755	1619
170.392	1631.67
168.028	1667
165.662	1701.33
163.297	1717.33
160.929	1766.33
158.561	1814.67
156.193	1815.33
153.823	1812
151.452	1866
149.08	1892.67
146.707	1858.67
144.334	1879.33
141.959	1923.67
139.584	1960.33
137.207	2023
134.829	2038.33
132.451	2071.33
130.071	2118
127.692	2186.33
125.31	2268
122.927	2338.67
120.545	2389
118.16	2422
115.775	2468.67
113.388	2536.33
111.001	2623.67
108.613	2734
106.224	2852
103.834	2938
101.444	3060.33
99.052	3164.67
96.6594	3337.33
94.2649	3464
91.8705	3656
89.4743	3820.33
87.0781	3965
84.68	4186.33
82.282	4422
79.882	4699.67
77.4812	5095.67
75.0805	5544
72.6778	6210
70.2743	7262.67
67.8698	8762
65.4644	10140
63.0582	11224
60.651	12124
58.2419	12969
55.8328	13789.3
53.4229	14508.3
51.011	15291.7
48.5993	16143
46.1856	17159.3
43.772	18206
41.3565	19573.7
38.941	21200.7
36.5237	23319.7
34.1054	26277
31.6862	29553
29.2661	33652.3
26.8451	39190
24.4231	49943.3
22.0002	64524
19.5764	64524
17.1517	64524
14.7261	64524
12.2995	64524
9.87099	64524
7.44256	64524
5.01321	64524
2.58195	64524
0.14975	64524