File: projects/python/data/20231030/blood_600_785 nm_2 s_1_2023_10_30_15_34_55.txt
#Sample=blood
#Laser=785 nm
#Grating=600
#Exposition=2
#Accumulation=1
#Acquired=30.10.2023 15:34:55
2745.96	54
2743.18	65
2740.41	54
2737.63	49
2734.85	56
2732.07	44
2729.29	48
2726.5	68
2723.72	53
2720.93	46
2718.14	49
2715.34	51
2712.55	62
2709.75	72
2706.95	58
2704.15	59
2701.35	63
2698.55	43
2695.74	65
2692.93	53
2690.12	44
2687.31	59
2684.49	55
2681.67	57
2678.85	55
2676.03	67
2673.21	73
2670.38	58
2667.56	57
2664.73	56
2661.9	49
2659.06	58
2656.23	45
2653.39	54
2650.55	68
2647.71	61
2644.86	61
2642.02	61
2639.17	55
2636.32	61
2633.47	58
2630.62	54
2627.76	63
2624.9	50
2622.04	50
2619.18	57
2616.31	64
2613.45	64
2610.58	52
2607.71	57
2604.84	54
2601.96	53
2599.08	63
2596.21	51
2593.32	53
2590.44	63
2587.56	62
2584.67	56
2581.78	51
2578.89	49
2575.99	50
2573.1	52
2570.2	51
2567.3	45
2564.4	46
2561.5	44
2558.59	64
2555.68	58
2552.77	46
2549.86	70
2546.94	53
2544.03	53
2541.11	62
2538.19	69
2535.26	58
2532.34	65
2529.41	64
2526.48	64
2523.55	65
2520.62	61
2517.68	72
2514.74	63
2511.8	50
2508.86	59
2505.92	54
2502.97	67
2500.02	54
2497.07	63
2494.12	53
2491.16	56
2488.2	58
2485.25	62
2482.28	55
2479.32	63
2476.35	44
2473.39	44
2470.42	55
2467.44	67
2464.47	65
2461.49	58
2458.51	52
2455.53	69
2452.55	56
2449.56	42
2446.58	71
2443.59	63
2440.59	65
2437.6	73
2434.6	57
2431.61	61
2428.61	66
2425.6	58
2422.6	61
2419.59	51
2416.58	55
2413.57	65
2410.56	46
2407.54	55
2404.52	64
2401.5	63
2398.48	69
2395.45	61
2392.43	59
2389.4	64
2386.37	54
2383.33	62
2380.3	58
2377.26	63
2374.22	55
2371.17	58
2368.13	54
2365.08	56
2362.03	59
2358.98	71
2355.93	56
2352.87	65
2349.81	65
2346.75	60
2343.69	65
2340.63	64
2337.56	61
2334.49	61
2331.42	74
2328.35	61
2325.27	56
2322.19	65
2319.11	63
2316.03	53
2312.94	58
2309.85	65
2306.77	45
2303.67	76
2300.58	57
2297.48	63
2294.38	69
2291.28	53
2288.18	72
2285.07	82
2281.97	70
2278.86	68
2275.74	76
2272.63	69
2269.51	65
2266.39	64
2263.27	50
2260.15	64
2257.02	69
2253.89	71
2250.76	78
2247.63	61
2244.49	75
2241.36	54
2238.22	76
2235.08	70
2231.93	60
2228.78	66
2225.63	73
2222.48	64
2219.33	71
2216.17	71
2213.01	71
2209.85	76
2206.69	62
2203.53	67
2200.36	69
2197.19	64
2194.02	59
2190.84	65
2187.66	77
2184.48	69
2181.3	82
2178.12	68
2174.93	60
2171.74	76
2168.55	61
2165.36	73
2162.16	78
2158.97	66
2155.76	79
2152.56	80
2149.36	65
2146.15	82
2142.94	71
2139.73	79
2136.51	73
2133.29	76
2130.08	81
2126.85	66
2123.63	88
2120.4	80
2117.17	77
2113.94	74
2110.71	63
2107.47	77
2104.23	69
2100.99	74
2097.75	85
2094.5	89
2091.26	82
2088.01	79
2084.75	74
2081.5	82
2078.24	87
2074.98	85
2071.72	75
2068.45	90
2065.18	95
2061.92	79
2058.64	82
2055.37	79
2052.09	88
2048.81	93
2045.53	91
2042.25	86
2038.96	79
2035.67	88
2032.38	79
2029.08	93
2025.79	96
2022.49	84
2019.19	100
2015.88	86
2012.58	91
2009.27	92
2005.96	108
2002.64	91
1999.33	113
1996.01	89
1992.69	86
1989.36	96
1986.04	96
1982.71	100
1979.38	103
1976.05	99
1972.71	124
1969.37	94
1966.03	106
1962.69	131
1959.34	117
1955.99	122
1952.64	104
1949.29	115
1945.93	109
1942.58	114
1939.21	115
1935.85	124
1932.49	126
1929.12	120
1925.75	109
1922.37	141
1919	125
1915.62	125
1912.24	125
1908.86	126
1905.47	127
1902.08	139
1898.69	140
1895.3	141
1891.9	129
1888.5	123
1885.1	127
1881.7	128
1878.29	143
1874.88	146
1871.47	139
1868.06	142
1864.64	128
1861.22	137
1857.8	128
1854.38	143
1850.95	133
1847.52	147
1844.09	145
1840.66	124
1837.22	144
1833.78	135
1830.34	130
1826.9	146
1823.45	142
1820	142
1816.55	146
1813.09	147
1809.64	138
1806.18	133
1802.71	148
1799.25	145
1795.78	131
1792.31	137
1788.84	142
1785.36	150
1781.88	150
1778.4	123
1774.92	136
1771.43	147
1767.95	150
1764.45	141
1760.96	139
1757.47	146
1753.97	142
1750.47	154
1746.96	153
1743.45	148
1739.94	164
1736.43	169
1732.92	156
1729.4	167
1725.88	159
1722.36	167
1718.83	154
1715.3	161
1711.77	159
1708.24	173
1704.71	171
1701.17	181
1697.63	170
1694.08	169
1690.54	201
1686.99	181
1683.44	192
1679.88	176
1676.32	163
1672.76	201
1669.2	207
1665.64	222
1662.07	214
1658.5	196
1654.92	204
1651.35	219
1647.77	218
1644.19	215
1640.61	225
1637.02	238
1633.43	224
1629.84	219
1626.24	218
1622.64	226
1619.04	227
1615.44	218
1611.84	200
1608.23	223
1604.62	225
1601	241
1597.39	234
1593.77	201
1590.15	211
1586.52	221
1582.89	227
1579.26	243
1575.63	242
1571.99	249
1568.36	230
1564.72	239
1561.07	230
1557.42	228
1553.78	235
1550.12	242
1546.47	236
1542.81	250
1539.15	240
1535.49	224
1531.82	230
1528.15	208
1524.48	207
1520.81	225
1517.13	225
1513.45	224
1509.77	226
1506.08	211
1502.39	210
1498.7	220
1495.01	223
1491.31	234
1487.61	229
1483.91	237
1480.21	223
1476.5	246
1472.79	244
1469.07	236
1465.36	260
1461.64	257
1457.92	258
1454.19	256
1450.46	260
1446.73	260
1443	279
1439.26	271
1435.52	269
1431.78	243
1428.04	275
1424.29	270
1420.54	262
1416.79	246
1413.03	260
1409.27	248
1405.51	265
1401.75	266
1397.98	273
1394.21	259
1390.44	273
1386.66	251
1382.88	258
1379.1	257
1375.31	274
1371.53	260
1367.74	261
1363.94	262
1360.15	251
1356.35	259
1352.55	257
1348.74	252
1344.93	232
1341.12	255
1337.31	221
1333.49	233
1329.67	230
1325.85	226
1322.03	231
1318.2	218
1314.37	225
1310.53	214
1306.7	215
1302.86	202
1299.01	213
1295.17	212
1291.32	213
1287.47	190
1283.61	200
1279.76	204
1275.9	203
1272.03	194
1268.17	199
1264.3	179
1260.42	199
1256.55	210
1252.67	185
1248.79	177
1244.91	193
1241.02	187
1237.13	202
1233.24	188
1229.34	195
1225.44	189
1221.54	185
1217.63	183
1213.73	179
1209.81	179
1205.9	175
1201.98	159
1198.06	156
1194.14	153
1190.21	169
1186.29	150
1182.35	155
1178.42	156
1174.48	165
1170.54	153
1166.6	166
1162.65	154
1158.7	171
1154.74	162
1150.79	147
1146.83	149
1142.87	152
1138.9	155
1134.93	153
1130.96	156
1126.99	142
1123.01	162
1119.03	160
1115.04	144
1111.06	155
1107.07	138
1103.08	154
1099.08	166
1095.08	146
1091.08	153
1087.07	147
1083.06	150
1079.05	130
1075.04	143
1071.02	146
1067	140
1062.98	149
1058.95	158
1054.92	142
1050.89	136
1046.85	140
1042.81	144
1038.77	145
1034.72	139
1030.67	128
1026.62	138
1022.57	133
1018.51	134
1014.45	150
1010.38	141
1006.32	148
1002.24	131
998.171	145
994.094	160
990.013	131
985.93	144
981.843	148
977.754	130
973.661	142
969.565	128
965.466	146
961.364	149
957.258	150
953.15	142
949.038	137
944.923	163
940.804	136
936.683	163
932.558	174
928.43	154
924.299	148
920.165	144
916.028	158
911.887	137
907.743	152
903.595	140
899.445	144
895.292	137
891.135	140
886.975	117
882.812	134
878.646	144
874.475	128
870.303	151
866.126	138
861.947	156
857.764	132
853.578	145
849.389	142
845.196	134
841	153
836.801	134
832.599	147
828.393	130
824.184	128
819.972	137
815.757	136
811.538	130
807.316	137
803.091	133
798.863	124
794.631	137
790.395	123
786.157	128
781.915	137
777.669	141
773.421	142
769.169	136
764.915	135
760.656	147
756.394	134
752.129	146
747.861	140
743.588	132
739.314	141
735.035	135
730.753	146
726.469	142
722.18	138
717.888	138
713.593	128
709.294	121
704.992	126
700.687	128
696.378	130
692.066	132
687.751	132
683.432	146
679.109	134
674.784	145
670.455	138
666.122	125
661.787	130
657.448	149
653.104	131
648.759	126
644.409	139
640.056	131
635.7	146
631.34	135
626.977	141
622.61	144
618.24	142
613.867	127
609.49	128
605.11	128
600.726	127
596.339	130
591.948	140
587.554	132
583.156	130
578.755	149
574.35	136
569.943	147
565.531	143
561.116	151
556.698	150
552.275	140
547.85	154
543.421	140
538.988	140
534.553	156
530.113	146
525.67	138
521.224	153
516.774	142
512.321	140
507.863	138
503.403	160
498.939	154
494.472	140
490.001	159
485.526	128
481.047	137
476.565	144
472.08	153
467.591	150
463.099	159
458.604	141
454.103	143
449.601	145
445.094	150
440.584	156
436.07	146
431.553	158
427.032	174
422.507	157
417.979	164
413.448	158
408.912	155
404.373	150
399.83	166
395.285	158
390.734	163
386.181	170
381.624	165
377.064	163
372.5	169
367.932	171
363.36	171
358.785	176
354.207	193
349.624	170
345.038	179
340.448	167
335.855	183
331.257	188
326.657	182
322.053	179
317.444	178
312.833	172
308.217	178
303.599	186
298.976	192
294.349	197
289.719	201
285.085	200
280.448	219
275.807	212
271.161	211
266.513	226
261.861	228
257.205	225
252.544	250
247.881	253
243.214	255
238.543	254
233.869	253
229.19	259
224.508	285
219.822	280
215.132	286
210.439	306
205.741	297
201.04	308
196.336	336
191.627	335
186.915	319
182.199	336
177.478	366
172.755	385
168.028	379
163.297	397
158.561	416
153.823	422
149.08	424
144.334	437
139.584	446
134.829	476
130.071	500
125.31	524
120.545	555
115.775	573
111.001	625
106.224	679
101.444	745
96.6594	786
91.8705	858
87.0781	942
82.282	1027
77.4812	1136
72.6778	1397
67.8698	1878
63.0582	2303
58.2419	2647
53.4229	2949
48.5993	3261
43.772	3649
38.941	4221
34.1054	5200
29.2661	6600
24.4231	9961
19.5764	62430
14.7261	64524
9.87099	64524
5.01321	64524
0.14975	64524
-4.71644	64524
-9.58634	64524
-14.461	64524
-19.3393	64524
-24.2214	64524
-29.1072	45066
-33.9977	8047
-38.892	4277
-43.7901	2887
-48.6919	2174
-53.5974	1663
-58.5078	1250
-63.4218	978
-68.3397	772
-73.2613	597
-78.1878	461
-83.117	384
-88.051	322
-92.9888	271
-97.9314	236
-102.877	179
-107.827	155
-112.781	129
-117.739	114
-122.701	97
-127.667	91
-132.637	86
-137.612	79
-142.59	72
-147.572	40
-152.558	65
-157.548	65
-162.542	58
-167.541	53
-172.544	56
-177.55	51
-182.561	39
-187.576	39
-192.595	40
-197.617	43
-202.645	54
-207.676	32
-212.711	41
-217.75	48
-222.794	53
-227.842	41
-232.893	46
-237.949	42
-243.009	44
-248.073	50
-253.142	47
-258.214	38
-263.291	38
-268.371	49
-273.456	50
-278.545	48
-283.639	45
-288.735	49
-293.837	30
-298.943	43
-304.053	51
-309.166	40
-314.285	41
-319.408	12
-324.534	46
-329.665	42
-334.801	25
-339.94	44
-345.083	26
-350.231	43
-355.383	45
-360.539	44
-365.699	33
-370.864	46
-376.033	32
-381.206	46
-386.384	44
-391.565	46
-396.751	44
-401.941	35
-407.136	34
-412.334	42
-417.537	38
-422.745	18
-427.956	38
-433.173	27
-438.392	30
-443.617	35
-448.846	37
-454.078	46
-459.317	40
-464.558	38
-469.804	33
-475.055	30
-480.309	34
-485.568	43
-490.832	40
-496.099	27
-501.372	50
-506.648	38
-511.929	30
-517.215	43
-522.504	44
-527.797	34
-533.097	37
-538.399	40
-543.706	44
-549.018	37
-554.334	36
-559.654	33
-564.979	30
-570.308	44
-575.641	39
-580.98	27
-586.322	39
-591.669	42
-597.02	36
-602.376	26
-607.736	30
-613.1	29
-618.47	37
-623.843	50
-629.222	29
-634.603	37
-639.99	34
-645.382	24
-650.779	42
-656.179	40
-661.583	30
-666.993	32
-672.407	32
-677.825	41
-683.248	31
-688.675	28
-694.108	42
-699.544	49
-704.985	35
-710.431	33
-715.88	43
-721.335	25
-726.795	40
-732.258	41
-737.727	35
-743.2	32
-748.678	36
-754.159	32
-759.646	44
-765.138	33
-770.633	31
-776.133	38
-781.638	34
-787.149	34
-792.663	48
-798.181	35
-803.705	31
-809.233	32
-814.766	43
-820.304	26
-825.846	27
-831.392	27
-836.944	42
-842.499	34
-848.06	37
-853.626	30
-859.195	34
-864.77	28
-870.35	33
-875.934	39
-881.522	24
-887.116	29
-892.714	39
-898.317	34
-903.924	31
-909.537	21
-915.153	34
-920.776	25
-926.401	29
-932.033	32
-937.669	36
-943.31	45
-948.955	27
-954.605	44
-960.26	36
-965.92	41
-971.584	26
-977.254	32
-982.928	32
-988.607	33
-994.291	39
-999.979	25
-1005.67	36
-1011.37	32
-1017.07	44
-1022.78	30
-1028.49	34
-1034.21	38
-1039.93	48
-1045.66	38
-1051.39	40
-1057.13	46
-1062.87	45
-1068.62	32
-1074.37	23
-1080.12	32
-1085.89	29
-1091.65	42
-1097.42	30
-1103.2	36
-1108.98	29
-1114.77	27
-1120.56	35
-1126.35	37
-1132.15	37
-1137.96	43
-1143.77	33
-1149.58	46
-1155.4	38
-1161.23	38
-1167.06	30
-1172.89	44
-1178.73	30
-1184.58	54
-1190.43	67
-1196.28	48
-1202.14	69
-1208.01	77
-1213.88	65
-1219.75	65
-1225.63	90
-1231.52	101
-1237.41	111
-1243.3	141
-1249.2	231
-1255.11	212
-1261.02	218
-1266.93	176
-1272.85	132
-1278.78	67
-1284.71	61
-1290.65	43
-1296.59	40
-1302.53	38
-1308.48	36
-1314.44	36
-1320.4	35
-1326.37	34
-1332.34	55
-1338.31	38
-1344.29	37
-1350.28	44
-1356.27	39
-1362.27	44
-1368.27	42
-1374.28	43
-1380.29	38
-1386.31	35
-1392.33	35
-971.584	26
-977.254	32
-982.928	32
-988.607	33
-994.291	39
-999.979	25
-1005.67	36
-1011.37	32
-1017.07	44
-1022.78	30
-1028.49	34
-1034.21	38
-1039.93	48
-1045.66	38
-1051.39	40
-1057.13	46
-1062.87	45
-1068.62	32
-1074.37	23
-1080.12	32
-1085.89	29
-1091.65	42
-1097.42	30
-1103.2	36
-1108.98	29
-1114.77	27
-1120.56	35
-1126.35	37
-1132.15	37
-1137.96	43
-1143.77	33
-1149.58	46
-1155.4	38
-1161.23	38
-1167.06	30
-1172.89	44
-1178.73	30
-1184.58	54
-1190.43	67
-1196.28	48
-1202.14	69
-1208.01	77
-1213.88	65
-1219.75	65
-1225.63	90
-1231.52	101
-1237.41	111
-1243.3	141
-1249.2	231
-1255.11	212
-1261.02	218
-1266.93	176
-1272.85	132
-1278.78	67
-1284.71	61
-1290.65	43
-1296.59	40
-1302.53	38
-1308.48	36
-1314.44	36
-1320.4	35
-1326.37	34
-1332.34	55
-1338.31	38
-1344.29	37
-1350.28	44
-1356.27	39
-1362.27	44
-1368.27	42
-1374.28	43
-1380.29	38
-1386.31	35
-1392.33	35