File: projects/python/data/20231030/bloodtip_600_785 nm_10 s_1_2023_10_30_15_53_50_01.txt
#Sample=bloodtip
#Laser=785 nm
#Grating=600
#Exposition=10
#Accumulation=1
#Acquired=30.10.2023 15:53:50
1599.2	316.333
1597.39	327.333
1595.58	326
1593.77	340.333
1591.96	326.667
1590.15	332
1588.33	344
1586.52	337.333
1584.71	335
1582.89	343.667
1581.08	338.333
1579.26	335.333
1577.45	349.667
1575.63	343
1573.81	355
1571.99	357.667
1570.18	352.667
1568.36	347.667
1566.54	371.333
1564.72	361.667
1562.89	359
1561.07	370
1559.25	359.333
1557.42	357.333
1555.6	358.333
1553.78	370.667
1551.95	362
1550.12	356.667
1548.3	355
1546.47	357.333
1544.64	365
1542.81	350.333
1540.98	365
1539.15	359
1537.32	344.667
1535.49	356.667
1533.65	359
1531.82	363.333
1529.99	351.667
1528.15	344
1526.32	356.333
1524.48	340.333
1522.64	342
1520.81	338.667
1518.97	349.667
1517.13	348.333
1515.29	336.333
1513.45	350
1511.61	347.333
1509.77	337.667
1507.92	341.667
1506.08	343.333
1504.24	337.667
1502.39	343.333
1500.55	343.667
1498.7	344.667
1496.86	339
1495.01	343
1493.16	337.333
1491.31	347.333
1489.46	356.333
1487.61	336.333
1485.76	347
1483.91	344
1482.06	350.667
1480.21	356.333
1478.35	340
1476.5	339
1474.64	373.667
1472.79	341
1470.93	353
1469.07	350.667
1467.22	350.333
1465.36	364
1463.5	356.667
1461.64	355.667
1459.78	359
1457.92	358.333
1456.05	361.667
1454.19	367.333
1452.33	363.333
1450.46	372.333
1448.6	366
1446.73	361.667
1444.87	363.667
1443	361
1441.13	368.333
1439.26	359.333
1437.39	368
1435.52	364.333
1433.65	352
1431.78	351.667
1429.91	371.333
1428.04	355
1426.17	358.667
1424.29	349
1422.42	360
1420.54	350.667
1418.66	351
1416.79	346.333
1414.91	352
1413.03	358.333
1411.15	357.667
1409.27	344.667
1407.39	349.333
1405.51	345
1403.63	355.333
1401.75	357
1399.86	354.667
1397.98	360.333
1396.09	352.333
1394.21	348
1392.32	358.667
1390.44	343
1388.55	355.667
1386.66	346.333
1384.77	355.667
1382.88	361
1380.99	359.667
1379.1	344.667
1377.21	358
1375.31	347
1373.42	347.333
1371.53	351.333
1369.63	334.667
1367.74	346
1365.84	355
1363.94	366
1362.05	352.667
1360.15	355
1358.25	355.667
1356.35	343.667
1354.45	359.333
1352.55	357.333
1350.64	358.333
1348.74	354.667
1346.84	367.667
1344.93	361
1343.03	354
1341.12	370
1339.22	352
1337.31	351
1335.4	355.667
1333.49	368.667
1331.58	357.333
1329.67	358.667
1327.76	371
1325.85	365.333
1323.94	375
1322.03	376
1320.11	366.667
1318.2	375.333
1316.28	377
1314.37	383
1312.45	378.333
1310.53	385
1308.62	372
1306.7	372.667
1304.78	373
1302.86	377.333
1300.94	387.333
1299.01	387
1297.09	383.667
1295.17	380.333
1293.24	383.667
1291.32	376.667
1289.39	389.667
1287.47	382.333
1285.54	395.667
1283.61	388
1281.68	391
1279.76	397.667
1277.83	386.667
1275.9	390.333
1273.96	390.333
1272.03	396.333
1270.1	394.333
1268.17	387.333
1266.23	390.333
1264.3	401.667
1262.36	408
1260.42	396
1258.49	392
1256.55	391.333
1254.61	398.333
1252.67	391
1250.73	401.333
1248.79	377.667
1246.85	391.333
1244.91	394
1242.96	377.667
1241.02	384.333
1239.07	390
1237.13	386
1235.18	384
1233.24	386
1231.29	366
1229.34	381.667
1227.39	368
1225.44	368.333
1223.49	360.667
1221.54	357.333
1219.59	349.333
1217.63	350.333
1215.68	350.333
1213.73	337.333
1211.77	333
1209.81	335.667
1207.86	338.667
1205.9	336.667
1203.94	323
1201.98	322.667
1200.02	326.667
1198.06	323.667
1196.1	313.333
1194.14	318.333
1192.18	303
1190.21	316
1188.25	320
1186.29	312.333
1184.32	318.667
1182.35	319
1180.39	327.667
1178.42	315.333
1176.45	314.333
1174.48	319
1172.51	329
1170.54	304
1168.57	318
1166.6	324.667
1164.62	317.333
1162.65	309.667
1160.67	315.333
1158.7	309.333
1156.72	319.333
1154.74	316
1152.77	304.667
1150.79	311.667
1148.81	317.333
1146.83	318
1144.85	311.667
1142.87	308
1140.88	322
1138.9	307
1136.92	321.333
1134.93	318
1132.95	316.667
1130.96	320.667
1128.97	320.333
1126.99	337
1125	321
1123.01	313.667
1121.02	313.333
1119.03	319.667
1117.04	304
1115.04	314.667
1113.05	317
1111.06	306
1109.06	320.667
1107.07	317
1105.07	314
1103.08	310
1101.08	313.333
1099.08	308
1097.08	294.667
1095.08	306.667
1093.08	305.333
1091.08	310.667
1089.08	311.667
1087.07	306.667
1085.07	309
1083.06	299
1081.06	311.667
1079.05	303.333
1077.05	302.333
1075.04	308
1073.03	304.333
1071.02	301.333
1069.01	306
1067	305.333
1064.99	292.667
1062.98	291.333
1060.96	308.667
1058.95	306
1056.93	290.333
1054.92	294.667
1052.9	287.333
1050.89	286.667
1048.87	296
1046.85	280
1044.83	295
1042.81	290
1040.79	287
1038.77	283.333
1036.75	287
1034.72	287.667
1032.7	292.667
1030.67	286.333
1028.65	286.333
1026.62	287.667
1024.59	292.667
1022.57	289.667
1020.54	294
1018.51	297.333
1016.48	291.333
1014.45	282
1012.42	297
1010.38	296
1008.35	306
1006.32	283
1004.28	286.667
1002.24	296
1000.21	287.667
998.171	303.333
996.133	287.667
994.094	295.667
992.054	290.333
990.013	305.333
987.972	286.667
985.93	298.667
983.888	300.667
981.843	305.667
979.799	302.333
977.754	296
975.708	300.333
973.661	294
971.614	313
969.565	298
967.516	291.667
965.466	303.333
963.415	300.667
961.364	296
959.312	298
957.258	291.333
955.204	306.667
953.15	297.333
951.094	304.333
949.038	294
946.98	305.667
944.923	310.333
942.864	310.333
940.804	301
938.744	303.333
936.683	296.333
934.621	299.667
932.558	294.667
930.495	305.333
928.43	295.667
926.365	301.667
924.299	303.667
922.233	299.667
920.165	307.667
918.096	296
916.028	292.333
913.957	295.333
911.887	306.667
909.815	288.667
907.743	291.333
905.669	301
903.595	288.667
901.521	294.333
899.445	303.333
897.369	290.333
895.292	293.333
893.214	297.667
891.135	294.667
889.055	294.667
886.975	288.667
884.894	287
882.812	290.667
880.729	296.333
878.646	287
876.561	292.667
874.475	295.333
872.389	297
870.303	281.333
868.215	297.667
866.126	285.333
864.037	293
861.947	290.667
859.856	295.667
857.764	286.667
855.671	288.333
853.578	297.667
851.484	295
849.389	291
847.293	285
845.196	292.333
843.099	296.667
841	302.333
838.901	299
836.801	295.333
834.701	287.667
832.599	298.667
830.496	290.667
828.393	297
826.29	293.333
824.184	274.667
822.079	286.333
819.972	297
817.865	297
815.757	284.333
813.648	293
811.538	282.333
809.428	287
807.316	278
805.204	286.333
803.091	286
800.977	286
798.863	286
796.747	277
794.631	280.667
792.513	272.667
790.395	280
788.276	286.667
786.157	280.333
784.036	288
781.915	288
779.793	284.667
777.669	292
775.546	284
773.421	295.667
771.296	295
769.169	290
767.042	301.333
764.915	287.333
762.786	289.333
760.656	288.333
758.526	294
756.394	283.667
754.262	290.667
752.129	291
749.995	284.333
747.861	296.667
745.725	296.667
743.588	289
741.452	296.667
739.314	297
737.175	293.333
735.035	290.667
732.895	279.667
730.753	289.333
728.611	280
726.469	290.333
724.324	283
722.18	272.667
720.034	281.667
717.888	275
715.741	278
713.593	285.667
711.444	280
709.294	272.333
707.144	272.333
704.992	278.333
702.84	262
700.687	282.667
698.533	271.667
696.378	282
694.222	283.333
692.066	274.333
689.909	271.667
687.751	272
685.592	260.667
683.432	278.667
681.271	280
679.109	262
676.947	255.667
674.784	276.667
672.62	270
670.455	275.333
668.289	264
666.122	277.333
663.955	281.667
661.787	279.667
659.618	262.667
657.448	274.333
655.277	277
653.104	272.333
650.932	270
648.759	265.333
646.584	269.333
644.409	284.667
642.233	284.333
640.056	278
637.879	283
635.7	289
633.52	290.667
631.34	286
629.159	291.667
626.977	290
624.794	276
622.61	271
620.426	291.333
618.24	272.667
616.054	279
613.867	268.333
611.679	266.667
609.49	265.333
607.301	261.333
605.11	260.333
602.919	273
600.726	267
598.532	266.333
596.339	275.333
594.144	257.667
591.948	263.333
589.751	279.667
587.554	271.333
585.355	267.333
583.156	289
580.956	271.333
578.755	292.667
576.553	289.333
574.35	290
572.147	273.333
569.943	294.667
567.737	285.333
565.531	288.333
563.323	283.333
561.116	296.333
558.907	283
556.698	277.667
554.487	293
552.275	277.667
550.063	281.333
547.85	279
545.636	287.333
543.421	285
541.206	285
538.988	279.667
536.771	275.333
534.553	272.667
532.333	283.333
530.113	286.667
527.892	283
525.67	276.667
523.447	277.333
521.224	274
518.999	284
516.774	281
514.548	271.333
512.321	280.333
510.093	291.333
507.863	277
505.634	284.667
503.403	282
501.172	275
498.939	280.667
496.705	280.333
494.472	273.667
492.237	272.667
490.001	291
487.764	276.333
485.526	279
483.287	284.333
481.047	282
478.807	285.667
476.565	271.333
474.324	278.667
472.08	287.667
469.837	276.667
467.591	277
465.346	286
463.099	298.333
460.852	301
458.604	287
456.354	293
454.103	300.667
451.852	308.667
449.601	297.333
447.348	307
445.094	310
442.84	300
440.584	303.333
438.327	321.333
436.07	319.667
433.812	315.333
431.553	335.667
429.293	312
427.032	343
424.77	334
422.507	336.667
420.244	326.667
417.979	345
415.714	337.667
413.448	337.667
411.18	337.333
408.912	340.333
406.643	342
404.373	354.333
402.102	363
399.83	337
397.558	363
395.285	343.333
393.01	350.667
390.734	354.333
388.458	349.333
386.181	354.333
383.903	363.333
381.624	355
379.345	359
377.064	369
374.782	372.333
372.5	356.667
370.216	370.333
367.932	373.667
365.646	367
363.36	369
361.073	372.333
358.785	371.333
356.496	375
354.207	387
351.915	383.333
349.624	383.667
347.331	389.333
345.038	383
342.743	375
340.448	391.333
338.152	394.667
335.855	381
333.556	396.333
331.257	399
328.958	394
326.657	400.333
324.355	402
322.053	401
319.749	394.667
317.444	396
315.139	399.667
312.833	411.333
310.526	406
308.217	415
305.908	412
303.599	415.333
301.288	422.667
298.976	421.333
296.663	420.333
294.349	435
292.035	442
289.719	456
287.403	449
285.085	462.667
282.767	462.333
280.448	468.333
278.128	475.667
275.807	472
273.485	477
271.161	481.667
268.837	491.667
266.513	503.333
264.187	510.667
261.861	510.667
259.533	516.667
257.205	521.333
254.875	526.667
252.544	533.333
250.213	536.333
247.881	562
245.548	569
243.214	579
240.879	578
238.543	593.667
236.206	610.667
233.869	608.667
231.53	622.333
229.19	638.667
226.849	646.333
224.508	663.667
222.165	666.667
219.822	668.667
217.478	671.667
215.132	692.333
212.785	697.667
210.439	703.667
208.091	712
205.741	766.667
203.391	758.667
201.04	758
198.688	758.333
196.336	780
193.982	805
191.627	790.667
189.271	819.333
186.915	840
184.557	841
182.199	842
179.84	842
177.478	848
175.117	888.333
172.755	885.333
170.392	902.667
168.028	923
165.662	942.667
163.297	953.667
160.929	961
158.561	948
156.193	969.667
153.823	1009.67
151.452	1029
149.08	1024.67
146.707	1031
144.334	1046.67
141.959	1075
139.584	1103.67
137.207	1119.33
134.829	1113.67
132.451	1109
130.071	1129.33
127.692	1174
125.31	1218.33
122.927	1247
120.545	1288.67
118.16	1326.67
115.775	1356
113.388	1364.67
111.001	1408.33
108.613	1455.33
106.224	1544
103.834	1606.67
101.444	1672.67
99.052	1754.33
96.6594	1807.67
94.2649	1911.33
91.8705	2019.67
89.4743	2130.33
87.0781	2292
84.68	2411.33
82.282	2597.33
79.882	2874
77.4812	3187.33
75.0805	3527
72.6778	4104
70.2743	5072.33
67.8698	6359.33
65.4644	7541
63.0582	8521.67
60.651	9310
58.2419	10063
55.8328	10770
53.4229	11472.7
51.011	12208.3
48.5993	12934.7
46.1856	13845
43.772	14884.3
41.3565	16217.3
38.941	17760.7
36.5237	19606.7
34.1054	22262.7
31.6862	25349.7
29.2661	29043
26.8451	33796
24.4231	43244
22.0002	64524
19.5764	64524
17.1517	64524
14.7261	64524
12.2995	64524
9.87099	64524
7.44256	64524
5.01321	64524
2.58195	64524
0.14975	64524