File: projects/python/data/20231030/noise_600_785 nm_10 s_1_2023_10_30_15_43_42_01.txt
#Sample=noise
#Laser=785 nm
#Grating=600
#Exposition=10
#Accumulation=1
#Acquired=30.10.2023 15:43:42
2745.96	53.3333
2743.18	45.3333
2740.41	46.3333
2737.63	37.6667
2734.85	47.3333
2732.07	47.6667
2729.29	49.6667
2726.5	53
2723.72	45.6667
2720.93	51.6667
2718.14	49
2715.34	47.3333
2712.55	43.3333
2709.75	53.3333
2706.95	48
2704.15	48
2701.35	43.3333
2698.55	49.6667
2695.74	47.3333
2692.93	45
2690.12	48.6667
2687.31	42.3333
2684.49	51.6667
2681.67	46.3333
2678.85	48
2676.03	47
2673.21	52.6667
2670.38	48
2667.56	46.6667
2664.73	43
2661.9	46
2659.06	48.6667
2656.23	49.3333
2653.39	52.3333
2650.55	42.3333
2647.71	46.3333
2644.86	41.3333
2642.02	45.3333
2639.17	50.6667
2636.32	45
2633.47	44
2630.62	39
2627.76	45
2624.9	44.3333
2622.04	38
2619.18	44.3333
2616.31	41
2613.45	40
2610.58	48.3333
2607.71	40
2604.84	45.6667
2601.96	47.6667
2599.08	48
2596.21	33.3333
2593.32	39
2590.44	39
2587.56	41
2584.67	41
2581.78	47.6667
2578.89	42.3333
2575.99	39
2573.1	39.6667
2570.2	43.3333
2567.3	40.3333
2564.4	44.6667
2561.5	47.6667
2558.59	39.6667
2555.68	40
2552.77	36
2549.86	34.6667
2546.94	46.6667
2544.03	42.3333
2541.11	49.6667
2538.19	38
2535.26	44
2532.34	48.3333
2529.41	35.3333
2526.48	39.6667
2523.55	40.3333
2520.62	49.3333
2517.68	39.3333
2514.74	42.6667
2511.8	42.6667
2508.86	46.6667
2505.92	41.6667
2502.97	36.6667
2500.02	24.3333
2497.07	41.6667
2494.12	30.6667
2491.16	40
2488.2	45
2485.25	45.6667
2482.28	36
2479.32	36.3333
2476.35	42.3333
2473.39	38
2470.42	40.3333
2467.44	46.6667
2464.47	37.3333
2461.49	45.6667
2458.51	42
2455.53	46
2452.55	41.6667
2449.56	42.3333
2446.58	38.6667
2443.59	38
2440.59	38.3333
2437.6	41.3333
2434.6	39.6667
2431.61	37.3333
2428.61	41.3333
2425.6	37
2422.6	31.3333
2419.59	39
2416.58	43.3333
2413.57	43.3333
2410.56	37.3333
2407.54	40.6667
2404.52	38
2401.5	42.3333
2398.48	35.3333
2395.45	34
2392.43	36.6667
2389.4	34
2386.37	36.6667
2383.33	37
2380.3	40.6667
2377.26	33.6667
2374.22	41.3333
2371.17	34.6667
2368.13	35.6667
2365.08	29.6667
2362.03	32.6667
2358.98	41.3333
2355.93	34
2352.87	35
2349.81	39.6667
2346.75	37.3333
2343.69	25.6667
2340.63	39.3333
2337.56	43.3333
2334.49	39
2331.42	33.3333
2328.35	36.6667
2325.27	37.6667
2322.19	34.6667
2319.11	30.6667
2316.03	35.6667
2312.94	38.6667
2309.85	38.3333
2306.77	30.3333
2303.67	32
2300.58	31.3333
2297.48	29.6667
2294.38	46.6667
2291.28	33
2288.18	33.6667
2285.07	32.3333
2281.97	34.3333
2278.86	40
2275.74	33.3333
2272.63	41.6667
2269.51	40
2266.39	32.6667
2263.27	34.6667
2260.15	32
2257.02	38.6667
2253.89	30.6667
2250.76	36.6667
2247.63	38
2244.49	28
2241.36	33
2238.22	38
2235.08	40
2231.93	29.6667
2228.78	33.3333
2225.63	35.3333
2222.48	33.6667
2219.33	43.3333
2216.17	30.3333
2213.01	34
2209.85	43.6667
2206.69	33.6667
2203.53	38
2200.36	37.3333
2197.19	40.6667
2194.02	32.3333
2190.84	30.6667
2187.66	34.6667
2184.48	38.6667
2181.3	36.6667
2178.12	38
2174.93	40
2171.74	35
2168.55	34
2165.36	36.6667
2162.16	35.3333
2158.97	33.3333
2155.76	33.3333
2152.56	38.6667
2149.36	30.6667
2146.15	37
2142.94	36.3333
2139.73	37.6667
2136.51	36
2133.29	38
2130.08	35.6667
2126.85	36.3333
2123.63	33.6667
2120.4	36
2117.17	34.6667
2113.94	32.3333
2110.71	41.3333
2107.47	40.6667
2104.23	36.6667
2100.99	31.6667
2097.75	38.6667
2094.5	34.6667
2091.26	35.6667
2088.01	39.3333
2084.75	30.6667
2081.5	38
2078.24	36.6667
2074.98	35.6667
2071.72	33
2068.45	29.6667
2065.18	41
2061.92	32.3333
2058.64	38
2055.37	37.6667
2052.09	39
2048.81	43
2045.53	37
2042.25	32
2038.96	35.3333
2035.67	32
2032.38	34.3333
2029.08	30.3333
2025.79	42
2022.49	39.3333
2019.19	28
2015.88	35.3333
2012.58	25.3333
2009.27	30.3333
2005.96	34.6667
2002.64	41
1999.33	38.3333
1996.01	33.6667
1992.69	41.3333
1989.36	38
1986.04	36.3333
1982.71	42
1979.38	43.3333
1976.05	29.6667
1972.71	38
1969.37	43.6667
1966.03	39
1962.69	34.3333
1959.34	41.6667
1955.99	47.6667
1952.64	42
1949.29	39
1945.93	43
1942.58	36
1939.21	38
1935.85	37.6667
1932.49	33.3333
1929.12	45
1925.75	45.3333
1922.37	47.6667
1919	54.3333
1915.62	44.3333
1912.24	48.6667
1908.86	44.6667
1905.47	45.3333
1902.08	59.3333
1898.69	50.6667
1895.3	51
1891.9	45.3333
1888.5	47
1885.1	48.6667
1881.7	47.3333
1878.29	44.3333
1874.88	46
1871.47	40.6667
1868.06	41.3333
1864.64	39.6667
1861.22	42
1857.8	42
1854.38	40.3333
1850.95	44.3333
1847.52	43.6667
1844.09	40
1840.66	40.3333
1837.22	47
1833.78	41.6667
1830.34	35.6667
1826.9	40.6667
1823.45	43.3333
1820	35
1816.55	38
1813.09	44.3333
1809.64	41
1806.18	39.3333
1802.71	44
1799.25	44
1795.78	40
1792.31	39.6667
1788.84	42.3333
1785.36	37.3333
1781.88	36.6667
1778.4	43.3333
1774.92	44.3333
1771.43	33.6667
1767.95	40.3333
1764.45	47.3333
1760.96	44.6667
1757.47	41.6667
1753.97	40
1750.47	47.6667
1746.96	42.3333
1743.45	38.6667
1739.94	42
1736.43	41
1732.92	42
1729.4	45.3333
1725.88	45.6667
1722.36	42.3333
1718.83	46
1715.3	45
1711.77	44.3333
1708.24	42.6667
1704.71	44.3333
1701.17	44.3333
1697.63	47.6667
1694.08	50.3333
1690.54	45
1686.99	53.6667
1683.44	50.3333
1679.88	44
1676.32	54.6667
1672.76	49.6667
1669.2	42
1665.64	35.3333
1662.07	41
1658.5	52
1654.92	45.3333
1651.35	41.3333
1647.77	42
1644.19	38.3333
1640.61	40.6667
1637.02	44.6667
1633.43	46.6667
1629.84	39.3333
1626.24	44.6667
1622.64	40.6667
1619.04	35
1615.44	30.6667
1611.84	46.6667
1608.23	43.3333
1604.62	46.6667
1601	41
1597.39	42.3333
1593.77	38
1590.15	42
1586.52	37.3333
1582.89	44
1579.26	46
1575.63	47.3333
1571.99	52.3333
1568.36	43.3333
1564.72	48.3333
1561.07	54.6667
1557.42	54
1553.78	52.3333
1550.12	45.3333
1546.47	54.6667
1542.81	54.6667
1539.15	48.3333
1535.49	58
1531.82	51.3333
1528.15	53
1524.48	50.6667
1520.81	57.6667
1517.13	56.3333
1513.45	56.6667
1509.77	56.3333
1506.08	65.6667
1502.39	51.3333
1498.7	52
1495.01	59.3333
1491.31	57.6667
1487.61	56
1483.91	58.3333
1480.21	49.6667
1476.5	53.3333
1472.79	58
1469.07	53.3333
1465.36	53.3333
1461.64	59.6667
1457.92	56.3333
1454.19	56
1450.46	56.6667
1446.73	61.3333
1443	54
1439.26	61
1435.52	56
1431.78	64.6667
1428.04	60
1424.29	60.6667
1420.54	52
1416.79	52.3333
1413.03	55
1409.27	62.3333
1405.51	54.6667
1401.75	49.6667
1397.98	50.6667
1394.21	58.6667
1390.44	55.6667
1386.66	60.3333
1382.88	50
1379.1	51.6667
1375.31	54.3333
1371.53	52.6667
1367.74	57
1363.94	62.3333
1360.15	56.6667
1356.35	62.3333
1352.55	59.3333
1348.74	60
1344.93	58.3333
1341.12	55.3333
1337.31	48.6667
1333.49	51.6667
1329.67	55
1325.85	58.3333
1322.03	56.3333
1318.2	57.3333
1314.37	57
1310.53	60.6667
1306.7	60.6667
1302.86	60.3333
1299.01	56
1295.17	50.6667
1291.32	53.3333
1287.47	49.3333
1283.61	60
1279.76	64.6667
1275.9	60.6667
1272.03	57.3333
1268.17	53.6667
1264.3	56
1260.42	56
1256.55	53.3333
1252.67	56.6667
1248.79	66.6667
1244.91	57
1241.02	64.3333
1237.13	54
1233.24	53
1229.34	50.6667
1225.44	54.3333
1221.54	51.3333
1217.63	52.6667
1213.73	58.6667
1209.81	47.3333
1205.9	61
1201.98	58.6667
1198.06	52
1194.14	58
1190.21	52.6667
1186.29	52
1182.35	57
1178.42	57.3333
1174.48	57.3333
1170.54	61.6667
1166.6	50.6667
1162.65	53.3333
1158.7	57
1154.74	54.3333
1150.79	52.6667
1146.83	51.3333
1142.87	60.3333
1138.9	53.6667
1134.93	57.6667
1130.96	56.6667
1126.99	56.3333
1123.01	65.3333
1119.03	48.3333
1115.04	52.6667
1111.06	60.6667
1107.07	52.3333
1103.08	55.3333
1099.08	58.6667
1095.08	52.3333
1091.08	52
1087.07	57.3333
1083.06	54.6667
1079.05	62.6667
1075.04	60
1071.02	52.6667
1067	57.6667
1062.98	55.3333
1058.95	49.6667
1054.92	51.3333
1050.89	57
1046.85	56.3333
1042.81	49
1038.77	54.6667
1034.72	51.6667
1030.67	53.6667
1026.62	55
1022.57	52.6667
1018.51	46.6667
1014.45	46.6667
1010.38	51.3333
1006.32	55.3333
1002.24	59.3333
998.171	52
994.094	58.3333
990.013	56
985.93	56
981.843	54.6667
977.754	57.6667
973.661	63.3333
969.565	53.6667
965.466	55.6667
961.364	55
957.258	58
953.15	49.6667
949.038	61
944.923	55.3333
940.804	62
936.683	63.6667
932.558	53.6667
928.43	57.6667
924.299	57
920.165	54.6667
916.028	50
911.887	56.6667
907.743	54
903.595	60.3333
899.445	50
895.292	48
891.135	52.3333
886.975	59
882.812	64.6667
878.646	57.6667
874.475	55.3333
870.303	58.3333
866.126	54.3333
861.947	51.3333
857.764	60.6667
853.578	53.3333
849.389	54.3333
845.196	56.6667
841	53
836.801	59.6667
832.599	54
828.393	47.6667
824.184	52.3333
819.972	53.6667
815.757	51.3333
811.538	50.3333
807.316	49.3333
803.091	50
798.863	58.6667
794.631	50.3333
790.395	52.6667
786.157	46.6667
781.915	49
777.669	55
773.421	60.6667
769.169	48
764.915	58.3333
760.656	45
756.394	45
752.129	50
747.861	47
743.588	50.6667
739.314	45.3333
735.035	51.3333
730.753	46
726.469	41.6667
722.18	53
717.888	42.6667
713.593	49.6667
709.294	44
704.992	47
700.687	47.6667
696.378	46.6667
692.066	44
687.751	44
683.432	39.6667
679.109	48.6667
674.784	43.6667
670.455	42
666.122	45.6667
661.787	45.6667
657.448	43.6667
653.104	42.6667
648.759	41.6667
644.409	47.3333
640.056	45
635.7	50.6667
631.34	48.3333
626.977	50.3333
622.61	45.3333
618.24	42
613.867	41
609.49	52.3333
605.11	40.6667
600.726	42.6667
596.339	49.6667
591.948	41
587.554	42.3333
583.156	47.3333
578.755	42.3333
574.35	39
569.943	47
565.531	45.3333
561.116	46.3333
556.698	45
552.275	52.6667
547.85	38.3333
543.421	34.3333
538.988	47.6667
534.553	42.3333
530.113	48
525.67	37.3333
521.224	41.6667
516.774	40.6667
512.321	36.3333
507.863	39.3333
503.403	43
498.939	48
494.472	40.3333
490.001	41
485.526	39
481.047	42.6667
476.565	44
472.08	41.6667
467.591	45.6667
463.099	38.6667
458.604	42.6667
454.103	44.6667
449.601	42
445.094	44.6667
440.584	45
436.07	54.6667
431.553	48.3333
427.032	50.3333
422.507	50
417.979	46.6667
413.448	55
408.912	49.6667
404.373	52.3333
399.83	55.6667
395.285	52.3333
390.734	51.3333
386.181	51.6667
381.624	57
377.064	50.3333
372.5	50
367.932	49
363.36	57.3333
358.785	53.6667
354.207	57
349.624	46
345.038	52.6667
340.448	48.3333
335.855	61.3333
331.257	59
326.657	48.6667
322.053	56
317.444	55.6667
312.833	52
308.217	60.3333
303.599	57.6667
298.976	57.3333
294.349	50.6667
289.719	51
285.085	50.6667
280.448	56.6667
275.807	58.3333
271.161	52.3333
266.513	46
261.861	50.3333
257.205	53
252.544	47.3333
247.881	44.6667
243.214	50.3333
238.543	50.6667
233.869	55.3333
229.19	59.6667
224.508	56.3333
219.822	58.6667
215.132	56
210.439	48
205.741	52.3333
201.04	59.3333
196.336	59.3333
191.627	60.3333
186.915	52
182.199	54.6667
177.478	47.3333
172.755	52.6667
168.028	56.3333
163.297	53.3333
158.561	60.6667
153.823	58
149.08	50.6667
144.334	56.3333
139.584	57.3333
134.829	57.3333
130.071	48
125.31	62.6667
120.545	51.6667
115.775	59.3333
111.001	57.6667
106.224	61.6667
101.444	56.3333
96.6594	53.3333
91.8705	53.3333
87.0781	53.3333
82.282	57.3333
77.4812	60
72.6778	46.3333
67.8698	50
63.0582	49.6667
58.2419	50
53.4229	42.6667
48.5993	43.6667
43.772	32
38.941	37.6667
34.1054	36.6667
29.2661	37.3333
24.4231	35.6667
19.5764	28.6667
14.7261	33.6667
9.87099	28.6667
5.01321	33
0.14975	36.6667
-4.71644	39.6667
-9.58634	39.6667
-14.461	36.3333
-19.3393	32.3333
-24.2214	33.3333
-29.1072	30.6667
-33.9977	34.3333
-38.892	34.6667
-43.7901	25
-48.6919	41.6667
-53.5974	36
-58.5078	38.6667
-63.4218	26
-68.3397	27.6667
-73.2613	40.3333
-78.1878	34
-83.117	36
-88.051	34.6667
-92.9888	33
-97.9314	43
-102.877	27.6667
-107.827	36.3333
-112.781	37.6667
-117.739	33.3333
-122.701	38.3333
-127.667	31.3333
-132.637	37
-137.612	32.3333
-142.59	34
-147.572	33.3333
-152.558	34.3333
-157.548	31.3333
-162.542	32.6667
-167.541	34.3333
-172.544	31.6667
-177.55	31.6667
-182.561	29
-187.576	36
-192.595	38.3333
-197.617	37
-202.645	33
-207.676	30.3333
-212.711	29.6667
-217.75	30.6667
-222.794	35.3333
-227.842	31.6667
-232.893	38
-237.949	38.3333
-243.009	30.3333
-248.073	34
-253.142	37.3333
-258.214	40.3333
-263.291	37.3333
-268.371	30.6667
-273.456	32
-278.545	38.6667
-283.639	32.3333
-288.735	41.6667
-293.837	29.3333
-298.943	33
-304.053	40
-309.166	38
-314.285	29.6667
-319.408	34.6667
-324.534	28
-329.665	35
-334.801	39.6667
-339.94	30.6667
-345.083	36
-350.231	34.3333
-355.383	32.6667
-360.539	31.3333
-365.699	42.3333
-370.864	33.3333
-376.033	33.3333
-381.206	36
-386.384	32.3333
-391.565	34
-396.751	29.6667
-401.941	38.3333
-407.136	44.6667
-412.334	36.6667
-417.537	32.3333
-422.745	33.3333
-427.956	30.6667
-433.173	26.6667
-438.392	25.3333
-443.617	34.6667
-448.846	36.3333
-454.078	36
-459.317	28.3333
-464.558	37.3333
-469.804	30
-475.055	34.6667
-480.309	33.3333
-485.568	39.3333
-490.832	24.6667
-496.099	38.3333
-501.372	27
-506.648	37.3333
-511.929	35
-517.215	34
-522.504	37.3333
-527.797	32.3333
-533.097	34.6667
-538.399	36
-543.706	37.3333
-549.018	28.3333
-554.334	38.6667
-559.654	32
-564.979	38.3333
-570.308	33.3333
-575.641	29.6667
-580.98	32.3333
-586.322	30
-591.669	31
-597.02	34.6667
-602.376	30.6667
-607.736	39.3333
-613.1	33
-618.47	22.3333
-623.843	35.3333
-629.222	40.6667
-634.603	37
-639.99	28
-645.382	28.6667
-650.779	32
-656.179	30.6667
-661.583	30.3333
-666.993	25.6667
-672.407	40
-677.825	35.3333
-683.248	30
-688.675	40
-694.108	37.6667
-699.544	36
-704.985	35.3333
-710.431	33.3333
-715.88	30.3333
-721.335	31.3333
-726.795	30.3333
-732.258	38.3333
-737.727	26.3333
-743.2	32
-748.678	37
-754.159	34.6667
-759.646	31.3333
-765.138	27.3333
-770.633	34.3333
-776.133	32
-781.638	36.3333
-787.149	38.3333
-792.663	38.6667
-798.181	33.6667
-803.705	39
-809.233	36.6667
-814.766	40.3333
-820.304	36
-825.846	28.6667
-831.392	32.3333
-836.944	33
-842.499	40
-848.06	26.3333
-853.626	32
-859.195	35
-864.77	37
-870.35	26.6667
-875.934	41
-881.522	30
-887.116	22.3333
-892.714	39
-898.317	28.6667
-903.924	38.3333
-909.537	31.3333
-915.153	36
-920.776	30.6667
-926.401	38.6667
-932.033	24.6667
-937.669	32
-943.31	30.3333
-948.955	36
-954.605	34.6667
-960.26	31.6667
-965.92	34
-971.584	35.3333
-977.254	33
-982.928	31.6667
-988.607	36
-994.291	38
-999.979	32.6667
-1005.67	29.6667
-1011.37	35
-1017.07	30
-1022.78	38.6667
-1028.49	36.6667
-1034.21	37
-1039.93	35.3333
-1045.66	35.6667
-1051.39	32.6667
-1057.13	27.3333
-1062.87	30.6667
-1068.62	31
-1074.37	30
-1080.12	34.6667
-1085.89	28.6667
-1091.65	36
-1097.42	37.3333
-1103.2	28.6667
-1108.98	30.3333
-1114.77	30
-1120.56	30.3333
-1126.35	30.3333
-1132.15	33.6667
-1137.96	27.6667
-1143.77	35.3333
-1149.58	31
-1155.4	32.3333
-1161.23	32.3333
-1167.06	30
-1172.89	31.6667
-1178.73	29.6667
-1184.58	34.6667
-1190.43	23
-1196.28	35.6667
-1202.14	38.6667
-1208.01	29.3333
-1213.88	31.6667
-1219.75	32.6667
-1225.63	33.3333
-1231.52	32.6667
-1237.41	35.6667
-1243.3	35.3333
-1249.2	35.6667
-1255.11	32.6667
-1261.02	33
-1266.93	28
-1272.85	37
-1278.78	34.6667
-1284.71	38
-1290.65	31
-1296.59	33
-1302.53	32.6667
-1308.48	29.3333
-1314.44	31.3333
-1320.4	36
-1326.37	24.6667
-1332.34	36
-1338.31	30.3333
-1344.29	29.3333
-1350.28	38.6667
-1356.27	31.3333
-1362.27	27
-1368.27	29.6667
-1374.28	34
-1380.29	29
-1386.31	31
-1392.33	35.6667
-1054.26	28.3333
-1060	30
-1065.74	35
-1071.49	32.6667
-1077.25	33
-1083.01	34.3333
-1088.77	33.6667
-1094.54	34.6667
-1100.31	28.6667
-1106.09	27.6667
-1111.87	36.3333
-1117.66	32.6667
-1123.45	41.3333
-1129.25	30.3333
-1135.05	38
-1140.86	30
-1146.67	39
-1152.49	32.3333
-1158.32	36
-1164.14	32
-1169.98	35.6667
-1175.81	30.3333
-1181.66	35
-1187.5	34
-1193.35	32.6667
-1199.21	37.6667
-1205.08	29
-1210.94	28.6667
-1216.82	30.3333
-1222.69	33.6667
-1228.58	25.6667
-1234.46	34
-1240.35	40.3333
-1246.25	28
-1252.16	37
-1258.06	30.6667
-1263.97	34.6667
-1269.89	38
-1275.82	25.3333
-1281.74	23.6667
-1287.68	34
-1293.62	34.3333
-1299.56	34
-1305.51	38.3333
-1311.46	35.6667
-1317.42	33.6667
-1323.38	36.3333
-1329.35	32.6667
-1335.32	31.6667
-1341.3	36.6667
-1347.29	32
-1353.28	38.6667
-1359.27	31.6667
-1365.27	33.6667
-1371.27	38.6667
-1377.28	35
-1383.3	29.6667
-1389.32	31
-1392.33	35.6667