File: projects/python/data/20231030/noise_600_785 nm_10 s_1_2023_10_30_16_29_00_01.txt
#Sample=noise
#Laser=785 nm
#Grating=600
#Exposition=10
#Accumulation=1
#Acquired=30.10.2023 16:29:00
2745.96	45
2743.18	38
2740.41	44
2737.63	39.6667
2734.85	45
2732.07	45.3333
2729.29	38
2726.5	44
2723.72	43.3333
2720.93	42.6667
2718.14	42.6667
2715.34	43.3333
2712.55	38
2709.75	42.6667
2706.95	36.3333
2704.15	29
2701.35	44
2698.55	43.3333
2695.74	36.6667
2692.93	42.6667
2690.12	41
2687.31	40
2684.49	30.3333
2681.67	30
2678.85	32.3333
2676.03	43.3333
2673.21	37.6667
2670.38	41.3333
2667.56	37.6667
2664.73	32.3333
2661.9	31.3333
2659.06	39.3333
2656.23	38.6667
2653.39	35.3333
2650.55	39.3333
2647.71	31.3333
2644.86	41
2642.02	41.6667
2639.17	34
2636.32	40.3333
2633.47	39
2630.62	37.3333
2627.76	45.6667
2624.9	32.6667
2622.04	38.3333
2619.18	31
2616.31	33.6667
2613.45	31.6667
2610.58	34.3333
2607.71	33.6667
2604.84	38.3333
2601.96	28
2599.08	35.3333
2596.21	31.6667
2593.32	33.6667
2590.44	33.3333
2587.56	36
2584.67	36.6667
2581.78	31
2578.89	34.3333
2575.99	33.3333
2573.1	30
2570.2	36
2567.3	32
2564.4	28.6667
2561.5	34.3333
2558.59	39
2555.68	38
2552.77	35.6667
2549.86	38
2546.94	34
2544.03	42.6667
2541.11	36.6667
2538.19	41.6667
2535.26	33
2532.34	36
2529.41	36.3333
2526.48	36
2523.55	37
2520.62	35.6667
2517.68	31
2514.74	33
2511.8	27.3333
2508.86	33
2505.92	37
2502.97	36
2500.02	40.6667
2497.07	37
2494.12	38.3333
2491.16	40.6667
2488.2	30.6667
2485.25	29.6667
2482.28	33.3333
2479.32	37
2476.35	26
2473.39	34.3333
2470.42	33
2467.44	41.3333
2464.47	34.6667
2461.49	31.6667
2458.51	42.3333
2455.53	30
2452.55	32.3333
2449.56	38.6667
2446.58	35
2443.59	39.3333
2440.59	32
2437.6	32
2434.6	29.6667
2431.61	32
2428.61	28.3333
2425.6	34.6667
2422.6	30.3333
2419.59	41.3333
2416.58	26.6667
2413.57	42.3333
2410.56	32.3333
2407.54	34.3333
2404.52	26.6667
2401.5	39.3333
2398.48	38.3333
2395.45	41.3333
2392.43	37.6667
2389.4	35.3333
2386.37	38
2383.33	29
2380.3	26.3333
2377.26	30.3333
2374.22	28
2371.17	29
2368.13	38.3333
2365.08	26.6667
2362.03	39.6667
2358.98	33.6667
2355.93	33
2352.87	31
2349.81	30.6667
2346.75	30.6667
2343.69	25
2340.63	27.6667
2337.56	38.3333
2334.49	37
2331.42	37.3333
2328.35	33.3333
2325.27	33
2322.19	29.6667
2319.11	34
2316.03	44
2312.94	35.6667
2309.85	36.3333
2306.77	31
2303.67	36.6667
2300.58	32.6667
2297.48	37.3333
2294.38	32
2291.28	35.3333
2288.18	31.6667
2285.07	28.6667
2281.97	33
2278.86	34.3333
2275.74	30
2272.63	39.6667
2269.51	34.3333
2266.39	27.3333
2263.27	38.3333
2260.15	31.6667
2257.02	30
2253.89	40.3333
2250.76	28.6667
2247.63	37.6667
2244.49	30.6667
2241.36	33
2238.22	33
2235.08	33.6667
2231.93	32.3333
2228.78	36.3333
2225.63	32.6667
2222.48	29.3333
2219.33	34.3333
2216.17	26
2213.01	33.6667
2209.85	38.6667
2206.69	33.3333
2203.53	30.6667
2200.36	30.6667
2197.19	24.6667
2194.02	30.6667
2190.84	24.6667
2187.66	33.3333
2184.48	40
2181.3	37.6667
2178.12	27
2174.93	30.3333
2171.74	28.3333
2168.55	31.3333
2165.36	35
2162.16	34
2158.97	25.3333
2155.76	37
2152.56	35.6667
2149.36	40.6667
2146.15	42
2142.94	31
2139.73	37
2136.51	36.6667
2133.29	28.3333
2130.08	36
2126.85	28.6667
2123.63	28.6667
2120.4	34.6667
2117.17	30
2113.94	34
2110.71	29.6667
2107.47	37.6667
2104.23	29.6667
2100.99	37.3333
2097.75	37
2094.5	26.6667
2091.26	34.3333
2088.01	28.6667
2084.75	36
2081.5	30.3333
2078.24	33.3333
2074.98	29
2071.72	27.3333
2068.45	32.3333
2065.18	40.6667
2061.92	28
2058.64	34.3333
2055.37	34
2052.09	26.3333
2048.81	30
2045.53	29.3333
2042.25	28.6667
2038.96	29
2035.67	27
2032.38	37
2029.08	34.3333
2025.79	30
2022.49	33.6667
2019.19	37.6667
2015.88	29
2012.58	29.3333
2009.27	28.6667
2005.96	34.6667
2002.64	26.3333
1999.33	43.6667
1996.01	35.6667
1992.69	25
1989.36	39.3333
1986.04	37.3333
1982.71	36.6667
1979.38	35.6667
1976.05	30.3333
1972.71	42
1969.37	34.3333
1966.03	35
1962.69	43
1959.34	37.6667
1955.99	42.6667
1952.64	38.3333
1949.29	28.6667
1945.93	34
1942.58	41.6667
1939.21	37.6667
1935.85	39
1932.49	32.3333
1929.12	29
1925.75	41
1922.37	33.6667
1919	33.3333
1915.62	37
1912.24	36.3333
1908.86	34.3333
1905.47	33
1902.08	37
1898.69	38
1895.3	36.6667
1891.9	34
1888.5	37
1885.1	28
1881.7	36.3333
1878.29	38
1874.88	39.6667
1871.47	28.6667
1868.06	26.6667
1864.64	39.6667
1861.22	37
1857.8	30
1854.38	31.3333
1850.95	37.3333
1847.52	39.3333
1844.09	39.6667
1840.66	41.3333
1837.22	34
1833.78	35
1830.34	28
1826.9	35.3333
1823.45	33.6667
1820	34.3333
1816.55	35
1813.09	37.6667
1809.64	38.6667
1806.18	42.3333
1802.71	32.3333
1799.25	37.6667
1795.78	33
1792.31	36.6667
1788.84	38.6667
1785.36	33.6667
1781.88	30
1778.4	37.6667
1774.92	35
1771.43	30.6667
1767.95	33.6667
1764.45	29.3333
1760.96	32.6667
1757.47	32
1753.97	33.3333
1750.47	35.3333
1746.96	34.6667
1743.45	33
1739.94	28.3333
1736.43	38.6667
1732.92	31
1729.4	36.6667
1725.88	37.3333
1722.36	37.6667
1718.83	33.3333
1715.3	35.6667
1711.77	34.3333
1708.24	34
1704.71	36
1701.17	33.6667
1697.63	36.6667
1694.08	38
1690.54	41.3333
1686.99	25
1683.44	40.6667
1679.88	30.3333
1676.32	33.3333
1672.76	38.6667
1669.2	28.6667
1665.64	31.6667
1662.07	33.6667
1658.5	39.3333
1654.92	37.3333
1651.35	34.3333
1647.77	36
1644.19	28
1640.61	31.3333
1637.02	39
1633.43	32.6667
1629.84	29.3333
1626.24	37
1622.64	32
1619.04	32.6667
1615.44	34
1611.84	35.6667
1608.23	41
1604.62	32
1601	36.3333
1597.39	36.3333
1593.77	40.6667
1590.15	30.3333
1586.52	31
1582.89	31
1579.26	29.3333
1575.63	32.3333
1571.99	33.3333
1568.36	35.3333
1564.72	36.6667
1561.07	39.6667
1557.42	40.3333
1553.78	40
1550.12	37.3333
1546.47	31.3333
1542.81	38.6667
1539.15	42
1535.49	39
1531.82	42.3333
1528.15	40.3333
1524.48	36
1520.81	36
1517.13	39.3333
1513.45	43.3333
1509.77	42
1506.08	30.6667
1502.39	36.3333
1498.7	37
1495.01	44.6667
1491.31	43.6667
1487.61	36.6667
1483.91	31
1480.21	45.6667
1476.5	30.3333
1472.79	29.3333
1469.07	37.6667
1465.36	41
1461.64	34
1457.92	36.6667
1454.19	44.3333
1450.46	38.3333
1446.73	31.6667
1443	35.6667
1439.26	39.6667
1435.52	39.6667
1431.78	43.3333
1428.04	39.3333
1424.29	36.6667
1420.54	34.3333
1416.79	39
1413.03	43.3333
1409.27	31.3333
1405.51	31.6667
1401.75	39
1397.98	38
1394.21	37.6667
1390.44	41
1386.66	32.6667
1382.88	38.6667
1379.1	37.3333
1375.31	39
1371.53	35.3333
1367.74	42.3333
1363.94	35
1360.15	43.3333
1356.35	31.3333
1352.55	36
1348.74	37
1344.93	39
1341.12	44.3333
1337.31	41.6667
1333.49	33.6667
1329.67	38.6667
1325.85	37.6667
1322.03	32
1318.2	44.3333
1314.37	44
1310.53	45.3333
1306.7	38.6667
1302.86	33.3333
1299.01	37.6667
1295.17	33.6667
1291.32	33
1287.47	36.6667
1283.61	37
1279.76	35.3333
1275.9	33.3333
1272.03	43
1268.17	36.3333
1264.3	44.3333
1260.42	31.6667
1256.55	31
1252.67	38
1248.79	41.3333
1244.91	35
1241.02	38.6667
1237.13	35.6667
1233.24	41
1229.34	39
1225.44	42
1221.54	43
1217.63	38.6667
1213.73	38.3333
1209.81	39.6667
1205.9	33
1201.98	37.6667
1198.06	31.3333
1194.14	37.6667
1190.21	34
1186.29	30
1182.35	33.6667
1178.42	38.3333
1174.48	26
1170.54	48
1166.6	38.3333
1162.65	37
1158.7	40
1154.74	33.3333
1150.79	39
1146.83	48
1142.87	39
1138.9	37
1134.93	34
1130.96	34.3333
1126.99	43
1123.01	40.6667
1119.03	39.6667
1115.04	36.6667
1111.06	41
1107.07	45.3333
1103.08	31.6667
1099.08	41.3333
1095.08	40.6667
1091.08	32.3333
1087.07	37.3333
1083.06	37
1079.05	42.6667
1075.04	35
1071.02	29.3333
1067	39.6667
1062.98	36.6667
1058.95	42
1054.92	36.3333
1050.89	30
1046.85	30.6667
1042.81	35.3333
1038.77	34
1034.72	35.3333
1030.67	41.3333
1026.62	35.6667
1022.57	41
1018.51	42.3333
1014.45	35
1010.38	39
1006.32	35.3333
1002.24	36
998.171	40.6667
994.094	30.3333
990.013	43
985.93	35
981.843	37
977.754	35
973.661	36.3333
969.565	32.6667
965.466	36.6667
961.364	37.3333
957.258	41.3333
953.15	33
949.038	33.3333
944.923	41.3333
940.804	32.6667
936.683	43
932.558	39.6667
928.43	43
924.299	38
920.165	37.3333
916.028	35
911.887	41
907.743	38.3333
903.595	40.3333
899.445	35
895.292	30.3333
891.135	36.6667
886.975	38.6667
882.812	34.6667
878.646	36.3333
874.475	41
870.303	33
866.126	36
861.947	27
857.764	33.3333
853.578	42
849.389	36.3333
845.196	37.6667
841	37.6667
836.801	39.6667
832.599	35
828.393	36.3333
824.184	36.6667
819.972	27.6667
815.757	38.3333
811.538	36.6667
807.316	42.6667
803.091	36
798.863	43
794.631	35.6667
790.395	36.3333
786.157	29
781.915	29
777.669	45.6667
773.421	39
769.169	35.3333
764.915	39.6667
760.656	46
756.394	37.3333
752.129	39
747.861	28.3333
743.588	36.6667
739.314	33.3333
735.035	39.3333
730.753	37
726.469	34
722.18	29.3333
717.888	38.6667
713.593	37.6667
709.294	31
704.992	35.6667
700.687	33.6667
696.378	29
692.066	33.3333
687.751	33.3333
683.432	32.6667
679.109	30
674.784	41.6667
670.455	33.3333
666.122	38.3333
661.787	31.3333
657.448	32.6667
653.104	29
648.759	44.6667
644.409	35
640.056	35
635.7	38.3333
631.34	40.6667
626.977	34
622.61	34.3333
618.24	30.3333
613.867	35.6667
609.49	34.3333
605.11	42
600.726	34
596.339	34.3333
591.948	30.3333
587.554	48.3333
583.156	34
578.755	38.3333
574.35	30
569.943	31
565.531	38.3333
561.116	32
556.698	35.3333
552.275	28
547.85	37.6667
543.421	29.3333
538.988	37
534.553	34.3333
530.113	31.6667
525.67	31.3333
521.224	35.6667
516.774	31
512.321	38.6667
507.863	35.6667
503.403	31
498.939	41.3333
494.472	29.6667
490.001	39.6667
485.526	39
481.047	34
476.565	38.3333
472.08	31
467.591	36
463.099	36.6667
458.604	39
454.103	41
449.601	32.3333
445.094	33.3333
440.584	31.6667
436.07	28.6667
431.553	33.6667
427.032	34.3333
422.507	42.6667
417.979	32.6667
413.448	34.6667
408.912	35.3333
404.373	40
399.83	34
395.285	39.3333
390.734	35.3333
386.181	29.6667
381.624	37
377.064	33.3333
372.5	34.6667
367.932	33.3333
363.36	29.6667
358.785	42.6667
354.207	41
349.624	31.6667
345.038	35
340.448	41.3333
335.855	37
331.257	29.6667
326.657	36.6667
322.053	32
317.444	33
312.833	38.3333
308.217	32
303.599	36.6667
298.976	36.6667
294.349	32.6667
289.719	31.3333
285.085	31
280.448	41
275.807	36.6667
271.161	29
266.513	45.6667
261.861	39
257.205	34.6667
252.544	33.6667
247.881	36.6667
243.214	41.6667
238.543	32.3333
233.869	29.3333
229.19	36
224.508	37.3333
219.822	37.6667
215.132	42
210.439	31
205.741	32
201.04	35
196.336	43
191.627	36
186.915	38.6667
182.199	37
177.478	32.3333
172.755	32
168.028	38
163.297	34.6667
158.561	33.6667
153.823	35
149.08	36.6667
144.334	33
139.584	36.3333
134.829	30
130.071	38
125.31	36.3333
120.545	37
115.775	36.3333
111.001	35.3333
106.224	35.6667
101.444	36.3333
96.6594	35.6667
91.8705	37.3333
87.0781	37.3333
82.282	37
77.4812	35.3333
72.6778	31
67.8698	33.3333
63.0582	35
58.2419	37.6667
53.4229	33.6667
48.5993	25
43.772	33.3333
38.941	36
34.1054	35.3333
29.2661	30
24.4231	27
19.5764	38.6667
14.7261	34.3333
9.87099	23.6667
5.01321	29
0.14975	28
-4.71644	34.6667
-9.58634	31
-14.461	32.3333
-19.3393	37
-24.2214	37.3333
-29.1072	33.3333
-33.9977	39
-38.892	29.6667
-43.7901	26.3333
-48.6919	36
-53.5974	38.3333
-58.5078	26.6667
-63.4218	33
-68.3397	35.6667
-73.2613	33
-78.1878	36
-83.117	27.6667
-88.051	26.6667
-92.9888	29
-97.9314	30.6667
-102.877	27.6667
-107.827	29
-112.781	30.3333
-117.739	34
-122.701	25.6667
-127.667	31.6667
-132.637	30.3333
-137.612	25.6667
-142.59	39.3333
-147.572	38.3333
-152.558	35.6667
-157.548	28.3333
-162.542	38.6667
-167.541	42.3333
-172.544	33
-177.55	21.3333
-182.561	33
-187.576	34.3333
-192.595	31.3333
-197.617	27
-202.645	36.3333
-207.676	30.3333
-212.711	39.6667
-217.75	38
-222.794	28.3333
-227.842	39
-232.893	30.6667
-237.949	40.6667
-243.009	29.6667
-248.073	26.6667
-253.142	37.6667
-258.214	30.6667
-263.291	39.3333
-268.371	30.3333
-273.456	34.3333
-278.545	29.3333
-283.639	28.6667
-288.735	42.6667
-293.837	32
-298.943	24
-304.053	36.6667
-309.166	30
-314.285	34
-319.408	35
-324.534	33.3333
-329.665	25
-334.801	35.3333
-339.94	35.3333
-345.083	36.6667
-350.231	33
-355.383	33.3333
-360.539	30
-365.699	33
-370.864	20.3333
-376.033	30
-381.206	34
-386.384	30.3333
-391.565	30
-396.751	34.3333
-401.941	33
-407.136	37.3333
-412.334	27.3333
-417.537	40.6667
-422.745	32
-427.956	32
-433.173	35.6667
-438.392	24
-443.617	28.3333
-448.846	28.3333
-454.078	32
-459.317	31
-464.558	32.3333
-469.804	26
-475.055	29.3333
-480.309	32
-485.568	27
-490.832	32
-496.099	25
-501.372	27.3333
-506.648	30.6667
-511.929	29
-517.215	36
-522.504	35.3333
-527.797	37.6667
-533.097	28.3333
-538.399	35.3333
-543.706	32.6667
-549.018	35
-554.334	33.3333
-559.654	33
-564.979	27.3333
-570.308	32.6667
-575.641	36
-580.98	31.3333
-586.322	27.3333
-591.669	35
-597.02	25.6667
-602.376	26.3333
-607.736	34.6667
-613.1	28.3333
-618.47	33
-623.843	30
-629.222	30.6667
-634.603	30
-639.99	34
-645.382	32
-650.779	35
-656.179	30.6667
-661.583	36.3333
-666.993	29.3333
-672.407	28.6667
-677.825	33
-683.248	37
-688.675	24.6667
-694.108	29.6667
-699.544	34
-704.985	28.6667
-710.431	33
-715.88	29
-721.335	32.3333
-726.795	33.6667
-732.258	33.3333
-737.727	32
-743.2	32.6667
-748.678	39
-754.159	28.3333
-759.646	32.6667
-765.138	33.3333
-770.633	33
-776.133	33.3333
-781.638	35.6667
-787.149	29.6667
-792.663	30
-798.181	26.6667
-803.705	32.3333
-809.233	28.6667
-814.766	33.3333
-820.304	34.3333
-825.846	36.6667
-831.392	28.6667
-836.944	33
-842.499	35
-848.06	30.6667
-853.626	29.6667
-859.195	27.6667
-864.77	28.3333
-870.35	33.6667
-875.934	36.3333
-881.522	28.6667
-887.116	39
-892.714	26
-898.317	35.3333
-903.924	28.3333
-909.537	27.3333
-915.153	28.6667
-920.776	27
-926.401	31.3333
-932.033	28
-937.669	39.3333
-943.31	30.6667
-948.955	31.3333
-954.605	31.3333
-960.26	40.6667
-965.92	32.3333
-971.584	34
-977.254	30.6667
-982.928	32.6667
-988.607	39.6667
-994.291	32
-999.979	28.6667
-1005.67	31.6667
-1011.37	29.3333
-1017.07	27.6667
-1022.78	36
-1028.49	37.3333
-1034.21	36
-1039.93	32
-1045.66	33.3333
-1051.39	28.6667
-1057.13	31.3333
-1062.87	31
-1068.62	28.6667
-1074.37	30.6667
-1080.12	32.6667
-1085.89	37.3333
-1091.65	29.6667
-1097.42	30
-1103.2	37.3333
-1108.98	27.6667
-1114.77	31.6667
-1120.56	28.6667
-1126.35	32
-1132.15	32
-1137.96	32
-1143.77	30.3333
-1149.58	38.3333
-1155.4	34.6667
-1161.23	29
-1167.06	27.3333
-1172.89	38.6667
-1178.73	35.3333
-1184.58	35.3333
-1190.43	23
-1196.28	33.3333
-1202.14	34
-1208.01	33
-1213.88	31.3333
-1219.75	31
-1225.63	30.6667
-1231.52	32.6667
-1237.41	38.6667
-1243.3	29.6667
-1249.2	30
-1255.11	33.6667
-1261.02	32.3333
-1266.93	32
-1272.85	29.6667
-1278.78	39
-1284.71	30
-1290.65	36.6667
-1296.59	39.6667
-1302.53	26.6667
-1308.48	29
-1314.44	31.3333
-1320.4	31.6667
-1326.37	34
-1332.34	36.6667
-1338.31	32.6667
-1344.29	33.3333
-1350.28	33
-1356.27	30.3333
-1362.27	28.6667
-1368.27	35
-1374.28	28.3333
-1380.29	30.6667
-1386.31	34.3333
-1392.33	34.6667
-1051.39	28.6667
-1057.13	31.3333
-1062.87	31
-1068.62	28.6667
-1074.37	30.6667
-1080.12	32.6667
-1085.89	37.3333
-1091.65	29.6667
-1097.42	30
-1103.2	37.3333
-1108.98	27.6667
-1114.77	31.6667
-1120.56	28.6667
-1126.35	32
-1132.15	32
-1137.96	32
-1143.77	30.3333
-1149.58	38.3333
-1155.4	34.6667
-1161.23	29
-1167.06	27.3333
-1172.89	38.6667
-1178.73	35.3333
-1184.58	35.3333
-1190.43	23
-1196.28	33.3333
-1202.14	34
-1208.01	33
-1213.88	31.3333
-1219.75	31
-1225.63	30.6667
-1231.52	32.6667
-1237.41	38.6667
-1243.3	29.6667
-1249.2	30
-1255.11	33.6667
-1261.02	32.3333
-1266.93	32
-1272.85	29.6667
-1278.78	39
-1284.71	30
-1290.65	36.6667
-1296.59	39.6667
-1302.53	26.6667
-1308.48	29
-1314.44	31.3333
-1320.4	31.6667
-1326.37	34
-1332.34	36.6667
-1338.31	32.6667
-1344.29	33.3333
-1350.28	33
-1356.27	30.3333
-1362.27	28.6667
-1368.27	35
-1374.28	28.3333
-1380.29	30.6667
-1386.31	34.3333
-1392.33	34.6667