File: projects/python/data/20231030/thenar_600_785 nm_10 s_1_2023_10_30_15_18_57_01.txt
#Sample=thenar
#Laser=785 nm
#Grating=600
#Exposition=10
#Accumulation=1
#Acquired=30.10.2023 15:18:57
1599.2	1415
1597.39	1429.67
1595.58	1413.67
1593.77	1403
1591.96	1405
1590.15	1403.67
1588.33	1400.33
1586.52	1419.67
1584.71	1415
1582.89	1398.67
1581.08	1398.67
1579.26	1406.33
1577.45	1397.67
1575.63	1423
1573.81	1402.33
1571.99	1417
1570.18	1416
1568.36	1413.33
1566.54	1425.67
1564.72	1433.33
1562.89	1443.67
1561.07	1433
1559.25	1433.67
1557.42	1445
1555.6	1431.67
1553.78	1430.67
1551.95	1442.67
1550.12	1428
1548.3	1438
1546.47	1437.33
1544.64	1451.33
1542.81	1452.33
1540.98	1457
1539.15	1448
1537.32	1453.67
1535.49	1470.33
1533.65	1431.33
1531.82	1438
1529.99	1450.33
1528.15	1445.67
1526.32	1455.33
1524.48	1464.67
1522.64	1447
1520.81	1464.67
1518.97	1460.33
1517.13	1449.33
1515.29	1460.67
1513.45	1461.67
1511.61	1459.67
1509.77	1473.67
1507.92	1464.67
1506.08	1466
1504.24	1475.33
1502.39	1466.33
1500.55	1468.33
1498.7	1467.33
1496.86	1478.67
1495.01	1472.67
1493.16	1469.33
1491.31	1479.67
1489.46	1485.33
1487.61	1515
1485.76	1496
1483.91	1520.33
1482.06	1530
1480.21	1514.67
1478.35	1521.67
1476.5	1540.33
1474.64	1550.67
1472.79	1561.33
1470.93	1559.67
1469.07	1556.33
1467.22	1582.33
1465.36	1593.67
1463.5	1632.33
1461.64	1608.33
1459.78	1610.33
1457.92	1612
1456.05	1620.33
1454.19	1632.33
1452.33	1617.33
1450.46	1646.33
1448.6	1646
1446.73	1617
1444.87	1618.33
1443	1620.33
1441.13	1584.33
1439.26	1624
1437.39	1604
1435.52	1601.67
1433.65	1615.33
1431.78	1593
1429.91	1600.67
1428.04	1597
1426.17	1598.33
1424.29	1587.33
1422.42	1574.67
1420.54	1596.67
1418.66	1568.67
1416.79	1583
1414.91	1586.67
1413.03	1578
1411.15	1578.67
1409.27	1568.67
1407.39	1548.33
1405.51	1574.33
1403.63	1566.67
1401.75	1569
1399.86	1538.67
1397.98	1562.33
1396.09	1556.33
1394.21	1556
1392.32	1544.67
1390.44	1549.67
1388.55	1555
1386.66	1534.33
1384.77	1548
1382.88	1546
1380.99	1543.67
1379.1	1547
1377.21	1556
1375.31	1543
1373.42	1533.33
1371.53	1543.33
1369.63	1541
1367.74	1568.67
1365.84	1544.33
1363.94	1530.33
1362.05	1551.33
1360.15	1560
1358.25	1585
1356.35	1590.33
1354.45	1594.67
1352.55	1610.67
1350.64	1617.67
1348.74	1584.67
1346.84	1608.33
1344.93	1617
1343.03	1603.67
1341.12	1633.67
1339.22	1610
1337.31	1621
1335.4	1608.67
1333.49	1625.33
1331.58	1598.33
1329.67	1643.33
1327.76	1636
1325.85	1630
1323.94	1639.67
1322.03	1659.33
1320.11	1645.33
1318.2	1655.67
1316.28	1655.33
1314.37	1653.67
1312.45	1654
1310.53	1681
1308.62	1656.67
1306.7	1666
1304.78	1674.33
1302.86	1668
1300.94	1691.67
1299.01	1680.67
1297.09	1677
1295.17	1674.67
1293.24	1676.33
1291.32	1705.33
1289.39	1693.33
1287.47	1696.67
1285.54	1694
1283.61	1705
1281.68	1707
1279.76	1697.33
1277.83	1724
1275.9	1714.67
1273.96	1710.67
1272.03	1712.33
1270.1	1703.67
1268.17	1725.67
1266.23	1709
1264.3	1713.33
1262.36	1678.67
1260.42	1693.33
1258.49	1704.33
1256.55	1680.33
1254.61	1662.33
1252.67	1699.67
1250.73	1691
1248.79	1676.33
1246.85	1684
1244.91	1655.67
1242.96	1662.67
1241.02	1663.67
1239.07	1656.33
1237.13	1664
1235.18	1622.33
1233.24	1626.33
1231.29	1622.67
1229.34	1627
1227.39	1609.67
1225.44	1600.33
1223.49	1578
1221.54	1587
1219.59	1581.67
1217.63	1565
1215.68	1573.67
1213.73	1551
1211.77	1547.67
1209.81	1538
1207.86	1540
1205.9	1520.67
1203.94	1515.67
1201.98	1527.33
1200.02	1507.67
1198.06	1507.67
1196.1	1484.67
1194.14	1486
1192.18	1494.67
1190.21	1507.33
1188.25	1487.33
1186.29	1506
1184.32	1496
1182.35	1498.33
1180.39	1486.33
1178.42	1486
1176.45	1493.33
1174.48	1481.67
1172.51	1504
1170.54	1493.33
1168.57	1494.67
1166.6	1503.67
1164.62	1486.33
1162.65	1479.67
1160.67	1485.67
1158.7	1480.67
1156.72	1477
1154.74	1484
1152.77	1487.33
1150.79	1498.33
1148.81	1495.67
1146.83	1526.67
1144.85	1482.67
1142.87	1502
1140.88	1511.33
1138.9	1497
1136.92	1487
1134.93	1496
1132.95	1477.67
1130.96	1508
1128.97	1512
1126.99	1497.33
1125	1528.33
1123.01	1510.33
1121.02	1511
1119.03	1498.33
1117.04	1528.67
1115.04	1509.67
1113.05	1502.67
1111.06	1528.33
1109.06	1536
1107.07	1542.67
1105.07	1531.67
1103.08	1528
1101.08	1551.67
1099.08	1531
1097.08	1536
1095.08	1570.33
1093.08	1553
1091.08	1564
1089.08	1576.67
1087.07	1568.33
1085.07	1577.33
1083.06	1540.33
1081.06	1566.33
1079.05	1545.67
1077.05	1572.33
1075.04	1578.67
1073.03	1553
1071.02	1582
1069.01	1547.67
1067	1549
1064.99	1560.33
1062.98	1572
1060.96	1566
1058.95	1560.67
1056.93	1583.67
1054.92	1551.33
1052.9	1574.67
1050.89	1548
1048.87	1534
1046.85	1558
1044.83	1557.67
1042.81	1579.33
1040.79	1576
1038.77	1562.33
1036.75	1570.67
1034.72	1556.33
1032.7	1577.33
1030.67	1575
1028.65	1563.33
1026.62	1575
1024.59	1571
1022.57	1612
1020.54	1583.67
1018.51	1598.33
1016.48	1587
1014.45	1598.33
1012.42	1605
1010.38	1609.33
1008.35	1594
1006.32	1621
1004.28	1622.67
1002.24	1620.67
1000.21	1605.67
998.171	1630.67
996.133	1606.67
994.094	1628.67
992.054	1608
990.013	1627
987.972	1630.33
985.93	1629.67
983.888	1626.33
981.843	1647
979.799	1673.33
977.754	1660.67
975.708	1652
973.661	1656
971.614	1662.33
969.565	1685.33
967.516	1684
965.466	1692.33
963.415	1685.67
961.364	1684
959.312	1714.67
957.258	1726
955.204	1711.33
953.15	1736
951.094	1729.33
949.038	1746.33
946.98	1720.67
944.923	1748.33
942.864	1713.67
940.804	1727
938.744	1727.33
936.683	1730.67
934.621	1744.33
932.558	1735
930.495	1725
928.43	1721.33
926.365	1746.33
924.299	1725.33
922.233	1756
920.165	1716.67
918.096	1732.33
916.028	1745.33
913.957	1717.67
911.887	1727.67
909.815	1711.33
907.743	1728.67
905.669	1737.33
903.595	1705.67
901.521	1736
899.445	1738.33
897.369	1735.33
895.292	1717.67
893.214	1733.67
891.135	1733
889.055	1737.33
886.975	1742.33
884.894	1739.67
882.812	1725.67
880.729	1746
878.646	1747
876.561	1756
874.475	1753
872.389	1736.33
870.303	1784
868.215	1776.33
866.126	1784.67
864.037	1792.67
861.947	1784.33
859.856	1807
857.764	1802.33
855.671	1781.33
853.578	1791.67
851.484	1783.67
849.389	1781
847.293	1790
845.196	1797.67
843.099	1750.33
841	1794.67
838.901	1782.67
836.801	1778.33
834.701	1758.33
832.599	1776.67
830.496	1795
828.393	1787.67
826.29	1771.33
824.184	1761.33
822.079	1774
819.972	1738.33
817.865	1727.33
815.757	1734.67
813.648	1744.33
811.538	1721.67
809.428	1748.33
807.316	1718
805.204	1737.33
803.091	1719
800.977	1717.67
798.863	1725.33
796.747	1717.33
794.631	1716.67
792.513	1749.67
790.395	1718.67
788.276	1707
786.157	1702
784.036	1717.33
781.915	1737.33
779.793	1746
777.669	1739
775.546	1744.33
773.421	1724.33
771.296	1739.33
769.169	1739.33
767.042	1743.33
764.915	1748.33
762.786	1731
760.656	1748.33
758.526	1741.67
756.394	1753.33
754.262	1762.33
752.129	1778.67
749.995	1751
747.861	1767.67
745.725	1793.67
743.588	1773.33
741.452	1789.67
739.314	1803.67
737.175	1780
735.035	1777.67
732.895	1809.33
730.753	1769.67
728.611	1753.67
726.469	1780.33
724.324	1774.33
722.18	1799.67
720.034	1789.67
717.888	1773
715.741	1779.67
713.593	1776.33
711.444	1768.67
709.294	1776.33
707.144	1768
704.992	1759.67
702.84	1756.33
700.687	1768.67
698.533	1763
696.378	1737.67
694.222	1766.67
692.066	1766
689.909	1750.67
687.751	1747.33
685.592	1727.67
683.432	1745.67
681.271	1752.67
679.109	1747.67
676.947	1740.67
674.784	1744.67
672.62	1731.33
670.455	1742.67
668.289	1766.67
666.122	1754
663.955	1742.33
661.787	1782
659.618	1749
657.448	1779.67
655.277	1772
653.104	1795.33
650.932	1790
648.759	1789.33
646.584	1790.67
644.409	1801
642.233	1803
640.056	1796
637.879	1814.33
635.7	1807
633.52	1821.33
631.34	1818
629.159	1837
626.977	1832
624.794	1813.67
622.61	1829.33
620.426	1815.33
618.24	1836.67
616.054	1827
613.867	1818.67
611.679	1822.33
609.49	1832
607.301	1796.67
605.11	1803
602.919	1795.67
600.726	1820
598.532	1800.67
596.339	1797
594.144	1789.67
591.948	1814
589.751	1808.67
587.554	1821.33
585.355	1813.33
583.156	1811
580.956	1814
578.755	1828
576.553	1818.33
574.35	1824.33
572.147	1821.33
569.943	1822.33
567.737	1832.33
565.531	1821.33
563.323	1841
561.116	1827
558.907	1830
556.698	1840
554.487	1833
552.275	1828.67
550.063	1823.67
547.85	1831.33
545.636	1847
543.421	1866
541.206	1840.33
538.988	1839
536.771	1844
534.553	1863.67
532.333	1864.67
530.113	1875.33
527.892	1864.67
525.67	1877
523.447	1864.67
521.224	1882
518.999	1877.33
516.774	1888.67
514.548	1867.33
512.321	1892
510.093	1898.67
507.863	1890.33
505.634	1880.67
503.403	1861.33
501.172	1885
498.939	1861
496.705	1875.67
494.472	1867
492.237	1853
490.001	1858.67
487.764	1876
485.526	1872.67
483.287	1859.67
481.047	1840
478.807	1863.67
476.565	1881
474.324	1858
472.08	1860.67
469.837	1871.67
467.591	1868
465.346	1854.67
463.099	1899.33
460.852	1876.67
458.604	1880.33
456.354	1903.33
454.103	1892.67
451.852	1908
449.601	1913.67
447.348	1907
445.094	1898
442.84	1938
440.584	1967.67
438.327	1945
436.07	1915.67
433.812	1947.67
431.553	1986
429.293	1978.33
427.032	1976.67
424.77	1986.67
422.507	1963.67
420.244	2012
417.979	2014
415.714	1994
413.448	2013.67
411.18	2000.67
408.912	2025.67
406.643	2011.33
404.373	2021.33
402.102	1995.67
399.83	1997.67
397.558	2021.67
395.285	2019.33
393.01	2028.33
390.734	2015.33
388.458	2028.33
386.181	2037.67
383.903	2020
381.624	2029.67
379.345	2032.67
377.064	2045.67
374.782	2041.33
372.5	2061.33
370.216	2060
367.932	2044
365.646	2034.33
363.36	2054.33
361.073	2045.33
358.785	2053.67
356.496	2072.33
354.207	2078
351.915	2076
349.624	2094.33
347.331	2110.33
345.038	2103.67
342.743	2117.33
340.448	2119
338.152	2096.33
335.855	2116
333.556	2135.33
331.257	2128
328.958	2127.67
326.657	2144.33
324.355	2148.33
322.053	2163.33
319.749	2179.67
317.444	2178.67
315.139	2194.33
312.833	2204.33
310.526	2219.33
308.217	2205.33
305.908	2250.67
303.599	2260.67
301.288	2253.67
298.976	2263.33
296.663	2278.33
294.349	2281.67
292.035	2322.33
289.719	2321.33
287.403	2344.67
285.085	2330.67
282.767	2380.33
280.448	2377
278.128	2427
275.807	2407.67
273.485	2443.67
271.161	2429.67
268.837	2448
266.513	2455
264.187	2478.33
261.861	2498
259.533	2536.67
257.205	2537.67
254.875	2549
252.544	2537.33
250.213	2597.67
247.881	2632
245.548	2644.33
243.214	2670.67
240.879	2695
238.543	2739.67
236.206	2755.67
233.869	2765
231.53	2825.67
229.19	2849.67
226.849	2834.33
224.508	2911.33
222.165	2910
219.822	2949.33
217.478	2979.67
215.132	3016
212.785	3076.67
210.439	3103.33
208.091	3129.67
205.741	3179.33
203.391	3221.67
201.04	3260.67
198.688	3267.33
196.336	3319.67
193.982	3376.33
191.627	3364.33
189.271	3415.67
186.915	3488.67
184.557	3475.67
182.199	3500
179.84	3522
177.478	3597.33
175.117	3646
172.755	3693
170.392	3727
168.028	3772.33
165.662	3851.67
163.297	3884.67
160.929	3908
158.561	3948.33
156.193	3972.33
153.823	4044
151.452	4056.33
149.08	4097
146.707	4128
144.334	4162
141.959	4246.33
139.584	4355.67
137.207	4430.67
134.829	4506.33
132.451	4579.33
130.071	4619.67
127.692	4730.67
125.31	4811.67
122.927	4853.33
120.545	4940.33
118.16	5069.67
115.775	5223
113.388	5308.67
111.001	5462.33
108.613	5593
106.224	5775.33
103.834	5983.67
101.444	6142
99.052	6364
96.6594	6570
94.2649	6838
91.8705	7073.67
89.4743	7432
87.0781	7821
84.68	8101.33
82.282	8512
79.882	9065.67
77.4812	9647.67
75.0805	10391.7
72.6778	11420.3
70.2743	12958.3
67.8698	14821.7
65.4644	16658
63.0582	18203.7
60.651	19579
58.2419	20879.3
55.8328	22248
53.4229	23918
51.011	25682.7
48.5993	27356.3
46.1856	29680
43.772	32233.7
41.3565	35396.7
38.941	39154.3
36.5237	43975.3
34.1054	50027
31.6862	57130.3
29.2661	64524
26.8451	64524
24.4231	64524
22.0002	64524
19.5764	64524
17.1517	64524
14.7261	64524
12.2995	64524
9.87099	64524
7.44256	64524
5.01321	64524
2.58195	64524
0.14975	64524