File: projects/python/data/20231030/thenar_600_785 nm_10 s_1_2023_10_30_15_15_07_01.txt
#Sample=thenar
#Laser=785 nm
#Grating=600
#Exposition=10
#Accumulation=1
#Acquired=30.10.2023 15:15:07
1599.2	1657
1597.39	1658.67
1595.58	1663.33
1593.77	1643.67
1591.96	1656.33
1590.15	1653.33
1588.33	1667.67
1586.52	1650.67
1584.71	1688.67
1582.89	1663.67
1581.08	1689.67
1579.26	1682.33
1577.45	1657
1575.63	1676.33
1573.81	1667.33
1571.99	1672.33
1570.18	1680.33
1568.36	1670.67
1566.54	1678
1564.72	1665.33
1562.89	1679.33
1561.07	1684
1559.25	1701
1557.42	1686
1555.6	1713.67
1553.78	1675.33
1551.95	1691
1550.12	1696
1548.3	1697.33
1546.47	1682.33
1544.64	1695.33
1542.81	1696
1540.98	1711.67
1539.15	1719
1537.32	1738.67
1535.49	1721.33
1533.65	1693.67
1531.82	1686
1529.99	1728
1528.15	1690
1526.32	1741
1524.48	1708.33
1522.64	1710.67
1520.81	1677.33
1518.97	1728.33
1517.13	1712.67
1515.29	1709
1513.45	1713.67
1511.61	1721
1509.77	1726.33
1507.92	1698.67
1506.08	1712.67
1504.24	1749.33
1502.39	1716.67
1500.55	1722
1498.7	1746.33
1496.86	1737.33
1495.01	1747
1493.16	1733.33
1491.31	1728.67
1489.46	1758.67
1487.61	1782.33
1485.76	1777.67
1483.91	1781.67
1482.06	1774
1480.21	1779
1478.35	1790
1476.5	1822.67
1474.64	1807.67
1472.79	1818.67
1470.93	1834.33
1469.07	1846.67
1467.22	1856.33
1465.36	1860.33
1463.5	1883
1461.64	1877.33
1459.78	1903.33
1457.92	1892.33
1456.05	1929.33
1454.19	1902.33
1452.33	1911.67
1450.46	1915.33
1448.6	1910.33
1446.73	1905
1444.87	1893
1443	1901
1441.13	1911.67
1439.26	1900
1437.39	1889.67
1435.52	1890.67
1433.65	1862
1431.78	1880
1429.91	1862.33
1428.04	1855.67
1426.17	1819
1424.29	1847.33
1422.42	1865.67
1420.54	1849
1418.66	1850.33
1416.79	1848
1414.91	1872
1413.03	1853.67
1411.15	1847.33
1409.27	1838
1407.39	1830.67
1405.51	1820
1403.63	1828.33
1401.75	1853.33
1399.86	1813.33
1397.98	1851
1396.09	1810.67
1394.21	1824.33
1392.32	1806
1390.44	1815.67
1388.55	1814.33
1386.66	1796.33
1384.77	1805.67
1382.88	1805.67
1380.99	1819.33
1379.1	1806
1377.21	1811.67
1375.31	1797.67
1373.42	1811.67
1371.53	1810
1369.63	1796.67
1367.74	1806
1365.84	1836.33
1363.94	1840.67
1362.05	1845.67
1360.15	1830.67
1358.25	1869.33
1356.35	1859.33
1354.45	1889.33
1352.55	1871.67
1350.64	1886.33
1348.74	1873.67
1346.84	1892
1344.93	1879.67
1343.03	1904
1341.12	1864
1339.22	1897
1337.31	1892.33
1335.4	1904
1333.49	1878.33
1331.58	1887
1329.67	1908.33
1327.76	1879.67
1325.85	1905
1323.94	1898.33
1322.03	1905.33
1320.11	1916.33
1318.2	1920.33
1316.28	1948.67
1314.37	1913.67
1312.45	1938
1310.53	1947
1308.62	1934.33
1306.7	1923.67
1304.78	1932.33
1302.86	1966
1300.94	1960.33
1299.01	1934
1297.09	1954.67
1295.17	1953.67
1293.24	1966
1291.32	1956
1289.39	1982.67
1287.47	1977
1285.54	1962.67
1283.61	1979.33
1281.68	1966
1279.76	1995.67
1277.83	1964.67
1275.9	1988.67
1273.96	2002
1272.03	1992
1270.1	1981.67
1268.17	1946.33
1266.23	1964.67
1264.3	1955.67
1262.36	1953.33
1260.42	1929.67
1258.49	1959.33
1256.55	1952.33
1254.61	1962.67
1252.67	1948
1250.73	1935.33
1248.79	1945.33
1246.85	1933.67
1244.91	1948.33
1242.96	1913.33
1241.02	1928.67
1239.07	1909
1237.13	1915.67
1235.18	1908
1233.24	1892.67
1231.29	1887
1229.34	1916.67
1227.39	1851
1225.44	1881.67
1223.49	1856.67
1221.54	1859.33
1219.59	1827.67
1217.63	1842.33
1215.68	1829
1213.73	1817.67
1211.77	1797.67
1209.81	1808.67
1207.86	1839
1205.9	1795.33
1203.94	1795
1201.98	1798.33
1200.02	1784
1198.06	1775.67
1196.1	1762
1194.14	1773
1192.18	1746
1190.21	1765
1188.25	1778
1186.29	1764.67
1184.32	1749.67
1182.35	1756
1180.39	1789.33
1178.42	1747.67
1176.45	1742
1174.48	1784.33
1172.51	1760.33
1170.54	1750.67
1168.57	1762
1166.6	1741
1164.62	1762
1162.65	1751
1160.67	1768.33
1158.7	1765.33
1156.72	1765.33
1154.74	1744.67
1152.77	1738.33
1150.79	1747.67
1148.81	1755
1146.83	1750.33
1144.85	1759
1142.87	1774.67
1140.88	1752
1138.9	1775.33
1136.92	1791.33
1134.93	1781.33
1132.95	1768.67
1130.96	1787
1128.97	1755.33
1126.99	1763.33
1125	1786.33
1123.01	1776
1121.02	1768
1119.03	1775
1117.04	1791.33
1115.04	1786.67
1113.05	1782.33
1111.06	1813
1109.06	1806.33
1107.07	1797.67
1105.07	1794.33
1103.08	1820
1101.08	1811.33
1099.08	1807
1097.08	1823.67
1095.08	1833
1093.08	1820.67
1091.08	1834.67
1089.08	1865.33
1087.07	1841
1085.07	1831.33
1083.06	1824.67
1081.06	1867.33
1079.05	1850
1077.05	1862.67
1075.04	1857.33
1073.03	1831.33
1071.02	1820.67
1069.01	1830
1067	1849.67
1064.99	1863.67
1062.98	1859.33
1060.96	1837.33
1058.95	1846.33
1056.93	1840.33
1054.92	1824.67
1052.9	1830.33
1050.89	1839.67
1048.87	1825
1046.85	1842.33
1044.83	1830.33
1042.81	1841.67
1040.79	1855.33
1038.77	1864.67
1036.75	1869
1034.72	1856.67
1032.7	1848
1030.67	1850.67
1028.65	1857.33
1026.62	1858
1024.59	1872.67
1022.57	1852.33
1020.54	1870.33
1018.51	1884
1016.48	1873.67
1014.45	1889.33
1012.42	1909
1010.38	1867.33
1008.35	1873.33
1006.32	1883.33
1004.28	1896.33
1002.24	1890.67
1000.21	1899.33
998.171	1898
996.133	1916.33
994.094	1929
992.054	1914
990.013	1914
987.972	1924
985.93	1936.33
983.888	1938
981.843	1940.67
979.799	1958.67
977.754	1964.33
975.708	1952.33
973.661	1976.67
971.614	1972
969.565	1963
967.516	1979.67
965.466	1994.33
963.415	1994.67
961.364	2019
959.312	2016.33
957.258	2026.67
955.204	2020
953.15	2035.67
951.094	2035
949.038	2014.33
946.98	2012.67
944.923	2036.33
942.864	2057.67
940.804	2032.33
938.744	2063.33
936.683	2050.67
934.621	2033.67
932.558	2039.67
930.495	2032.33
928.43	2029.33
926.365	2017.67
924.299	2015.33
922.233	2050.33
920.165	2032.33
918.096	2038.33
916.028	2012.67
913.957	2052
911.887	2049.33
909.815	2038.33
907.743	2024.67
905.669	2036.33
903.595	1997.67
901.521	2049.67
899.445	2030
897.369	2017.33
895.292	2033.67
893.214	2031
891.135	2049.67
889.055	2050.67
886.975	2047
884.894	2027.67
882.812	2044.33
880.729	2047.33
878.646	2069.67
876.561	2055.67
874.475	2065.33
872.389	2081
870.303	2088.33
868.215	2079.67
866.126	2092.33
864.037	2103
861.947	2108
859.856	2091.67
857.764	2104
855.671	2066.33
853.578	2108.33
851.484	2111
849.389	2084.67
847.293	2101
845.196	2088.33
843.099	2095.67
841	2075.33
838.901	2076.67
836.801	2076.33
834.701	2114.33
832.599	2100
830.496	2067.33
828.393	2088.67
826.29	2072
824.184	2068.67
822.079	2067
819.972	2062
817.865	2045.33
815.757	2075.67
813.648	2035.33
811.538	2034.33
809.428	2042.33
807.316	2039.33
805.204	2055
803.091	2025.67
800.977	2050
798.863	2021.33
796.747	2031.67
794.631	2060.33
792.513	2014.33
790.395	2024.67
788.276	2037
786.157	2009.33
784.036	2011.67
781.915	2006.33
779.793	1995.33
777.669	2032
775.546	2043
773.421	2010
771.296	2043.33
769.169	2035.33
767.042	2052
764.915	2029
762.786	2056
760.656	2038.67
758.526	2077.33
756.394	2062.67
754.262	2085.33
752.129	2062.33
749.995	2089.33
747.861	2066.33
745.725	2047.67
743.588	2070.33
741.452	2086.67
739.314	2095.67
737.175	2099.67
735.035	2091.33
732.895	2107.33
730.753	2101
728.611	2096
726.469	2099.33
724.324	2107.33
722.18	2117.67
720.034	2083.33
717.888	2105
715.741	2086.67
713.593	2098.67
711.444	2101.67
709.294	2068.67
707.144	2085.33
704.992	2077
702.84	2078.67
700.687	2093
698.533	2055.33
696.378	2063
694.222	2085
692.066	2082
689.909	2039.33
687.751	2046
685.592	2053.67
683.432	2046
681.271	2024
679.109	2037.33
676.947	2032.33
674.784	2036.33
672.62	2040.67
670.455	2051.67
668.289	2060.33
666.122	2071.33
663.955	2070
661.787	2080
659.618	2084
657.448	2066
655.277	2082
653.104	2075.67
650.932	2095
648.759	2089.67
646.584	2104.67
644.409	2131.33
642.233	2104.33
640.056	2095
637.879	2105.67
635.7	2133.33
633.52	2140.67
631.34	2159.67
629.159	2126.33
626.977	2120.33
624.794	2134.67
622.61	2150
620.426	2122.67
618.24	2156.67
616.054	2163
613.867	2145.67
611.679	2138.67
609.49	2124
607.301	2118.67
605.11	2119.67
602.919	2129
600.726	2109.67
598.532	2119
596.339	2116.33
594.144	2119.33
591.948	2117.67
589.751	2105
587.554	2128.33
585.355	2104.33
583.156	2120.67
580.956	2143.67
578.755	2129
576.553	2119.67
574.35	2119
572.147	2156.33
569.943	2133.33
567.737	2159.67
565.531	2137.67
563.323	2138.67
561.116	2135.67
558.907	2117
556.698	2135
554.487	2143.67
552.275	2144.33
550.063	2165.33
547.85	2130
545.636	2141
543.421	2150
541.206	2154
538.988	2173.67
536.771	2155.33
534.553	2163
532.333	2189.33
530.113	2191.33
527.892	2153.67
525.67	2184.67
523.447	2182
521.224	2190.33
518.999	2219.33
516.774	2214
514.548	2214
512.321	2196
510.093	2209.33
507.863	2191
505.634	2178
503.403	2178
501.172	2191.67
498.939	2183.67
496.705	2164.67
494.472	2151.33
492.237	2166.67
490.001	2162
487.764	2176
485.526	2149
483.287	2161.67
481.047	2150
478.807	2166.67
476.565	2146.67
474.324	2187.33
472.08	2164.67
469.837	2149.33
467.591	2195.33
465.346	2158.33
463.099	2202
460.852	2180.67
458.604	2183.67
456.354	2182.67
454.103	2209.33
451.852	2208.67
449.601	2208.33
447.348	2216
445.094	2221.67
442.84	2243.67
440.584	2222.67
438.327	2254
436.07	2267.67
433.812	2241
431.553	2254
429.293	2271.67
427.032	2289.67
424.77	2306
422.507	2320.67
420.244	2322
417.979	2310.67
415.714	2297
413.448	2329.33
411.18	2309.33
408.912	2350
406.643	2305.33
404.373	2300.67
402.102	2315
399.83	2301.67
397.558	2324.67
395.285	2325
393.01	2327.33
390.734	2322
388.458	2343.67
386.181	2331.33
383.903	2307.67
381.624	2322.67
379.345	2337.33
377.064	2320
374.782	2320.67
372.5	2338.33
370.216	2363
367.932	2328.67
365.646	2362.33
363.36	2366
361.073	2370.67
358.785	2347.67
356.496	2368.67
354.207	2382
351.915	2399.67
349.624	2397
347.331	2396.67
345.038	2430
342.743	2405.67
340.448	2456
338.152	2448
335.855	2427.33
333.556	2432.33
331.257	2414.33
328.958	2436.67
326.657	2461
324.355	2469.33
322.053	2451.67
319.749	2481.67
317.444	2498
315.139	2478.67
312.833	2514.33
310.526	2528
308.217	2537.33
305.908	2557.33
303.599	2580.67
301.288	2579.33
298.976	2564.33
296.663	2592
294.349	2620.33
292.035	2627.33
289.719	2680.67
287.403	2672.67
285.085	2682.33
282.767	2707
280.448	2717
278.128	2755.33
275.807	2760.67
273.485	2771.67
271.161	2787.67
268.837	2790
266.513	2777.33
264.187	2834.33
261.861	2832.67
259.533	2811.33
257.205	2862.67
254.875	2895
252.544	2908
250.213	2912.67
247.881	2955
245.548	3002.67
243.214	3020.33
240.879	3053
238.543	3062
236.206	3099
233.869	3139
231.53	3177.67
229.19	3228.33
226.849	3277.67
224.508	3269
222.165	3344.67
219.822	3349
217.478	3357.33
215.132	3392.33
212.785	3438
210.439	3493.33
208.091	3495.33
205.741	3530.33
203.391	3576.33
201.04	3627.33
198.688	3655.33
196.336	3731.33
193.982	3752
191.627	3755
189.271	3831.33
186.915	3896.67
184.557	3917.33
182.199	3960.67
179.84	4029
177.478	4050.67
175.117	4082.67
172.755	4134.67
170.392	4167.67
168.028	4252
165.662	4305
163.297	4303
160.929	4391
158.561	4422.67
156.193	4456.33
153.823	4479.67
151.452	4567
149.08	4590
146.707	4630.33
144.334	4671
141.959	4747.33
139.584	4865.67
137.207	4960.67
134.829	4995.33
132.451	5097.67
130.071	5157.33
127.692	5218.33
125.31	5398.67
122.927	5451.33
120.545	5547
118.16	5644.33
115.775	5790
113.388	5934.33
111.001	6161.33
108.613	6325.67
106.224	6486.33
103.834	6692
101.444	6874
99.052	7142.33
96.6594	7348.33
94.2649	7580.67
91.8705	7907.33
89.4743	8246
87.0781	8620
84.68	9061
82.282	9476
79.882	10046
77.4812	10625.3
75.0805	11409
72.6778	12437
70.2743	13962.7
67.8698	15818.7
65.4644	17534.3
63.0582	19106
60.651	20481.3
58.2419	21888.3
55.8328	23339
53.4229	24944.7
51.011	26653.3
48.5993	28594.3
46.1856	30726
43.772	33503
41.3565	36794
38.941	40731.7
36.5237	45717
34.1054	51736
31.6862	59341.7
29.2661	64524
26.8451	64524
24.4231	64524
22.0002	64524
19.5764	64524
17.1517	64524
14.7261	64524
12.2995	64524
9.87099	64524
7.44256	64524
5.01321	64524
2.58195	64524
0.14975	64524