File: projects/python/data/20231030/thenar_600_785 nm_10 s_1_2023_10_30_15_18_57_01.txt
#Sample=thenar
#Laser=785 nm
#Grating=600
#Exposition=10
#Accumulation=1
#Acquired=30.10.2023 15:18:57
2745.96	208
2743.18	209
2740.41	206.667
2737.63	209.333
2734.85	213
2732.07	215.667
2729.29	221
2726.5	220.667
2723.72	215.333
2720.93	209
2718.14	211
2715.34	214
2712.55	221.333
2709.75	219.667
2706.95	207
2704.15	217.333
2701.35	233.667
2698.55	214.333
2695.74	236.667
2692.93	240
2690.12	231
2687.31	231
2684.49	237.333
2681.67	241.333
2678.85	232.333
2676.03	236
2673.21	236.667
2670.38	239.667
2667.56	231.667
2664.73	244.333
2661.9	237.667
2659.06	247.333
2656.23	249.667
2653.39	252.667
2650.55	249
2647.71	257.333
2644.86	251
2642.02	257.333
2639.17	254
2636.32	258
2633.47	265.333
2630.62	273
2627.76	277.333
2624.9	269.667
2622.04	285.333
2619.18	273
2616.31	274.667
2613.45	282.667
2610.58	269.333
2607.71	278.667
2604.84	277
2601.96	274.333
2599.08	284.667
2596.21	282.333
2593.32	273.333
2590.44	271.667
2587.56	283.667
2584.67	286.333
2581.78	289
2578.89	285.667
2575.99	290
2573.1	286.333
2570.2	292.667
2567.3	293.667
2564.4	298
2561.5	310.333
2558.59	303
2555.68	307.667
2552.77	301.667
2549.86	308
2546.94	311
2544.03	314.667
2541.11	321
2538.19	323
2535.26	329.333
2532.34	322.667
2529.41	315.667
2526.48	325
2523.55	326
2520.62	337.667
2517.68	334.667
2514.74	334
2511.8	342.333
2508.86	336
2505.92	344.333
2502.97	341
2500.02	345
2497.07	352.333
2494.12	336.667
2491.16	355
2488.2	354.667
2485.25	343
2482.28	359.333
2479.32	359
2476.35	351.667
2473.39	361.333
2470.42	360.667
2467.44	371
2464.47	360.667
2461.49	371
2458.51	369.333
2455.53	368.667
2452.55	373.667
2449.56	380
2446.58	381.333
2443.59	374.667
2440.59	381
2437.6	385.333
2434.6	419
2431.61	402.667
2428.61	407
2425.6	417.333
2422.6	404.333
2419.59	417.667
2416.58	416.333
2413.57	420.333
2410.56	426.667
2407.54	408.667
2404.52	422.333
2401.5	434.667
2398.48	415.333
2395.45	423.667
2392.43	418.333
2389.4	430.667
2386.37	421.333
2383.33	436.667
2380.3	433.333
2377.26	435
2374.22	453
2371.17	442
2368.13	445.667
2365.08	454.333
2362.03	449
2358.98	455.667
2355.93	458.333
2352.87	472.667
2349.81	465.667
2346.75	480
2343.69	476.333
2340.63	476.333
2337.56	481.333
2334.49	464
2331.42	481.333
2328.35	466.667
2325.27	482.333
2322.19	484.667
2319.11	487.667
2316.03	483
2312.94	554.667
2309.85	500.333
2306.77	489.667
2303.67	498.667
2300.58	503.333
2297.48	510.667
2294.38	516.333
2291.28	520
2288.18	512
2285.07	518.333
2281.97	512.667
2278.86	531.667
2275.74	530.333
2272.63	525.333
2269.51	520
2266.39	531
2263.27	525.667
2260.15	534
2257.02	534.333
2253.89	536.667
2250.76	539.667
2247.63	540.667
2244.49	553.333
2241.36	535.333
2238.22	556
2235.08	548.667
2231.93	544.333
2228.78	563
2225.63	548.333
2222.48	564.667
2219.33	569.333
2216.17	566
2213.01	588
2209.85	589
2206.69	580.667
2203.53	592
2200.36	587
2197.19	592.667
2194.02	595
2190.84	593.333
2187.66	599.333
2184.48	589.667
2181.3	623.667
2178.12	608.333
2174.93	608
2171.74	620.333
2168.55	635.333
2165.36	632
2162.16	624.333
2158.97	613.667
2155.76	636.333
2152.56	621
2149.36	647
2146.15	661
2142.94	644.667
2139.73	641
2136.51	648.667
2133.29	656.667
2130.08	643.333
2126.85	660.667
2123.63	661.667
2120.4	677
2117.17	672
2113.94	660
2110.71	667
2107.47	681
2104.23	675.667
2100.99	683.333
2097.75	685
2094.5	678.667
2091.26	676
2088.01	685
2084.75	685.667
2081.5	689.333
2078.24	686.667
2074.98	703.333
2071.72	705.667
2068.45	698
2065.18	711
2061.92	715.333
2058.64	725
2055.37	739.333
2052.09	728.333
2048.81	741
2045.53	725.333
2042.25	743
2038.96	732
2035.67	753
2032.38	761.667
2029.08	751
2025.79	753.333
2022.49	759.667
2019.19	766.667
2015.88	745.333
2012.58	771
2009.27	787.333
2005.96	771.667
2002.64	770.333
1999.33	772.333
1996.01	791.333
1992.69	785
1989.36	790.333
1986.04	809
1982.71	787
1979.38	796.333
1976.05	802
1972.71	818
1969.37	830.667
1966.03	834.333
1962.69	855
1959.34	853.333
1955.99	857.667
1952.64	843
1949.29	848
1945.93	864.333
1942.58	854.667
1939.21	864.667
1935.85	878.667
1932.49	886.333
1929.12	876.667
1925.75	900.333
1922.37	905.667
1919	913.333
1915.62	894.667
1912.24	913
1908.86	888.667
1905.47	905.333
1902.08	900.333
1898.69	922.333
1895.3	931.667
1891.9	919
1888.5	929
1885.1	929.333
1881.7	926
1878.29	936
1874.88	938
1871.47	952
1868.06	963.667
1864.64	958.667
1861.22	973.667
1857.8	955.667
1854.38	980.667
1850.95	963
1847.52	979.333
1844.09	975.333
1840.66	985
1837.22	979.333
1833.78	962.667
1830.34	1010.67
1826.9	994
1823.45	1005.67
1820	1004.33
1816.55	1021.33
1813.09	1026.67
1809.64	1022.33
1806.18	1045
1802.71	1035.67
1799.25	1051.33
1795.78	1044.67
1792.31	1069
1788.84	1062.67
1785.36	1071
1781.88	1066.67
1778.4	1076
1774.92	1086.67
1771.43	1097.67
1767.95	1089.33
1764.45	1106
1760.96	1111.33
1757.47	1103.33
1753.97	1106.33
1750.47	1141.33
1746.96	1116.33
1743.45	1153.67
1739.94	1145.33
1736.43	1151
1732.92	1168
1729.4	1161
1725.88	1178.33
1722.36	1194.33
1718.83	1181.67
1715.3	1198
1711.77	1221.33
1708.24	1238.33
1704.71	1279.67
1701.17	1266
1697.63	1303
1694.08	1318.33
1690.54	1339.33
1686.99	1353.33
1683.44	1365.67
1679.88	1390.67
1676.32	1419
1672.76	1420.67
1669.2	1446.33
1665.64	1466
1662.07	1477.33
1658.5	1501.33
1654.92	1486.33
1651.35	1455.67
1647.77	1463.33
1644.19	1483.67
1640.61	1459.33
1637.02	1465
1633.43	1441
1629.84	1434
1626.24	1437.67
1622.64	1426
1619.04	1416.67
1615.44	1436
1611.84	1400
1608.23	1387
1604.62	1413.33
1601	1398
1597.39	1429.67
1593.77	1403
1590.15	1403.67
1586.52	1419.67
1582.89	1398.67
1579.26	1406.33
1575.63	1423
1571.99	1417
1568.36	1413.33
1564.72	1433.33
1561.07	1433
1557.42	1445
1553.78	1430.67
1550.12	1428
1546.47	1437.33
1542.81	1452.33
1539.15	1448
1535.49	1470.33
1531.82	1438
1528.15	1445.67
1524.48	1464.67
1520.81	1464.67
1517.13	1449.33
1513.45	1461.67
1509.77	1473.67
1506.08	1466
1502.39	1466.33
1498.7	1467.33
1495.01	1472.67
1491.31	1479.67
1487.61	1515
1483.91	1520.33
1480.21	1514.67
1476.5	1540.33
1472.79	1561.33
1469.07	1556.33
1465.36	1593.67
1461.64	1608.33
1457.92	1612
1454.19	1632.33
1450.46	1646.33
1446.73	1617
1443	1620.33
1439.26	1624
1435.52	1601.67
1431.78	1593
1428.04	1597
1424.29	1587.33
1420.54	1596.67
1416.79	1583
1413.03	1578
1409.27	1568.67
1405.51	1574.33
1401.75	1569
1397.98	1562.33
1394.21	1556
1390.44	1549.67
1386.66	1534.33
1382.88	1546
1379.1	1547
1375.31	1543
1371.53	1543.33
1367.74	1568.67
1363.94	1530.33
1360.15	1560
1356.35	1590.33
1352.55	1610.67
1348.74	1584.67
1344.93	1617
1341.12	1633.67
1337.31	1621
1333.49	1625.33
1329.67	1643.33
1325.85	1630
1322.03	1659.33
1318.2	1655.67
1314.37	1653.67
1310.53	1681
1306.7	1666
1302.86	1668
1299.01	1680.67
1295.17	1674.67
1291.32	1705.33
1287.47	1696.67
1283.61	1705
1279.76	1697.33
1275.9	1714.67
1272.03	1712.33
1268.17	1725.67
1264.3	1713.33
1260.42	1693.33
1256.55	1680.33
1252.67	1699.67
1248.79	1676.33
1244.91	1655.67
1241.02	1663.67
1237.13	1664
1233.24	1626.33
1229.34	1627
1225.44	1600.33
1221.54	1587
1217.63	1565
1213.73	1551
1209.81	1538
1205.9	1520.67
1201.98	1527.33
1198.06	1507.67
1194.14	1486
1190.21	1507.33
1186.29	1506
1182.35	1498.33
1178.42	1486
1174.48	1481.67
1170.54	1493.33
1166.6	1503.67
1162.65	1479.67
1158.7	1480.67
1154.74	1484
1150.79	1498.33
1146.83	1526.67
1142.87	1502
1138.9	1497
1134.93	1496
1130.96	1508
1126.99	1497.33
1123.01	1510.33
1119.03	1498.33
1115.04	1509.67
1111.06	1528.33
1107.07	1542.67
1103.08	1528
1099.08	1531
1095.08	1570.33
1091.08	1564
1087.07	1568.33
1083.06	1540.33
1079.05	1545.67
1075.04	1578.67
1071.02	1582
1067	1549
1062.98	1572
1058.95	1560.67
1054.92	1551.33
1050.89	1548
1046.85	1558
1042.81	1579.33
1038.77	1562.33
1034.72	1556.33
1030.67	1575
1026.62	1575
1022.57	1612
1018.51	1598.33
1014.45	1598.33
1010.38	1609.33
1006.32	1621
1002.24	1620.67
998.171	1630.67
994.094	1628.67
990.013	1627
985.93	1629.67
981.843	1647
977.754	1660.67
973.661	1656
969.565	1685.33
965.466	1692.33
961.364	1684
957.258	1726
953.15	1736
949.038	1746.33
944.923	1748.33
940.804	1727
936.683	1730.67
932.558	1735
928.43	1721.33
924.299	1725.33
920.165	1716.67
916.028	1745.33
911.887	1727.67
907.743	1728.67
903.595	1705.67
899.445	1738.33
895.292	1717.67
891.135	1733
886.975	1742.33
882.812	1725.67
878.646	1747
874.475	1753
870.303	1784
866.126	1784.67
861.947	1784.33
857.764	1802.33
853.578	1791.67
849.389	1781
845.196	1797.67
841	1794.67
836.801	1778.33
832.599	1776.67
828.393	1787.67
824.184	1761.33
819.972	1738.33
815.757	1734.67
811.538	1721.67
807.316	1718
803.091	1719
798.863	1725.33
794.631	1716.67
790.395	1718.67
786.157	1702
781.915	1737.33
777.669	1739
773.421	1724.33
769.169	1739.33
764.915	1748.33
760.656	1748.33
756.394	1753.33
752.129	1778.67
747.861	1767.67
743.588	1773.33
739.314	1803.67
735.035	1777.67
730.753	1769.67
726.469	1780.33
722.18	1799.67
717.888	1773
713.593	1776.33
709.294	1776.33
704.992	1759.67
700.687	1768.67
696.378	1737.67
692.066	1766
687.751	1747.33
683.432	1745.67
679.109	1747.67
674.784	1744.67
670.455	1742.67
666.122	1754
661.787	1782
657.448	1779.67
653.104	1795.33
648.759	1789.33
644.409	1801
640.056	1796
635.7	1807
631.34	1818
626.977	1832
622.61	1829.33
618.24	1836.67
613.867	1818.67
609.49	1832
605.11	1803
600.726	1820
596.339	1797
591.948	1814
587.554	1821.33
583.156	1811
578.755	1828
574.35	1824.33
569.943	1822.33
565.531	1821.33
561.116	1827
556.698	1840
552.275	1828.67
547.85	1831.33
543.421	1866
538.988	1839
534.553	1863.67
530.113	1875.33
525.67	1877
521.224	1882
516.774	1888.67
512.321	1892
507.863	1890.33
503.403	1861.33
498.939	1861
494.472	1867
490.001	1858.67
485.526	1872.67
481.047	1840
476.565	1881
472.08	1860.67
467.591	1868
463.099	1899.33
458.604	1880.33
454.103	1892.67
449.601	1913.67
445.094	1898
440.584	1967.67
436.07	1915.67
431.553	1986
427.032	1976.67
422.507	1963.67
417.979	2014
413.448	2013.67
408.912	2025.67
404.373	2021.33
399.83	1997.67
395.285	2019.33
390.734	2015.33
386.181	2037.67
381.624	2029.67
377.064	2045.67
372.5	2061.33
367.932	2044
363.36	2054.33
358.785	2053.67
354.207	2078
349.624	2094.33
345.038	2103.67
340.448	2119
335.855	2116
331.257	2128
326.657	2144.33
322.053	2163.33
317.444	2178.67
312.833	2204.33
308.217	2205.33
303.599	2260.67
298.976	2263.33
294.349	2281.67
289.719	2321.33
285.085	2330.67
280.448	2377
275.807	2407.67
271.161	2429.67
266.513	2455
261.861	2498
257.205	2537.67
252.544	2537.33
247.881	2632
243.214	2670.67
238.543	2739.67
233.869	2765
229.19	2849.67
224.508	2911.33
219.822	2949.33
215.132	3016
210.439	3103.33
205.741	3179.33
201.04	3260.67
196.336	3319.67
191.627	3364.33
186.915	3488.67
182.199	3500
177.478	3597.33
172.755	3693
168.028	3772.33
163.297	3884.67
158.561	3948.33
153.823	4044
149.08	4097
144.334	4162
139.584	4355.67
134.829	4506.33
130.071	4619.67
125.31	4811.67
120.545	4940.33
115.775	5223
111.001	5462.33
106.224	5775.33
101.444	6142
96.6594	6570
91.8705	7073.67
87.0781	7821
82.282	8512
77.4812	9647.67
72.6778	11420.3
67.8698	14821.7
63.0582	18203.7
58.2419	20879.3
53.4229	23918
48.5993	27356.3
43.772	32233.7
38.941	39154.3
34.1054	50027
29.2661	64524
24.4231	64524
19.5764	64524
14.7261	64524
9.87099	64524
5.01321	64524
0.14975	64524
-4.71644	64524
-9.58634	64524
-14.461	64524
-19.3393	64524
-24.2214	64524
-29.1072	64524
-33.9977	64524
-38.892	42520.3
-43.7901	28647.3
-48.6919	21425
-53.5974	16298.3
-58.5078	12540.7
-63.4218	9733.67
-68.3397	7557
-73.2613	5908
-78.1878	4659
-83.117	3691.33
-88.051	2959
-92.9888	2444
-97.9314	2025.67
-102.877	1654.67
-107.827	1310.33
-112.781	1055
-117.739	889
-122.701	744.667
-127.667	620.667
-132.637	509
-137.612	417
-142.59	366.333
-147.572	326.333
-152.558	288
-157.548	247
-162.542	231.333
-167.541	216.667
-172.544	198
-177.55	200.667
-182.561	181.333
-187.576	174
-192.595	157.667
-197.617	171
-202.645	154.333
-207.676	158.333
-212.711	167
-217.75	156.333
-222.794	154.667
-227.842	134.333
-232.893	138.333
-237.949	131
-243.009	129.333
-248.073	135.667
-253.142	124.333
-258.214	125.333
-263.291	125.667
-268.371	116.667
-273.456	119
-278.545	106.667
-283.639	111
-288.735	109.333
-293.837	100
-298.943	100.667
-304.053	92.3333
-309.166	99
-314.285	101.667
-319.408	85.3333
-324.534	96
-329.665	82.6667
-334.801	83.6667
-339.94	84
-345.083	82
-350.231	89.6667
-355.383	79.6667
-360.539	82
-365.699	75.3333
-370.864	71.3333
-376.033	75.3333
-381.206	72.3333
-386.384	69.6667
-391.565	81
-396.751	68.3333
-401.941	70.3333
-407.136	64
-412.334	72.3333
-417.537	66.3333
-422.745	69
-427.956	70.3333
-433.173	63.6667
-438.392	67.6667
-443.617	67
-448.846	69.6667
-454.078	64.6667
-459.317	66
-464.558	58.6667
-469.804	61
-475.055	58.6667
-480.309	61.6667
-485.568	56.3333
-490.832	57.3333
-496.099	69.6667
-501.372	61
-506.648	61.6667
-511.929	60
-517.215	62
-522.504	65
-527.797	57.3333
-533.097	56.6667
-538.399	61
-543.706	64
-549.018	68
-554.334	63.3333
-559.654	69.3333
-564.979	60.6667
-570.308	63.6667
-575.641	57
-580.98	60.3333
-586.322	61
-591.669	62
-597.02	57.6667
-602.376	58
-607.736	58.6667
-613.1	64
-618.47	62
-623.843	56.3333
-629.222	57.6667
-634.603	63
-639.99	62
-645.382	65.3333
-650.779	54
-656.179	66
-661.583	60
-666.993	55.3333
-672.407	66.3333
-677.825	66.6667
-683.248	68.6667
-688.675	66.3333
-694.108	65
-699.544	66.3333
-704.985	65.3333
-710.431	65.6667
-715.88	69.3333
-721.335	64.3333
-726.795	68.6667
-732.258	63
-737.727	68
-743.2	63
-748.678	72.3333
-754.159	61
-759.646	63.6667
-765.138	63
-770.633	61
-776.133	58.6667
-781.638	61.3333
-787.149	62
-792.663	64.3333
-798.181	65.3333
-803.705	64
-809.233	61.3333
-814.766	61
-820.304	65.6667
-825.846	58.3333
-831.392	70
-836.944	57
-842.499	67
-848.06	62.3333
-853.626	57.6667
-859.195	56.3333
-864.77	58.3333
-870.35	57.3333
-875.934	61
-881.522	55.3333
-887.116	58.6667
-892.714	61.3333
-898.317	61
-903.924	57.6667
-909.537	65
-915.153	57.6667
-920.776	64
-926.401	48
-932.033	65.6667
-937.669	63.6667
-943.31	63
-948.955	65
-954.605	68.3333
-960.26	60.6667
-965.92	66.6667
-971.584	67
-977.254	66
-982.928	70.6667
-988.607	60
-994.291	72.3333
-999.979	67.3333
-1005.67	60.3333
-1011.37	62.6667
-1017.07	71.6667
-1022.78	69.6667
-1028.49	68.3333
-1034.21	63
-1039.93	67.3333
-1045.66	71
-1051.39	63
-1057.13	72
-1062.87	73
-1068.62	65
-1074.37	72.6667
-1080.12	70
-1085.89	73
-1091.65	76.3333
-1097.42	66.6667
-1103.2	80
-1108.98	82.6667
-1114.77	84.3333
-1120.56	81
-1126.35	83.3333
-1132.15	80.3333
-1137.96	77.6667
-1143.77	89.6667
-1149.58	84
-1155.4	99
-1161.23	93.3333
-1167.06	101
-1172.89	124
-1178.73	152
-1184.58	214
-1190.43	247.333
-1196.28	300.667
-1202.14	354
-1208.01	429.667
-1213.88	498
-1219.75	536.333
-1225.63	608.667
-1231.52	701
-1237.41	857
-1243.3	1077.67
-1249.2	1839.67
-1255.11	1929.33
-1261.02	1729.33
-1266.93	1478
-1272.85	934.333
-1278.78	411
-1284.71	190.667
-1290.65	161.667
-1296.59	137
-1302.53	108.333
-1308.48	114.667
-1314.44	111
-1320.4	98
-1326.37	99.3333
-1332.34	104
-1338.31	99.6667
-1344.29	93.3333
-1350.28	93
-1356.27	85
-1362.27	91.6667
-1368.27	80
-1374.28	73
-1380.29	74
-1386.31	61
-1392.33	61.6667
-1051.39	63
-1057.13	72
-1062.87	73
-1068.62	65
-1074.37	72.6667
-1080.12	70
-1085.89	73
-1091.65	76.3333
-1097.42	66.6667
-1103.2	80
-1108.98	82.6667
-1114.77	84.3333
-1120.56	81
-1126.35	83.3333
-1132.15	80.3333
-1137.96	77.6667
-1143.77	89.6667
-1149.58	84
-1155.4	99
-1161.23	93.3333
-1167.06	101
-1172.89	124
-1178.73	152
-1184.58	214
-1190.43	247.333
-1196.28	300.667
-1202.14	354
-1208.01	429.667
-1213.88	498
-1219.75	536.333
-1225.63	608.667
-1231.52	701
-1237.41	857
-1243.3	1077.67
-1249.2	1839.67
-1255.11	1929.33
-1261.02	1729.33
-1266.93	1478
-1272.85	934.333
-1278.78	411
-1284.71	190.667
-1290.65	161.667
-1296.59	137
-1302.53	108.333
-1308.48	114.667
-1314.44	111
-1320.4	98
-1326.37	99.3333
-1332.34	104
-1338.31	99.6667
-1344.29	93.3333
-1350.28	93
-1356.27	85
-1362.27	91.6667
-1368.27	80
-1374.28	73
-1380.29	74
-1386.31	61
-1392.33	61.6667