File: projects/python/data/20231030/thenar_600_785 nm_10 s_1_2023_10_30_15_15_07_01.txt
#Sample=thenar
#Laser=785 nm
#Grating=600
#Exposition=10
#Accumulation=1
#Acquired=30.10.2023 15:15:07
2745.96	249
2743.18	250.667
2740.41	255.667
2737.63	256
2734.85	257.333
2732.07	256.333
2729.29	266
2726.5	255.667
2723.72	256
2720.93	261
2718.14	266
2715.34	264
2712.55	263
2709.75	262
2706.95	265.667
2704.15	271.667
2701.35	269.333
2698.55	266.667
2695.74	277.333
2692.93	285
2690.12	281.333
2687.31	287.333
2684.49	281
2681.67	286.667
2678.85	277
2676.03	290.333
2673.21	288.667
2670.38	292
2667.56	305.333
2664.73	295.667
2661.9	293
2659.06	280.333
2656.23	299
2653.39	298
2650.55	302
2647.71	300
2644.86	313
2642.02	314
2639.17	314.667
2636.32	313
2633.47	328.333
2630.62	321.667
2627.76	320
2624.9	334.667
2622.04	328.667
2619.18	341.333
2616.31	319
2613.45	330.667
2610.58	327.333
2607.71	337
2604.84	345.667
2601.96	330.333
2599.08	342.333
2596.21	339.667
2593.32	332
2590.44	339.667
2587.56	346.333
2584.67	360.333
2581.78	351.667
2578.89	360
2575.99	358.667
2573.1	357.333
2570.2	369.667
2567.3	370.333
2564.4	375.667
2561.5	375
2558.59	375.667
2555.68	381.333
2552.77	391.667
2549.86	382
2546.94	377.333
2544.03	390
2541.11	393.667
2538.19	390.333
2535.26	400
2532.34	390.667
2529.41	402.333
2526.48	408
2523.55	399.333
2520.62	405
2517.68	415.333
2514.74	408.333
2511.8	414.333
2508.86	418.333
2505.92	422.333
2502.97	423
2500.02	426.333
2497.07	428
2494.12	416
2491.16	431
2488.2	431.333
2485.25	440.333
2482.28	442
2479.32	445.667
2476.35	446.333
2473.39	458.333
2470.42	444.667
2467.44	457
2464.47	464
2461.49	464.667
2458.51	468.667
2455.53	460
2452.55	474.667
2449.56	482.333
2446.58	491.333
2443.59	483.667
2440.59	498.667
2437.6	485.333
2434.6	484.667
2431.61	497.667
2428.61	499.667
2425.6	500
2422.6	503.333
2419.59	511.667
2416.58	503
2413.57	518.333
2410.56	524.667
2407.54	511
2404.52	523
2401.5	517.333
2398.48	529
2395.45	518
2392.43	532.333
2389.4	512
2386.37	540
2383.33	536.333
2380.3	548
2377.26	551
2374.22	547.667
2371.17	554.667
2368.13	561
2365.08	557.667
2362.03	566.333
2358.98	569.333
2355.93	571.667
2352.87	580
2349.81	569.667
2346.75	591
2343.69	583.667
2340.63	574
2337.56	592.667
2334.49	584
2331.42	605.333
2328.35	585
2325.27	597.667
2322.19	599.667
2319.11	603.333
2316.03	590.667
2312.94	613.333
2309.85	618.333
2306.77	606
2303.67	624
2300.58	641.333
2297.48	634
2294.38	649
2291.28	637.667
2288.18	642
2285.07	641
2281.97	649.667
2278.86	663.333
2275.74	651.667
2272.63	661
2269.51	657
2266.39	672.333
2263.27	661.333
2260.15	667
2257.02	671
2253.89	665.667
2250.76	679
2247.63	701.667
2244.49	677.667
2241.36	676.333
2238.22	688.667
2235.08	702.667
2231.93	704.333
2228.78	709.333
2225.63	699.667
2222.48	690.333
2219.33	708
2216.17	709.333
2213.01	719.333
2209.85	712
2206.69	705.333
2203.53	713.333
2200.36	733
2197.19	728
2194.02	724.333
2190.84	732.667
2187.66	758
2184.48	728.333
2181.3	754.667
2178.12	756.667
2174.93	757.333
2171.74	761.333
2168.55	755.667
2165.36	765
2162.16	770
2158.97	783.333
2155.76	778.333
2152.56	789.333
2149.36	785.333
2146.15	791.667
2142.94	812.333
2139.73	801.333
2136.51	796
2133.29	814
2130.08	830.333
2126.85	812.667
2123.63	832.333
2120.4	821.667
2117.17	816
2113.94	812
2110.71	838
2107.47	826
2104.23	825.667
2100.99	843.333
2097.75	834.333
2094.5	839.667
2091.26	844
2088.01	855
2084.75	845.333
2081.5	872.667
2078.24	862
2074.98	868
2071.72	891
2068.45	861.333
2065.18	890.333
2061.92	877
2058.64	910.333
2055.37	894
2052.09	902.333
2048.81	900.667
2045.53	916.667
2042.25	923
2038.96	919
2035.67	909.333
2032.38	933.667
2029.08	920.667
2025.79	936.333
2022.49	923.333
2019.19	935.333
2015.88	932
2012.58	950.333
2009.27	939.333
2005.96	963.667
2002.64	962.667
1999.33	957
1996.01	958
1992.69	963.667
1989.36	971.333
1986.04	989
1982.71	984.333
1979.38	1001.33
1976.05	1013.67
1972.71	1009.33
1969.37	1002
1966.03	1041
1962.69	1044.67
1959.34	1045.33
1955.99	1038.33
1952.64	1056.33
1949.29	1041.67
1945.93	1068
1942.58	1063
1939.21	1081.67
1935.85	1077.33
1932.49	1076.33
1929.12	1083.67
1925.75	1097
1922.37	1087
1919	1115.67
1915.62	1099
1912.24	1121.67
1908.86	1102
1905.47	1107.33
1902.08	1094
1898.69	1132.33
1895.3	1131.33
1891.9	1129.33
1888.5	1134.67
1885.1	1152.67
1881.7	1133.33
1878.29	1123.67
1874.88	1165.67
1871.47	1165
1868.06	1154
1864.64	1142
1861.22	1172.67
1857.8	1163.33
1854.38	1163.33
1850.95	1175
1847.52	1187.33
1844.09	1185.33
1840.66	1198
1837.22	1191.33
1833.78	1197
1830.34	1214.33
1826.9	1193
1823.45	1214.33
1820	1223.33
1816.55	1252.67
1813.09	1255
1809.64	1248
1806.18	1254
1802.71	1263.67
1799.25	1264.33
1795.78	1258.33
1792.31	1283
1788.84	1280.33
1785.36	1289
1781.88	1286
1778.4	1321.33
1774.92	1309
1771.43	1322
1767.95	1304.67
1764.45	1303
1760.96	1336
1757.47	1326.33
1753.97	1334.33
1750.47	1337
1746.96	1330
1743.45	1386.33
1739.94	1369
1736.43	1394.67
1732.92	1386
1729.4	1404.67
1725.88	1415.33
1722.36	1449.67
1718.83	1436.33
1715.3	1438
1711.77	1464
1708.24	1477.33
1704.71	1476.33
1701.17	1522.33
1697.63	1542.67
1694.08	1551.33
1690.54	1615.33
1686.99	1618
1683.44	1623.33
1679.88	1649.67
1676.32	1655.33
1672.76	1678.33
1669.2	1709
1665.64	1703.33
1662.07	1717.33
1658.5	1734.67
1654.92	1749
1651.35	1724.33
1647.77	1772.67
1644.19	1758.33
1640.61	1756.33
1637.02	1725.33
1633.43	1715
1629.84	1712.33
1626.24	1693
1622.64	1669
1619.04	1680
1615.44	1659.67
1611.84	1646.33
1608.23	1660.67
1604.62	1680.67
1601	1663.67
1597.39	1658.67
1593.77	1643.67
1590.15	1653.33
1586.52	1650.67
1582.89	1663.67
1579.26	1682.33
1575.63	1676.33
1571.99	1672.33
1568.36	1670.67
1564.72	1665.33
1561.07	1684
1557.42	1686
1553.78	1675.33
1550.12	1696
1546.47	1682.33
1542.81	1696
1539.15	1719
1535.49	1721.33
1531.82	1686
1528.15	1690
1524.48	1708.33
1520.81	1677.33
1517.13	1712.67
1513.45	1713.67
1509.77	1726.33
1506.08	1712.67
1502.39	1716.67
1498.7	1746.33
1495.01	1747
1491.31	1728.67
1487.61	1782.33
1483.91	1781.67
1480.21	1779
1476.5	1822.67
1472.79	1818.67
1469.07	1846.67
1465.36	1860.33
1461.64	1877.33
1457.92	1892.33
1454.19	1902.33
1450.46	1915.33
1446.73	1905
1443	1901
1439.26	1900
1435.52	1890.67
1431.78	1880
1428.04	1855.67
1424.29	1847.33
1420.54	1849
1416.79	1848
1413.03	1853.67
1409.27	1838
1405.51	1820
1401.75	1853.33
1397.98	1851
1394.21	1824.33
1390.44	1815.67
1386.66	1796.33
1382.88	1805.67
1379.1	1806
1375.31	1797.67
1371.53	1810
1367.74	1806
1363.94	1840.67
1360.15	1830.67
1356.35	1859.33
1352.55	1871.67
1348.74	1873.67
1344.93	1879.67
1341.12	1864
1337.31	1892.33
1333.49	1878.33
1329.67	1908.33
1325.85	1905
1322.03	1905.33
1318.2	1920.33
1314.37	1913.67
1310.53	1947
1306.7	1923.67
1302.86	1966
1299.01	1934
1295.17	1953.67
1291.32	1956
1287.47	1977
1283.61	1979.33
1279.76	1995.67
1275.9	1988.67
1272.03	1992
1268.17	1946.33
1264.3	1955.67
1260.42	1929.67
1256.55	1952.33
1252.67	1948
1248.79	1945.33
1244.91	1948.33
1241.02	1928.67
1237.13	1915.67
1233.24	1892.67
1229.34	1916.67
1225.44	1881.67
1221.54	1859.33
1217.63	1842.33
1213.73	1817.67
1209.81	1808.67
1205.9	1795.33
1201.98	1798.33
1198.06	1775.67
1194.14	1773
1190.21	1765
1186.29	1764.67
1182.35	1756
1178.42	1747.67
1174.48	1784.33
1170.54	1750.67
1166.6	1741
1162.65	1751
1158.7	1765.33
1154.74	1744.67
1150.79	1747.67
1146.83	1750.33
1142.87	1774.67
1138.9	1775.33
1134.93	1781.33
1130.96	1787
1126.99	1763.33
1123.01	1776
1119.03	1775
1115.04	1786.67
1111.06	1813
1107.07	1797.67
1103.08	1820
1099.08	1807
1095.08	1833
1091.08	1834.67
1087.07	1841
1083.06	1824.67
1079.05	1850
1075.04	1857.33
1071.02	1820.67
1067	1849.67
1062.98	1859.33
1058.95	1846.33
1054.92	1824.67
1050.89	1839.67
1046.85	1842.33
1042.81	1841.67
1038.77	1864.67
1034.72	1856.67
1030.67	1850.67
1026.62	1858
1022.57	1852.33
1018.51	1884
1014.45	1889.33
1010.38	1867.33
1006.32	1883.33
1002.24	1890.67
998.171	1898
994.094	1929
990.013	1914
985.93	1936.33
981.843	1940.67
977.754	1964.33
973.661	1976.67
969.565	1963
965.466	1994.33
961.364	2019
957.258	2026.67
953.15	2035.67
949.038	2014.33
944.923	2036.33
940.804	2032.33
936.683	2050.67
932.558	2039.67
928.43	2029.33
924.299	2015.33
920.165	2032.33
916.028	2012.67
911.887	2049.33
907.743	2024.67
903.595	1997.67
899.445	2030
895.292	2033.67
891.135	2049.67
886.975	2047
882.812	2044.33
878.646	2069.67
874.475	2065.33
870.303	2088.33
866.126	2092.33
861.947	2108
857.764	2104
853.578	2108.33
849.389	2084.67
845.196	2088.33
841	2075.33
836.801	2076.33
832.599	2100
828.393	2088.67
824.184	2068.67
819.972	2062
815.757	2075.67
811.538	2034.33
807.316	2039.33
803.091	2025.67
798.863	2021.33
794.631	2060.33
790.395	2024.67
786.157	2009.33
781.915	2006.33
777.669	2032
773.421	2010
769.169	2035.33
764.915	2029
760.656	2038.67
756.394	2062.67
752.129	2062.33
747.861	2066.33
743.588	2070.33
739.314	2095.67
735.035	2091.33
730.753	2101
726.469	2099.33
722.18	2117.67
717.888	2105
713.593	2098.67
709.294	2068.67
704.992	2077
700.687	2093
696.378	2063
692.066	2082
687.751	2046
683.432	2046
679.109	2037.33
674.784	2036.33
670.455	2051.67
666.122	2071.33
661.787	2080
657.448	2066
653.104	2075.67
648.759	2089.67
644.409	2131.33
640.056	2095
635.7	2133.33
631.34	2159.67
626.977	2120.33
622.61	2150
618.24	2156.67
613.867	2145.67
609.49	2124
605.11	2119.67
600.726	2109.67
596.339	2116.33
591.948	2117.67
587.554	2128.33
583.156	2120.67
578.755	2129
574.35	2119
569.943	2133.33
565.531	2137.67
561.116	2135.67
556.698	2135
552.275	2144.33
547.85	2130
543.421	2150
538.988	2173.67
534.553	2163
530.113	2191.33
525.67	2184.67
521.224	2190.33
516.774	2214
512.321	2196
507.863	2191
503.403	2178
498.939	2183.67
494.472	2151.33
490.001	2162
485.526	2149
481.047	2150
476.565	2146.67
472.08	2164.67
467.591	2195.33
463.099	2202
458.604	2183.67
454.103	2209.33
449.601	2208.33
445.094	2221.67
440.584	2222.67
436.07	2267.67
431.553	2254
427.032	2289.67
422.507	2320.67
417.979	2310.67
413.448	2329.33
408.912	2350
404.373	2300.67
399.83	2301.67
395.285	2325
390.734	2322
386.181	2331.33
381.624	2322.67
377.064	2320
372.5	2338.33
367.932	2328.67
363.36	2366
358.785	2347.67
354.207	2382
349.624	2397
345.038	2430
340.448	2456
335.855	2427.33
331.257	2414.33
326.657	2461
322.053	2451.67
317.444	2498
312.833	2514.33
308.217	2537.33
303.599	2580.67
298.976	2564.33
294.349	2620.33
289.719	2680.67
285.085	2682.33
280.448	2717
275.807	2760.67
271.161	2787.67
266.513	2777.33
261.861	2832.67
257.205	2862.67
252.544	2908
247.881	2955
243.214	3020.33
238.543	3062
233.869	3139
229.19	3228.33
224.508	3269
219.822	3349
215.132	3392.33
210.439	3493.33
205.741	3530.33
201.04	3627.33
196.336	3731.33
191.627	3755
186.915	3896.67
182.199	3960.67
177.478	4050.67
172.755	4134.67
168.028	4252
163.297	4303
158.561	4422.67
153.823	4479.67
149.08	4590
144.334	4671
139.584	4865.67
134.829	4995.33
130.071	5157.33
125.31	5398.67
120.545	5547
115.775	5790
111.001	6161.33
106.224	6486.33
101.444	6874
96.6594	7348.33
91.8705	7907.33
87.0781	8620
82.282	9476
77.4812	10625.3
72.6778	12437
67.8698	15818.7
63.0582	19106
58.2419	21888.3
53.4229	24944.7
48.5993	28594.3
43.772	33503
38.941	40731.7
34.1054	51736
29.2661	64524
24.4231	64524
19.5764	64524
14.7261	64524
9.87099	64524
5.01321	64524
0.14975	64524
-4.71644	64524
-9.58634	64524
-14.461	64524
-19.3393	64524
-24.2214	64524
-29.1072	64524
-33.9977	64524
-38.892	44341.3
-43.7901	29926.7
-48.6919	22307.3
-53.5974	16902
-58.5078	12951
-63.4218	10100
-68.3397	7845
-73.2613	6107.67
-78.1878	4811.67
-83.117	3798
-88.051	3049.67
-92.9888	2508.33
-97.9314	2069
-102.877	1711.67
-107.827	1341.67
-112.781	1064.67
-117.739	906.333
-122.701	778.333
-127.667	656
-132.637	516
-137.612	437
-142.59	384.333
-147.572	333.667
-152.558	292.667
-157.548	264.333
-162.542	242
-167.541	214.333
-172.544	210.667
-177.55	191
-182.561	174.667
-187.576	177
-192.595	179.667
-197.617	172.667
-202.645	156.667
-207.676	160.333
-212.711	158
-217.75	157.333
-222.794	141.667
-227.842	142
-232.893	143.333
-237.949	128.667
-243.009	133
-248.073	130.667
-253.142	127
-258.214	135
-263.291	132.333
-268.371	112
-273.456	126.333
-278.545	111.667
-283.639	114.333
-288.735	105.667
-293.837	103.667
-298.943	113.667
-304.053	102.667
-309.166	99.3333
-314.285	96.3333
-319.408	85.3333
-324.534	96
-329.665	94
-334.801	92
-339.94	81.3333
-345.083	82
-350.231	82.3333
-355.383	91
-360.539	79.3333
-365.699	78.3333
-370.864	84.6667
-376.033	83
-381.206	79.6667
-386.384	76
-391.565	74.6667
-396.751	83
-401.941	72
-407.136	70.6667
-412.334	72
-417.537	77
-422.745	68.3333
-427.956	73.3333
-433.173	63.3333
-438.392	68.6667
-443.617	77
-448.846	62
-454.078	68
-459.317	66.6667
-464.558	69.6667
-469.804	75
-475.055	72
-480.309	65.3333
-485.568	68.3333
-490.832	67.6667
-496.099	65.3333
-501.372	68
-506.648	63.6667
-511.929	60
-517.215	68
-522.504	67.3333
-527.797	72.3333
-533.097	69
-538.399	65
-543.706	68.6667
-549.018	62.3333
-554.334	59.6667
-559.654	51.6667
-564.979	54.6667
-570.308	75.3333
-575.641	62.3333
-580.98	63.6667
-586.322	59
-591.669	60
-597.02	67.6667
-602.376	66.6667
-607.736	65
-613.1	62
-618.47	73.6667
-623.843	64.6667
-629.222	68.6667
-634.603	62.6667
-639.99	59.6667
-645.382	63
-650.779	67.6667
-656.179	68.3333
-661.583	58.3333
-666.993	65.3333
-672.407	69.3333
-677.825	63.6667
-683.248	63.6667
-688.675	60.3333
-694.108	63.3333
-699.544	62.3333
-704.985	67.6667
-710.431	61
-715.88	62.6667
-721.335	66.3333
-726.795	59.6667
-732.258	66.3333
-737.727	63
-743.2	65.6667
-748.678	70
-754.159	56.3333
-759.646	72.3333
-765.138	60.3333
-770.633	59.6667
-776.133	62
-781.638	62.6667
-787.149	74.3333
-792.663	68.3333
-798.181	60.6667
-803.705	59.6667
-809.233	61.6667
-814.766	63
-820.304	68
-825.846	64.6667
-831.392	63.6667
-836.944	57
-842.499	60.6667
-848.06	65.3333
-853.626	64.3333
-859.195	66.6667
-864.77	59.3333
-870.35	62.3333
-875.934	65.3333
-881.522	60
-887.116	66.3333
-892.714	63.3333
-898.317	66.3333
-903.924	63.6667
-909.537	76
-915.153	63
-920.776	68
-926.401	66.6667
-932.033	68
-937.669	69
-943.31	70.3333
-948.955	68.3333
-954.605	68.6667
-960.26	66.3333
-965.92	74
-971.584	61.6667
-977.254	60
-982.928	65.3333
-988.607	68
-994.291	66
-999.979	70.6667
-1005.67	68.6667
-1011.37	72
-1017.07	72.6667
-1022.78	70.3333
-1028.49	69.3333
-1034.21	76.6667
-1039.93	68
-1045.66	69.6667
-1051.39	77.3333
-1057.13	80.3333
-1062.87	75
-1068.62	74.3333
-1074.37	76.3333
-1080.12	77.6667
-1085.89	84
-1091.65	78.3333
-1097.42	75
-1103.2	79.6667
-1108.98	79.3333
-1114.77	87.6667
-1120.56	75.3333
-1126.35	82
-1132.15	76.6667
-1137.96	88.6667
-1143.77	80.6667
-1149.58	93.6667
-1155.4	90.6667
-1161.23	96
-1167.06	99.6667
-1172.89	119.667
-1178.73	171.333
-1184.58	229
-1190.43	270.667
-1196.28	315.667
-1202.14	378.667
-1208.01	454.667
-1213.88	486.333
-1219.75	550
-1225.63	624
-1231.52	731
-1237.41	852.333
-1243.3	1184.67
-1249.2	1907
-1255.11	2153.33
-1261.02	1909
-1266.93	1550
-1272.85	1015.33
-1278.78	409
-1284.71	186
-1290.65	160.667
-1296.59	146
-1302.53	125
-1308.48	118
-1314.44	116.667
-1320.4	111.667
-1326.37	109.667
-1332.34	103.667
-1338.31	100
-1344.29	96
-1350.28	99.3333
-1356.27	91.3333
-1362.27	86.6667
-1368.27	82.3333
-1374.28	74
-1380.29	65.3333
-1386.31	64.3333
-1392.33	60.3333
-1054.26	68.3333
-1060	81.6667
-1065.74	75.6667
-1071.49	77
-1077.25	73.6667
-1083.01	81
-1088.77	75
-1094.54	78
-1100.31	77.6667
-1106.09	89.6667
-1111.87	91
-1117.66	79.3333
-1123.45	77
-1129.25	82
-1135.05	84.6667
-1140.86	86
-1146.67	87.3333
-1152.49	94.6667
-1158.32	97.3333
-1164.14	96.6667
-1169.98	112
-1175.81	147.333
-1181.66	202.667
-1187.5	250
-1193.35	286
-1199.21	338.667
-1205.08	411.333
-1210.94	481.333
-1216.82	516
-1222.69	591
-1228.58	660.667
-1234.46	778.667
-1240.35	1014.33
-1246.25	1602.33
-1252.16	2015.33
-1258.06	2090.33
-1263.97	1721.33
-1269.89	1293
-1275.82	684
-1281.74	246
-1287.68	166.667
-1293.62	163.333
-1299.56	130.667
-1305.51	119.333
-1311.46	111.333
-1317.42	108
-1323.38	118
-1329.35	110.667
-1335.32	102
-1341.3	94
-1347.29	98
-1353.28	94.3333
-1359.27	91.3333
-1365.27	80.6667
-1371.27	82.6667
-1377.28	71
-1383.3	72
-1389.32	61.3333
-1392.33	60.3333