File: projects/python/data/20231030/tip_600_785 nm_10 s_1_2023_10_30_14_56_22_01.txt
#Sample=tip
#Laser=785 nm
#Grating=600
#Exposition=10
#Accumulation=1
#Acquired=30.10.2023 14:56:22
2745.96	124.667
2743.18	131
2740.41	128
2737.63	135
2734.85	124.333
2732.07	121.333
2729.29	121.667
2726.5	129.667
2723.72	133.333
2720.93	129.333
2718.14	131.333
2715.34	131.333
2712.55	129
2709.75	135
2706.95	131.667
2704.15	140.667
2701.35	134
2698.55	125.667
2695.74	137.333
2692.93	139
2690.12	135.667
2687.31	133
2684.49	135.667
2681.67	134.667
2678.85	146
2676.03	133
2673.21	137.333
2670.38	141.333
2667.56	139.333
2664.73	139.333
2661.9	144.667
2659.06	175.667
2656.23	153.667
2653.39	144
2650.55	150.333
2647.71	144.333
2644.86	147.667
2642.02	143
2639.17	153.667
2636.32	148.667
2633.47	148.667
2630.62	157.667
2627.76	159.333
2624.9	152.333
2622.04	154
2619.18	161
2616.31	157.667
2613.45	156
2610.58	162.667
2607.71	148
2604.84	161
2601.96	161.333
2599.08	164
2596.21	167.667
2593.32	159
2590.44	154.667
2587.56	162.667
2584.67	156
2581.78	167
2578.89	164.667
2575.99	168
2573.1	178.333
2570.2	165.667
2567.3	166
2564.4	173.333
2561.5	168.333
2558.59	172.333
2555.68	175
2552.77	176
2549.86	166.667
2546.94	179.667
2544.03	189.667
2541.11	184.333
2538.19	185.333
2535.26	181.333
2532.34	186.667
2529.41	184.333
2526.48	181.333
2523.55	184.333
2520.62	196.333
2517.68	198.333
2514.74	190.667
2511.8	192
2508.86	188.667
2505.92	183
2502.97	188.667
2500.02	187
2497.07	190
2494.12	195.667
2491.16	197.667
2488.2	207.667
2485.25	200.333
2482.28	196.667
2479.32	199
2476.35	211
2473.39	215
2470.42	195
2467.44	212.333
2464.47	216.333
2461.49	206.667
2458.51	215
2455.53	217.333
2452.55	222.333
2449.56	214.333
2446.58	219
2443.59	223
2440.59	220.333
2437.6	216.667
2434.6	229
2431.61	215.667
2428.61	227
2425.6	221.333
2422.6	229.667
2419.59	228.667
2416.58	233
2413.57	240.667
2410.56	232
2407.54	231.667
2404.52	242.667
2401.5	230.667
2398.48	244.667
2395.45	243
2392.43	244
2389.4	243
2386.37	249
2383.33	236
2380.3	244.333
2377.26	248.667
2374.22	250
2371.17	249.667
2368.13	262.667
2365.08	255.333
2362.03	245
2358.98	267.667
2355.93	250
2352.87	269
2349.81	250.333
2346.75	247.667
2343.69	266
2340.63	266.667
2337.56	262.667
2334.49	266.667
2331.42	263.667
2328.35	263
2325.27	280
2322.19	262.333
2319.11	274.667
2316.03	273.333
2312.94	280
2309.85	277.667
2306.77	281.333
2303.67	277.333
2300.58	279.333
2297.48	285.333
2294.38	294
2291.28	278.333
2288.18	296
2285.07	293.333
2281.97	288
2278.86	292.333
2275.74	291
2272.63	292.333
2269.51	305.667
2266.39	299.333
2263.27	297.667
2260.15	308.333
2257.02	302.667
2253.89	298
2250.76	291
2247.63	308.667
2244.49	313
2241.36	326.333
2238.22	316.667
2235.08	304
2231.93	316.333
2228.78	310
2225.63	306
2222.48	319
2219.33	321.333
2216.17	324
2213.01	320.333
2209.85	323
2206.69	328.333
2203.53	326.333
2200.36	324.667
2197.19	337
2194.02	333.333
2190.84	322
2187.66	328.667
2184.48	335
2181.3	333.333
2178.12	335.333
2174.93	341
2171.74	350.667
2168.55	342.667
2165.36	350.333
2162.16	343.333
2158.97	351.333
2155.76	360.667
2152.56	350.667
2149.36	361.333
2146.15	355.333
2142.94	370.667
2139.73	365
2136.51	376.333
2133.29	365.333
2130.08	371
2126.85	370
2123.63	373
2120.4	370
2117.17	365.667
2113.94	375
2110.71	380.667
2107.47	384.667
2104.23	380.667
2100.99	380
2097.75	379.333
2094.5	381.333
2091.26	386
2088.01	391.333
2084.75	388.333
2081.5	390
2078.24	380.667
2074.98	400.667
2071.72	402
2068.45	401
2065.18	399.667
2061.92	419.333
2058.64	409.333
2055.37	415.667
2052.09	412.333
2048.81	413
2045.53	418.333
2042.25	416
2038.96	427.333
2035.67	416.333
2032.38	429
2029.08	408.667
2025.79	428.667
2022.49	426
2019.19	422
2015.88	430
2012.58	427.667
2009.27	431.333
2005.96	446.667
2002.64	432.333
1999.33	443.333
1996.01	448.333
1992.69	433.667
1989.36	446.667
1986.04	445
1982.71	457.333
1979.38	451
1976.05	457
1972.71	467.333
1969.37	447
1966.03	460.333
1962.69	485.333
1959.34	483
1955.99	486.667
1952.64	471
1949.29	484.333
1945.93	486.667
1942.58	503.333
1939.21	515.667
1935.85	496
1932.49	496
1929.12	520
1925.75	506
1922.37	508.333
1919	523.333
1915.62	518
1912.24	530
1908.86	529
1905.47	515
1902.08	525.333
1898.69	526.667
1895.3	530.667
1891.9	526.667
1888.5	548.667
1885.1	537.333
1881.7	531
1878.29	544.333
1874.88	544
1871.47	544
1868.06	565.667
1864.64	554
1861.22	561.333
1857.8	554
1854.38	559.667
1850.95	558.667
1847.52	582.333
1844.09	583.333
1840.66	579.333
1837.22	581.667
1833.78	588.333
1830.34	585.667
1826.9	580.667
1823.45	600.333
1820	593.667
1816.55	588
1813.09	603.333
1809.64	591.333
1806.18	621.667
1802.71	627.667
1799.25	630.667
1795.78	632.333
1792.31	645.333
1788.84	650.667
1785.36	621.333
1781.88	654.333
1778.4	657.667
1774.92	663.333
1771.43	663
1767.95	677.667
1764.45	666.667
1760.96	678.667
1757.47	682.333
1753.97	679.667
1750.47	688.333
1746.96	685.333
1743.45	692
1739.94	698.667
1736.43	705.667
1732.92	726.333
1729.4	721.667
1725.88	724.333
1722.36	720.667
1718.83	752.667
1715.3	735.667
1711.77	752
1708.24	764.333
1704.71	773
1701.17	774.333
1697.63	795.333
1694.08	801.333
1690.54	784
1686.99	799.333
1683.44	809
1679.88	824.667
1676.32	819.667
1672.76	849.667
1669.2	830.333
1665.64	823.667
1662.07	857.667
1658.5	847.667
1654.92	868.333
1651.35	879
1647.77	887.333
1644.19	876.333
1640.61	878.333
1637.02	874
1633.43	880
1629.84	892.333
1626.24	865.333
1622.64	872.333
1619.04	865.667
1615.44	870.333
1611.84	860.333
1608.23	870.667
1604.62	869
1601	868.667
1597.39	873.667
1593.77	858
1590.15	885.667
1586.52	862
1582.89	882.667
1579.26	875.333
1575.63	901.333
1571.99	910.667
1568.36	910.333
1564.72	885.333
1561.07	901.333
1557.42	920
1553.78	901.667
1550.12	913.333
1546.47	899.333
1542.81	915.667
1539.15	930
1535.49	904.333
1531.82	899.333
1528.15	910.333
1524.48	932
1520.81	935
1517.13	913.667
1513.45	915
1509.77	929.667
1506.08	923
1502.39	916.667
1498.7	932.333
1495.01	946
1491.31	936
1487.61	948.333
1483.91	930
1480.21	951.333
1476.5	949.667
1472.79	963.667
1469.07	962
1465.36	977.333
1461.64	978.667
1457.92	975.333
1454.19	987
1450.46	991.667
1446.73	996.333
1443	971.667
1439.26	982.333
1435.52	972.667
1431.78	949.667
1428.04	974.667
1424.29	961.333
1420.54	957
1416.79	962.667
1413.03	977
1409.27	936
1405.51	950.667
1401.75	953.333
1397.98	962.667
1394.21	977.333
1390.44	957
1386.66	945.333
1382.88	941
1379.1	929
1375.31	941.333
1371.53	935.667
1367.74	958.333
1363.94	959.667
1360.15	968
1356.35	960
1352.55	965
1348.74	983.333
1344.93	977
1341.12	983.333
1337.31	976.667
1333.49	977.333
1329.67	985
1325.85	994.333
1322.03	1000
1318.2	998.333
1314.37	1002
1310.53	1038.67
1306.7	1044.33
1302.86	1024
1299.01	1045.67
1295.17	1057.33
1291.32	1052
1287.47	1071.33
1283.61	1080
1279.76	1071.67
1275.9	1084.33
1272.03	1087.67
1268.17	1096
1264.3	1093.33
1260.42	1069
1256.55	1064.33
1252.67	1065.33
1248.79	1059.67
1244.91	1047
1241.02	1065.67
1237.13	1040
1233.24	1026.67
1229.34	1015.67
1225.44	1010.67
1221.54	992.667
1217.63	974.667
1213.73	959
1209.81	946.333
1205.9	959.333
1201.98	957
1198.06	918.667
1194.14	919.667
1190.21	912.333
1186.29	933
1182.35	925.667
1178.42	913.667
1174.48	901.333
1170.54	913.667
1166.6	911.333
1162.65	892
1158.7	901.333
1154.74	905
1150.79	907.667
1146.83	924.333
1142.87	914.667
1138.9	916
1134.93	932.667
1130.96	917.667
1126.99	939.667
1123.01	925
1119.03	932
1115.04	930
1111.06	939
1107.07	937.667
1103.08	936.667
1099.08	948.333
1095.08	930
1091.08	961.333
1087.07	934.333
1083.06	945.333
1079.05	941
1075.04	954.667
1071.02	933.667
1067	969
1062.98	959
1058.95	945.667
1054.92	929.667
1050.89	939.667
1046.85	933
1042.81	940.333
1038.77	945
1034.72	929
1030.67	943.667
1026.62	929
1022.57	932
1018.51	955.667
1014.45	938
1010.38	946
1006.32	952.333
1002.24	952.667
998.171	952
994.094	944.667
990.013	956.333
985.93	962.333
981.843	975.667
977.754	967.333
973.661	979.667
969.565	981.333
965.466	993.333
961.364	988
957.258	1008
953.15	1018.67
949.038	1006
944.923	1011.33
940.804	1022
936.683	1024.67
932.558	1005
928.43	1029.33
924.299	1034.33
920.165	1032
916.028	1020.67
911.887	1004
907.743	1023.33
903.595	1018.33
899.445	1017
895.292	1013
891.135	1019
886.975	1022.33
882.812	1018.67
878.646	1022.33
874.475	1035.33
870.303	1047
866.126	1054.67
861.947	1039.33
857.764	1051.33
853.578	1051.33
849.389	1064.67
845.196	1066.67
841	1065.67
836.801	1062
832.599	1064.33
828.393	1065
824.184	1072.67
819.972	1063
815.757	1027.33
811.538	1045.67
807.316	1066.33
803.091	1033.67
798.863	1042
794.631	1049.33
790.395	1055
786.157	1067.33
781.915	1088.33
777.669	1063.67
773.421	1081.67
769.169	1060
764.915	1082.33
760.656	1076.67
756.394	1101.33
752.129	1080.67
747.861	1091.67
743.588	1105.33
739.314	1093.67
735.035	1106.67
730.753	1110.67
726.469	1120
722.18	1120.33
717.888	1102.33
713.593	1106
709.294	1091
704.992	1086.33
700.687	1102.33
696.378	1067.33
692.066	1090.67
687.751	1081.67
683.432	1082
679.109	1085
674.784	1096.33
670.455	1054
666.122	1085.67
661.787	1093.33
657.448	1100.33
653.104	1072.33
648.759	1103.33
644.409	1066.33
640.056	1112.33
635.7	1110.67
631.34	1128.33
626.977	1141.67
622.61	1143.67
618.24	1140.67
613.867	1133.33
609.49	1121.33
605.11	1134.33
600.726	1115.67
596.339	1125
591.948	1115.33
587.554	1128
583.156	1134.33
578.755	1130
574.35	1153.33
569.943	1141.33
565.531	1155
561.116	1141.67
556.698	1148
552.275	1148.67
547.85	1122
543.421	1140
538.988	1170
534.553	1144.67
530.113	1182
525.67	1163.67
521.224	1171.67
516.774	1159
512.321	1182.33
507.863	1175
503.403	1165
498.939	1166.33
494.472	1171
490.001	1177
485.526	1166
481.047	1164
476.565	1165.33
472.08	1176.33
467.591	1176.33
463.099	1182.33
458.604	1180.67
454.103	1208.33
449.601	1209.67
445.094	1212
440.584	1230.67
436.07	1238
431.553	1232
427.032	1255
422.507	1260.33
417.979	1267.67
413.448	1257.33
408.912	1274.67
404.373	1267.33
399.83	1273.33
395.285	1290.67
390.734	1274.67
386.181	1291.67
381.624	1292.33
377.064	1289
372.5	1312.33
367.932	1311.67
363.36	1289
358.785	1307
354.207	1320.67
349.624	1325.33
345.038	1323.33
340.448	1333.67
335.855	1339
331.257	1336
326.657	1353.67
322.053	1379.67
317.444	1381.67
312.833	1416.33
308.217	1417.67
303.599	1422.33
298.976	1453.33
294.349	1454.67
289.719	1484.67
285.085	1517.67
280.448	1527
275.807	1571.67
271.161	1566
266.513	1590
261.861	1624.67
257.205	1660.67
252.544	1685.67
247.881	1709.67
243.214	1747
238.543	1780.33
233.869	1845
229.19	1859.33
224.508	1914
219.822	1956
215.132	2047.67
210.439	2089.33
205.741	2113.33
201.04	2207.33
196.336	2274.33
191.627	2263
186.915	2338.33
182.199	2339.67
177.478	2380.33
172.755	2461.67
168.028	2514.33
163.297	2535.67
158.561	2635.67
153.823	2681.33
149.08	2726.33
144.334	2717.67
139.584	2821
134.829	2850.67
130.071	3018
125.31	3069
120.545	3228.33
115.775	3322.33
111.001	3523
106.224	3747.33
101.444	3940
96.6594	4216.33
91.8705	4653
87.0781	5183
82.282	5847
77.4812	6920
72.6778	8473.33
67.8698	11787.3
63.0582	15426
58.2419	18441.3
53.4229	21514
48.5993	25160.3
43.772	30050.7
38.941	37162
34.1054	47877
29.2661	63339
24.4231	64524
19.5764	64524
14.7261	64524
9.87099	64524
5.01321	64524
0.14975	64524
-4.71644	64524
-9.58634	64524
-14.461	64524
-19.3393	64524
-24.2214	64524
-29.1072	64524
-33.9977	64524
-38.892	43365
-43.7901	28575.3
-48.6919	21318
-53.5974	16134.7
-58.5078	12409.7
-63.4218	9640
-68.3397	7482.67
-73.2613	5833.33
-78.1878	4615
-83.117	3652.33
-88.051	2950.33
-92.9888	2420
-97.9314	2007.33
-102.877	1671.33
-107.827	1318.67
-112.781	1046
-117.739	868
-122.701	733.333
-127.667	618
-132.637	508
-137.612	430
-142.59	378.667
-147.572	323.667
-152.558	283.667
-157.548	255.667
-162.542	231.667
-167.541	220.333
-172.544	204
-177.55	192
-182.561	176.333
-187.576	172.333
-192.595	169.667
-197.617	159.667
-202.645	165
-207.676	153
-212.711	156.333
-217.75	147.333
-222.794	145.333
-227.842	146.667
-232.893	132.667
-237.949	124
-243.009	126.667
-248.073	124
-253.142	124
-258.214	117
-263.291	107.667
-268.371	117
-273.456	94.6667
-278.545	117.333
-283.639	97
-288.735	97
-293.837	105.333
-298.943	100.333
-304.053	89.6667
-309.166	98
-314.285	95.3333
-319.408	91.3333
-324.534	82
-329.665	85.6667
-334.801	83.6667
-339.94	75.6667
-345.083	82.6667
-350.231	84.6667
-355.383	83.3333
-360.539	72
-365.699	84.6667
-370.864	78.3333
-376.033	78.3333
-381.206	73
-386.384	78.3333
-391.565	67.6667
-396.751	69.3333
-401.941	65
-407.136	64.6667
-412.334	75.3333
-417.537	63.3333
-422.745	62.6667
-427.956	75
-433.173	62.3333
-438.392	61.3333
-443.617	63.6667
-448.846	64.3333
-454.078	68.3333
-459.317	65.6667
-464.558	67.6667
-469.804	63.6667
-475.055	60
-480.309	62
-485.568	51.6667
-490.832	62.3333
-496.099	58.3333
-501.372	58.6667
-506.648	61.3333
-511.929	66.3333
-517.215	56
-522.504	59
-527.797	58
-533.097	53.6667
-538.399	53.3333
-543.706	57.6667
-549.018	59
-554.334	66
-559.654	56
-564.979	56.6667
-570.308	50.3333
-575.641	58
-580.98	60
-586.322	65.3333
-591.669	60.3333
-597.02	68.3333
-602.376	65.3333
-607.736	62.3333
-613.1	57.6667
-618.47	57.6667
-623.843	63.6667
-629.222	63.3333
-634.603	56.6667
-639.99	64.3333
-645.382	55.6667
-650.779	63
-656.179	54.3333
-661.583	61.6667
-666.993	58.6667
-672.407	64.6667
-677.825	57
-683.248	61
-688.675	63.6667
-694.108	54.6667
-699.544	54
-704.985	64.3333
-710.431	55
-715.88	64.3333
-721.335	60
-726.795	66
-732.258	65.3333
-737.727	64.3333
-743.2	62.6667
-748.678	59.6667
-754.159	57.6667
-759.646	58
-765.138	61
-770.633	61
-776.133	57.3333
-781.638	64
-787.149	57.6667
-792.663	52.3333
-798.181	56.6667
-803.705	63.6667
-809.233	57.6667
-814.766	58.3333
-820.304	61
-825.846	57.3333
-831.392	59
-836.944	67.6667
-842.499	61
-848.06	56.3333
-853.626	56.3333
-859.195	57.6667
-864.77	60.6667
-870.35	67.6667
-875.934	50
-881.522	62
-887.116	59.3333
-892.714	62.6667
-898.317	63.3333
-903.924	63
-909.537	62
-915.153	58.3333
-920.776	67.3333
-926.401	63.3333
-932.033	62
-937.669	51
-943.31	66
-948.955	61
-954.605	59.3333
-960.26	50.6667
-965.92	69
-971.584	62.6667
-977.254	63.3333
-982.928	75.3333
-988.607	63.6667
-994.291	69.3333
-999.979	70.3333
-1005.67	68
-1011.37	65
-1017.07	68
-1022.78	68.6667
-1028.49	69
-1034.21	73.3333
-1039.93	73
-1045.66	64.3333
-1051.39	67.3333
-1057.13	66.3333
-1062.87	71.6667
-1068.62	76.6667
-1074.37	75
-1080.12	73
-1085.89	69.3333
-1091.65	78.6667
-1097.42	72.6667
-1103.2	76
-1108.98	79
-1114.77	74.3333
-1120.56	76
-1126.35	79
-1132.15	75
-1137.96	80.3333
-1143.77	85.6667
-1149.58	80
-1155.4	89.3333
-1161.23	96
-1167.06	109.667
-1172.89	119.333
-1178.73	163.333
-1184.58	217.333
-1190.43	266.667
-1196.28	274.667
-1202.14	338
-1208.01	373.333
-1213.88	449.333
-1219.75	529.667
-1225.63	593.667
-1231.52	693.333
-1237.41	822.333
-1243.3	1079
-1249.2	1778.67
-1255.11	1953.33
-1261.02	1746
-1266.93	1489.67
-1272.85	1090.67
-1278.78	451.667
-1284.71	194.333
-1290.65	160.333
-1296.59	156.333
-1302.53	120.667
-1308.48	107.333
-1314.44	121.667
-1320.4	109.333
-1326.37	96.6667
-1332.34	99.3333
-1338.31	92.6667
-1344.29	84
-1350.28	89.6667
-1356.27	86.3333
-1362.27	77.3333
-1368.27	77.3333
-1374.28	61.3333
-1380.29	65.3333
-1386.31	59
-1392.33	56.3333
-1060	68.3333
-1065.74	69.3333
-1071.49	71.3333
-1077.25	82
-1083.01	67.3333
-1088.77	70
-1094.54	71
-1100.31	75.6667
-1106.09	72.3333
-1111.87	81.3333
-1117.66	76.3333
-1123.45	75
-1129.25	79
-1135.05	77.6667
-1140.86	80.6667
-1146.67	82.3333
-1152.49	77.6667
-1158.32	83
-1164.14	90.3333
-1169.98	110.333
-1175.81	137.333
-1181.66	194
-1187.5	239.333
-1193.35	271.667
-1199.21	300
-1205.08	355
-1210.94	411.333
-1216.82	498
-1222.69	556.333
-1228.58	652.333
-1234.46	765
-1240.35	895
-1246.25	1508.67
-1252.16	1936
-1258.06	1893
-1263.97	1650.67
-1269.89	1296.33
-1275.82	746.667
-1281.74	258.667
-1287.68	169
-1293.62	156.667
-1299.56	136.667
-1305.51	129.667
-1311.46	111.667
-1317.42	109
-1323.38	111.667
-1329.35	103.333
-1335.32	95
-1341.3	97.6667
-1347.29	92.6667
-1353.28	92
-1359.27	83.6667
-1365.27	75.6667
-1371.27	78.6667
-1377.28	67
-1383.3	64.3333
-1389.32	56.6667
-1392.33	56.3333