File: projects/python/data/20231030/wristback_600_785 nm_10 s_1_2023_10_30_15_20_07_01.txt
#Sample=wristback
#Laser=785 nm
#Grating=600
#Exposition=10
#Accumulation=1
#Acquired=30.10.2023 15:20:07
2745.96	535.333
2743.18	529
2740.41	539.667
2737.63	544.667
2734.85	545.333
2732.07	573.667
2729.29	585
2726.5	571.333
2723.72	576
2720.93	591.333
2718.14	588.333
2715.34	602.333
2712.55	599.333
2709.75	578.667
2706.95	599.667
2704.15	602
2701.35	610.333
2698.55	632.333
2695.74	635
2692.93	649.667
2690.12	648.333
2687.31	655.667
2684.49	663.667
2681.67	653.667
2678.85	659
2676.03	665.333
2673.21	657.667
2670.38	666.667
2667.56	667
2664.73	678
2661.9	669
2659.06	675
2656.23	699
2653.39	699.667
2650.55	724
2647.71	720.333
2644.86	717.333
2642.02	749.333
2639.17	737
2636.32	750
2633.47	767.667
2630.62	771.333
2627.76	785.333
2624.9	778
2622.04	799.333
2619.18	776
2616.31	804
2613.45	797
2610.58	802
2607.71	810.333
2604.84	811.667
2601.96	817
2599.08	819.667
2596.21	817.333
2593.32	826.333
2590.44	823.333
2587.56	831
2584.67	847.333
2581.78	869
2578.89	870.667
2575.99	876.667
2573.1	878
2570.2	903.667
2567.3	880.333
2564.4	916.667
2561.5	883.667
2558.59	929.333
2555.68	929.333
2552.77	933.333
2549.86	965
2546.94	958.667
2544.03	952.333
2541.11	962
2538.19	975.667
2535.26	968
2532.34	991.667
2529.41	1024.67
2526.48	993.667
2523.55	1008.33
2520.62	1026.33
2517.68	1019.67
2514.74	1025
2511.8	1054.67
2508.86	1037.67
2505.92	1063.67
2502.97	1061
2500.02	1064
2497.07	1070.67
2494.12	1067
2491.16	1087.33
2488.2	1087
2485.25	1108.33
2482.28	1107.33
2479.32	1093.67
2476.35	1121
2473.39	1121.67
2470.42	1138.33
2467.44	1165
2464.47	1139
2461.49	1164.33
2458.51	1150.67
2455.53	1198.33
2452.55	1182.67
2449.56	1232
2446.58	1212.33
2443.59	1236
2440.59	1227.33
2437.6	1237.67
2434.6	1233.67
2431.61	1263
2428.61	1247.33
2425.6	1280.67
2422.6	1269
2419.59	1282.67
2416.58	1308.67
2413.57	1308
2410.56	1346
2407.54	1337
2404.52	1338
2401.5	1346.67
2398.48	1332
2395.45	1316.67
2392.43	1349
2389.4	1378
2386.37	1384.33
2383.33	1378.67
2380.3	1388.67
2377.26	1399.33
2374.22	1425.33
2371.17	1433.33
2368.13	1430.33
2365.08	1433.67
2362.03	1437.67
2358.98	1451
2355.93	1478.67
2352.87	1462.67
2349.81	1500.67
2346.75	1485.67
2343.69	1503.33
2340.63	1492.33
2337.56	1497.33
2334.49	1514
2331.42	1523.67
2328.35	1526.67
2325.27	1538.33
2322.19	1535.33
2319.11	1547
2316.03	1570.33
2312.94	1569.33
2309.85	1587
2306.77	1613.33
2303.67	1628.67
2300.58	1635
2297.48	1633
2294.38	1659
2291.28	1648.67
2288.18	1657
2285.07	1676.33
2281.97	1681.67
2278.86	1673.67
2275.74	1701.33
2272.63	1681.67
2269.51	1691.67
2266.39	1678.67
2263.27	1705.33
2260.15	1706.67
2257.02	1715
2253.89	1735
2250.76	1739
2247.63	1754.67
2244.49	1738
2241.36	1788
2238.22	1761
2235.08	1782
2231.93	1798.67
2228.78	1815
2225.63	1814.33
2222.48	1829
2219.33	1811.33
2216.17	1821.33
2213.01	1839.67
2209.85	1850
2206.69	1843
2203.53	1861.33
2200.36	1848.67
2197.19	1859.33
2194.02	1883
2190.84	1893.67
2187.66	1899
2184.48	1915.67
2181.3	1922.33
2178.12	1935
2174.93	1957
2171.74	1941.67
2168.55	1949
2165.36	1973.33
2162.16	1980
2158.97	2001.33
2155.76	2027.67
2152.56	2018.33
2149.36	2066.33
2146.15	2058.33
2142.94	2040
2139.73	2090
2136.51	2037
2133.29	2062.33
2130.08	2086.67
2126.85	2097.67
2123.63	2111
2120.4	2105.67
2117.17	2120.33
2113.94	2126
2110.71	2132.67
2107.47	2126.67
2104.23	2114.67
2100.99	2101.33
2097.75	2138
2094.5	2162.33
2091.26	2152.33
2088.01	2184.33
2084.75	2179.67
2081.5	2198.33
2078.24	2202.33
2074.98	2216
2071.72	2211.67
2068.45	2259
2065.18	2256
2061.92	2285
2058.64	2288.67
2055.37	2315.33
2052.09	2316.67
2048.81	2312.33
2045.53	2318
2042.25	2314.33
2038.96	2329
2035.67	2346.33
2032.38	2368.67
2029.08	2338
2025.79	2353.33
2022.49	2378.33
2019.19	2367
2015.88	2393.67
2012.58	2374.67
2009.27	2395.33
2005.96	2392
2002.64	2445
1999.33	2425.33
1996.01	2436.67
1992.69	2463.33
1989.36	2478.67
1986.04	2471.67
1982.71	2515.33
1979.38	2461.67
1976.05	2524.33
1972.71	2537.33
1969.37	2561
1966.03	2598
1962.69	2595
1959.34	2643
1955.99	2612.33
1952.64	2601.67
1949.29	2633.67
1945.93	2631.67
1942.58	2636.33
1939.21	2663.67
1935.85	2695.67
1932.49	2699.67
1929.12	2690.33
1925.75	2707.33
1922.37	2695.33
1919	2735
1915.62	2698.67
1912.24	2721.67
1908.86	2728.67
1905.47	2723
1902.08	2722
1898.69	2734.67
1895.3	2754.67
1891.9	2766.33
1888.5	2769.67
1885.1	2788
1881.7	2805
1878.29	2773.33
1874.88	2793.33
1871.47	2822
1868.06	2812
1864.64	2819.33
1861.22	2828
1857.8	2836.67
1854.38	2842.67
1850.95	2849.67
1847.52	2889
1844.09	2880
1840.66	2886
1837.22	2933
1833.78	2943
1830.34	2932.33
1826.9	2934.33
1823.45	2920.67
1820	2971.67
1816.55	2969.67
1813.09	2999.67
1809.64	3020.67
1806.18	3049.33
1802.71	3031.67
1799.25	3037.33
1795.78	3020.33
1792.31	3034.67
1788.84	3050
1785.36	3082
1781.88	3066
1778.4	3098
1774.92	3081.67
1771.43	3093
1767.95	3094
1764.45	3099.67
1760.96	3107.33
1757.47	3124.33
1753.97	3114.33
1750.47	3118.67
1746.96	3150.33
1743.45	3148
1739.94	3147.33
1736.43	3189.67
1732.92	3184.33
1729.4	3191
1725.88	3200.67
1722.36	3276
1718.83	3264.33
1715.3	3219.67
1711.77	3278.67
1708.24	3281
1704.71	3334
1701.17	3316
1697.63	3333
1694.08	3333.67
1690.54	3389.33
1686.99	3386
1683.44	3425
1679.88	3429
1676.32	3394
1672.76	3420.67
1669.2	3419.33
1665.64	3456.33
1662.07	3432.67
1658.5	3440.67
1654.92	3461.67
1651.35	3474.33
1647.77	3528.33
1644.19	3496.33
1640.61	3468
1637.02	3527.67
1633.43	3494
1629.84	3506.67
1626.24	3468.33
1622.64	3498
1619.04	3501.33
1615.44	3477
1611.84	3492.67
1608.23	3521.67
1604.62	3524
1601	3534.33
1597.39	3496.67
1593.77	3523.67
1590.15	3537
1586.52	3531
1582.89	3515.33
1579.26	3529.33
1575.63	3583.33
1571.99	3587
1568.36	3591.67
1564.72	3598.67
1561.07	3583.67
1557.42	3620
1553.78	3557.67
1550.12	3584
1546.47	3621.33
1542.81	3629.33
1539.15	3646.67
1535.49	3640
1531.82	3614
1528.15	3623
1524.48	3591
1520.81	3623
1517.13	3593
1513.45	3629.67
1509.77	3616
1506.08	3650.33
1502.39	3665
1498.7	3627
1495.01	3622.33
1491.31	3633.67
1487.61	3627
1483.91	3650
1480.21	3672.67
1476.5	3645.67
1472.79	3675
1469.07	3678.33
1465.36	3689.33
1461.64	3724.33
1457.92	3716
1454.19	3758
1450.46	3732.67
1446.73	3701.67
1443	3729
1439.26	3735
1435.52	3688.67
1431.78	3692
1428.04	3687.67
1424.29	3660
1420.54	3665.33
1416.79	3673
1413.03	3688
1409.27	3646
1405.51	3660
1401.75	3685.67
1397.98	3664.33
1394.21	3676.67
1390.44	3675
1386.66	3658.33
1382.88	3641.67
1379.1	3610.67
1375.31	3661
1371.53	3632.67
1367.74	3625.67
1363.94	3664.33
1360.15	3663.67
1356.35	3680.33
1352.55	3681.67
1348.74	3711.67
1344.93	3700.67
1341.12	3707.33
1337.31	3702.67
1333.49	3738
1329.67	3678.67
1325.85	3707.33
1322.03	3719.67
1318.2	3709.67
1314.37	3697
1310.53	3738
1306.7	3764.67
1302.86	3754.67
1299.01	3776.33
1295.17	3785.67
1291.32	3788.67
1287.47	3800.33
1283.61	3792.33
1279.76	3762
1275.9	3802.33
1272.03	3787.33
1268.17	3791.33
1264.3	3786
1260.42	3781
1256.55	3755.67
1252.67	3789
1248.79	3777.33
1244.91	3794
1241.02	3786
1237.13	3781
1233.24	3739
1229.34	3717
1225.44	3725
1221.54	3687
1217.63	3675
1213.73	3696.33
1209.81	3664.33
1205.9	3632.67
1201.98	3638.67
1198.06	3647.33
1194.14	3638.67
1190.21	3635.33
1186.29	3641.67
1182.35	3642.67
1178.42	3591.67
1174.48	3617
1170.54	3634.33
1166.6	3625.67
1162.65	3609.67
1158.7	3582.33
1154.74	3620.33
1150.79	3627
1146.83	3635.67
1142.87	3643
1138.9	3597.33
1134.93	3592
1130.96	3626
1126.99	3625.33
1123.01	3658
1119.03	3687.67
1115.04	3684.33
1111.06	3656.33
1107.07	3706
1103.08	3690
1099.08	3723.67
1095.08	3721.33
1091.08	3716.33
1087.07	3790.67
1083.06	3785.67
1079.05	3766.67
1075.04	3790
1071.02	3790.67
1067	3810.67
1062.98	3814
1058.95	3767.33
1054.92	3826.67
1050.89	3796.33
1046.85	3780.33
1042.81	3819.67
1038.77	3840
1034.72	3856
1030.67	3809.67
1026.62	3837
1022.57	3843
1018.51	3893
1014.45	3874.33
1010.38	3906
1006.32	3879.33
1002.24	3935.67
998.171	3966.33
994.094	3943
990.013	3969
985.93	3996.67
981.843	4003
977.754	4046
973.661	4082.67
969.565	4131.33
965.466	4142
961.364	4147
957.258	4147.67
953.15	4181
949.038	4138.33
944.923	4195.67
940.804	4175.33
936.683	4209.67
932.558	4220.33
928.43	4225.33
924.299	4143.33
920.165	4213.67
916.028	4163.67
911.887	4198.67
907.743	4176.33
903.595	4155
899.445	4132.67
895.292	4195
891.135	4161.33
886.975	4167.67
882.812	4223.33
878.646	4209
874.475	4223.33
870.303	4245
866.126	4280.33
861.947	4291
857.764	4294
853.578	4334.67
849.389	4308.33
845.196	4300
841	4342
836.801	4335.33
832.599	4352.33
828.393	4345.33
824.184	4337.67
819.972	4315.33
815.757	4296
811.538	4242.67
807.316	4295.33
803.091	4289.33
798.863	4289.67
794.631	4268.33
790.395	4285
786.157	4263.67
781.915	4279.67
777.669	4312.33
773.421	4298
769.169	4283
764.915	4320.33
760.656	4351.67
756.394	4342.67
752.129	4359.33
747.861	4376.67
743.588	4394.33
739.314	4379.67
735.035	4400
730.753	4439
726.469	4416.33
722.18	4466.67
717.888	4390.33
713.593	4432.67
709.294	4410.67
704.992	4418.33
700.687	4382.33
696.378	4373
692.066	4368.67
687.751	4363.33
683.432	4336.67
679.109	4312.33
674.784	4320.67
670.455	4276
666.122	4321
661.787	4330.33
657.448	4365.67
653.104	4371
648.759	4361
644.409	4378.33
640.056	4411.33
635.7	4442.67
631.34	4490
626.977	4424
622.61	4451.33
618.24	4506.33
613.867	4454.67
609.49	4429.33
605.11	4365
600.726	4427.67
596.339	4399.67
591.948	4357
587.554	4389.67
583.156	4363
578.755	4346.67
574.35	4363.33
569.943	4374.67
565.531	4351
561.116	4351
556.698	4338.67
552.275	4329.33
547.85	4348.67
543.421	4365
538.988	4377
534.553	4373.67
530.113	4392.67
525.67	4447.33
521.224	4425.67
516.774	4438
512.321	4406
507.863	4437.33
503.403	4423.67
498.939	4367.67
494.472	4370.67
490.001	4371.33
485.526	4327.33
481.047	4335
476.565	4322.33
472.08	4305.67
467.591	4361
463.099	4392.33
458.604	4352.67
454.103	4395
449.601	4418.33
445.094	4415.67
440.584	4407.67
436.07	4447.67
431.553	4481.67
427.032	4517.67
422.507	4512
417.979	4514.67
413.448	4513.33
408.912	4539
404.373	4527
399.83	4516.33
395.285	4478.67
390.734	4507
386.181	4517.67
381.624	4508.33
377.064	4527
372.5	4481
367.932	4515.33
363.36	4511.33
358.785	4479.67
354.207	4483.33
349.624	4528
345.038	4550.33
340.448	4538
335.855	4506.67
331.257	4496.67
326.657	4539.33
322.053	4543.67
317.444	4561.67
312.833	4589.67
308.217	4613
303.599	4636.33
298.976	4666.33
294.349	4669.67
289.719	4677.33
285.085	4748
280.448	4749
275.807	4781.33
271.161	4791.33
266.513	4805
261.861	4814.33
257.205	4768
252.544	4865.33
247.881	4912
243.214	4907.33
238.543	4961.33
233.869	4965.33
229.19	5041
224.508	5084
219.822	5162.33
215.132	5172.33
210.439	5209
205.741	5318.67
201.04	5381.33
196.336	5436
191.627	5499.33
186.915	5548.33
182.199	5507.67
177.478	5646
172.755	5684
168.028	5735.33
163.297	5807.33
158.561	5850.33
153.823	5908
149.08	5862.33
144.334	5976.33
139.584	6001.33
134.829	6070.67
130.071	6251.33
125.31	6302.33
120.545	6416
115.775	6641
111.001	6796
106.224	7037
101.444	7297
96.6594	7611.67
91.8705	8052.33
87.0781	8710
82.282	9375
77.4812	10461.7
72.6778	12077.3
67.8698	15449.7
63.0582	18901
58.2419	21520.7
53.4229	24659.7
48.5993	28437.3
43.772	33304.3
38.941	40568
34.1054	51638
29.2661	64524
24.4231	64524
19.5764	64524
14.7261	64524
9.87099	64524
5.01321	64524
0.14975	64524
-4.71644	64524
-9.58634	64524
-14.461	64524
-19.3393	64524
-24.2214	64524
-29.1072	64524
-33.9977	64524
-38.892	44121.3
-43.7901	29722
-48.6919	22250
-53.5974	16874
-58.5078	12921
-63.4218	10075
-68.3397	7821
-73.2613	6128.67
-78.1878	4811.33
-83.117	3815
-88.051	3057.67
-92.9888	2507.67
-97.9314	2076.67
-102.877	1708.67
-107.827	1363.67
-112.781	1097
-117.739	896.667
-122.701	766.333
-127.667	645.667
-132.637	529.667
-137.612	459.333
-142.59	387.667
-147.572	340.667
-152.558	296
-157.548	277.333
-162.542	242
-167.541	228.333
-172.544	212.333
-177.55	201.667
-182.561	184.333
-187.576	181.667
-192.595	176.667
-197.617	175.667
-202.645	169
-207.676	161
-212.711	159.667
-217.75	156.667
-222.794	149.667
-227.842	146.667
-232.893	141.333
-237.949	148
-243.009	133.667
-248.073	133.667
-253.142	128.667
-258.214	129
-263.291	128.667
-268.371	121.667
-273.456	117.333
-278.545	109.667
-283.639	113
-288.735	97
-293.837	102.667
-298.943	102
-304.053	97
-309.166	99.3333
-314.285	96
-319.408	100.333
-324.534	85.3333
-329.665	93.6667
-334.801	98
-339.94	86.3333
-345.083	86
-350.231	83.6667
-355.383	76.3333
-360.539	91
-365.699	87.3333
-370.864	84.6667
-376.033	83
-381.206	81
-386.384	83.6667
-391.565	71.6667
-396.751	81.3333
-401.941	65.6667
-407.136	73.6667
-412.334	83
-417.537	72
-422.745	75.3333
-427.956	74.6667
-433.173	68.6667
-438.392	82
-443.617	71
-448.846	78.3333
-454.078	70.3333
-459.317	67.6667
-464.558	71.6667
-469.804	74
-475.055	69.6667
-480.309	70.3333
-485.568	70.3333
-490.832	71.3333
-496.099	61.6667
-501.372	67.6667
-506.648	68.6667
-511.929	71
-517.215	66.6667
-522.504	64.6667
-527.797	67
-533.097	61
-538.399	64.3333
-543.706	61.6667
-549.018	64.6667
-554.334	60
-559.654	70.3333
-564.979	65.6667
-570.308	67
-575.641	66.6667
-580.98	69.3333
-586.322	69
-591.669	64
-597.02	60.6667
-602.376	61.6667
-607.736	62.3333
-613.1	66
-618.47	69.3333
-623.843	64.6667
-629.222	61.3333
-634.603	73.6667
-639.99	63.3333
-645.382	66
-650.779	73.6667
-656.179	79
-661.583	65.3333
-666.993	65.6667
-672.407	69
-677.825	61.3333
-683.248	65
-688.675	67
-694.108	75
-699.544	74.3333
-704.985	76
-710.431	64.6667
-715.88	65.3333
-721.335	68
-726.795	66.3333
-732.258	63.3333
-737.727	66.3333
-743.2	65.6667
-748.678	62.6667
-754.159	69
-759.646	64
-765.138	68
-770.633	68.6667
-776.133	66.3333
-781.638	68.6667
-787.149	64.6667
-792.663	66.6667
-798.181	69.3333
-803.705	74.6667
-809.233	71.3333
-814.766	76.3333
-820.304	72.6667
-825.846	69.6667
-831.392	63
-836.944	68.3333
-842.499	72.6667
-848.06	67.6667
-853.626	65.3333
-859.195	63
-864.77	68.6667
-870.35	62
-875.934	60.6667
-881.522	65.6667
-887.116	67.3333
-892.714	59
-898.317	63.6667
-903.924	58.6667
-909.537	72
-915.153	66.3333
-920.776	67.3333
-926.401	73.3333
-932.033	69.3333
-937.669	61.6667
-943.31	68.6667
-948.955	69
-954.605	68
-960.26	69
-965.92	75
-971.584	66
-977.254	69
-982.928	71
-988.607	71
-994.291	72.6667
-999.979	71
-1005.67	69
-1011.37	68
-1017.07	70.3333
-1022.78	75.3333
-1028.49	72.6667
-1034.21	75
-1039.93	69.3333
-1045.66	70
-1051.39	73.3333
-1057.13	77.6667
-1062.87	70.3333
-1068.62	80.6667
-1074.37	78.3333
-1080.12	81
-1085.89	81.6667
-1091.65	68.6667
-1097.42	76.6667
-1103.2	80
-1108.98	88
-1114.77	87.6667
-1120.56	87.6667
-1126.35	80.6667
-1132.15	81.3333
-1137.96	83.3333
-1143.77	92
-1149.58	93.6667
-1155.4	95.3333
-1161.23	99.3333
-1167.06	112
-1172.89	132
-1178.73	179
-1184.58	217
-1190.43	266.333
-1196.28	316.667
-1202.14	396
-1208.01	459.333
-1213.88	534.333
-1219.75	615
-1225.63	663.667
-1231.52	724.333
-1237.41	868.667
-1243.3	1141.67
-1249.2	1915
-1255.11	2040.67
-1261.02	1768.33
-1266.93	1523
-1272.85	943.333
-1278.78	412.333
-1284.71	192
-1290.65	160
-1296.59	145.667
-1302.53	126
-1308.48	108.333
-1314.44	111
-1320.4	107
-1326.37	103.667
-1332.34	103
-1338.31	96.3333
-1344.29	96.3333
-1350.28	92.3333
-1356.27	95.6667
-1362.27	84
-1368.27	78.3333
-1374.28	78
-1380.29	68.6667
-1386.31	66
-1392.33	61.3333
-1054.26	70.3333
-1060	74
-1065.74	79
-1071.49	77.6667
-1077.25	81.3333
-1083.01	82
-1088.77	78
-1094.54	78.6667
-1100.31	80
-1106.09	80
-1111.87	81.3333
-1117.66	77.6667
-1123.45	83.3333
-1129.25	78
-1135.05	90
-1140.86	87.3333
-1146.67	91.6667
-1152.49	95
-1158.32	103
-1164.14	94.6667
-1169.98	118.667
-1175.81	146.667
-1181.66	192.333
-1187.5	253
-1193.35	291.667
-1199.21	360
-1205.08	434
-1210.94	500.333
-1216.82	580.333
-1222.69	650.667
-1228.58	685.333
-1234.46	777.333
-1240.35	976
-1246.25	1583
-1252.16	2036
-1258.06	1899.33
-1263.97	1610.33
-1269.89	1252
-1275.82	661.667
-1281.74	238.333
-1287.68	171.667
-1293.62	159
-1299.56	128.333
-1305.51	124.333
-1311.46	119
-1317.42	101.667
-1323.38	99.6667
-1329.35	104.333
-1335.32	99
-1341.3	97.3333
-1347.29	99
-1353.28	87.3333
-1359.27	85
-1365.27	79
-1371.27	78.6667
-1377.28	77
-1383.3	66.6667
-1389.32	62
-1392.33	61.3333