File: projects/python/data/20231030/wristback_600_785 nm_10 s_1_2023_10_30_15_20_59_01.txt
#Sample=wristback
#Laser=785 nm
#Grating=600
#Exposition=10
#Accumulation=1
#Acquired=30.10.2023 15:20:59
2745.96	416.333
2743.18	406.333
2740.41	418.333
2737.63	420
2734.85	421.333
2732.07	432.667
2729.29	439.333
2726.5	446
2723.72	446
2720.93	438.333
2718.14	443
2715.34	442.333
2712.55	451
2709.75	454
2706.95	472
2704.15	457
2701.35	469.333
2698.55	474
2695.74	478.333
2692.93	471
2690.12	492
2687.31	497
2684.49	505.333
2681.67	503.667
2678.85	498
2676.03	503.667
2673.21	513.667
2670.38	495
2667.56	516.667
2664.73	507.333
2661.9	525.333
2659.06	525.667
2656.23	545
2653.39	543.667
2650.55	528
2647.71	551
2644.86	564.333
2642.02	551.333
2639.17	558.667
2636.32	572.667
2633.47	569.333
2630.62	589
2627.76	590
2624.9	589.333
2622.04	591.667
2619.18	593
2616.31	585
2613.45	584.333
2610.58	595.333
2607.71	606.333
2604.84	608.333
2601.96	605.667
2599.08	611.667
2596.21	617
2593.32	607.667
2590.44	647
2587.56	621.667
2584.67	646.667
2581.78	630
2578.89	648
2575.99	660.333
2573.1	658.333
2570.2	658
2567.3	675.667
2564.4	685.333
2561.5	654.667
2558.59	687.333
2555.68	700.333
2552.77	699
2549.86	700.667
2546.94	696.333
2544.03	733.333
2541.11	712.667
2538.19	725.667
2535.26	716
2532.34	730
2529.41	741.333
2526.48	745.333
2523.55	736.667
2520.62	756.333
2517.68	747.667
2514.74	762.333
2511.8	773.667
2508.86	771
2505.92	797.333
2502.97	764.667
2500.02	782.333
2497.07	781.333
2494.12	776.333
2491.16	800.333
2488.2	805
2485.25	793.333
2482.28	804
2479.32	818.333
2476.35	841.333
2473.39	825.333
2470.42	832
2467.44	838
2464.47	841.667
2461.49	856.667
2458.51	867.333
2455.53	875.667
2452.55	891
2449.56	878.333
2446.58	896.667
2443.59	900
2440.59	912.333
2437.6	903.667
2434.6	903.333
2431.61	918
2428.61	939.667
2425.6	925.333
2422.6	927
2419.59	959
2416.58	961.667
2413.57	975.333
2410.56	990
2407.54	971.333
2404.52	978.333
2401.5	981.333
2398.48	973.667
2395.45	995.333
2392.43	985.333
2389.4	982
2386.37	1012.33
2383.33	1000.33
2380.3	1017.67
2377.26	1033
2374.22	1032.67
2371.17	1031.67
2368.13	1059.33
2365.08	1048.33
2362.03	1046.67
2358.98	1059.33
2355.93	1077.67
2352.87	1060.67
2349.81	1096.33
2346.75	1091
2343.69	1094.33
2340.63	1093
2337.56	1097
2334.49	1105.33
2331.42	1113.67
2328.35	1127.67
2325.27	1125.33
2322.19	1120.33
2319.11	1136.33
2316.03	1157.67
2312.94	1150.33
2309.85	1176
2306.77	1159.67
2303.67	1150
2300.58	1191.67
2297.48	1193
2294.38	1202.33
2291.28	1202
2288.18	1195.33
2285.07	1215.33
2281.97	1221
2278.86	1206
2275.74	1222.33
2272.63	1230
2269.51	1223.33
2266.39	1244.33
2263.27	1240
2260.15	1242.67
2257.02	1255.33
2253.89	1254
2250.76	1255.33
2247.63	1243
2244.49	1265.33
2241.36	1289.67
2238.22	1312.67
2235.08	1294.33
2231.93	1313
2228.78	1297.33
2225.63	1304.33
2222.48	1303
2219.33	1311.67
2216.17	1330.33
2213.01	1340.33
2209.85	1339.33
2206.69	1331.67
2203.53	1349.67
2200.36	1356
2197.19	1366.67
2194.02	1355.33
2190.84	1387.33
2187.66	1372.33
2184.48	1367.33
2181.3	1398
2178.12	1388.33
2174.93	1408.67
2171.74	1409
2168.55	1421
2165.36	1437
2162.16	1442
2158.97	1450
2155.76	1443.33
2152.56	1467.33
2149.36	1464.33
2146.15	1475.33
2142.94	1514.67
2139.73	1483
2136.51	1475.33
2133.29	1502.67
2130.08	1504
2126.85	1533
2123.63	1498.33
2120.4	1511.33
2117.17	1515.67
2113.94	1526.67
2110.71	1550.67
2107.47	1534.67
2104.23	1533.33
2100.99	1544.33
2097.75	1542.67
2094.5	1569.67
2091.26	1583
2088.01	1586.33
2084.75	1560.33
2081.5	1573.33
2078.24	1619
2074.98	1620.67
2071.72	1627.33
2068.45	1613.33
2065.18	1643.33
2061.92	1616
2058.64	1635
2055.37	1672.33
2052.09	1649
2048.81	1670.67
2045.53	1672
2042.25	1673
2038.96	1672.67
2035.67	1665
2032.38	1697.33
2029.08	1713.67
2025.79	1692
2022.49	1712.33
2019.19	1732
2015.88	1685
2012.58	1734.67
2009.27	1721.67
2005.96	1754
2002.64	1765.67
1999.33	1751.33
1996.01	1775.67
1992.69	1776
1989.36	1762
1986.04	1793.67
1982.71	1791
1979.38	1787.67
1976.05	1810.33
1972.71	1799
1969.37	1796
1966.03	1869.33
1962.69	1899.67
1959.34	1885
1955.99	1883.67
1952.64	1881.67
1949.29	1860.33
1945.93	1901.67
1942.58	1922.33
1939.21	1952.33
1935.85	1948.33
1932.49	1932.33
1929.12	1957
1925.75	1971.67
1922.37	1941.67
1919	1973.67
1915.62	1917.33
1912.24	1967.33
1908.86	1969.67
1905.47	1976.33
1902.08	1963.33
1898.69	2001.33
1895.3	1994.33
1891.9	1972.33
1888.5	2018
1885.1	2005
1881.7	2016.33
1878.29	2018
1874.88	2016.67
1871.47	2016.67
1868.06	2032
1864.64	2048
1861.22	2074.67
1857.8	2052.67
1854.38	2066.67
1850.95	2108.67
1847.52	2092
1844.09	2066.67
1840.66	2087.67
1837.22	2081
1833.78	2098.67
1830.34	2128.33
1826.9	2108
1823.45	2119
1820	2143.33
1816.55	2145.67
1813.09	2163.33
1809.64	2197.33
1806.18	2158.67
1802.71	2200
1799.25	2180.33
1795.78	2188.33
1792.31	2196
1788.84	2212.67
1785.36	2215.33
1781.88	2206.67
1778.4	2208
1774.92	2227.33
1771.43	2230.67
1767.95	2252.67
1764.45	2232.33
1760.96	2281
1757.47	2272
1753.97	2262
1750.47	2290.33
1746.96	2275
1743.45	2271.67
1739.94	2307
1736.43	2302.33
1732.92	2295.33
1729.4	2311
1725.88	2299.33
1722.36	2355
1718.83	2353.67
1715.3	2391.33
1711.77	2405
1708.24	2395
1704.71	2402
1701.17	2422
1697.63	2444.67
1694.08	2440.67
1690.54	2458.67
1686.99	2489
1683.44	2461.67
1679.88	2498.67
1676.32	2481
1672.76	2498.67
1669.2	2504.33
1665.64	2503
1662.07	2536.67
1658.5	2524.67
1654.92	2533.67
1651.35	2538.67
1647.77	2553.67
1644.19	2549
1640.61	2556
1637.02	2538.67
1633.43	2558
1629.84	2538
1626.24	2557.33
1622.64	2537
1619.04	2565
1615.44	2576.67
1611.84	2560
1608.23	2582.33
1604.62	2553
1601	2611.33
1597.39	2582.67
1593.77	2577
1590.15	2577
1586.52	2604.67
1582.89	2593.33
1579.26	2629.67
1575.63	2602.67
1571.99	2627.33
1568.36	2639.67
1564.72	2648.67
1561.07	2658.67
1557.42	2642.33
1553.78	2651
1550.12	2659.33
1546.47	2641.33
1542.81	2671.67
1539.15	2653.67
1535.49	2675.33
1531.82	2663.67
1528.15	2654.67
1524.48	2675
1520.81	2683.33
1517.13	2649.67
1513.45	2665.33
1509.77	2672.33
1506.08	2680.67
1502.39	2665.67
1498.7	2668.67
1495.01	2650
1491.31	2669.33
1487.61	2674
1483.91	2656.67
1480.21	2667.33
1476.5	2681.33
1472.79	2702.33
1469.07	2706
1465.36	2755
1461.64	2749.33
1457.92	2749
1454.19	2741.33
1450.46	2737.33
1446.73	2737.67
1443	2750.33
1439.26	2735
1435.52	2737
1431.78	2725
1428.04	2715.67
1424.29	2695
1420.54	2727.67
1416.79	2687.67
1413.03	2662.67
1409.27	2709.67
1405.51	2686.67
1401.75	2684
1397.98	2705.33
1394.21	2700.67
1390.44	2668.33
1386.66	2680.67
1382.88	2663.67
1379.1	2691
1375.31	2671
1371.53	2669
1367.74	2684.67
1363.94	2671.33
1360.15	2693
1356.35	2709.67
1352.55	2696.67
1348.74	2729.33
1344.93	2739.33
1341.12	2740
1337.31	2718.67
1333.49	2733.33
1329.67	2751.67
1325.85	2714
1322.03	2722.33
1318.2	2752
1314.37	2741.67
1310.53	2748.67
1306.7	2753.67
1302.86	2780.67
1299.01	2755
1295.17	2783.33
1291.32	2775
1287.47	2750.67
1283.61	2789.67
1279.76	2791.67
1275.9	2756.67
1272.03	2813.67
1268.17	2790.67
1264.3	2810.33
1260.42	2825
1256.55	2776
1252.67	2784
1248.79	2830
1244.91	2783.67
1241.02	2778
1237.13	2778.33
1233.24	2761.67
1229.34	2765
1225.44	2736.33
1221.54	2681.67
1217.63	2699.67
1213.73	2696.33
1209.81	2692.33
1205.9	2653
1201.98	2649.67
1198.06	2645
1194.14	2648
1190.21	2632.67
1186.29	2644
1182.35	2652.33
1178.42	2619
1174.48	2613.33
1170.54	2638
1166.6	2631.67
1162.65	2619
1158.7	2621
1154.74	2654
1150.79	2648.33
1146.83	2647.33
1142.87	2617.67
1138.9	2603.33
1134.93	2638.67
1130.96	2616
1126.99	2625.33
1123.01	2649.33
1119.03	2627.33
1115.04	2672.67
1111.06	2667.33
1107.07	2637.67
1103.08	2692.33
1099.08	2685
1095.08	2727
1091.08	2702.33
1087.07	2714.67
1083.06	2735.67
1079.05	2746.67
1075.04	2741
1071.02	2742.33
1067	2747
1062.98	2743.33
1058.95	2737.67
1054.92	2739.67
1050.89	2726.33
1046.85	2714
1042.81	2755
1038.77	2750.67
1034.72	2724
1030.67	2740
1026.62	2734.67
1022.57	2754
1018.51	2791.67
1014.45	2793
1010.38	2792.33
1006.32	2826.67
1002.24	2812.67
998.171	2822.33
994.094	2814
990.013	2854.33
985.93	2868.33
981.843	2892
977.754	2895.67
973.661	2897
969.565	2940.67
965.466	2982
961.364	2973.67
957.258	2965
953.15	2976.67
949.038	2981
944.923	3000.67
940.804	3001.67
936.683	3028
932.558	2999.33
928.43	2979.67
924.299	2989
920.165	3021
916.028	2994.33
911.887	2997.67
907.743	2969.33
903.595	3000.67
899.445	2955.67
895.292	2985.33
891.135	2974
886.975	2958
882.812	2975.33
878.646	2991.33
874.475	3015
870.303	3014.67
866.126	3023
861.947	3052
857.764	3072.67
853.578	3060.33
849.389	3069.67
845.196	3063.67
841	3074.67
836.801	3083.33
832.599	3091.67
828.393	3075
824.184	3106
819.972	3040
815.757	3047
811.538	3020.33
807.316	3036
803.091	3054.67
798.863	3064.67
794.631	3042.33
790.395	3031.33
786.157	3013.33
781.915	3025.67
777.669	3022
773.421	3081
769.169	3062.33
764.915	3076.67
760.656	3085.33
756.394	3090.33
752.129	3100.33
747.861	3093.67
743.588	3125
739.314	3126.67
735.035	3128.33
730.753	3145.33
726.469	3149.67
722.18	3155.33
717.888	3150.33
713.593	3100.67
709.294	3131
704.992	3109
700.687	3118.33
696.378	3078
692.066	3074.67
687.751	3062
683.432	3061.33
679.109	3034.33
674.784	3063.33
670.455	3022.67
666.122	3065
661.787	3060
657.448	3081.67
653.104	3080.33
648.759	3112.67
644.409	3113.67
640.056	3081.33
635.7	3125.67
631.34	3139
626.977	3125.67
622.61	3118.33
618.24	3149
613.867	3129.67
609.49	3150.67
605.11	3152.33
600.726	3103
596.339	3115
591.948	3095
587.554	3084.67
583.156	3094.33
578.755	3052
574.35	3112
569.943	3068
565.531	3072.67
561.116	3101.67
556.698	3082
552.275	3070
547.85	3071.33
543.421	3094.33
538.988	3104.33
534.553	3098
530.113	3099.67
525.67	3143.33
521.224	3132.67
516.774	3122
512.321	3163.67
507.863	3136.67
503.403	3134.67
498.939	3101.67
494.472	3106.67
490.001	3087
485.526	3064
481.047	3076.33
476.565	3088.67
472.08	3078.33
467.591	3084.67
463.099	3109.67
458.604	3119.33
454.103	3148
449.601	3124.33
445.094	3121
440.584	3145.67
436.07	3151.33
431.553	3189.33
427.032	3217.67
422.507	3239.33
417.979	3217.67
413.448	3237.67
408.912	3205.33
404.373	3243.33
399.83	3230
395.285	3236.67
390.734	3212.33
386.181	3223.67
381.624	3221.67
377.064	3221.67
372.5	3248.33
367.932	3269
363.36	3245.67
358.785	3194.33
354.207	3251.33
349.624	3228.67
345.038	3266.33
340.448	3262.33
335.855	3241
331.257	3271.67
326.657	3246
322.053	3305.33
317.444	3301.67
312.833	3351.33
308.217	3336.67
303.599	3343.67
298.976	3399.67
294.349	3419.33
289.719	3444.33
285.085	3450.33
280.448	3503.67
275.807	3499.33
271.161	3508
266.513	3527.33
261.861	3574
257.205	3548
252.544	3635
247.881	3660.33
243.214	3690.67
238.543	3758.33
233.869	3755
229.19	3808.67
224.508	3864.33
219.822	3882.33
215.132	3974
210.439	3994.67
205.741	4083.33
201.04	4132.67
196.336	4241.67
191.627	4262.67
186.915	4321.33
182.199	4309.33
177.478	4377.67
172.755	4432.33
168.028	4481
163.297	4567
158.561	4656
153.823	4662
149.08	4659.67
144.334	4771
139.584	4822.67
134.829	4852
130.071	5006
125.31	5124.67
120.545	5268.67
115.775	5442
111.001	5580.67
106.224	5784.33
101.444	6053.67
96.6594	6400.67
91.8705	6884.33
87.0781	7499.33
82.282	8246.67
77.4812	9286.33
72.6778	10953
67.8698	14483
63.0582	17839.7
58.2419	20857.3
53.4229	23987
48.5993	27704.3
43.772	32979.3
38.941	40572.3
34.1054	51738.7
29.2661	64524
24.4231	64524
19.5764	64524
14.7261	64524
9.87099	64524
5.01321	64524
0.14975	64524
-4.71644	64524
-9.58634	64524
-14.461	64524
-19.3393	64524
-24.2214	64524
-29.1072	64524
-33.9977	64524
-38.892	44592.3
-43.7901	30034
-48.6919	22384.3
-53.5974	17045.3
-58.5078	13066.7
-63.4218	10098
-68.3397	7858.67
-73.2613	6115.67
-78.1878	4841.67
-83.117	3820.67
-88.051	3065.33
-92.9888	2524.33
-97.9314	2117.67
-102.877	1725.33
-107.827	1373.67
-112.781	1082.33
-117.739	909.333
-122.701	768.333
-127.667	654.667
-132.637	533.333
-137.612	455.333
-142.59	386.667
-147.572	358.333
-152.558	306.667
-157.548	270
-162.542	242.333
-167.541	240.667
-172.544	196.333
-177.55	200
-182.561	181
-187.576	172.333
-192.595	166
-197.617	173
-202.645	159.333
-207.676	167
-212.711	156
-217.75	152.667
-222.794	158
-227.842	144
-232.893	152.667
-237.949	133
-243.009	132
-248.073	128.333
-253.142	118.667
-258.214	121
-263.291	124.667
-268.371	126
-273.456	120.667
-278.545	110
-283.639	107
-288.735	109.667
-293.837	112.333
-298.943	96.6667
-304.053	106
-309.166	100
-314.285	88.3333
-319.408	95
-324.534	91
-329.665	92
-334.801	88.3333
-339.94	86.6667
-345.083	87.3333
-350.231	91.6667
-355.383	85.3333
-360.539	76.3333
-365.699	67.6667
-370.864	81
-376.033	79.6667
-381.206	84.6667
-386.384	87
-391.565	77.3333
-396.751	75.6667
-401.941	79.6667
-407.136	77
-412.334	73.6667
-417.537	79.6667
-422.745	65.6667
-427.956	71
-433.173	69
-438.392	69
-443.617	72.3333
-448.846	71.3333
-454.078	75
-459.317	74
-464.558	72.6667
-469.804	62.6667
-475.055	69.6667
-480.309	68.6667
-485.568	62.3333
-490.832	76
-496.099	72.3333
-501.372	65.3333
-506.648	67
-511.929	59
-517.215	79.3333
-522.504	62.3333
-527.797	66.6667
-533.097	64
-538.399	60
-543.706	70
-549.018	65.3333
-554.334	60
-559.654	71.3333
-564.979	63.6667
-570.308	54.6667
-575.641	65
-580.98	66.6667
-586.322	64.3333
-591.669	64.3333
-597.02	69.3333
-602.376	63.6667
-607.736	67
-613.1	65.6667
-618.47	68.3333
-623.843	67.6667
-629.222	67.3333
-634.603	65.3333
-639.99	60.6667
-645.382	66.3333
-650.779	64.6667
-656.179	65
-661.583	68.6667
-666.993	70.6667
-672.407	73.3333
-677.825	73.3333
-683.248	58.3333
-688.675	74
-694.108	67
-699.544	67
-704.985	69
-710.431	64.6667
-715.88	78
-721.335	74.6667
-726.795	69.3333
-732.258	67.6667
-737.727	68
-743.2	63.3333
-748.678	73.6667
-754.159	63.6667
-759.646	65
-765.138	71
-770.633	74
-776.133	64.3333
-781.638	72.3333
-787.149	67.3333
-792.663	71.6667
-798.181	64.6667
-803.705	67
-809.233	63.3333
-814.766	65.6667
-820.304	56
-825.846	67
-831.392	73
-836.944	63
-842.499	71
-848.06	55.3333
-853.626	65
-859.195	67.3333
-864.77	69.3333
-870.35	62
-875.934	65
-881.522	65
-887.116	64
-892.714	74.3333
-898.317	59.3333
-903.924	69.3333
-909.537	67.3333
-915.153	74
-920.776	70.3333
-926.401	61.6667
-932.033	73
-937.669	73
-943.31	73.6667
-948.955	66.3333
-954.605	66
-960.26	63
-965.92	68
-971.584	59
-977.254	70.6667
-982.928	75
-988.607	76.6667
-994.291	69.6667
-999.979	73.6667
-1005.67	73.6667
-1011.37	64.6667
-1017.07	72
-1022.78	67.6667
-1028.49	71.3333
-1034.21	69
-1039.93	72.6667
-1045.66	71.6667
-1051.39	67
-1057.13	74.3333
-1062.87	75.3333
-1068.62	70.6667
-1074.37	71.3333
-1080.12	83
-1085.89	81.3333
-1091.65	67
-1097.42	79.6667
-1103.2	76.3333
-1108.98	85
-1114.77	85
-1120.56	75.6667
-1126.35	84.6667
-1132.15	72.3333
-1137.96	83
-1143.77	83.6667
-1149.58	86
-1155.4	103.333
-1161.23	96.3333
-1167.06	105.667
-1172.89	136.333
-1178.73	157.333
-1184.58	230.333
-1190.43	260.333
-1196.28	307.667
-1202.14	374.333
-1208.01	434.333
-1213.88	497.333
-1219.75	576.333
-1225.63	654
-1231.52	719
-1237.41	904
-1243.3	1115.33
-1249.2	1910.67
-1255.11	2014.33
-1261.02	1925.33
-1266.93	1534.67
-1272.85	1000.33
-1278.78	414.333
-1284.71	195
-1290.65	155.333
-1296.59	149
-1302.53	127
-1308.48	124.333
-1314.44	108.667
-1320.4	104
-1326.37	99.6667
-1332.34	107.333
-1338.31	102
-1344.29	103
-1350.28	93.3333
-1356.27	87.6667
-1362.27	89.6667
-1368.27	82.3333
-1374.28	74
-1380.29	71.6667
-1386.31	61.6667
-1392.33	63.3333
-1060	74.3333
-1065.74	81.6667
-1071.49	75.3333
-1077.25	82
-1083.01	78.3333
-1088.77	75.3333
-1094.54	80
-1100.31	72.6667
-1106.09	79
-1111.87	78.6667
-1117.66	80.3333
-1123.45	90
-1129.25	85.3333
-1135.05	86
-1140.86	92.6667
-1146.67	92.3333
-1152.49	83.6667
-1158.32	93.3333
-1164.14	101
-1169.98	125.333
-1175.81	151
-1181.66	194.667
-1187.5	247
-1193.35	281
-1199.21	315.333
-1205.08	389.667
-1210.94	454
-1216.82	537.333
-1222.69	602
-1228.58	668.333
-1234.46	777
-1240.35	968
-1246.25	1534.33
-1252.16	2065
-1258.06	1984
-1263.97	1711.67
-1269.89	1261.33
-1275.82	661.667
-1281.74	245.667
-1287.68	175.333
-1293.62	149.333
-1299.56	127.667
-1305.51	121.667
-1311.46	115
-1317.42	111
-1323.38	111.333
-1329.35	112
-1335.32	102
-1341.3	96.3333
-1347.29	98.6667
-1353.28	99
-1359.27	91.6667
-1365.27	81.6667
-1371.27	78
-1377.28	64.6667
-1383.3	66.6667
-1389.32	63.3333
-1392.33	63.3333