File: projects/python/data/20231030/wrist_600_785 nm_10 s_1_2023_10_30_15_16_43_01.txt
#Sample=wrist
#Laser=785 nm
#Grating=600
#Exposition=10
#Accumulation=1
#Acquired=30.10.2023 15:16:43
1599.2	4503.67
1597.39	4537
1595.58	4516.33
1593.77	4515.33
1591.96	4468.67
1590.15	4519.33
1588.33	4531.33
1586.52	4464.33
1584.71	4504.67
1582.89	4501.33
1581.08	4511
1579.26	4503.33
1577.45	4501.67
1575.63	4525.33
1573.81	4503.67
1571.99	4535
1570.18	4564.67
1568.36	4569
1566.54	4577
1564.72	4568.67
1562.89	4577.33
1561.07	4578.67
1559.25	4584
1557.42	4552.67
1555.6	4537.33
1553.78	4583
1551.95	4578.33
1550.12	4605
1548.3	4570.67
1546.47	4603.67
1544.64	4616
1542.81	4621.33
1540.98	4595.33
1539.15	4592.67
1537.32	4609.67
1535.49	4601.67
1533.65	4573
1531.82	4625.33
1529.99	4616
1528.15	4598
1526.32	4599.33
1524.48	4562
1522.64	4567
1520.81	4569
1518.97	4592
1517.13	4584
1515.29	4612.67
1513.45	4592.33
1511.61	4584.33
1509.77	4613.67
1507.92	4585.67
1506.08	4609.33
1504.24	4611.67
1502.39	4596
1500.55	4608.33
1498.7	4613.33
1496.86	4553.67
1495.01	4639.67
1493.16	4581
1491.31	4603
1489.46	4580.33
1487.61	4593.67
1485.76	4644
1483.91	4578
1482.06	4614.33
1480.21	4635
1478.35	4632.67
1476.5	4637
1474.64	4636.33
1472.79	4678.33
1470.93	4673.67
1469.07	4631
1467.22	4697.33
1465.36	4704.33
1463.5	4706
1461.64	4735
1459.78	4727.67
1457.92	4746.33
1456.05	4757.67
1454.19	4771.33
1452.33	4773
1450.46	4728.67
1448.6	4724.67
1446.73	4751.33
1444.87	4758.33
1443	4749
1441.13	4742
1439.26	4742.33
1437.39	4740
1435.52	4682.67
1433.65	4684.67
1431.78	4728.33
1429.91	4672
1428.04	4684.67
1426.17	4659
1424.29	4686
1422.42	4655
1420.54	4681
1418.66	4668
1416.79	4713.67
1414.91	4677.33
1413.03	4681.67
1411.15	4648
1409.27	4651.67
1407.39	4632
1405.51	4656.33
1403.63	4648.33
1401.75	4656.33
1399.86	4681.33
1397.98	4671.33
1396.09	4613
1394.21	4628.67
1392.32	4661.67
1390.44	4628.33
1388.55	4634
1386.66	4640.67
1384.77	4603.33
1382.88	4590.67
1380.99	4588.33
1379.1	4606
1377.21	4642
1375.31	4593.33
1373.42	4585.67
1371.53	4622.33
1369.63	4611
1367.74	4607
1365.84	4597.67
1363.94	4624.33
1362.05	4631.33
1360.15	4671
1358.25	4637.67
1356.35	4662.33
1354.45	4708.67
1352.55	4682.67
1350.64	4682.33
1348.74	4702.67
1346.84	4702
1344.93	4709
1343.03	4693.67
1341.12	4716.67
1339.22	4696.33
1337.31	4702.67
1335.4	4671.33
1333.49	4709
1331.58	4663.67
1329.67	4697.67
1327.76	4689
1325.85	4691.33
1323.94	4692
1322.03	4673.33
1320.11	4709.67
1318.2	4738
1316.28	4714.67
1314.37	4738.33
1312.45	4701
1310.53	4728.33
1308.62	4706.67
1306.7	4703.33
1304.78	4758
1302.86	4732
1300.94	4707.67
1299.01	4744
1297.09	4748
1295.17	4770.33
1293.24	4744
1291.32	4730
1289.39	4719.67
1287.47	4740.33
1285.54	4730
1283.61	4738.33
1281.68	4758.33
1279.76	4723
1277.83	4735.67
1275.9	4778.67
1273.96	4762.67
1272.03	4749.33
1270.1	4770.33
1268.17	4732.33
1266.23	4762.33
1264.3	4771.67
1262.36	4738.33
1260.42	4772
1258.49	4769
1256.55	4727.33
1254.61	4753.33
1252.67	4738.67
1250.73	4731.33
1248.79	4750
1246.85	4752
1244.91	4766.33
1242.96	4785.33
1241.02	4752
1239.07	4754.67
1237.13	4727.67
1235.18	4729.33
1233.24	4722.33
1231.29	4759.67
1229.34	4687.67
1227.39	4669
1225.44	4685
1223.49	4691
1221.54	4668.67
1219.59	4655.33
1217.63	4651.67
1215.68	4611.33
1213.73	4645.67
1211.77	4634.67
1209.81	4630.33
1207.86	4612.67
1205.9	4624.67
1203.94	4608
1201.98	4610.33
1200.02	4596
1198.06	4576.67
1196.1	4554.33
1194.14	4597
1192.18	4582.67
1190.21	4586.33
1188.25	4580
1186.29	4571
1184.32	4594.67
1182.35	4572
1180.39	4578.67
1178.42	4600.33
1176.45	4581.67
1174.48	4549.33
1172.51	4546
1170.54	4613
1168.57	4550.33
1166.6	4591.67
1164.62	4553
1162.65	4574
1160.67	4559
1158.7	4553.67
1156.72	4544.67
1154.74	4585.33
1152.77	4549.33
1150.79	4551
1148.81	4619.33
1146.83	4589.33
1144.85	4540.33
1142.87	4573.67
1140.88	4539.67
1138.9	4562.67
1136.92	4559.67
1134.93	4549.67
1132.95	4524.33
1130.96	4592.67
1128.97	4579
1126.99	4571.33
1125	4545
1123.01	4608.33
1121.02	4626.67
1119.03	4605.67
1117.04	4601.33
1115.04	4630
1113.05	4612.67
1111.06	4627.67
1109.06	4683
1107.07	4644.33
1105.07	4689.33
1103.08	4647.33
1101.08	4711.33
1099.08	4708.33
1097.08	4709
1095.08	4734.33
1093.08	4722.67
1091.08	4725.33
1089.08	4756.33
1087.07	4769
1085.07	4746
1083.06	4770.33
1081.06	4813
1079.05	4778.67
1077.05	4782.67
1075.04	4765.33
1073.03	4783
1071.02	4754
1069.01	4787
1067	4791
1064.99	4751.67
1062.98	4847.67
1060.96	4815.67
1058.95	4803
1056.93	4787.67
1054.92	4763.67
1052.9	4817.67
1050.89	4789.67
1048.87	4819
1046.85	4818.33
1044.83	4834
1042.81	4810.33
1040.79	4785.33
1038.77	4864.67
1036.75	4852
1034.72	4845.33
1032.7	4850.33
1030.67	4829.67
1028.65	4881
1026.62	4851.33
1024.59	4850.33
1022.57	4920.67
1020.54	4901.67
1018.51	4859.33
1016.48	4874
1014.45	4898
1012.42	4904
1010.38	4922.67
1008.35	4948.67
1006.32	4922
1004.28	4883.33
1002.24	4944
1000.21	4985
998.171	4970
996.133	5016.33
994.094	4970.67
992.054	5033
990.013	4980
987.972	5036.33
985.93	5029.67
983.888	5068.33
981.843	5075
979.799	5085.33
977.754	5099
975.708	5077
973.661	5143.67
971.614	5178
969.565	5191.67
967.516	5154
965.466	5220.67
963.415	5202
961.364	5223.33
959.312	5266
957.258	5257.33
955.204	5260.33
953.15	5280
951.094	5245.67
949.038	5251.67
946.98	5264.33
944.923	5253.67
942.864	5269.67
940.804	5235.33
938.744	5281.67
936.683	5253.33
934.621	5314.33
932.558	5284
930.495	5254
928.43	5211.67
926.365	5271.67
924.299	5298.67
922.233	5262.33
920.165	5273.33
918.096	5265
916.028	5262.67
913.957	5277.33
911.887	5275.33
909.815	5263.67
907.743	5244.67
905.669	5240.33
903.595	5251.33
901.521	5200.33
899.445	5208
897.369	5204.67
895.292	5207.67
893.214	5238
891.135	5243
889.055	5226.33
886.975	5224.33
884.894	5250
882.812	5285.33
880.729	5260.33
878.646	5266
876.561	5273.33
874.475	5333
872.389	5309
870.303	5380.33
868.215	5369.33
866.126	5316.33
864.037	5363
861.947	5370
859.856	5374.33
857.764	5399
855.671	5403.67
853.578	5403.67
851.484	5405.33
849.389	5407.33
847.293	5420
845.196	5410.33
843.099	5448.67
841	5406.33
838.901	5407.67
836.801	5433.67
834.701	5446.67
832.599	5441.33
830.496	5437.33
828.393	5427.33
826.29	5426.33
824.184	5435.67
822.079	5390.33
819.972	5380.67
817.865	5364.67
815.757	5325.33
813.648	5349.33
811.538	5357.33
809.428	5359
807.316	5346
805.204	5353.67
803.091	5363
800.977	5362.33
798.863	5346.33
796.747	5350.67
794.631	5307
792.513	5318.67
790.395	5352.33
788.276	5321.67
786.157	5334.33
784.036	5331
781.915	5292.67
779.793	5332.33
777.669	5302.33
775.546	5337
773.421	5300.33
771.296	5333.67
769.169	5308.33
767.042	5332.67
764.915	5364
762.786	5349
760.656	5406
758.526	5399.67
756.394	5406.67
754.262	5432.33
752.129	5438
749.995	5441.67
747.861	5456.67
745.725	5459.67
743.588	5502.33
741.452	5466
739.314	5437
737.175	5474
735.035	5455.67
732.895	5523.33
730.753	5496.67
728.611	5476.33
726.469	5480.67
724.324	5510
722.18	5450
720.034	5493.67
717.888	5511
715.741	5506.67
713.593	5458.67
711.444	5455
709.294	5451
707.144	5487.67
704.992	5473
702.84	5435.67
700.687	5439.67
698.533	5400.33
696.378	5372
694.222	5356.67
692.066	5350.67
689.909	5397
687.751	5369
685.592	5355
683.432	5310.67
681.271	5316.67
679.109	5335.33
676.947	5320
674.784	5338.33
672.62	5317.67
670.455	5353.67
668.289	5330
666.122	5346.33
663.955	5314
661.787	5355
659.618	5366.33
657.448	5332.67
655.277	5352.67
653.104	5356
650.932	5388
648.759	5402.33
646.584	5405.67
644.409	5379
642.233	5423.67
640.056	5437
637.879	5419
635.7	5437.67
633.52	5483
631.34	5445.67
629.159	5451.33
626.977	5420.33
624.794	5473
622.61	5482.33
620.426	5471.67
618.24	5519.33
616.054	5464.33
613.867	5449
611.679	5472
609.49	5440
607.301	5463.67
605.11	5459.67
602.919	5454
600.726	5397.67
598.532	5402.33
596.339	5378.33
594.144	5368
591.948	5366.67
589.751	5394
587.554	5330
585.355	5352
583.156	5332.67
580.956	5344.33
578.755	5324.67
576.553	5358
574.35	5287
572.147	5349.33
569.943	5325.67
567.737	5355.33
565.531	5312.67
563.323	5330
561.116	5321
558.907	5298.67
556.698	5325.67
554.487	5296.67
552.275	5351.33
550.063	5323.33
547.85	5303.67
545.636	5303
543.421	5361.67
541.206	5347
538.988	5335.33
536.771	5371.33
534.553	5337.33
532.333	5389.67
530.113	5380
527.892	5439.33
525.67	5396
523.447	5385.33
521.224	5379.67
518.999	5419.67
516.774	5398.67
514.548	5414.33
512.321	5368.33
510.093	5418.67
507.863	5379
505.634	5371
503.403	5360.67
501.172	5365
498.939	5337.67
496.705	5311.67
494.472	5326.33
492.237	5344.67
490.001	5298.33
487.764	5289.67
485.526	5268.33
483.287	5259
481.047	5261.33
478.807	5267.33
476.565	5263.67
474.324	5307.33
472.08	5282.33
469.837	5238.33
467.591	5307.33
465.346	5311.33
463.099	5267.33
460.852	5284
458.604	5317.33
456.354	5316
454.103	5333.33
451.852	5366
449.601	5360.67
447.348	5365.67
445.094	5360
442.84	5399.67
440.584	5348
438.327	5394
436.07	5398.33
433.812	5377.33
431.553	5410.33
429.293	5445
427.032	5449.33
424.77	5476
422.507	5494.33
420.244	5506
417.979	5514
415.714	5462.33
413.448	5469.67
411.18	5447.33
408.912	5506
406.643	5507.33
404.373	5482.67
402.102	5486.67
399.83	5454
397.558	5453
395.285	5450
393.01	5428.33
390.734	5389
388.458	5428.67
386.181	5425.33
383.903	5462
381.624	5450.33
379.345	5427.33
377.064	5429.33
374.782	5401.67
372.5	5439.33
370.216	5423.33
367.932	5406.67
365.646	5430.67
363.36	5459.67
361.073	5380.67
358.785	5432.33
356.496	5459.67
354.207	5433.33
351.915	5440.67
349.624	5432.67
347.331	5449.67
345.038	5469.33
342.743	5454.33
340.448	5454.67
338.152	5444
335.855	5435.67
333.556	5420.33
331.257	5481
328.958	5461.33
326.657	5463.33
324.355	5443.33
322.053	5469.33
319.749	5538
317.444	5555.67
315.139	5543.33
312.833	5557.67
310.526	5579.33
308.217	5544.33
305.908	5568.67
303.599	5600.67
301.288	5600.33
298.976	5609
296.663	5633
294.349	5625.33
292.035	5625.67
289.719	5689.67
287.403	5665.33
285.085	5665.33
282.767	5693.67
280.448	5702.33
278.128	5672.33
275.807	5705
273.485	5745.67
271.161	5740
268.837	5716
266.513	5700.33
264.187	5695.33
261.861	5718.33
259.533	5775
257.205	5771
254.875	5808.33
252.544	5777.33
250.213	5779.33
247.881	5803
245.548	5823
243.214	5850.33
240.879	5905.33
238.543	5913.33
236.206	5919.33
233.869	5970.33
231.53	5953.33
229.19	5985.67
226.849	6039.67
224.508	6059.33
222.165	6056.67
219.822	6114.33
217.478	6117
215.132	6164.67
212.785	6192
210.439	6213.67
208.091	6238.67
205.741	6288.33
203.391	6325.33
201.04	6356.33
198.688	6391
196.336	6436
193.982	6493.67
191.627	6544.33
189.271	6545.67
186.915	6605
184.557	6644.33
182.199	6624.33
179.84	6698
177.478	6719
175.117	6773.33
172.755	6822.67
170.392	6813
168.028	6915.33
165.662	6939
163.297	6958.67
160.929	6943
158.561	6963.33
156.193	7043.33
153.823	7105.67
151.452	7085.67
149.08	7184.33
146.707	7077.33
144.334	7174
141.959	7243.33
139.584	7302.67
137.207	7268.33
134.829	7362.67
132.451	7404
130.071	7528.67
127.692	7605
125.31	7617.33
122.927	7699
120.545	7807.33
118.16	7878.67
115.775	7986
113.388	8069
111.001	8200.33
108.613	8349.67
106.224	8523
103.834	8702
101.444	8860
99.052	9081
96.6594	9295
94.2649	9573.67
91.8705	9703.67
89.4743	10003
87.0781	10394.7
84.68	10734.3
82.282	11135.3
79.882	11557.3
77.4812	12129
75.0805	12935.7
72.6778	13853.3
70.2743	15164.3
67.8698	17097.7
65.4644	18679.3
63.0582	20122.3
60.651	21489.7
58.2419	22713.7
55.8328	24028.3
53.4229	25504.7
51.011	26930.3
48.5993	28682.3
46.1856	30748
43.772	33175.7
41.3565	36312.3
38.941	39824.7
36.5237	44394
34.1054	50288.3
31.6862	57361.3
29.2661	64524
26.8451	64524
24.4231	64524
22.0002	64524
19.5764	64524
17.1517	64524
14.7261	64524
12.2995	64524
9.87099	64524
7.44256	64524
5.01321	64524
2.58195	64524
0.14975	64524