File: projects/python/data/20231030/wristback_600_785 nm_10 s_1_2023_10_30_15_22_22_01.txt
#Sample=wristback
#Laser=785 nm
#Grating=600
#Exposition=10
#Accumulation=1
#Acquired=30.10.2023 15:22:22
2745.96	978
2743.18	968.667
2740.41	971
2737.63	998.667
2734.85	1017.33
2732.07	1021.33
2729.29	1049.67
2726.5	1069.67
2723.72	1064.67
2720.93	1065
2718.14	1055
2715.34	1060
2712.55	1074.67
2709.75	1088.67
2706.95	1095.33
2704.15	1118.67
2701.35	1129.33
2698.55	1125.33
2695.74	1148.67
2692.93	1164.33
2690.12	1181.67
2687.31	1207.67
2684.49	1191.67
2681.67	1214.67
2678.85	1220
2676.03	1203.33
2673.21	1226.67
2670.38	1224.33
2667.56	1229.67
2664.73	1238.33
2661.9	1236.67
2659.06	1259.33
2656.23	1274.67
2653.39	1298
2650.55	1313.67
2647.71	1322.33
2644.86	1360.67
2642.02	1350.67
2639.17	1383.33
2636.32	1388.67
2633.47	1398
2630.62	1435.67
2627.76	1429
2624.9	1445.67
2622.04	1448
2619.18	1449
2616.31	1468.33
2613.45	1468.33
2610.58	1480
2607.71	1485
2604.84	1505
2601.96	1490.33
2599.08	1508.33
2596.21	1516.33
2593.32	1524.33
2590.44	1544
2587.56	1568.33
2584.67	1569
2581.78	1609.33
2578.89	1621.67
2575.99	1629.67
2573.1	1638.67
2570.2	1640.67
2567.3	1681
2564.4	1674.33
2561.5	1687
2558.59	1713.67
2555.68	1706.67
2552.77	1740.67
2549.86	1765
2546.94	1779.67
2544.03	1770
2541.11	1788
2538.19	1814.33
2535.26	1840
2532.34	1845.33
2529.41	1870
2526.48	1881.67
2523.55	1882
2520.62	1892
2517.68	1877.33
2514.74	1911.33
2511.8	1896.67
2508.86	1956
2505.92	1948.33
2502.97	1962.67
2500.02	1948.33
2497.07	2003
2494.12	1998
2491.16	2023.67
2488.2	2011.67
2485.25	2062
2482.28	2050.33
2479.32	2073.33
2476.35	2081.67
2473.39	2109.33
2470.42	2126
2467.44	2135.33
2464.47	2148.33
2461.49	2171.67
2458.51	2167.33
2455.53	2217.33
2452.55	2229
2449.56	2233.33
2446.58	2214
2443.59	2250.67
2440.59	2275.67
2437.6	2286
2434.6	2312.33
2431.61	2328
2428.61	2339.33
2425.6	2348
2422.6	2356.67
2419.59	2396
2416.58	2440.67
2413.57	2422.33
2410.56	2438.33
2407.54	2445
2404.52	2461.33
2401.5	2489.67
2398.48	2485
2395.45	2522.33
2392.43	2534.67
2389.4	2554.33
2386.37	2559.33
2383.33	2575.33
2380.3	2600
2377.26	2595
2374.22	2635.67
2371.17	2672.67
2368.13	2647.67
2365.08	2675.67
2362.03	2709.33
2358.98	2742.33
2355.93	2740.67
2352.87	2754
2349.81	2740.67
2346.75	2758.33
2343.69	2795.67
2340.63	2771
2337.56	2811
2334.49	2798.67
2331.42	2826.67
2328.35	2835
2325.27	2882.33
2322.19	2884
2319.11	2897.67
2316.03	2924.67
2312.94	2929.67
2309.85	2953
2306.77	2953.67
2303.67	2978.67
2300.58	2989.33
2297.48	3016
2294.38	3030
2291.28	3054.67
2288.18	3069.67
2285.07	3080.67
2281.97	3103
2278.86	3134.33
2275.74	3117.67
2272.63	3150.33
2269.51	3150.67
2266.39	3159
2263.27	3213.67
2260.15	3201.33
2257.02	3195
2253.89	3221.33
2250.76	3217.33
2247.63	3278.33
2244.49	3265.67
2241.36	3304.67
2238.22	3327.67
2235.08	3315.67
2231.93	3309
2228.78	3367
2225.63	3357.33
2222.48	3368
2219.33	3403
2216.17	3411.33
2213.01	3417.67
2209.85	3424
2206.69	3425
2203.53	3425.33
2200.36	3457
2197.19	3481.33
2194.02	3490
2190.84	3528
2187.66	3525.33
2184.48	3548.33
2181.3	3525.33
2178.12	3567.33
2174.93	3599.67
2171.74	3630
2168.55	3634
2165.36	3657.33
2162.16	3688.33
2158.97	3719.33
2155.76	3719.67
2152.56	3751.67
2149.36	3768
2146.15	3792
2142.94	3819.67
2139.73	3783.67
2136.51	3838.33
2133.29	3829
2130.08	3858.33
2126.85	3875
2123.63	3877.33
2120.4	3895.67
2117.17	3860
2113.94	3921
2110.71	3874
2107.47	3954
2104.23	3949.33
2100.99	3980.67
2097.75	3966.67
2094.5	4007
2091.26	4029.67
2088.01	4027.33
2084.75	4053
2081.5	4091.33
2078.24	4098.67
2074.98	4127.67
2071.72	4146.67
2068.45	4189.67
2065.18	4179.67
2061.92	4204.67
2058.64	4270
2055.37	4250.67
2052.09	4277.67
2048.81	4270
2045.53	4255.67
2042.25	4306.33
2038.96	4318.33
2035.67	4379.33
2032.38	4387.67
2029.08	4361.33
2025.79	4368.67
2022.49	4376.33
2019.19	4365
2015.88	4426.67
2012.58	4428
2009.27	4416.33
2005.96	4440.67
2002.64	4460.67
1999.33	4500
1996.01	4513
1992.69	4538.67
1989.36	4553.33
1986.04	4576.33
1982.71	4607.67
1979.38	4608.33
1976.05	4621.33
1972.71	4639.67
1969.37	4660
1966.03	4727
1962.69	4807.67
1959.34	4766
1955.99	4749.67
1952.64	4780.67
1949.29	4780.67
1945.93	4815
1942.58	4838.67
1939.21	4875
1935.85	4901.33
1932.49	4876.67
1929.12	4964.67
1925.75	4957.67
1922.37	4965.67
1919	4974.67
1915.62	4954
1912.24	4932
1908.86	4973.67
1905.47	4999
1902.08	4961.67
1898.69	4974.67
1895.3	5024.33
1891.9	5041.67
1888.5	5073.33
1885.1	5075.33
1881.7	5106.67
1878.29	5092.33
1874.88	5082
1871.47	5086
1868.06	5110.67
1864.64	5119
1861.22	5163.67
1857.8	5184
1854.38	5199.67
1850.95	5231
1847.52	5240.33
1844.09	5231.33
1840.66	5262.33
1837.22	5267.67
1833.78	5297.67
1830.34	5319.67
1826.9	5313
1823.45	5315.67
1820	5330.67
1816.55	5380
1813.09	5450
1809.64	5455.67
1806.18	5407
1802.71	5405.67
1799.25	5488
1795.78	5477.33
1792.31	5464.33
1788.84	5500.33
1785.36	5553
1781.88	5493.33
1778.4	5534.67
1774.92	5546.67
1771.43	5546.33
1767.95	5553
1764.45	5553.33
1760.96	5571.33
1757.47	5583.67
1753.97	5582.67
1750.47	5614
1746.96	5651.33
1743.45	5629
1739.94	5647
1736.43	5671
1732.92	5682.33
1729.4	5711
1725.88	5711
1722.36	5747.67
1718.83	5767.67
1715.3	5818
1711.77	5843.67
1708.24	5842.33
1704.71	5863
1701.17	5884.33
1697.63	5903.67
1694.08	5977
1690.54	5966.33
1686.99	5986.67
1683.44	5987
1679.88	6046
1676.32	6016
1672.76	6029.33
1669.2	6055.67
1665.64	6050.33
1662.07	6089
1658.5	6087.67
1654.92	6144
1651.35	6114.67
1647.77	6105.33
1644.19	6148
1640.61	6111.33
1637.02	6161.67
1633.43	6176.67
1629.84	6172
1626.24	6139
1622.64	6123.33
1619.04	6184
1615.44	6122.67
1611.84	6164.67
1608.23	6189
1604.62	6174
1601	6177.67
1597.39	6213.33
1593.77	6195
1590.15	6197.67
1586.52	6209.67
1582.89	6219.67
1579.26	6211.33
1575.63	6237
1571.99	6249
1568.36	6313.67
1564.72	6275.33
1561.07	6332.67
1557.42	6339.67
1553.78	6320
1550.12	6348.67
1546.47	6292
1542.81	6351.33
1539.15	6362.67
1535.49	6346.33
1531.82	6340
1528.15	6375.67
1524.48	6314
1520.81	6341
1517.13	6358.33
1513.45	6353
1509.77	6313.33
1506.08	6311.67
1502.39	6340.67
1498.7	6310.33
1495.01	6326
1491.31	6364
1487.61	6367.67
1483.91	6352.33
1480.21	6365.67
1476.5	6397.33
1472.79	6380.67
1469.07	6416
1465.36	6463.67
1461.64	6456
1457.92	6468.67
1454.19	6454.33
1450.46	6489.33
1446.73	6487.67
1443	6402.33
1439.26	6471
1435.52	6445.33
1431.78	6388.33
1428.04	6395.67
1424.29	6402
1420.54	6393.67
1416.79	6383
1413.03	6414.33
1409.27	6394
1405.51	6357.33
1401.75	6357
1397.98	6380.33
1394.21	6397
1390.44	6365
1386.66	6347
1382.88	6315
1379.1	6306
1375.31	6358
1371.53	6344.67
1367.74	6326.67
1363.94	6325.67
1360.15	6380.67
1356.35	6439
1352.55	6447
1348.74	6412
1344.93	6407.33
1341.12	6446.67
1337.31	6404.67
1333.49	6411.33
1329.67	6422.33
1325.85	6431.67
1322.03	6433
1318.2	6445.33
1314.37	6447.67
1310.53	6411
1306.7	6457.33
1302.86	6412
1299.01	6437.33
1295.17	6450.33
1291.32	6463.67
1287.47	6442.33
1283.61	6487.33
1279.76	6431.67
1275.9	6475.33
1272.03	6456.33
1268.17	6500
1264.3	6490.67
1260.42	6461
1256.55	6440.33
1252.67	6491.33
1248.79	6445.33
1244.91	6465
1241.02	6475
1237.13	6465
1233.24	6464.33
1229.34	6405.33
1225.44	6398.67
1221.54	6418
1217.63	6377
1213.73	6384.33
1209.81	6377.67
1205.9	6370.33
1201.98	6349
1198.06	6347.67
1194.14	6352
1190.21	6307
1186.29	6325
1182.35	6344.33
1178.42	6361.33
1174.48	6323.33
1170.54	6305.67
1166.6	6304.67
1162.65	6282.33
1158.7	6272.67
1154.74	6297
1150.79	6327.67
1146.83	6299.33
1142.87	6321.67
1138.9	6317
1134.93	6315
1130.96	6299.67
1126.99	6261.67
1123.01	6353
1119.03	6372
1115.04	6395.33
1111.06	6388
1107.07	6474.33
1103.08	6422.67
1099.08	6502
1095.08	6506.33
1091.08	6567.67
1087.07	6541.67
1083.06	6591.33
1079.05	6596
1075.04	6584.33
1071.02	6569
1067	6646.33
1062.98	6627.33
1058.95	6658.67
1054.92	6592.67
1050.89	6621.33
1046.85	6609.67
1042.81	6666
1038.77	6671.33
1034.72	6726
1030.67	6637
1026.62	6744.33
1022.57	6699.67
1018.51	6734.33
1014.45	6754.67
1010.38	6807.33
1006.32	6862
1002.24	6834.33
998.171	6910.33
994.094	6906.33
990.013	6933.67
985.93	6954.67
981.843	7009
977.754	7061.67
973.661	7067.67
969.565	7192.33
965.466	7180.33
961.364	7224
957.258	7217
953.15	7270.67
949.038	7254
944.923	7264.33
940.804	7221.67
936.683	7296.33
932.558	7265.67
928.43	7284
924.299	7297.67
920.165	7289.67
916.028	7310.33
911.887	7257
907.743	7248.33
903.595	7232.33
899.445	7210
895.292	7177
891.135	7228
886.975	7186
882.812	7254.33
878.646	7254
874.475	7294
870.303	7355
866.126	7376.67
861.947	7402.33
857.764	7458
853.578	7465.33
849.389	7484.33
845.196	7457
841	7482.67
836.801	7522.33
832.599	7538.67
828.393	7497.33
824.184	7497.67
819.972	7478
815.757	7378.67
811.538	7431.33
807.316	7385
803.091	7420.67
798.863	7364.33
794.631	7360.67
790.395	7318.67
786.157	7336.67
781.915	7334.67
777.669	7305.33
773.421	7350.67
769.169	7397
764.915	7476.33
760.656	7503.33
756.394	7472.67
752.129	7489.67
747.861	7531.33
743.588	7558
739.314	7573
735.035	7612.67
730.753	7644
726.469	7602.67
722.18	7601.33
717.888	7621.67
713.593	7630.33
709.294	7567.33
704.992	7543.67
700.687	7511
696.378	7490
692.066	7466.33
687.751	7379.33
683.432	7428
679.109	7378
674.784	7407.67
670.455	7345
666.122	7366
661.787	7399.67
657.448	7386.67
653.104	7432.67
648.759	7483.33
644.409	7498
640.056	7574
635.7	7600
631.34	7574.33
626.977	7566.67
622.61	7636.33
618.24	7631
613.867	7586
609.49	7525.33
605.11	7504.67
600.726	7482.67
596.339	7452
591.948	7403.67
587.554	7430
583.156	7391
578.755	7373
574.35	7356.33
569.943	7390.67
565.531	7348.67
561.116	7401.67
556.698	7335.33
552.275	7328.33
547.85	7336.67
543.421	7309.33
538.988	7359.33
534.553	7371
530.113	7424.67
525.67	7456.33
521.224	7426.67
516.774	7497.33
512.321	7440.33
507.863	7451
503.403	7394
498.939	7431.33
494.472	7338.33
490.001	7299.33
485.526	7285.67
481.047	7250
476.565	7260.33
472.08	7245.67
467.591	7321
463.099	7278
458.604	7322.67
454.103	7327.67
449.601	7364.33
445.094	7308.67
440.584	7390.33
436.07	7352.33
431.553	7419.33
427.032	7462.33
422.507	7521
417.979	7520.67
413.448	7512
408.912	7494.33
404.373	7478.67
399.83	7471
395.285	7461.33
390.734	7410
386.181	7448.33
381.624	7389
377.064	7415
372.5	7409.33
367.932	7399
363.36	7342.33
358.785	7313
354.207	7391.33
349.624	7367.67
345.038	7416
340.448	7402.67
335.855	7411.33
331.257	7386.67
326.657	7410.67
322.053	7460
317.444	7502.67
312.833	7495.67
308.217	7532
303.599	7549.33
298.976	7576.33
294.349	7628.33
289.719	7618
285.085	7604.67
280.448	7652.33
275.807	7647
271.161	7647
266.513	7670
261.861	7700.67
257.205	7714.33
252.544	7651.67
247.881	7654.67
243.214	7791
238.543	7762.67
233.869	7888.33
229.19	7903.33
224.508	7844.67
219.822	7885.33
215.132	7994
210.439	8014.33
205.741	8081.33
201.04	8206
196.336	8312
191.627	8371
186.915	8372.67
182.199	8468.33
177.478	8531.33
172.755	8574.33
168.028	8699
163.297	8697.67
158.561	8788.33
153.823	8843.33
149.08	8811.67
144.334	8814
139.584	8912
134.829	9076.33
130.071	9117.67
125.31	9333
120.545	9438
115.775	9623.67
111.001	9857.33
106.224	10153.7
101.444	10476.7
96.6594	10848
91.8705	11382.3
87.0781	12003
82.282	12704.7
77.4812	13727.7
72.6778	15260.3
67.8698	18410.3
63.0582	21388.7
58.2419	23807.7
53.4229	26221.3
48.5993	29489
43.772	34164.7
38.941	41056.3
34.1054	51867.3
29.2661	64524
24.4231	64524
19.5764	64524
14.7261	64524
9.87099	64524
5.01321	64524
0.14975	64524
-4.71644	64524
-9.58634	64524
-14.461	64524
-19.3393	64524
-24.2214	64524
-29.1072	64524
-33.9977	64524
-38.892	44362.3
-43.7901	29865
-48.6919	22216.7
-53.5974	16924.3
-58.5078	13027.7
-63.4218	9996.33
-68.3397	7859.67
-73.2613	6123
-78.1878	4790
-83.117	3783.33
-88.051	3052.33
-92.9888	2495
-97.9314	2075.67
-102.877	1725.33
-107.827	1376.67
-112.781	1078.33
-117.739	905
-122.701	783
-127.667	655.333
-132.637	532.667
-137.612	451.333
-142.59	395.667
-147.572	353
-152.558	304.333
-157.548	276.667
-162.542	245.333
-167.541	230.667
-172.544	207.667
-177.55	206.667
-182.561	175.333
-187.576	185
-192.595	175.667
-197.617	180
-202.645	179
-207.676	165.667
-212.711	172.333
-217.75	157.667
-222.794	165.333
-227.842	153
-232.893	144.333
-237.949	144.333
-243.009	143
-248.073	137
-253.142	143
-258.214	137
-263.291	133
-268.371	123
-273.456	114.333
-278.545	124.333
-283.639	115
-288.735	119.333
-293.837	118
-298.943	110.667
-304.053	109
-309.166	108.667
-314.285	110.667
-319.408	99.3333
-324.534	92.3333
-329.665	104
-334.801	103
-339.94	96.6667
-345.083	92.6667
-350.231	93
-355.383	86
-360.539	89.3333
-365.699	86.6667
-370.864	90.6667
-376.033	84
-381.206	89.3333
-386.384	93.3333
-391.565	86
-396.751	85.3333
-401.941	84.3333
-407.136	87.6667
-412.334	76.3333
-417.537	80.3333
-422.745	82.6667
-427.956	76
-433.173	81.6667
-438.392	77.6667
-443.617	88
-448.846	77.6667
-454.078	66.3333
-459.317	74
-464.558	81.3333
-469.804	77.3333
-475.055	75.3333
-480.309	69
-485.568	74
-490.832	74
-496.099	68
-501.372	75.3333
-506.648	75.3333
-511.929	70
-517.215	70.3333
-522.504	59
-527.797	73.6667
-533.097	66.6667
-538.399	74.3333
-543.706	75.6667
-549.018	71.3333
-554.334	67
-559.654	69.3333
-564.979	70
-570.308	77.3333
-575.641	69.3333
-580.98	77.6667
-586.322	67.6667
-591.669	66.6667
-597.02	69.6667
-602.376	72.6667
-607.736	66.6667
-613.1	75
-618.47	80.6667
-623.843	75.3333
-629.222	73.3333
-634.603	81
-639.99	83
-645.382	70.3333
-650.779	69
-656.179	74
-661.583	74
-666.993	68.6667
-672.407	64
-677.825	75.6667
-683.248	74
-688.675	69
-694.108	78.6667
-699.544	71.6667
-704.985	69.6667
-710.431	76.6667
-715.88	57.3333
-721.335	70.3333
-726.795	63.3333
-732.258	70.6667
-737.727	75.3333
-743.2	77.3333
-748.678	78.3333
-754.159	72.3333
-759.646	72.3333
-765.138	73.6667
-770.633	75.3333
-776.133	75.6667
-781.638	65
-787.149	67
-792.663	72.6667
-798.181	75
-803.705	71.3333
-809.233	73
-814.766	75.6667
-820.304	73
-825.846	77.3333
-831.392	65.3333
-836.944	69
-842.499	72
-848.06	64.6667
-853.626	73.3333
-859.195	69
-864.77	78
-870.35	69
-875.934	77
-881.522	79
-887.116	68.6667
-892.714	78.3333
-898.317	74.6667
-903.924	74.6667
-909.537	74.3333
-915.153	79
-920.776	74
-926.401	77
-932.033	68.3333
-937.669	72.6667
-943.31	67.6667
-948.955	70.3333
-954.605	75.6667
-960.26	80
-965.92	71.3333
-971.584	79.3333
-977.254	77
-982.928	72.3333
-988.607	74.6667
-994.291	79
-999.979	75.3333
-1005.67	83.6667
-1011.37	76.3333
-1017.07	76
-1022.78	79
-1028.49	74
-1034.21	80
-1039.93	80.3333
-1045.66	81.3333
-1051.39	77.3333
-1057.13	84
-1062.87	85.3333
-1068.62	79.3333
-1074.37	84
-1080.12	79
-1085.89	83
-1091.65	79.6667
-1097.42	91
-1103.2	85.6667
-1108.98	91
-1114.77	78
-1120.56	92
-1126.35	83.6667
-1132.15	97
-1137.96	88.6667
-1143.77	100.667
-1149.58	104.667
-1155.4	100.333
-1161.23	102.667
-1167.06	117.333
-1172.89	138.667
-1178.73	182.667
-1184.58	241
-1190.43	274
-1196.28	319.333
-1202.14	359.333
-1208.01	435
-1213.88	488.333
-1219.75	555
-1225.63	660
-1231.52	747.333
-1237.41	867.333
-1243.3	1083.67
-1249.2	1938.33
-1255.11	2068.67
-1261.02	1868.33
-1266.93	1625.33
-1272.85	984.333
-1278.78	416.333
-1284.71	192.333
-1290.65	166
-1296.59	156.667
-1302.53	133.667
-1308.48	122.667
-1314.44	111.667
-1320.4	102.667
-1326.37	106
-1332.34	106.333
-1338.31	102.333
-1344.29	103
-1350.28	98.3333
-1356.27	104.333
-1362.27	88.3333
-1368.27	78.3333
-1374.28	69
-1380.29	70.3333
-1386.31	70.6667
-1392.33	66
-1057.13	84
-1062.87	85.3333
-1068.62	79.3333
-1074.37	84
-1080.12	79
-1085.89	83
-1091.65	79.6667
-1097.42	91
-1103.2	85.6667
-1108.98	91
-1114.77	78
-1120.56	92
-1126.35	83.6667
-1132.15	97
-1137.96	88.6667
-1143.77	100.667
-1149.58	104.667
-1155.4	100.333
-1161.23	102.667
-1167.06	117.333
-1172.89	138.667
-1178.73	182.667
-1184.58	241
-1190.43	274
-1196.28	319.333
-1202.14	359.333
-1208.01	435
-1213.88	488.333
-1219.75	555
-1225.63	660
-1231.52	747.333
-1237.41	867.333
-1243.3	1083.67
-1249.2	1938.33
-1255.11	2068.67
-1261.02	1868.33
-1266.93	1625.33
-1272.85	984.333
-1278.78	416.333
-1284.71	192.333
-1290.65	166
-1296.59	156.667
-1302.53	133.667
-1308.48	122.667
-1314.44	111.667
-1320.4	102.667
-1326.37	106
-1332.34	106.333
-1338.31	102.333
-1344.29	103
-1350.28	98.3333
-1356.27	104.333
-1362.27	88.3333
-1368.27	78.3333
-1374.28	69
-1380.29	70.3333
-1386.31	70.6667
-1392.33	66