File: projects/python/data/20231114-slide/middleblood_600_785 nm_30 s_1_2023_11_14_20_54_00_01.txt
#Sample=middleblood
#Laser=785 nm
#Grating=600
#Exposition=30
#Accumulation=1
#Acquired=14.11.2023 20:54:00
1568.95	5281
1567.13	5342
1565.31	5350
1563.49	5357
1561.66	5384
1559.84	5367
1558.02	5363
1556.19	5393
1554.37	5323
1552.54	5402
1550.72	5350
1548.89	5376
1547.06	5393
1545.23	5374
1543.41	5455
1541.58	5421
1539.75	5394
1537.92	5357
1536.08	5321
1534.25	5340
1532.42	5411
1530.58	5299
1528.75	5373
1526.91	5375
1525.08	5370
1523.24	5392
1521.4	5402
1519.57	5329
1517.73	5398
1515.89	5377
1514.05	5388
1512.21	5385
1510.37	5307
1508.52	5391
1506.68	5299
1504.84	5308
1502.99	5407
1501.15	5396
1499.3	5340
1497.46	5418
1495.61	5356
1493.76	5498
1491.91	5426
1490.07	5506
1488.22	5465
1486.36	5476
1484.51	5449
1482.66	5445
1480.81	5545
1478.96	5503
1477.1	5450
1475.25	5431
1473.39	5609
1471.54	5635
1469.68	5646
1467.82	5623
1465.96	5638
1464.1	5699
1462.24	5716
1460.38	5723
1458.52	5680
1456.66	5733
1454.8	5852
1452.94	5786
1451.07	5780
1449.21	5786
1447.34	5863
1445.48	5814
1443.61	5859
1441.74	5804
1439.87	5861
1438	5798
1436.14	5847
1434.26	5818
1432.39	5854
1430.52	5813
1428.65	5857
1426.78	5762
1424.9	5793
1423.03	5729
1421.15	5731
1419.28	5825
1417.4	5847
1415.52	5753
1413.65	5771
1411.77	5782
1409.89	5769
1408.01	5790
1406.13	5797
1404.24	5710
1402.36	5757
1400.48	5727
1398.59	5735
1396.71	5813
1394.82	5791
1392.94	5791
1391.05	5816
1389.16	5718
1387.28	5683
1385.39	5684
1383.5	5796
1381.61	5756
1379.72	5737
1377.83	5792
1375.93	5742
1374.04	5770
1372.15	5694
1370.25	5677
1368.36	5680
1366.46	5733
1364.56	5659
1362.67	5715
1360.77	5715
1358.87	5678
1356.97	5753
1355.07	5720
1353.17	5664
1351.27	5712
1349.36	5721
1347.46	5741
1345.56	5696
1343.65	5696
1341.75	5670
1339.84	5635
1337.93	5661
1336.03	5624
1334.12	5662
1332.21	5539
1330.3	5586
1328.39	5515
1326.48	5582
1324.56	5555
1322.65	5562
1320.74	5507
1318.82	5458
1316.91	5465
1314.99	5498
1313.08	5535
1311.16	5470
1309.24	5377
1307.32	5417
1305.4	5401
1303.48	5392
1301.56	5365
1299.64	5407
1297.72	5343
1295.8	5397
1293.87	5418
1291.95	5333
1290.02	5346
1288.1	5398
1286.17	5393
1284.24	5353
1282.32	5361
1280.39	5361
1278.46	5413
1276.53	5317
1274.6	5415
1272.66	5345
1270.73	5337
1268.8	5363
1266.86	5275
1264.93	5262
1262.99	5343
1261.06	5293
1259.12	5280
1257.18	5262
1255.24	5219
1253.31	5184
1251.36	5193
1249.42	5146
1247.48	5123
1245.54	5152
1243.6	5048
1241.65	5091
1239.71	5131
1237.76	5072
1235.82	5044
1233.87	4992
1231.93	4998
1229.98	4972
1228.03	4908
1226.08	4884
1224.13	4878
1222.18	4827
1220.23	4776
1218.27	4786
1216.32	4682
1214.36	4741
1212.41	4702
1210.45	4652
1208.5	4663
1206.54	4633
1204.58	4607
1202.62	4589
1200.67	4598
1198.7	4480
1196.74	4527
1194.78	4456
1192.82	4455
1190.86	4499
1188.89	4430
1186.93	4396
1184.96	4412
1183	4418
1181.03	4442
1179.06	4403
1177.09	4372
1175.13	4388
1173.16	4389
1171.18	4337
1169.21	4360
1167.24	4354
1165.27	4370
1163.29	4311
1161.32	4335
1159.34	4330
1157.37	4319
1155.39	4331
1153.41	4294
1151.44	4298
1149.46	4323
1147.48	4324
1145.5	4310
1143.52	4323
1141.53	4307
1139.55	4340
1137.57	4310
1135.58	4395
1133.6	4274
1131.61	4310
1129.62	4286
1127.64	4325
1125.65	4308
1123.66	4275
1121.67	4391
1119.68	4307
1117.69	4325
1115.7	4328
1113.7	4292
1111.71	4276
1109.72	4320
1107.72	4365
1105.73	4368
1103.73	4350
1101.73	4336
1099.73	4384
1097.74	4343
1095.74	4378
1093.73	4409
1091.73	4364
1089.73	4346
1087.73	4368
1085.73	4337
1083.72	4331
1081.72	4378
1079.71	4381
1077.7	4422
1075.7	4343
1073.69	4394
1071.68	4347
1069.67	4407
1067.66	4381
1065.65	4376
1063.64	4385
1061.62	4348
1059.61	4398
1057.59	4349
1055.58	4356
1053.56	4405
1051.55	4366
1049.53	4297
1047.51	4431
1045.49	4432
1043.47	4321
1041.45	4353
1039.43	4341
1037.41	4358
1035.39	4288
1033.36	4349
1031.34	4349
1029.31	4363
1027.29	4349
1025.26	4372
1023.23	4319
1021.2	4283
1019.17	4322
1017.14	4257
1015.11	4354
1013.08	4320
1011.05	4348
1009.02	4307
1006.98	4295
1004.95	4361
1002.91	4322
1000.88	4334
998.839	4444
996.801	4338
994.763	4365
992.723	4407
990.683	4373
988.642	4456
986.601	4419
984.557	4367
982.514	4432
980.47	4477
978.425	4456
976.379	4442
974.333	4498
972.286	4526
970.237	4581
968.189	4570
966.139	4505
964.089	4573
962.037	4523
959.985	4653
957.932	4561
955.878	4693
953.824	4629
951.768	4660
949.712	4563
947.656	4611
945.598	4615
943.539	4617
941.48	4644
939.42	4678
937.359	4680
935.298	4634
933.235	4651
931.172	4710
929.108	4783
927.043	4654
924.978	4627
922.911	4684
920.844	4659
918.775	4668
916.707	4677
914.637	4708
912.567	4684
910.495	4746
908.424	4704
906.351	4653
904.277	4682
902.202	4654
900.127	4687
898.05	4670
895.974	4591
893.896	4697
891.817	4709
889.739	4710
887.658	4641
885.577	4690
883.496	4645
881.413	4705
879.33	4649
877.245	4687
875.16	4717
873.075	4659
870.988	4781
868.9	4763
866.813	4688
864.723	4815
862.633	4748
860.542	4817
858.451	4796
856.358	4834
854.265	4834
852.172	4844
850.077	4869
847.981	4862
845.885	4823
843.787	4865
841.69	4828
839.591	4803
837.491	4887
835.391	4852
833.289	4899
831.187	4874
829.084	4896
826.981	4878
824.876	4826
822.771	4854
820.664	4811
818.558	4874
816.45	4831
814.341	4797
812.231	4835
810.121	4822
808.01	4831
805.898	4800
803.785	4803
801.672	4800
799.557	4827
797.442	4776
795.326	4738
793.208	4760
791.091	4814
788.973	4796
786.853	4768
784.733	4773
782.612	4820
780.49	4805
778.367	4776
776.244	4810
774.119	4865
771.994	4804
769.868	4881
767.741	4854
765.614	4929
763.485	4953
761.356	4910
759.226	4879
757.095	4949
754.962	4931
752.83	4959
750.697	4939
748.562	5018
746.426	4999
744.291	5030
742.154	4998
740.016	5004
737.878	5123
735.738	5100
733.598	5065
731.457	5057
729.315	5106
727.172	5052
725.029	5048
722.885	5087
720.74	5075
718.593	5049
716.446	5040
714.299	5052
712.15	5074
710.001	5000
707.851	5017
705.699	5016
703.547	5102
701.395	5037
699.241	4964
697.086	4989
694.931	5008
692.775	4959
690.618	4977
688.46	4950
686.301	4997
684.142	4930
681.981	4954
679.82	4913
677.657	4949
675.495	4981
673.331	5039
671.166	5009
669.001	4915
666.835	4963
664.667	5015
662.499	5060
660.33	5001
658.16	5002
655.99	5042
653.818	5012
651.646	4992
649.473	5139
647.299	5069
645.124	5107
642.948	5048
640.771	5134
638.595	5118
636.416	5139
634.237	5220
632.057	5196
629.876	5179
627.694	5191
625.512	5202
623.328	5252
621.144	5202
618.958	5244
616.773	5326
614.586	5247
612.398	5282
610.21	5229
608.02	5238
605.83	5241
603.639	5278
601.447	5205
599.254	5213
597.06	5319
594.865	5239
592.67	5219
590.473	5137
588.276	5311
586.078	5282
583.879	5190
581.68	5212
579.479	5263
577.277	5246
575.075	5223
572.872	5281
570.667	5270
568.462	5298
566.256	5325
564.049	5334
561.842	5283
559.633	5289
557.424	5347
555.214	5287
553.002	5331
550.79	5336
548.577	5357
546.364	5250
544.149	5338
541.934	5326
539.718	5348
537.5	5421
535.282	5399
533.063	5367
530.843	5453
528.622	5436
526.401	5423
524.179	5566
521.955	5544
519.731	5545
517.506	5544
515.28	5636
513.053	5585
510.825	5556
508.596	5593
506.367	5632
504.136	5606
501.906	5583
499.673	5578
497.44	5593
495.206	5630
492.972	5571
490.736	5586
488.499	5559
486.262	5541
484.023	5563
481.784	5600
479.544	5515
477.302	5552
475.061	5495
472.818	5520
470.574	5614
468.33	5562
466.084	5616
463.838	5520
461.591	5584
459.343	5565
457.094	5613
454.844	5666
452.592	5646
450.341	5662
448.089	5703
445.835	5705
443.581	5701
441.325	5711
439.069	5805
436.812	5722
434.554	5853
432.296	5819
430.036	5678
427.775	5811
425.514	5847
423.251	5839
420.988	5946
418.724	5821
416.459	5908
414.192	5934
411.926	5874
409.658	5865
407.389	5973
405.12	5898
402.849	5903
400.577	5875
398.305	5897
396.032	5919
393.758	5887
391.483	5924
389.207	5960
386.93	5907
384.652	5946
382.374	5914
380.094	5984
377.814	5966
375.532	5984
373.25	5981
370.967	5965
368.683	5994
366.397	6075
364.112	5988
361.825	6003
359.537	6021
357.249	6139
354.959	6060
352.669	5990
350.377	6038
348.085	6107
345.792	6116
343.498	6088
341.203	6109
338.907	6095
336.61	6164
334.313	6070
332.014	6182
329.714	6187
327.414	6172
325.112	6182
322.809	6225
320.506	6227
318.202	6226
315.897	6270
313.591	6345
311.284	6333
308.977	6346
306.667	6435
304.358	6391
302.048	6399
299.736	6409
297.424	6467
295.11	6574
292.796	6482
290.481	6494
288.164	6531
285.847	6636
283.529	6615
281.21	6701
278.89	6699
276.569	6770
274.248	6748
271.925	6822
269.601	6859
267.278	6940
264.952	6955
262.626	7042
260.298	7059
257.97	7108
255.641	7174
253.311	7126
250.98	7133
248.648	7278
246.315	7292
243.981	7293
241.647	7363
239.311	7425
236.974	7457
234.637	7554
232.298	7621
229.959	7614
227.618	7659
225.277	7797
222.935	7937
220.592	7953
218.248	8037
215.903	8236
213.557	8209
211.21	8409
208.862	8383
206.513	8603
204.164	8668
201.813	8793
199.462	8885
197.109	9036
194.755	9050
192.401	8912
190.045	9233
187.69	9437
185.333	9368
182.974	9357
180.615	9532
178.255	9615
175.894	9821
173.531	9896
171.169	9883
168.805	9978
166.44	10232
164.075	10341
161.708	10360
159.34	10364
156.971	10471
154.602	10622
152.231	10781
149.86	10794
147.487	10746
145.114	10820
142.74	10983
140.364	11417
137.988	11437
135.611	11559
133.232	11632
130.854	11656
128.473	11897
126.092	12259
123.71	12528
121.328	12712
118.944	12788
116.559	13067
114.173	13472
111.786	13742
109.398	13982
107.009	14508
104.62	14738
102.229	15030
99.8379	15617
97.4456	16117
95.0515	16852
92.6574	17489
90.2624	18181
87.8655	19011
85.4677	19789
83.07	20984
80.6704	22105
78.2698	23101
75.8694	24778
73.467	26647
71.0638	29028
68.6596	32317
66.2546	37115
63.8486	44931
61.4417	53668
59.0339	61014
56.6241	64524
54.2145	64524
51.8039	64524
49.3915	64524
46.9791	64524
44.5648	64524
42.1506	64524
39.7344	64524
37.3174	64524
34.8994	64524
32.4815	64524
30.0617	64524
27.641	64524
25.2193	64524
22.7968	64524
20.3733	64524
17.9488	64524
15.5225	64524
13.0962	64524
10.669	64524
8.23993	64524
5.81088	64524
3.37992	64524
0.949017	64524