File: projects/python/data/20231114-slide/middlenoblood_600_785 nm_30 s_1_2023_11_14_20_54_46_01.txt
#Sample=middlenoblood
#Laser=785 nm
#Grating=600
#Exposition=30
#Accumulation=1
#Acquired=14.11.2023 20:54:46
1568.95	6064
1567.13	6112
1565.31	6088
1563.49	6160
1561.66	6074
1559.84	6096
1558.02	6158
1556.19	6116
1554.37	6044
1552.54	6091
1550.72	6168
1548.89	6111
1547.06	6104
1545.23	6096
1543.41	6106
1541.58	6144
1539.75	6196
1537.92	6140
1536.08	6196
1534.25	6135
1532.42	6112
1530.58	6156
1528.75	6140
1526.91	6108
1525.08	6128
1523.24	6120
1521.4	6114
1519.57	6092
1517.73	6098
1515.89	6178
1514.05	6224
1512.21	6117
1510.37	6212
1508.52	6167
1506.68	6083
1504.84	6156
1502.99	6161
1501.15	6164
1499.3	6196
1497.46	6202
1495.61	6224
1493.76	6203
1491.91	6144
1490.07	6168
1488.22	6215
1486.36	6188
1484.51	6272
1482.66	6288
1480.81	6298
1478.96	6272
1477.1	6338
1475.25	6312
1473.39	6488
1471.54	6443
1469.68	6470
1467.82	6503
1465.96	6558
1464.1	6576
1462.24	6550
1460.38	6539
1458.52	6688
1456.66	6627
1454.8	6736
1452.94	6707
1451.07	6678
1449.21	6716
1447.34	6700
1445.48	6752
1443.61	6796
1441.74	6707
1439.87	6762
1438	6672
1436.14	6714
1434.26	6754
1432.39	6660
1430.52	6677
1428.65	6690
1426.78	6651
1424.9	6673
1423.03	6706
1421.15	6677
1419.28	6741
1417.4	6632
1415.52	6713
1413.65	6579
1411.77	6675
1409.89	6685
1408.01	6656
1406.13	6583
1404.24	6678
1402.36	6600
1400.48	6699
1398.59	6666
1396.71	6688
1394.82	6653
1392.94	6672
1391.05	6580
1389.16	6583
1387.28	6608
1385.39	6555
1383.5	6616
1381.61	6572
1379.72	6606
1377.83	6572
1375.93	6606
1374.04	6592
1372.15	6590
1370.25	6579
1368.36	6532
1366.46	6579
1364.56	6612
1362.67	6563
1360.77	6532
1358.87	6520
1356.97	6596
1355.07	6624
1353.17	6534
1351.27	6598
1349.36	6572
1347.46	6598
1345.56	6584
1343.65	6583
1341.75	6463
1339.84	6500
1337.93	6393
1336.03	6432
1334.12	6402
1332.21	6450
1330.3	6362
1328.39	6361
1326.48	6352
1324.56	6329
1322.65	6279
1320.74	6283
1318.82	6259
1316.91	6244
1314.99	6159
1313.08	6204
1311.16	6098
1309.24	6138
1307.32	6124
1305.4	6148
1303.48	6138
1301.56	6083
1299.64	6077
1297.72	6100
1295.8	6030
1293.87	6051
1291.95	6038
1290.02	5991
1288.1	5966
1286.17	5971
1284.24	5950
1282.32	5975
1280.39	5878
1278.46	5899
1276.53	5890
1274.6	5907
1272.66	5976
1270.73	5939
1268.8	5946
1266.86	5901
1264.93	5768
1262.99	5762
1261.06	5908
1259.12	5803
1257.18	5801
1255.24	5746
1253.31	5777
1251.36	5750
1249.42	5726
1247.48	5641
1245.54	5737
1243.6	5709
1241.65	5673
1239.71	5641
1237.76	5641
1235.82	5669
1233.87	5557
1231.93	5533
1229.98	5491
1228.03	5401
1226.08	5321
1224.13	5317
1222.18	5367
1220.23	5356
1218.27	5289
1216.32	5227
1214.36	5171
1212.41	5198
1210.45	5174
1208.5	5103
1206.54	5092
1204.58	5104
1202.62	5011
1200.67	4991
1198.7	4968
1196.74	4952
1194.78	4948
1192.82	4872
1190.86	4948
1188.89	4888
1186.93	4806
1184.96	4848
1183	4964
1181.03	4838
1179.06	4898
1177.09	4861
1175.13	4844
1173.16	4852
1171.18	4835
1169.21	4811
1167.24	4765
1165.27	4808
1163.29	4762
1161.32	4734
1159.34	4752
1157.37	4743
1155.39	4712
1153.41	4779
1151.44	4747
1149.46	4752
1147.48	4764
1145.5	4748
1143.52	4810
1141.53	4724
1139.55	4708
1137.57	4720
1135.58	4742
1133.6	4773
1131.61	4730
1129.62	4754
1127.64	4774
1125.65	4687
1123.66	4769
1121.67	4759
1119.68	4733
1117.69	4663
1115.7	4732
1113.7	4713
1111.71	4758
1109.72	4691
1107.72	4720
1105.73	4716
1103.73	4763
1101.73	4775
1099.73	4826
1097.74	4780
1095.74	4816
1093.73	4742
1091.73	4798
1089.73	4813
1087.73	4874
1085.73	4812
1083.72	4771
1081.72	4809
1079.71	4819
1077.7	4841
1075.7	4838
1073.69	4798
1071.68	4731
1069.67	4760
1067.66	4801
1065.65	4815
1063.64	4781
1061.62	4738
1059.61	4768
1057.59	4747
1055.58	4770
1053.56	4787
1051.55	4687
1049.53	4724
1047.51	4802
1045.49	4745
1043.47	4732
1041.45	4698
1039.43	4710
1037.41	4791
1035.39	4779
1033.36	4798
1031.34	4799
1029.31	4741
1027.29	4686
1025.26	4706
1023.23	4655
1021.2	4760
1019.17	4697
1017.14	4711
1015.11	4759
1013.08	4722
1011.05	4748
1009.02	4719
1006.98	4748
1004.95	4758
1002.91	4741
1000.88	4778
998.839	4760
996.801	4816
994.763	4799
992.723	4791
990.683	4761
988.642	4812
986.601	4844
984.557	4862
982.514	4828
980.47	4845
978.425	4854
976.379	4830
974.333	4911
972.286	4904
970.237	4955
968.189	4971
966.139	4955
964.089	5016
962.037	4978
959.985	5010
957.932	5058
955.878	4974
953.824	5130
951.768	5089
949.712	5073
947.656	5079
945.598	5061
943.539	5055
941.48	5071
939.42	5111
937.359	5064
935.298	5105
933.235	5112
931.172	5078
929.108	5066
927.043	5154
924.978	5073
922.911	5108
920.844	5091
918.775	5107
916.707	5081
914.637	5077
912.567	5086
910.495	5116
908.424	5116
906.351	5131
904.277	5107
902.202	5009
900.127	5100
898.05	5070
895.974	5052
893.896	5042
891.817	5051
889.739	5094
887.658	5079
885.577	5094
883.496	5067
881.413	5042
879.33	5115
877.245	5114
875.16	5097
873.075	5146
870.988	5213
868.9	5230
866.813	5217
864.723	5181
862.633	5205
860.542	5229
858.451	5219
856.358	5177
854.265	5255
852.172	5213
850.077	5205
847.981	5282
845.885	5149
843.787	5222
841.69	5269
839.591	5241
837.491	5321
835.391	5273
833.289	5245
831.187	5269
829.084	5307
826.981	5225
824.876	5219
822.771	5231
820.664	5255
818.558	5180
816.45	5187
814.341	5208
812.231	5170
810.121	5156
808.01	5174
805.898	5066
803.785	5192
801.672	5165
799.557	5132
797.442	5159
795.326	5131
793.208	5084
791.091	5131
788.973	5164
786.853	5152
784.733	5164
782.612	5114
780.49	5100
778.367	5082
776.244	5112
774.119	5162
771.994	5195
769.868	5148
767.741	5155
765.614	5266
763.485	5287
761.356	5218
759.226	5268
757.095	5216
754.962	5319
752.83	5246
750.697	5299
748.562	5298
746.426	5292
744.291	5304
742.154	5339
740.016	5348
737.878	5403
735.738	5402
733.598	5372
731.457	5426
729.315	5394
727.172	5410
725.029	5397
722.885	5400
720.74	5437
718.593	5357
716.446	5479
714.299	5369
712.15	5318
710.001	5447
707.851	5445
705.699	5450
703.547	5339
701.395	5401
699.241	5346
697.086	5303
694.931	5317
692.775	5352
690.618	5299
688.46	5333
686.301	5284
684.142	5285
681.981	5228
679.82	5290
677.657	5279
675.495	5258
673.331	5303
671.166	5256
669.001	5291
666.835	5264
664.667	5355
662.499	5308
660.33	5348
658.16	5304
655.99	5376
653.818	5340
651.646	5356
649.473	5440
647.299	5424
645.124	5442
642.948	5436
640.771	5516
638.595	5484
636.416	5450
634.237	5513
632.057	5510
629.876	5510
627.694	5522
625.512	5553
623.328	5687
621.144	5597
618.958	5543
616.773	5555
614.586	5579
612.398	5616
610.21	5651
608.02	5500
605.83	5612
603.639	5548
601.447	5632
599.254	5580
597.06	5538
594.865	5636
592.67	5536
590.473	5538
588.276	5590
586.078	5609
583.879	5566
581.68	5584
579.479	5659
577.277	5547
575.075	5589
572.872	5651
570.667	5622
568.462	5600
566.256	5654
564.049	5631
561.842	5608
559.633	5567
557.424	5676
555.214	5651
553.002	5616
550.79	5636
548.577	5722
546.364	5692
544.149	5720
541.934	5764
539.718	5762
537.5	5709
535.282	5808
533.063	5806
530.843	5826
528.622	5797
526.401	5893
524.179	5884
521.955	5857
519.731	5901
517.506	5941
515.28	5917
513.053	5916
510.825	5961
508.596	5995
506.367	6007
504.136	5951
501.906	5908
499.673	5957
497.44	5892
495.206	5912
492.972	5894
490.736	5970
488.499	5889
486.262	5940
484.023	5876
481.784	5971
479.544	5897
477.302	5859
475.061	5978
472.818	5924
470.574	5924
468.33	5929
466.084	5900
463.838	5953
461.591	5940
459.343	6034
457.094	6035
454.844	6042
452.592	5999
450.341	6094
448.089	6087
445.835	6108
443.581	6059
441.325	6178
439.069	6137
436.812	6158
434.554	6186
432.296	6154
430.036	6217
427.775	6315
425.514	6249
423.251	6289
420.988	6311
418.724	6263
416.459	6288
414.192	6301
411.926	6361
409.658	6350
407.389	6350
405.12	6326
402.849	6277
400.577	6317
398.305	6305
396.032	6267
393.758	6261
391.483	6265
389.207	6361
386.93	6301
384.652	6320
382.374	6331
380.094	6315
377.814	6365
375.532	6407
373.25	6312
370.967	6404
368.683	6366
366.397	6345
364.112	6414
361.825	6394
359.537	6422
357.249	6487
354.959	6411
352.669	6407
350.377	6495
348.085	6463
345.792	6462
343.498	6532
341.203	6588
338.907	6582
336.61	6540
334.313	6469
332.014	6538
329.714	6598
327.414	6569
325.112	6580
322.809	6679
320.506	6621
318.202	6653
315.897	6705
313.591	6638
311.284	6684
308.977	6751
306.667	6677
304.358	6829
302.048	6765
299.736	6808
297.424	6888
295.11	6961
292.796	6915
290.481	6959
288.164	7080
285.847	7024
283.529	7037
281.21	7104
278.89	7158
276.569	7248
274.248	7166
271.925	7309
269.601	7312
267.278	7409
264.952	7454
262.626	7475
260.298	7425
257.97	7522
255.641	7515
253.311	7533
250.98	7546
248.648	7689
246.315	7769
243.981	7856
241.647	7843
239.311	7931
236.974	8045
234.637	8123
232.298	8134
229.959	8240
227.618	8422
225.277	8349
222.935	8478
220.592	8519
218.248	8700
215.903	8823
213.557	8779
211.21	8911
208.862	9176
206.513	9316
204.164	9272
201.813	9388
199.462	9500
197.109	9702
194.755	9820
192.401	9802
190.045	9842
187.69	10134
185.333	10249
182.974	10272
180.615	10289
178.255	10501
175.894	10681
173.531	10715
171.169	10798
168.805	10833
166.44	10981
164.075	11225
161.708	11216
159.34	11307
156.971	11571
154.602	11803
152.231	11823
149.86	11792
147.487	11752
145.114	11978
142.74	12124
140.364	12382
137.988	12620
135.611	12582
133.232	12595
130.854	12810
128.473	13119
126.092	13504
123.71	13569
121.328	13798
118.944	14019
116.559	14396
114.173	14842
111.786	15207
109.398	15513
107.009	15938
104.62	16266
102.229	16635
99.8379	17412
97.4456	17883
95.0515	18651
92.6574	19457
90.2624	20164
87.8655	21058
85.4677	22110
83.07	23234
80.6704	24385
78.2698	25738
75.8694	27381
73.467	29303
71.0638	31687
68.6596	34873
66.2546	39575
63.8486	47397
61.4417	56316
59.0339	64028
56.6241	64524
54.2145	64524
51.8039	64524
49.3915	64524
46.9791	64524
44.5648	64524
42.1506	64524
39.7344	64524
37.3174	64524
34.8994	64524
32.4815	64524
30.0617	64524
27.641	64524
25.2193	64524
22.7968	64524
20.3733	64524
17.9488	64524
15.5225	64524
13.0962	64524
10.669	64524
8.23993	64524
5.81088	64524
3.37992	64524
0.949017	64524