File: projects/python/data/20231114-slide/noise_600_785 nm_30 s_1_2023_11_14_20_43_14_01.txt
#Sample=noise
#Laser=785 nm
#Grating=600
#Exposition=30
#Accumulation=1
#Acquired=14.11.2023 20:43:14
1568.95	39
1567.13	30
1565.31	27
1563.49	22
1561.66	39
1559.84	22
1558.02	35
1556.19	28
1554.37	29
1552.54	28
1550.72	31
1548.89	32
1547.06	46
1545.23	29
1543.41	36
1541.58	32
1539.75	30
1537.92	27
1536.08	33
1534.25	32
1532.42	26
1530.58	33
1528.75	30
1526.91	45
1525.08	30
1523.24	37
1521.4	33
1519.57	37
1517.73	25
1515.89	35
1514.05	35
1512.21	27
1510.37	31
1508.52	33
1506.68	26
1504.84	26
1502.99	40
1501.15	42
1499.3	35
1497.46	31
1495.61	37
1493.76	42
1491.91	37
1490.07	32
1488.22	38
1486.36	27
1484.51	23
1482.66	27
1480.81	32
1478.96	31
1477.1	32
1475.25	34
1473.39	30
1471.54	34
1469.68	32
1467.82	26
1465.96	41
1464.1	37
1462.24	29
1460.38	28
1458.52	37
1456.66	31
1454.8	23
1452.94	29
1451.07	38
1449.21	29
1447.34	32
1445.48	22
1443.61	47
1441.74	33
1439.87	27
1438	48
1436.14	31
1434.26	26
1432.39	33
1430.52	34
1428.65	26
1426.78	24
1424.9	27
1423.03	33
1421.15	35
1419.28	25
1417.4	32
1415.52	42
1413.65	31
1411.77	44
1409.89	25
1408.01	42
1406.13	29
1404.24	36
1402.36	34
1400.48	41
1398.59	33
1396.71	39
1394.82	30
1392.94	33
1391.05	33
1389.16	33
1387.28	36
1385.39	41
1383.5	21
1381.61	35
1379.72	43
1377.83	42
1375.93	29
1374.04	33
1372.15	26
1370.25	32
1368.36	27
1366.46	29
1364.56	37
1362.67	41
1360.77	36
1358.87	28
1356.97	37
1355.07	33
1353.17	35
1351.27	32
1349.36	30
1347.46	39
1345.56	37
1343.65	44
1341.75	36
1339.84	31
1337.93	38
1336.03	31
1334.12	30
1332.21	42
1330.3	36
1328.39	25
1326.48	38
1324.56	31
1322.65	25
1320.74	26
1318.82	33
1316.91	41
1314.99	28
1313.08	41
1311.16	35
1309.24	33
1307.32	47
1305.4	40
1303.48	37
1301.56	38
1299.64	31
1297.72	26
1295.8	46
1293.87	27
1291.95	53
1290.02	32
1288.1	35
1286.17	27
1284.24	24
1282.32	39
1280.39	28
1278.46	28
1276.53	26
1274.6	44
1272.66	30
1270.73	44
1268.8	38
1266.86	21
1264.93	30
1262.99	23
1261.06	36
1259.12	41
1257.18	39
1255.24	27
1253.31	28
1251.36	24
1249.42	51
1247.48	38
1245.54	40
1243.6	30
1241.65	28
1239.71	32
1237.76	47
1235.82	40
1233.87	29
1231.93	28
1229.98	34
1228.03	42
1226.08	34
1224.13	31
1222.18	34
1220.23	33
1218.27	37
1216.32	35
1214.36	36
1212.41	27
1210.45	41
1208.5	35
1206.54	40
1204.58	34
1202.62	28
1200.67	33
1198.7	14
1196.74	40
1194.78	29
1192.82	36
1190.86	29
1188.89	31
1186.93	30
1184.96	35
1183	26
1181.03	33
1179.06	36
1177.09	43
1175.13	22
1173.16	37
1171.18	49
1169.21	46
1167.24	30
1165.27	27
1163.29	39
1161.32	39
1159.34	35
1157.37	21
1155.39	40
1153.41	16
1151.44	44
1149.46	22
1147.48	33
1145.5	38
1143.52	34
1141.53	30
1139.55	37
1137.57	27
1135.58	39
1133.6	37
1131.61	31
1129.62	41
1127.64	22
1125.65	36
1123.66	39
1121.67	26
1119.68	21
1117.69	33
1115.7	28
1113.7	42
1111.71	23
1109.72	31
1107.72	37
1105.73	38
1103.73	21
1101.73	42
1099.73	32
1097.74	35
1095.74	35
1093.73	29
1091.73	25
1089.73	28
1087.73	24
1085.73	34
1083.72	35
1081.72	35
1079.71	22
1077.7	32
1075.7	29
1073.69	18
1071.68	30
1069.67	23
1067.66	30
1065.65	31
1063.64	31
1061.62	25
1059.61	26
1057.59	31
1055.58	50
1053.56	34
1051.55	37
1049.53	25
1047.51	30
1045.49	43
1043.47	33
1041.45	43
1039.43	39
1037.41	47
1035.39	40
1033.36	31
1031.34	34
1029.31	28
1027.29	34
1025.26	26
1023.23	36
1021.2	37
1019.17	40
1017.14	23
1015.11	33
1013.08	36
1011.05	39
1009.02	24
1006.98	34
1004.95	27
1002.91	32
1000.88	34
998.839	36
996.801	37
994.763	40
992.723	30
990.683	35
988.642	24
986.601	29
984.557	48
982.514	41
980.47	28
978.425	32
976.379	35
974.333	34
972.286	27
970.237	20
968.189	32
966.139	24
964.089	41
962.037	26
959.985	28
957.932	32
955.878	36
953.824	23
951.768	33
949.712	46
947.656	26
945.598	30
943.539	28
941.48	39
939.42	27
937.359	33
935.298	29
933.235	40
931.172	38
929.108	42
927.043	31
924.978	31
922.911	38
920.844	31
918.775	37
916.707	30
914.637	28
912.567	33
910.495	30
908.424	23
906.351	45
904.277	30
902.202	33
900.127	15
898.05	38
895.974	37
893.896	25
891.817	29
889.739	38
887.658	39
885.577	31
883.496	31
881.413	39
879.33	25
877.245	36
875.16	24
873.075	42
870.988	24
868.9	39
866.813	20
864.723	40
862.633	35
860.542	28
858.451	32
856.358	30
854.265	30
852.172	36
850.077	36
847.981	22
845.885	31
843.787	31
841.69	38
839.591	30
837.491	45
835.391	32
833.289	30
831.187	27
829.084	35
826.981	35
824.876	36
822.771	27
820.664	30
818.558	32
816.45	32
814.341	32
812.231	36
810.121	29
808.01	42
805.898	28
803.785	34
801.672	28
799.557	27
797.442	35
795.326	36
793.208	17
791.091	34
788.973	46
786.853	24
784.733	30
782.612	43
780.49	33
778.367	35
776.244	12
774.119	29
771.994	40
769.868	35
767.741	30
765.614	36
763.485	49
761.356	14
759.226	28
757.095	23
754.962	30
752.83	43
750.697	25
748.562	28
746.426	22
744.291	29
742.154	42
740.016	37
737.878	28
735.738	37
733.598	25
731.457	45
729.315	39
727.172	32
725.029	43
722.885	23
720.74	35
718.593	36
716.446	22
714.299	32
712.15	36
710.001	22
707.851	40
705.699	31
703.547	42
701.395	38
699.241	37
697.086	28
694.931	42
692.775	27
690.618	25
688.46	31
686.301	32
684.142	29
681.981	34
679.82	21
677.657	26
675.495	24
673.331	39
671.166	39
669.001	25
666.835	35
664.667	36
662.499	36
660.33	40
658.16	31
655.99	28
653.818	46
651.646	38
649.473	26
647.299	40
645.124	30
642.948	25
640.771	33
638.595	31
636.416	28
634.237	25
632.057	37
629.876	31
627.694	38
625.512	34
623.328	25
621.144	33
618.958	56
616.773	43
614.586	29
612.398	27
610.21	19
608.02	32
605.83	30
603.639	33
601.447	38
599.254	30
597.06	36
594.865	35
592.67	33
590.473	53
588.276	37
586.078	48
583.879	34
581.68	23
579.479	27
577.277	35
575.075	34
572.872	31
570.667	22
568.462	42
566.256	28
564.049	35
561.842	28
559.633	37
557.424	21
555.214	46
553.002	34
550.79	28
548.577	45
546.364	25
544.149	27
541.934	41
539.718	34
537.5	33
535.282	23
533.063	34
530.843	39
528.622	29
526.401	37
524.179	20
521.955	41
519.731	32
517.506	19
515.28	29
513.053	34
510.825	41
508.596	34
506.367	26
504.136	23
501.906	29
499.673	27
497.44	47
495.206	39
492.972	20
490.736	35
488.499	26
486.262	30
484.023	24
481.784	42
479.544	30
477.302	31
475.061	39
472.818	24
470.574	37
468.33	43
466.084	32
463.838	34
461.591	22
459.343	35
457.094	40
454.844	30
452.592	35
450.341	25
448.089	32
445.835	34
443.581	39
441.325	36
439.069	25
436.812	30
434.554	39
432.296	44
430.036	36
427.775	35
425.514	37
423.251	34
420.988	38
418.724	40
416.459	32
414.192	27
411.926	37
409.658	27
407.389	34
405.12	36
402.849	36
400.577	21
398.305	26
396.032	33
393.758	34
391.483	40
389.207	47
386.93	33
384.652	35
382.374	37
380.094	30
377.814	28
375.532	45
373.25	34
370.967	29
368.683	25
366.397	38
364.112	37
361.825	25
359.537	35
357.249	33
354.959	29
352.669	31
350.377	31
348.085	30
345.792	41
343.498	27
341.203	34
338.907	30
336.61	39
334.313	31
332.014	38
329.714	39
327.414	31
325.112	28
322.809	32
320.506	25
318.202	40
315.897	16
313.591	36
311.284	44
308.977	33
306.667	40
304.358	40
302.048	32
299.736	54
297.424	35
295.11	38
292.796	40
290.481	32
288.164	47
285.847	40
283.529	33
281.21	44
278.89	32
276.569	40
274.248	42
271.925	27
269.601	30
267.278	36
264.952	28
262.626	25
260.298	36
257.97	45
255.641	28
253.311	20
250.98	41
248.648	18
246.315	35
243.981	34
241.647	26
239.311	39
236.974	17
234.637	40
232.298	29
229.959	39
227.618	32
225.277	29
222.935	34
220.592	31
218.248	30
215.903	34
213.557	23
211.21	43
208.862	28
206.513	37
204.164	33
201.813	28
199.462	36
197.109	26
194.755	31
192.401	35
190.045	32
187.69	40
185.333	43
182.974	34
180.615	42
178.255	42
175.894	44
173.531	36
171.169	41
168.805	31
166.44	39
164.075	24
161.708	32
159.34	49
156.971	30
154.602	14
152.231	38
149.86	28
147.487	29
145.114	35
142.74	35
140.364	23
137.988	42
135.611	31
133.232	40
130.854	30
128.473	34
126.092	29
123.71	42
121.328	42
118.944	19
116.559	35
114.173	31
111.786	33
109.398	43
107.009	30
104.62	26
102.229	42
99.8379	31
97.4456	38
95.0515	31
92.6574	29
90.2624	23
87.8655	38
85.4677	49
83.07	44
80.6704	27
78.2698	32
75.8694	25
73.467	41
71.0638	28
68.6596	32
66.2546	26
63.8486	33
61.4417	37
59.0339	22
56.6241	36
54.2145	29
51.8039	23
49.3915	21
46.9791	37
44.5648	40
42.1506	41
39.7344	26
37.3174	33
34.8994	37
32.4815	36
30.0617	27
27.641	53
25.2193	25
22.7968	41
20.3733	42
17.9488	28
15.5225	33
13.0962	35
10.669	33
8.23993	33
5.81088	28
3.37992	25
0.949017	36